Workbook

Sheet COMO_USAR
A1: CONSTRUDATA ENGENHARIA | PLANILHA MESTRE SLNR SANTOS — COMO USAR | 20/03/2026
A3: ABA | B3: DESCRIÇÃO
A4: CRONO_MACRO | B4: Cronograma macro — controle de metros, equipes e datas por núcleo
A5: FATORES | B5: Fatores de composição de material (editável — amarelo)
A6: CUSTOS | B6: Preços unitários SINAPI/SABESP + premissas do contrato
A7: DIMENSIONAMENTO | B7: Equipes por setor (linkado ao CRONO_MACRO)
A8: PLEITO | B8: Pleito de acréscimo — análise financeira
A9: ADITIVOS | B9: Aditivos contratuais — 8 itens
A10: PRIMAVERA_P6 | B10: Exportação para MS Project / Primavera P6
A11: N07_NOROESTE | B11: Novos núcleos — Zona Noroeste (883LA + 2.113LE = 2.996 lig)
A12: N08_V_PROGRESSO | B12: Novos núcleos — Vila Progresso (585LA + 1.280LE = 1.865 lig)
A13: N09_Z_LESTE | B13: Novos núcleos — Zona Leste (480LA + 921LE = 1.401 lig)
A14: N10_CONJUNTO | B14: Novos núcleos — Conjunto (656LA + 1.016LE = 1.672 lig)
... A36: PEDIDO_URGENTE | B36: Pedido urgente 30 dias — R$4,2M (emitir AGORA)
A38: ⚙ PREMISSAS — editar estas células antes de usar
A39: PREMISSA | B39: VALOR ATUAL / INSTRUÇÃO
A40: M/Lig (metros por ligação) | B40: 2 — CRONO_MACRO F3 — mantido em 2 (vala compartilhada água+esgoto)
A41: R$/m (custo médio contrato) | B41: 910 — CRONO_MACRO H3 — atualizar se BDI mudar
A42: Produtividade padrão | B42: 6 m/eq/dia — Editável por equipe no CRONO_MACRO coluna K
B45: ABAS INTEGRADAS (v2 - 20/03/2026):
B46: PROJETO — Dados primários editáveis (azul). Fonte de TUDO.
B47: SALDO — Projeto - Executado. 100% fórmulas de PROJETO.
B48: MATERIAIS — Fatores (amarelo) × Saldo = QTD. Muda fator → muda tudo.
B49: COMPRAS_MENSAL — Projeção mensal por núcleo (fórmulas de MATERIAIS).
B50: PEDIDO_URGENTE — O que comprar nos próximos 30 dias.
B51: GANTT_COMPRAS — Visual de execução + compras.
B52: PRIMAVERA_P6 — Exportação para Oracle Primavera P6.
B54: CADEIA: PROJETO → SALDO → MATERIAIS → COMPRAS_MENSAL + PEDIDO_URGENTE
B55: Muda 1 metro em PROJETO → cascateia até o pedido de compras.
B57: ABAS DO CONSTRUDATA PLANEJADOR (integradas):
B58: PAINEL_EXECUTIVO — Dashboard geral do projeto (extensão, custos, progresso)
... B63: FORNECEDORES — Catálogo com contatos, leads e normas técnicas

Sheet PROJETO
A1: PROJETO — Dados primários | AZUL = editável | Todas as abas de compras puxam daqui
A2: Fonte: DXFs reais + SHP executado + campo | CT 11481051 R$241M | 20/03/2026
A4: NÚCLEO | B4: PROJ AG(m) | C4: PROJ ESG(m) | D4: PROJ TOTAL | E4: EXEC AG(m) | F4: EXEC ESG(m) | G4: EXEC TOTAL | H4: MESES REST | I4: EQUIPES | J4: FONTE
A5: SM+JC | B5: 6000 | C5: 6000 | D5: =B5+C5 | E5: 5749 | F5: 2057 | G5: =E5+F5 | H5: 4 | I5: 9 | J5: DXF + SHP
A6: ISRAEL | B6: 1900 | C6: 1900 | D6: =B6+C6 | E6: 1900 | F6: 1900 | G6: =E6+F6 | H6: 0 | I6: 4 | J6: DXF + SHP
A7: TETEU | B7: 5000 | C7: 5000 | D7: =B7+C7 | E7: 1000 | F7: 1000 | G7: =E7+F7 | H7: 5 | I7: 10 | J7: Campo ~2km
A8: CRIADORES | B8: 5000 | C8: 5000 | D8: =B8+C8 | E8: 3298 | F8: 424 | G8: =E8+F8 | H8: 5 | I8: 8 | J8: DXF + SHP
A9: PANTANAL | B9: 4000 | C9: 4000 | D9: =B9+C9 | E9: 252 | F9: 260 | G9: =E9+F9 | H9: 5 | I9: 8 | J9: DXF + SHP
A10: TOTAL | B10: =SUM(B5:B9) | C10: =SUM(C5:C9) | D10: =SUM(D5:D9) | E10: =SUM(E5:E9) | F10: =SUM(F5:F9) | G10: =SUM(G5:G9)

Sheet SALDO
A1: SALDO — Projeto - Executado | 100% fórmulas da aba PROJETO
A3: NÚCLEO | B3: SALDO AG | C3: SALDO ESG | D3: SALDO TOTAL | E3: % AG | F3: % ESG | G3: % TOTAL | H3: STATUS AG | I3: STATUS ESG | J3: MESES | K3: RITMO AG/mês | L3: RITMO ESG/mês
A4: =PROJETO!A5 | B4: =PROJETO!B5-PROJETO!E5 | C4: =PROJETO!C5-PROJETO!F5 | D4: =B4+C4 | E4: =IF(PROJETO!B5>0,PROJETO!E5/PROJETO!B5,1) | F4: =IF(PROJETO!C5>0,PROJETO!F5/PROJETO!C5,1) | G4: =IF(PROJETO!D5>0,PROJETO!G5/PROJETO!D5,1) | H4: =IF(E4>=1,"PRONTO",IF(E4>=0.9,"FINALIZANDO","EM EXECUÇÃO")) | I4: =IF(F4>=1,"PRONTO",IF(F4>=0.9,"FINALIZANDO","EM EXECUÇÃO")) | J4: =PROJETO!H5 | K4: =IF(J4>0,B4/J4,0) | L4: =IF(J4>0,C4/J4,0)
A5: =PROJETO!A6 | B5: =PROJETO!B6-PROJETO!E6 | C5: =PROJETO!C6-PROJETO!F6 | D5: =B5+C5 | E5: =IF(PROJETO!B6>0,PROJETO!E6/PROJETO!B6,1) | F5: =IF(PROJETO!C6>0,PROJETO!F6/PROJETO!C6,1) | G5: =IF(PROJETO!D6>0,PROJETO!G6/PROJETO!D6,1) | H5: =IF(E5>=1,"PRONTO",IF(E5>=0.9,"FINALIZANDO","EM EXECUÇÃO")) | I5: =IF(F5>=1,"PRONTO",IF(F5>=0.9,"FINALIZANDO","EM EXECUÇÃO")) | J5: =PROJETO!H6 | K5: =IF(J5>0,B5/J5,0) | L5: =IF(J5>0,C5/J5,0)
A6: =PROJETO!A7 | B6: =PROJETO!B7-PROJETO!E7 | C6: =PROJETO!C7-PROJETO!F7 | D6: =B6+C6 | E6: =IF(PROJETO!B7>0,PROJETO!E7/PROJETO!B7,1) | F6: =IF(PROJETO!C7>0,PROJETO!F7/PROJETO!C7,1) | G6: =IF(PROJETO!D7>0,PROJETO!G7/PROJETO!D7,1) | H6: =IF(E6>=1,"PRONTO",IF(E6>=0.9,"FINALIZANDO","EM EXECUÇÃO")) | I6: =IF(F6>=1,"PRONTO",IF(F6>=0.9,"FINALIZANDO","EM EXECUÇÃO")) | J6: =PROJETO!H7 | K6: =IF(J6>0,B6/J6,0) | L6: =IF(J6>0,C6/J6,0)
A7: =PROJETO!A8 | B7: =PROJETO!B8-PROJETO!E8 | C7: =PROJETO!C8-PROJETO!F8 | D7: =B7+C7 | E7: =IF(PROJETO!B8>0,PROJETO!E8/PROJETO!B8,1) | F7: =IF(PROJETO!C8>0,PROJETO!F8/PROJETO!C8,1) | G7: =IF(PROJETO!D8>0,PROJETO!G8/PROJETO!D8,1) | H7: =IF(E7>=1,"PRONTO",IF(E7>=0.9,"FINALIZANDO","EM EXECUÇÃO")) | I7: =IF(F7>=1,"PRONTO",IF(F7>=0.9,"FINALIZANDO","EM EXECUÇÃO")) | J7: =PROJETO!H8 | K7: =IF(J7>0,B7/J7,0) | L7: =IF(J7>0,C7/J7,0)
A8: =PROJETO!A9 | B8: =PROJETO!B9-PROJETO!E9 | C8: =PROJETO!C9-PROJETO!F9 | D8: =B8+C8 | E8: =IF(PROJETO!B9>0,PROJETO!E9/PROJETO!B9,1) | F8: =IF(PROJETO!C9>0,PROJETO!F9/PROJETO!C9,1) | G8: =IF(PROJETO!D9>0,PROJETO!G9/PROJETO!D9,1) | H8: =IF(E8>=1,"PRONTO",IF(E8>=0.9,"FINALIZANDO","EM EXECUÇÃO")) | I8: =IF(F8>=1,"PRONTO",IF(F8>=0.9,"FINALIZANDO","EM EXECUÇÃO")) | J8: =PROJETO!H9 | K8: =IF(J8>0,B8/J8,0) | L8: =IF(J8>0,C8/J8,0)
A9: TOTAL | B9: =SUM(B4:B8) | C9: =SUM(C4:C8) | D9: =SUM(D4:D8) | E9: =IF(PROJETO!B10>0,PROJETO!E10/PROJETO!B10,0) | F9: =IF(PROJETO!C10>0,PROJETO!F10/PROJETO!C10,0) | G9: =IF(PROJETO!D10>0,PROJETO!G10/PROJETO!D10,0)

Sheet CRONO_MACRO
A1: CRONOGRAMA MACRO — CONTROLE TOTAL SLNR SANTOS | M/Lig=2 | R$/m=910
A2: J=EQ (equipes) | K=PROD (m/eq/dia) | L=INI (mês início 1=Abr..10=Jan) | Cores: AMARELO=editável | VERDE=calculado
B3: PREMISSAS | E3: M/Lig | F3: 2 | G3: R$/m | H3: 910
B4: NUM MES → | M4: 1 | N4: 2 | O4: 3 | P4: 4 | Q4: 5 | R4: 6 | S4: 7 | T4: 8 | U4: 9 | V4: 10
B5: DIAS UTEIS → | M5: 18 | N5: 22 | O5: 22 | P5: 23 | Q5: 23 | R5: 21 | S5: 21 | T5: 18 | U5: 17 | V5: 21
B6: MESES → | M6: Abr | N6: Mai | O6: Jun | P6: Jul | Q6: Ago | R6: Set | S6: Out | T6: Nov | U6: Dez | V6: Jan/27
A7: ON | B7: Nucleo | C7: SETOR | D7: LA | E7: LE | F7: LIG_TOT | G7: METR_TOT | H7: Inicio | I7: Fim | J7: EQ | K7: PROD | L7: INI | M7: Abr (m) | N7: Mai (m) | O7: Jun (m) | P7: Jul (m) | Q7: Ago (m) | R7: Set (m) | S7: Out (m) | T7: Nov (m) | U7: Dez (m) | V7: Jan/27 (m) | W7: MET PLAN | X7: MET SALDO | Y7: CUSTO (R$) | Z7: PESSOAS
A8: 1 | B8: JOAO CARLOS | C8: SALDO | D8: 0 | E8: 350 | F8: =D8+E8 | G8: =F8*$F$3 | H8: 15/09/25 | I8: 30/04/26 | J8: 4 | K8: 6 | L8: 1 | M8: 432 | N8: 268 | O8: 0 | P8: 0 | Q8: 0 | R8: 0 | S8: 0 | T8: 0 | U8: 0 | V8: 0 | W8: 700 | X8: 0 | Y8: 637000 | Z8: 34
A9: 1 | B9: SAO MANOEL | C9: SALDO | D9: 200 | E9: 400 | F9: =D9+E9 | G9: =F9*$F$3 | H9: 10/09/25 | I9: 29/05/26 | J9: 5 | K9: 6 | L9: 1 | M9: 540 | N9: 660 | O9: 0 | P9: 0 | Q9: 0 | R9: 0 | S9: 0 | T9: 0 | U9: 0 | V9: 0 | W9: 1200 | X9: 0 | Y9: 1092000 | Z9: 42.5
A10: 1 | B10: VILA ISRAEL | C10: SALDO | D10: 150 | E10: 300 | F10: =D10+E10 | G10: =F10*$F$3 | H10: 04/08/25 | I10: 29/05/26 | J10: 4 | K10: 6 | L10: 1 | M10: 432 | N10: 468 | O10: 0 | P10: 0 | Q10: 0 | R10: 0 | S10: 0 | T10: 0 | U10: 0 | V10: 0 | W10: 900 | X10: 0 | Y10: 819000 | Z10: 34
A11: 1 | B11: MORRO DO TETEU | C11: SALDO | D11: 700 | E11: 800 | F11: =D11+E11 | G11: =F11*$F$3 | H11: 27/10/25 | I11: 31/07/26 | J11: 10 | K11: 6 | L11: 1 | M11: 1080 | N11: 1320 | O11: 600 | P11: 0 | Q11: 0 | R11: 0 | S11: 0 | T11: 0 | U11: 0 | V11: 0 | W11: 3000 | X11: 0 | Y11: 2730000 | Z11: 85
A12: 1 | B12: VILA CRIADORES | C12: SALDO | D12: 500 | E12: 600 | F12: =D12+E12 | G12: =F12*$F$3 | H12: 15/10/25 | I12: 31/07/26 | J12: 8 | K12: 6 | L12: 1 | M12: 864 | N12: 1056 | O12: 280 | P12: 0 | Q12: 0 | R12: 0 | S12: 0 | T12: 0 | U12: 0 | V12: 0 | W12: 2200 | X12: 0 | Y12: 2002000 | Z12: 68
A13: 1 | B13: PANTANAL BAIXO | C13: SALDO | D13: 623 | E13: 453 | F13: =D13+E13 | G13: =F13*$F$3 | H13: 20/10/25 | I13: 31/07/26 | J13: 8 | K13: 6 | L13: 1 | M13: 864 | N13: 1056 | O13: 232 | P13: 0 | Q13: 0 | R13: 0 | S13: 0 | T13: 0 | U13: 0 | V13: 0 | W13: 2152 | X13: 0 | Y13: 1958320 | Z13: 68
A14: 1 | B14: NOVO NUCLEO 07 | C14: ST-ZONA NOROESTE | D14: 883 | E14: 2113 | F14: =D14+E14 | G14: =F14*$F$3 | H14: 10/04/26 | I14: 24/09/26 | J14: 10 | K14: 6 | L14: 2 | M14: 0 | N14: 1320 | O14: 1320 | P14: 1380 | Q14: 1380 | R14: 592 | S14: 0 | T14: 0 | U14: 0 | V14: 0 | W14: 5992 | X14: 0 | Y14: 5452720 | Z14: 85
A15: 1 | B15: NOVO NUCLEO 08 | C15: ST-VILA PROGRESSO | D15: 585 | E15: 1280 | F15: =D15+E15 | G15: =F15*$F$3 | H15: 11/05/26 | I15: 23/10/26 | J15: 10 | K15: 6 | L15: 2 | M15: 0 | N15: 1320 | O15: 1320 | P15: 1090 | Q15: 0 | R15: 0 | S15: 0 | T15: 0 | U15: 0 | V15: 0 | W15: 3730 | X15: 0 | Y15: 3394300 | Z15: 85
A16: 1 | B16: NOVO NUCLEO 09 | C16: ST-ZONA LESTE | D16: 480 | E16: 921 | F16: =D16+E16 | G16: =F16*$F$3 | H16: 11/05/26 | I16: 12/10/26 | J16: 10 | K16: 6 | L16: 3 | M16: 0 | N16: 0 | O16: 1320 | P16: 1380 | Q16: 102 | R16: 0 | S16: 0 | T16: 0 | U16: 0 | V16: 0 | W16: 2802 | X16: 0 | Y16: 2549820 | Z16: 85
A17: 1 | B17: NOVO NUCLEO 10 | C17: ST-CONJUNTO | D17: 656 | E17: 1016 | F17: =D17+E17 | G17: =F17*$F$3 | H17: 03/08/26 | I17: 04/01/27 | J17: 10 | K17: 6 | L17: 5 | M17: 0 | N17: 0 | O17: 0 | P17: 0 | Q17: 1380 | R17: 1260 | S17: 704 | T17: 0 | U17: 0 | V17: 0 | W17: 3344 | X17: 0 | Y17: 3043040 | Z17: 85
A18: 1 | B18: NOVO NUCLEO 11 | C18: ALAGADO/DIQUE | D18: 638 | E18: 1224 | F18: =D18+E18 | G18: =F18*$F$3 | H18: 03/08/26 | I18: 04/01/27 | J18: 10 | K18: 6 | L18: 5 | M18: 0 | N18: 0 | O18: 0 | P18: 0 | Q18: 1380 | R18: 1260 | S18: 1084 | T18: 0 | U18: 0 | V18: 0 | W18: 3724 | X18: 0 | Y18: 3388840 | Z18: 85
A19: 1 | B19: NOVO NUCLEO 12 | C19: MONTANHOSO | D19: 4367 | E19: 6144 | F19: =D19+E19 | G19: =F19*$F$3 | H19: 03/08/26 | I19: 04/01/27 | J19: 15 | K19: 12 | L19: 5 | M19: 0 | N19: 0 | O19: 0 | P19: 0 | Q19: 4140 | R19: 3780 | S19: 3780 | T19: 3240 | U19: 3060 | V19: 3022 | W19: 21022 | X19: 0 | Y19: 19130020 | Z19: 127.5
B20: TOTAL METROS | D20: =SUM(D8:D19) | E20: =SUM(E8:E19) | F20: =SUM(F8:F19) | G20: =SUM(G8:G19) | J20: =SUM(J8:J19) | M20: =SUM(M8:M19) | N20: =SUM(N8:N19) | O20: =SUM(O8:O19) | P20: =SUM(P8:P19) | Q20: =SUM(Q8:Q19) | R20: =SUM(R8:R19) | S20: =SUM(S8:S19) | T20: =SUM(T8:T19) | ... Z20: =SUM(Z8:Z19)

Sheet FATORES
A1: FATORES DE COMPOSIÇÃO — ConstruData SLNR Santos | Editável (amarelo) → propaga para MATERIAIS e COMPRAS
A2: QTD = metros_faltantes × fator. Fonte: SINAPI + histórico SLNR. SM+JC usa DXF real (não usa fator genérico)
A3: MATERIAL | B3: TIPO | C3: UN | D3: FATOR/m | E3: PRAZO ENTREGA | F3: APLICA SOBRE | G3: CBUQ TIPO | H3: OBS
A4: Tubo PVC DN200 | B4: ESG | C4: m | D4: 0.6 | E4: 3 semanas | F4: FALTA ESG
A5: Tubo PVC DN300 | B5: ESG | C5: m | D5: 0.4 | E5: 3 semanas | F5: FALTA ESG | H5: Estoque: 200m
A6: PV concreto DN1200 | B6: ESG | C6: un | D6: 0.068 | E6: 2 semanas | F6: FALTA ESG
A7: PI plástico DN600 | B7: ESG | C7: un | D7: 0.022 | E7: 2 semanas | F7: FALTA ESG
A8: Caixa inspeção | B8: ESG | C8: un | D8: 0.055 | E8: 2 semanas | F8: FALTA ESG
A9: Tubo PEAD DN63 | B9: AG | C9: m | D9: 0.7 | E9: 4 semanas | F9: FALTA AG
A10: Tubo PEAD DN110 | B10: AG | C10: m | D10: 0.3 | E10: 4 semanas | F10: FALTA AG
A11: Sela eletrofusão | B11: AG | C11: un | D11: 0.022 | E11: 2 semanas | F11: FALTA AG
A12: Cavalete/hidrom. | B12: AG | C12: un | D12: 0.017 | E12: 3 semanas | F12: FALTA AG
A13: Conexões diversas | B13: AG | C13: vb | D13: 0.011 | E13: 2 semanas | F13: FALTA AG
A14: Areia | B14: GERAL | C14: m³ | D14: 0.25 | E14: 1 semana | F14: FALTA TOTAL | H14: Fundação de vala
A15: Berço | B15: GERAL | C15: m³ | D15: 0.24 | E15: 1 semana | F15: FALTA TOTAL | H15: Apoio do tubo
A16: Brita base | B16: GERAL | C16: m³ | D16: 0.22 | E16: 1 semana | F16: FALTA TOTAL
A17: Concreto | B17: GERAL | C17: m³ | D17: 0.18 | E17: 1 semana | F17: FALTA TOTAL
A18: CBUQ provisório | B18: GERAL | C18: m² | D18: 0.88 | E18: 2 semanas | F18: FALTA TOTAL | G18: PROVISÓRIO | H18: Tapa-buraco
A19: CBUQ definitivo | B19: GERAL | C19: m² | D19: 0.88 | E19: 3 semanas | F19: FALTA TOTAL | G19: DEFINITIVO | H19: Repavimentação final
A20: PEAD PE80 PN12.5 DN63 | B20: AG | C20: m | D20: 0.6503 | E20: 4 semanas | F20: FALTA AG
A21: PEAD PE80 PN12.5 DN160 | B21: AG | C21: m | D21: 0.3107 | E21: 4 semanas | F21: FALTA AG
A22: PEAD PE80 PN10 | B22: AG | C22: m | D22: 0.0026 | E22: 4 semanas | F22: FALTA AG
A23: PVC JE PBA DN20 | B23: AG | C23: m | D23: 0.0366 | E23: 3 semanas | F23: FALTA AG
A24: Sela eletrofusão | B24: AG | C24: un | D24: 0.022 | E24: 2 semanas | F24: FALTA AG
A25: Cavalete/hidrom. | B25: AG | C25: un | D25: 0.017 | E25: 3 semanas | F25: FALTA AG
A26: Conexões diversas | B26: AG | C26: vb | D26: 0.011 | E26: 2 semanas | F26: FALTA AG
A27: Areia | B27: GERAL | C27: m³ | D27: 0.25 | E27: 1 semana | F27: FALTA TOTAL
A28: Berço | B28: GERAL | C28: m³ | D28: 0.24 | E28: 1 semana | F28: FALTA TOTAL
A29: Brita base | B29: GERAL | C29: m³ | D29: 0.22 | E29: 1 semana | F29: FALTA TOTAL
A30: Concreto | B30: GERAL | C30: m³ | D30: 0.18 | E30: 1 semana | F30: FALTA TOTAL
A31: CBUQ provisório | B31: GERAL | C31: m² | D31: 0.88 | E31: 2 semanas | F31: FALTA TOTAL | G31: PROVISÓRIO
A32: CBUQ definitivo | B32: GERAL | C32: m² | D32: 0.88 | E32: 3 semanas | F32: FALTA TOTAL | G32: DEFINITIVO
A33: METROS FALTANTES POR NÚCLEO (atualizar com cadastro)
A34: NÚCLEO | B34: FALTA ESG(m) | C34: FALTA AG(m) | D34: FALTA TOTAL(m) | E34: MESES PROD | F34: REF CRONO
A35: SM+JC | B35: 0 | C35: 5759 | D35: 5759 | E35: 4 | F35: 8+9
A36: Vila Israel | B36: 734 | C36: 1191 | D36: 1925 | E36: 3 | F36: 10
A37: Morro do Tetéu | B37: 3997 | C37: 4696 | D37: 8693 | E37: 5 | F37: 11
A38: Vila Criadores | B38: 2633 | C38: 0 | D38: 2633 | E38: 5 | F38: 12
A39: Pantanal Baixo | B39: 3318 | C39: 3402 | D39: 6720 | E39: 5 | F39: 13

Sheet CUSTOS
A1: CUSTOS — ConstruData SLNR Santos | Contrato 11481051 | TODAS as composições
A3: PREMISSAS GERAIS
A4: Metros por ligação | B4: 2 | C4: m/lig | D4: Vala compartilhada água + esgoto
A5: Custo médio por metro | B5: 910 | C5: R$/m | D5: Média ponderada escav+tubo+PV+ramal+pavim+BDI
A6: BDI | B6: 0.25 | C6: % | D6: Sobre custos diretos
A7: Total ligações | B7: 25383 | C7: lig | D7: Soma de todos os núcleos
A8: Total metros | B8: =B7*B4 | C8: m | D8: Ligações × m/lig
A9: Custo total planejado | B9: =B8*B5 | C9: R$ | D9: Metros plan × R$/m
A10: PREÇOS UNITÁRIOS DE MATERIAIS
A11: MATERIAL | B11: TIPO | C11: UN | D11: PREÇO UNIT. (R$) | E11: FONTE | F11: DATA REF. | G11: VALIDADE | H11: OBS
A12: Tubo PVC DN200 | B12: ESG | C12: m | D12: 200.12 | E12: SINAPI/SABESP | F12: Mar/26 | G12: 90 dias
A13: Tubo PVC DN300 | B13: ESG | C13: m | D13: 310 | E13: SINAPI/SABESP | F13: Mar/26 | G13: 90 dias
A14: PV concreto DN1200 | B14: ESG | C14: un | D14: 3686 | E14: SINAPI/SABESP | F14: Mar/26 | G14: 90 dias
A15: PI plástico DN600 | B15: ESG | C15: un | D15: 1412 | E15: SINAPI/SABESP | F15: Mar/26 | G15: 90 dias
A16: Caixa inspeção | B16: ESG | C16: un | D16: 1034 | E16: SINAPI/SABESP | F16: Mar/26 | G16: 90 dias
A17: Tubo PEAD DN63 | B17: AG | C17: m | D17: 85 | E17: SINAPI/SABESP | F17: Mar/26 | G17: 90 dias
A18: Tubo PEAD DN110 | B18: AG | C18: m | D18: 101.8 | E18: SINAPI/SABESP | F18: Mar/26 | G18: 90 dias
A19: PEAD PE80 PN12.5 DN63 | B19: AG | C19: m | D19: 85 | E19: SINAPI/SABESP | F19: Mar/26 | G19: 90 dias | H19: SM+JC DXF
A20: PEAD PE80 PN12.5 DN160 | B20: AG | C20: m | D20: 145 | E20: SINAPI/SABESP | F20: Mar/26 | G20: 90 dias | H20: SM+JC DXF
A21: PEAD PE80 PN10 | B21: AG | C21: m | D21: 95 | E21: SINAPI/SABESP | F21: Mar/26 | G21: 90 dias
A22: PVC JE PBA DN20 | B22: AG | C22: m | D22: 42 | E22: SINAPI/SABESP | F22: Mar/26 | G22: 90 dias
A23: Sela eletrofusão | B23: AG | C23: un | D23: 660 | E23: SINAPI/SABESP | F23: Mar/26 | G23: 90 dias
A24: Cavalete/hidrom. | B24: AG | C24: un | D24: 490 | E24: SINAPI/SABESP | F24: Mar/26 | G24: 90 dias
A25: Conexões diversas | B25: AG | C25: vb | D25: 120 | E25: SINAPI/SABESP | F25: Mar/26 | G25: 90 dias | H25: Estimativa
A26: Areia | B26: GERAL | C26: m³ | D26: 160 | E26: SINAPI | F26: Mar/26 | G26: 30 dias | H26: Fundação
A27: Berço | B27: GERAL | C27: m³ | D27: 160 | E27: SINAPI | F27: Mar/26 | G27: 30 dias | H27: Apoio tubo
A28: Brita base | B28: GERAL | C28: m³ | D28: 210 | E28: SINAPI | F28: Mar/26 | G28: 30 dias
A29: Concreto | B29: GERAL | C29: m³ | D29: 720 | E29: SINAPI | F29: Mar/26 | G29: 30 dias | H29: fck 20 MPa
A30: CBUQ provisório | B30: GERAL | C30: m² | D30: 55 | E30: SINAPI | F30: Mar/26 | G30: 30 dias | H30: Tapa-buraco 3cm
A31: CBUQ definitivo | B31: GERAL | C31: m² | D31: 120 | E31: SINAPI | F31: Mar/26 | G31: 60 dias | H31: Repavim. 5cm
A32: CUSTO POR MATERIAL — A COMPRAR × PREÇO UNITÁRIO
A33: MATERIAL | B33: UN | C33: SALDO PROJETO | D33: A COMPRAR | E33: PREÇO UNIT.(R$) | F33: CUSTO COMPRA(R$) | G33: CUSTO C/ BDI(R$) | H33: % DO TOTAL
A34: Tubo PVC DN200 | B34: m | C34: 6409.2 | D34: 6409.2 | E34: 200.12 | F34: =D34*E34 | G34: =F34*(1+CUSTOS!$B$6) | H34: =IF(SUM(G34:G53)>0,G34/SUM(G34:G53),0)
A35: Tubo PVC DN300 | B35: m | C35: 4272.8 | D35: 4072.8 | E35: 310 | F35: =D35*E35 | G35: =F35*(1+CUSTOS!$B$6) | H35: =IF(SUM(G34:G53)>0,G35/SUM(G34:G53),0)
A36: PV concreto DN1200 | B36: un | C36: 726.376 | D36: 726.376 | E36: 3686 | F36: =D36*E36 | G36: =F36*(1+CUSTOS!$B$6) | H36: =IF(SUM(G34:G53)>0,G36/SUM(G34:G53),0)
A37: PI plástico DN600 | B37: un | C37: 235.004 | D37: 235.004 | E37: 1412 | F37: =D37*E37 | G37: =F37*(1+CUSTOS!$B$6) | H37: =IF(SUM(G34:G53)>0,G37/SUM(G34:G53),0)
A38: Caixa inspeção | B38: un | C38: 587.51 | D38: 587.51 | E38: 1034 | F38: =D38*E38 | G38: =F38*(1+CUSTOS!$B$6) | H38: =IF(SUM(G34:G53)>0,G38/SUM(G34:G53),0)
A39: Tubo PEAD DN63 | B39: m | C39: 6502.3 | D39: 6502.3 | E39: 85 | F39: =D39*E39 | G39: =F39*(1+CUSTOS!$B$6) | H39: =IF(SUM(G34:G53)>0,G39/SUM(G34:G53),0)
A40: Tubo PEAD DN110 | B40: m | C40: 2786.7 | D40: 2786.7 | E40: 101.8 | F40: =D40*E40 | G40: =F40*(1+CUSTOS!$B$6) | H40: =IF(SUM(G34:G53)>0,G40/SUM(G34:G53),0)
A41: PEAD PE80 PN12.5 DN63 | B41: m | C41: 3745.0777 | D41: 3745.0777 | E41: 85 | F41: =D41*E41 | G41: =F41*(1+CUSTOS!$B$6) | H41: =IF(SUM(G34:G53)>0,G41/SUM(G34:G53),0)
...

Sheet DIMENSIONAMENTO
A1: DIMENSIONAMENTO — Equipes por setor (linkado CRONO_MACRO)
A3: DIMENSIONAMENTO LINKADO
A4: NUCLEO | B4: SETOR | C4: LIG | D4: EQ | E4: PESSOAS | F4: CUSTO
A5: N07 | B5: ST-NOROESTE | C5: 2996 | D5: 10 | E5: =D5*8.5 | F5: =C5*CUSTOS!$B$4*CUSTOS!$B$5
A6: N08 | B6: ST-V.PROGRESSO | C6: 1865 | D6: 10 | E6: =D6*8.5 | F6: =C6*CUSTOS!$B$4*CUSTOS!$B$5
A7: N09 | B7: ST-Z.LESTE | C7: 1401 | D7: 10 | E7: =D7*8.5 | F7: =C7*CUSTOS!$B$4*CUSTOS!$B$5
A8: N10 | B8: ST-CONJUNTO | C8: 1672 | D8: 10 | E8: =D8*8.5 | F8: =C8*CUSTOS!$B$4*CUSTOS!$B$5
A9: N11 | B9: ALAGADO | C9: 1862 | D9: 10 | E9: =D9*8.5 | F9: =C9*CUSTOS!$B$4*CUSTOS!$B$5
A10: N12 | B10: MONTANHOSO | C10: 10511 | D10: 15 | E10: =D10*8.5 | F10: =C10*CUSTOS!$B$4*CUSTOS!$B$5
A11: TOTAL | C11: =SUM(C5:C10) | D11: =SUM(D5:D10) | E11: =SUM(E5:E10) | F11: =SUM(F5:F10)

Sheet PLEITO
A1: PLEITO — Acréscimo R$13,7M + aditivos
A3: PLEITO LINKADO
A4: INDICADOR | B4: CONTRATO | C4: REAL | D4: VALOR
A5: Produtividade | B5: 6.0 | C5: 0
A6: M/Ligacao | B6: 2.85 | C6: 0
A7: Total LIG | C7: 25383
A8: Total EQ | C8: 104
A9: Total CUSTO | D9: 50766
A10: Delta metragem | D10: R$ 9.140.812
A11: Delta produtividade | D11: R$ 4.570.406
A12: TOTAL PLEITO | D12: R$ 13.711.217
A13: Aditivos | D13: R$ 40.965.978
A14: GRANDE TOTAL | D14: R$ 64.589.554

Sheet ADITIVOS
A1: ADITIVOS — 8 itens + elevatórias
A3: ADITIVOS + ELEVATORIAS
A4: # | B4: Desc | C4: Un | D4: Qtd | E4: P.Unit | F4: Total
A5: AD-01 | B5: ESCADA CONCRETO | C5: M | D5: 900 | E5: 2856 | F5: =D5*E5
A6: AD-02 | B6: REDE ESG DN300 | C6: M | D6: 6000 | E6: 2350 | F6: =D6*E6
A7: AD-03 | B7: MND PEAD AGUA 160 | C7: M | D7: 3200 | E7: 1812.07 | F7: =D7*E7
A8: AD-04 | B8: MND PEAD ESG 315 | C8: M | D8: 1600 | E8: 3202.84 | F8: =D8*E8
A9: AD-05 | B9: PRA PEAD 150-200 | C9: M | D9: 6000 | E9: 1523.34 | F9: =D9*E9
A10: AD-07 | B10: TRANSPORTE RES | C10: UND | D10: 60 | E10: 9100 | F10: =D10*E10
A11: AD-08 | B11: SOLIDOS NAO REC | C11: KG | D11: 2430000 | E11: 1.2 | F11: =D11*E11
A12: AD-09 | B12: REATERRO HIDR | C12: M | D12: 3000 | E12: 256.79 | F12: =D12*E12
A13: EEE-1 | B13: EEE 82x50 (x2) | C13: CJ | D13: 2 | E13: 2284948.7 | F13: =D13*E13
A14: EEE-2 | B14: EEE 38x20 (x2) | C14: CJ | D14: 2 | E14: 1208730.7 | F14: =D14*E14
B15: TOTAL | F15: =SUM(F5:F14)

Sheet PRIMAVERA_P6
A1: PRIMAVERA P6 LINKADO - EQ e custo do CRONO_MACRO
A3: Act_ID | B3: WBS | C3: Activity | D3: Type | E3: Dur | F3: Start | G3: Finish | H3: Cal | I3: Cost | J3: Resource | K3: EQ | L3: LIG | M3: Notes
A4: A2000 | B4: S7.NOR.010524.PRJ | C4: PRJ Vila Alemoa | D4: TaskDep | E4: 15 | F4: 10/04/26 | H4: 5d/w | I4: 614578 | J4: Eng.Proj | K4: 1 | L4: 0
A5: A2010 | B5: S7.NOR.010524.EXE | C5: EXE Vila Alemoa | D5: TaskDep | E5: =IFERROR(ROUND(1407*CRONO_MACRO!$F$4/(CRONO_MACRO!J14/CRONO_MACRO!F14*1407*CRONO_MACRO!$D$4),0),0) | F5: 10/04/26 | G5: 24/09/26 | H5: 5d/w | I5: 6529887 | J5: Eq.Campo | K5: =IFERROR(ROUND(CRONO_MACRO!J14*1407/CRONO_MACRO!F14,0),0) | L5: 1407 | M5: 1407lig
A6: A2020 | B6: S7.NOR.010524.ASB | C6: ASB Vila Alemoa | D6: TaskDep | E6: 10 | G6: 24/09/26 | H6: 5d/w | I6: 614578 | J6: Eng.Asb | K6: 1 | L6: 0
A7: A2100 | B7: S7.NOR.010518.PRJ | C7: PRJ Ilheu Baixo | D7: TaskDep | E7: 15 | F7: 10/04/26 | H7: 5d/w | I7: 295277 | J7: Eng.Proj | K7: 1 | L7: 0
A8: A2110 | B8: S7.NOR.010518.EXE | C8: EXE Ilheu Baixo | D8: TaskDep | E8: =IFERROR(ROUND(676*CRONO_MACRO!$F$4/(CRONO_MACRO!J14/CRONO_MACRO!F14*676*CRONO_MACRO!$D$4),0),0) | F8: 10/04/26 | G8: 24/09/26 | H8: 5d/w | I8: 3137316 | J8: Eq.Campo | K8: =IFERROR(ROUND(CRONO_MACRO!J14*676/CRONO_MACRO!F14,0),0) | L8: 676 | M8: 676lig
A9: A2120 | B9: S7.NOR.010518.ASB | C9: ASB Ilheu Baixo | D9: TaskDep | E9: 10 | G9: 24/09/26 | H9: 5d/w | I9: 295277 | J9: Eng.Asb | K9: 1 | L9: 0
A10: A2200 | B10: S7.NOR.010522.PRJ | C10: PRJ NSRA Fatima | D10: TaskDep | E10: 15 | F10: 10/04/26 | H10: 5d/w | I10: 114005 | J10: Eng.Proj | K10: 1 | L10: 0
A11: A2210 | B11: S7.NOR.010522.EXE | C11: EXE NSRA Fatima | D11: TaskDep | E11: =IFERROR(ROUND(261*CRONO_MACRO!$F$4/(CRONO_MACRO!J14/CRONO_MACRO!F14*261*CRONO_MACRO!$D$4),0),0) | F11: 10/04/26 | G11: 24/09/26 | H11: 5d/w | I11: 1211301 | J11: Eq.Campo | K11: =IFERROR(ROUND(CRONO_MACRO!J14*261/CRONO_MACRO!F14,0),0) | L11: 261 | M11: 261lig
A12: A2220 | B12: S7.NOR.010522.ASB | C12: ASB NSRA Fatima | D12: TaskDep | E12: 10 | G12: 24/09/26 | H12: 5d/w | I12: 114005 | J12: Eng.Asb | K12: 1 | L12: 0
A13: A2300 | B13: S7.NOR.010526.PRJ | C13: PRJ Vila Telma | D13: TaskDep | E13: 15 | F13: 10/04/26 | H13: 5d/w | I13: 83429 | J13: Eng.Proj | K13: 1 | L13: 0
A14: A2310 | B14: S7.NOR.010526.EXE | C14: EXE Vila Telma | D14: TaskDep | E14: =IFERROR(ROUND(191*CRONO_MACRO!$F$4/(CRONO_MACRO!J14/CRONO_MACRO!F14*191*CRONO_MACRO!$D$4),0),0) | F14: 10/04/26 | G14: 24/09/26 | H14: 5d/w | I14: 886431 | J14: Eq.Campo | K14: =IFERROR(ROUND(CRONO_MACRO!J14*191/CRONO_MACRO!F14,0),0) | L14: 191 | M14: 191lig
A15: A2320 | B15: S7.NOR.010526.ASB | C15: ASB Vila Telma | D15: TaskDep | E15: 10 | G15: 24/09/26 | H15: 5d/w | I15: 83429 | J15: Eng.Asb | K15: 1 | L15: 0
A16: A2400 | B16: S7.NOR.010525.PRJ | C16: PRJ V.Alemoa Rem | D16: TaskDep | E16: 15 | F16: 10/04/26 | H16: 5d/w | I16: 43680 | J16: Eng.Proj | K16: 1 | L16: 0
A17: A2410 | B17: S7.NOR.010525.EXE | C17: EXE V.Alemoa Rem | D17: TaskDep | E17: =IFERROR(ROUND(100*CRONO_MACRO!$F$4/(CRONO_MACRO!J14/CRONO_MACRO!F14*100*CRONO_MACRO!$D$4),0),0) | F17: 10/04/26 | G17: 24/09/26 | H17: 5d/w | I17: 464100 | J17: Eq.Campo | K17: =IFERROR(ROUND(CRONO_MACRO!J14*100/CRONO_MACRO!F14,0),0) | L17: 100 | M17: 100lig
A18: A2420 | B18: S7.NOR.010525.ASB | C18: ASB V.Alemoa Rem | D18: TaskDep | E18: 10 | G18: 24/09/26 | H18: 5d/w | I18: 43680 | J18: Eng.Asb | K18: 1 | L18: 0
A19: A2500 | B19: S7.NOR.010521.PRJ | C19: PRJ Lote L Chico | D19: TaskDep | E19: 15 | F19: 10/04/26 | H19: 5d/w | I19: 41933 | J19: Eng.Proj | K19: 1 | L19: 0
A20: A2510 | B20: S7.NOR.010521.EXE | C20: EXE Lote L Chico | D20: TaskDep | E20: =IFERROR(ROUND(96*CRONO_MACRO!$F$4/(CRONO_MACRO!J14/CRONO_MACRO!F14*96*CRONO_MACRO!$D$4),0),0) | F20: 10/04/26 | G20: 24/09/26 | H20: 5d/w | I20: 445536 | J20: Eq.Campo | K20: =IFERROR(ROUND(CRONO_MACRO!J14*96/CRONO_MACRO!F14,0),0) | L20: 96 | M20: 96lig
A21: A2520 | B21: S7.NOR.010521.ASB | C21: ASB Lote L Chico | D21: TaskDep | E21: 10 | G21: 24/09/26 | H21: 5d/w | I21: 41933 | J21: Eng.Asb | K21: 1 | L21: 0
A22: A2600 | B22: S7.NOR.010523.PRJ | C22: PRJ V.Alemoa COHAB | D22: TaskDep | E22: 15 | F22: 10/04/26 | H22: 5d/w | I22: 34070 | J22: Eng.Proj | K22: 1 | L22: 0
A23: A2610 | B23: S7.NOR.010523.EXE | C23: EXE V.Alemoa COHAB | D23: TaskDep | E23: =IFERROR(ROUND(78*CRONO_MACRO!$F$4/(CRONO_MACRO!J14/CRONO_MACRO!F14*78*CRONO_MACRO!$D$4),0),0) | F23: 10/04/26 | G23: 24/09/26 | H23: 5d/w | I23: 361998 | J23: Eq.Campo | K23: =IFERROR(ROUND(CRONO_MACRO!J14*78/CRONO_MACRO!F14,0),0) | L23: 78 | M23: 78lig
A24: A2620 | B24: S7.NOR.010523.ASB | C24: ASB V.Alemoa COHAB | D24: TaskDep | E24: 10 | G24: 24/09/26 | H24: 5d/w | I24: 34070 | J24: Eng.Asb | K24: 1 | L24: 0
A25: A2700 | B25: S7.NOR.010520.PRJ | C25: PRJ Joao Barro | D25: TaskDep | E25: 15 | F25: 10/04/26 | H25: 5d/w | I25: 38002 | J25: Eng.Proj | K25: 1 | L25: 0
A26: A2710 | B26: S7.NOR.010520.EXE | C26: EXE Joao Barro | D26: TaskDep | E26: =IFERROR(ROUND(87*CRONO_MACRO!$F$4/(CRONO_MACRO!J14/CRONO_MACRO!F14*87*CRONO_MACRO!$D$4),0),0) | F26: 10/04/26 | G26: 24/09/26 | H26: 5d/w | I26: 403767 | J26: Eq.Campo | K26: =IFERROR(ROUND(CRONO_MACRO!J14*87/CRONO_MACRO!F14,0),0) | L26: 87 | M26: 87lig
A27: A2720 | B27: S7.NOR.010520.ASB | C27: ASB Joao Barro | D27: TaskDep | E27: 10 | G27: 24/09/26 | H27: 5d/w | I27: 38002 | J27: Eng.Asb | K27: 1 | L27: 0
A28: A2800 | B28: S7.NOR.010515.PRJ | C28: PRJ Saboo II | D28: TaskDep | E28: 15 | F28: 10/04/26 | H28: 5d/w | I28: 37565 | J28: Eng.Proj | K28: 1 | L28: 0
A29: A2810 | B29: S7.NOR.010515.EXE | C29: EXE Saboo II | D29: TaskDep | E29: =IFERROR(ROUND(86*CRONO_MACRO!$F$4/(CRONO_MACRO!J14/CRONO_MACRO!F14*86*CRONO_MACRO!$D$4),0),0) | F29: 10/04/26 | G29: 24/09/26 | H29: 5d/w | I29: 399126 | J29: Eq.Campo | K29: =IFERROR(ROUND(CRONO_MACRO!J14*86/CRONO_MACRO!F14,0),0) | L29: 86 | M29: 86lig
A30: A2820 | B30: S7.NOR.010515.ASB | C30: ASB Saboo II | D30: TaskDep | E30: 10 | G30: 24/09/26 | H30: 5d/w | I30: 37565 | J30: Eng.Asb | K30: 1 | L30: 0
A31: A2900 | B31: S7.NOR.010517.PRJ | C31: PRJ Fav.Butanta | D31: TaskDep | E31: 15 | F31: 10/04/26 | H31: 5d/w | I31: 6115 | J31: Eng.Proj | K31: 1 | L31: 0
A32: A2910 | B32: S7.NOR.010517.EXE | C32: EXE Fav.Butanta | D32: TaskDep | E32: =IFERROR(ROUND(14*CRONO_MACRO!$F$4/(CRONO_MACRO!J14/CRONO_MACRO!F14*14*CRONO_MACRO!$D$4),0),0) | F32: 10/04/26 | G32: 24/09/26 | H32: 5d/w | I32: 64974 | J32: Eq.Campo | K32: =IFERROR(ROUND(CRONO_MACRO!J14*14/CRONO_MACRO!F14,0),0) | L32: 14 | M32: 14lig
A33: A2920 | B33: S7.NOR.010517.ASB | C33: ASB Fav.Butanta | D33: TaskDep | E33: 10 | G33: 24/09/26 | H33: 5d/w | I33: 6115 | J33: Eng.Asb | K33: 1 | L33: 0
A34: A3000 | B34: S8.VPR.010502.PRJ | C34: PRJ R Um N.Cintra | D34: TaskDep | E34: 15 | F34: 11/05/26 | H34: 5d/w | I34: 304013 | J34: Eng.Proj | K34: 1 | L34: 0
A35: A3010 | B35: S8.VPR.010502.EXE | C35: EXE R Um N.Cintra | D35: TaskDep | E35: =IFERROR(ROUND(696*CRONO_MACRO!$F$4/(CRONO_MACRO!J15/CRONO_MACRO!F15*696*CRONO_MACRO!$D$4),0),0) | F35: 11/05/26 | G35: 23/10/26 | H35: 5d/w | I35: 3230136 | J35: Eq.Campo | K35: =IFERROR(ROUND(CRONO_MACRO!J15*696/CRONO_MACRO!F15,0),0) | L35: 696 | M35: 696lig
A36: A3020 | B36: S8.VPR.010502.ASB | C36: ASB R Um N.Cintra | D36: TaskDep | E36: 10 | G36: 23/10/26 | H36: 5d/w | I36: 304013 | J36: Eng.Asb | K36: 1 | L36: 0
A37: A3100 | B37: S8.VPR.010507.PRJ | C37: PRJ V.Progresso | D37: TaskDep | E37: 15 | F37: 11/05/26 | H37: 5d/w | I37: 265574 | J37: Eng.Proj | K37: 1 | L37: 0
A38: A3110 | B38: S8.VPR.010507.EXE | C38: EXE V.Progresso | D38: TaskDep | E38: =IFERROR(ROUND(608*CRONO_MACRO!$F$4/(CRONO_MACRO!J15/CRONO_MACRO!F15*608*CRONO_MACRO!$D$4),0),0) | F38: 11/05/26 | G38: 23/10/26 | H38: 5d/w | I38: 2821728 | J38: Eq.Campo | K38: =IFERROR(ROUND(CRONO_MACRO!J15*608/CRONO_MACRO!F15,0),0) | L38: 608 | M38: 608lig
A39: A3120 | B39: S8.VPR.010507.ASB | C39: ASB V.Progresso | D39: TaskDep | E39: 10 | G39: 23/10/26 | H39: 5d/w | I39: 265574 | J39: Eng.Asb | K39: 1 | L39: 0
A40: A3200 | B40: S8.VPR.010503.PRJ | C40: PRJ Encosta Saboo | D40: TaskDep | E40: 15 | F40: 11/05/26 | H40: 5d/w | I40: 122304 | J40: Eng.Proj | K40: 1 | L40: 0
A41: A3210 | B41: S8.VPR.010503.EXE | C41: EXE Encosta Saboo | D41: TaskDep | E41: =IFERROR(ROUND(280*CRONO_MACRO!$F$4/(CRONO_MACRO!J15/CRONO_MACRO!F15*280*CRONO_MACRO!$D$4),0),0) | F41: 11/05/26 | G41: 23/10/26 | H41: 5d/w | I41: 1299480 | J41: Eq.Campo | K41: =IFERROR(ROUND(CRONO_MACRO!J15*280/CRONO_MACRO!F15,0),0) | L41: 280 | M41: 280lig
...

Sheet N07_NOROESTE
A1: N07 — Zona Noroeste | 2.996 lig | M/Lig=2
A2: TAG | B2: NOME | C2: TIPO | D2: LA | E2: LE | F2: LIG | G2: EQ | H2: PROD | I2: Abr | J2: Mai | K2: Jun | L2: Jul | M2: Ago | N2: Set | O2: Out | P2: Nov | Q2: Dez | R2: Jan/27 | S2: PLAN | T2: SALDO | U2: CUSTO | V2: PESS
A3: 010524 | B3: Vila Alemoa | C3: UD | D3: 461 | E3: 946 | F3: 1407 | G3: 5 | H3: 6 | I3: 0 | J3: 0 | K3: 0 | L3: 0 | M3: 0 | N3: 0 | O3: 0 | P3: 0 | Q3: 0 | R3: 0 | S3: 0 | T3: 1407 | U3: 0 | V3: 42.5
A4: 010518 | B4: Ilheu Baixo | C4: UD | D4: 73 | E4: 603 | F4: 676 | G4: 2 | H4: 6 | I4: 0 | J4: 0 | K4: 0 | L4: 0 | M4: 0 | N4: 0 | O4: 0 | P4: 0 | Q4: 0 | R4: 0 | S4: 0 | T4: 676 | U4: 0 | V4: 17
A5: 010522 | B5: NSRA Fatima | C5: UD | D5: 91 | E5: 170 | F5: 261 | G5: 1 | H5: 6 | I5: 0 | J5: 0 | K5: 0 | L5: 0 | M5: 0 | N5: 0 | O5: 0 | P5: 0 | Q5: 0 | R5: 0 | S5: 0 | T5: 261 | U5: 0 | V5: 8.5
A6: 010526 | B6: Vila Telma | C6: UD | D6: 48 | E6: 143 | F6: 191 | G6: 1 | H6: 6 | I6: 0 | J6: 0 | K6: 0 | L6: 0 | M6: 0 | N6: 0 | O6: 0 | P6: 0 | Q6: 0 | R6: 0 | S6: 0 | T6: 191 | U6: 0 | V6: 8.5
A7: 010525 | B7: V.Alemoa Rem | C7: UD | D7: 50 | E7: 50 | F7: 100 | G7: 1 | H7: 6 | I7: 0 | J7: 0 | K7: 0 | L7: 0 | M7: 0 | N7: 0 | O7: 0 | P7: 0 | Q7: 0 | R7: 0 | S7: 0 | T7: 100 | U7: 0 | V7: 8.5
A8: 010521 | B8: Lote L Chico | C8: UD | D8: 48 | E8: 48 | F8: 96 | G8: 1 | H8: 6 | I8: 0 | J8: 0 | K8: 0 | L8: 0 | M8: 0 | N8: 0 | O8: 0 | P8: 0 | Q8: 0 | R8: 0 | S8: 0 | T8: 96 | U8: 0 | V8: 8.5
A9: 010523 | B9: V.Alemoa COHAB | C9: UD | D9: 39 | E9: 39 | F9: 78 | G9: 1 | H9: 6 | I9: 0 | J9: 0 | K9: 0 | L9: 0 | M9: 0 | N9: 0 | O9: 0 | P9: 0 | Q9: 0 | R9: 0 | S9: 0 | T9: 78 | U9: 0 | V9: 8.5
A10: 010520 | B10: Joao Barro | C10: UD | D10: 29 | E10: 58 | F10: 87 | G10: 1 | H10: 6 | I10: 0 | J10: 0 | K10: 0 | L10: 0 | M10: 0 | N10: 0 | O10: 0 | P10: 0 | Q10: 0 | R10: 0 | S10: 0 | T10: 87 | U10: 0 | V10: 8.5
A11: 010515 | B11: Saboo II | C11: UD | D11: 37 | E11: 49 | F11: 86 | G11: 1 | H11: 6 | I11: 0 | J11: 0 | K11: 0 | L11: 0 | M11: 0 | N11: 0 | O11: 0 | P11: 0 | Q11: 0 | R11: 0 | S11: 0 | T11: 86 | U11: 0 | V11: 8.5
A12: 010517 | B12: Fav.Butanta | C12: UD | D12: 7 | E12: 7 | F12: 14 | G12: 1 | H12: 6 | I12: 0 | J12: 0 | K12: 0 | L12: 0 | M12: 0 | N12: 0 | O12: 0 | P12: 0 | Q12: 0 | R12: 0 | S12: 0 | T12: 14 | U12: 0 | V12: 8.5
B13: TOTAL | D13: 883 | E13: 2113 | F13: 2996 | G13: 15 | I13: 0 | J13: 0 | K13: 0 | L13: 0 | M13: 0 | N13: 0 | O13: 0 | P13: 0 | Q13: 0 | R13: 0 | S13: 0 | T13: 2996 | U13: 0 | V13: 127.5
A14: MATERIAL
A15: Material | B15: Fator | C15: Total | D15: Abr | E15: Mai | F15: Jun | G15: Jul | H15: Ago | I15: Set | J15: Out | K15: Nov | L15: Dez | M15: Jan/27
A16: Tubo PVC ESG | B16: 0.55 | C16: 0 | D16: 0 | E16: 0 | F16: 0 | G16: 0 | H16: 0 | I16: 0 | J16: 0 | K16: 0 | L16: 0 | M16: 0
A17: Tubo PEAD Agua | B17: 0.65 | C17: 0 | D17: 0 | E17: 0 | F17: 0 | G17: 0 | H17: 0 | I17: 0 | J17: 0 | K17: 0 | L17: 0 | M17: 0
A18: Areia | B18: 0.27 | C18: 0 | D18: 0 | E18: 0 | F18: 0 | G18: 0 | H18: 0 | I18: 0 | J18: 0 | K18: 0 | L18: 0 | M18: 0
A19: Brita | B19: 0.12 | C19: 0 | D19: 0 | E19: 0 | F19: 0 | G19: 0 | H19: 0 | I19: 0 | J19: 0 | K19: 0 | L19: 0 | M19: 0
A20: Concreto | B20: 0.1 | C20: 0 | D20: 0 | E20: 0 | F20: 0 | G20: 0 | H20: 0 | I20: 0 | J20: 0 | K20: 0 | L20: 0 | M20: 0
A21: CBUQ | B21: 0.12 | C21: 0 | D21: 0 | E21: 0 | F21: 0 | G21: 0 | H21: 0 | I21: 0 | J21: 0 | K21: 0 | L21: 0 | M21: 0

Sheet N08_V_PROGRESSO
A1: N08 — Vila Progresso | 1.865 lig
A2: TAG | B2: NOME | C2: TIPO | D2: LA | E2: LE | F2: LIG | G2: EQ | H2: PROD | I2: Abr | J2: Mai | K2: Jun | L2: Jul | M2: Ago | N2: Set | O2: Out | P2: Nov | Q2: Dez | R2: Jan/27 | S2: PLAN | T2: SALDO | U2: CUSTO | V2: PESS
A3: 010502 | B3: R Um N.Cintra | C3: UM | D3: 246 | E3: 450 | F3: 696 | G3: 4 | H3: 3 | I3: 0 | J3: 0 | K3: 0 | L3: 0 | M3: 0 | N3: 0 | O3: 0 | P3: 0 | Q3: 0 | R3: 0 | S3: 0 | T3: 696 | U3: 0 | V3: 34
A4: 010507 | B4: V.Progresso | C4: UM | D4: 71 | E4: 537 | F4: 608 | G4: 3 | H4: 3 | I4: 0 | J4: 0 | K4: 0 | L4: 0 | M4: 0 | N4: 0 | O4: 0 | P4: 0 | Q4: 0 | R4: 0 | S4: 0 | T4: 608 | U4: 0 | V4: 25.5
A5: 010503 | B5: Encosta Saboo | C5: UM | D5: 140 | E5: 140 | F5: 280 | G5: 2 | H5: 3 | I5: 0 | J5: 0 | K5: 0 | L5: 0 | M5: 0 | N5: 0 | O5: 0 | P5: 0 | Q5: 0 | R5: 0 | S5: 0 | T5: 280 | U5: 0 | V5: 17
A6: 010504 | B6: Menino Jesus | C6: UM | D6: 79 | E6: 79 | F6: 158 | G6: 1 | H6: 3 | I6: 0 | J6: 0 | K6: 0 | L6: 0 | M6: 0 | N6: 0 | O6: 0 | P6: 0 | Q6: 0 | R6: 0 | S6: 0 | T6: 158 | U6: 0 | V6: 8.5
A7: 010506 | B7: Rua Nove | C7: UM | D7: 27 | E7: 27 | F7: 54 | G7: 1 | H7: 3 | I7: 0 | J7: 0 | K7: 0 | L7: 0 | M7: 0 | N7: 0 | O7: 0 | P7: 0 | Q7: 0 | R7: 0 | S7: 0 | T7: 54 | U7: 0 | V7: 8.5
A8: 010509 | B8: R.M.Mercedes | C8: UM | D8: 11 | E8: 36 | F8: 47 | G8: 1 | H8: 3 | I8: 0 | J8: 0 | K8: 0 | L8: 0 | M8: 0 | N8: 0 | O8: 0 | P8: 0 | Q8: 0 | R8: 0 | S8: 0 | T8: 47 | U8: 0 | V8: 8.5
A9: 010508 | B9: V.Telma Cima | C9: UM | D9: 11 | E9: 11 | F9: 22 | G9: 1 | H9: 3 | I9: 0 | J9: 0 | K9: 0 | L9: 0 | M9: 0 | N9: 0 | O9: 0 | P9: 0 | Q9: 0 | R9: 0 | S9: 0 | T9: 22 | U9: 0 | V9: 8.5
B10: TOTAL | D10: 585 | E10: 1280 | F10: 1865 | G10: 13 | I10: 0 | J10: 0 | K10: 0 | L10: 0 | M10: 0 | N10: 0 | O10: 0 | P10: 0 | Q10: 0 | R10: 0 | S10: 0 | T10: 1865 | U10: 0 | V10: 110.5
A11: MATERIAL
A12: Material | B12: Fator | C12: Total | D12: Abr | E12: Mai | F12: Jun | G12: Jul | H12: Ago | I12: Set | J12: Out | K12: Nov | L12: Dez | M12: Jan/27
A13: Tubo PVC ESG | B13: 0.55 | C13: 0 | D13: 0 | E13: 0 | F13: 0 | G13: 0 | H13: 0 | I13: 0 | J13: 0 | K13: 0 | L13: 0 | M13: 0
A14: Tubo PEAD Agua | B14: 0.65 | C14: 0 | D14: 0 | E14: 0 | F14: 0 | G14: 0 | H14: 0 | I14: 0 | J14: 0 | K14: 0 | L14: 0 | M14: 0
A15: Areia | B15: 0.27 | C15: 0 | D15: 0 | E15: 0 | F15: 0 | G15: 0 | H15: 0 | I15: 0 | J15: 0 | K15: 0 | L15: 0 | M15: 0
A16: Brita | B16: 0.12 | C16: 0 | D16: 0 | E16: 0 | F16: 0 | G16: 0 | H16: 0 | I16: 0 | J16: 0 | K16: 0 | L16: 0 | M16: 0
A17: Concreto | B17: 0.1 | C17: 0 | D17: 0 | E17: 0 | F17: 0 | G17: 0 | H17: 0 | I17: 0 | J17: 0 | K17: 0 | L17: 0 | M17: 0
A18: CBUQ | B18: 0.12 | C18: 0 | D18: 0 | E18: 0 | F18: 0 | G18: 0 | H18: 0 | I18: 0 | J18: 0 | K18: 0 | L18: 0 | M18: 0

Sheet N09_Z_LESTE
A1: N09 — Zona Leste | 1.401 lig
A2: TAG | B2: NOME | C2: TIPO | D2: LA | E2: LE | F2: LIG | G2: EQ | H2: PROD | I2: Abr | J2: Mai | K2: Jun | L2: Jul | M2: Ago | N2: Set | O2: Out | P2: Nov | Q2: Dez | R2: Jan/27 | S2: PLAN | T2: SALDO | U2: CUSTO | V2: PESS
A3: 010473 | B3: Clovis Galvao | C3: UM | D3: 172 | E3: 504 | F3: 676 | G3: 5 | H3: 3 | I3: 0 | J3: 0 | K3: 0 | L3: 0 | M3: 0 | N3: 0 | O3: 0 | P3: 0 | Q3: 0 | R3: 0 | S3: 0 | T3: 676 | U3: 0 | V3: 42.5
A4: 010468 | B4: Div.Tiro Naval | C4: MO | D4: 217 | E4: 519 | F4: 736 | G4: 5 | H4: 2.3 | I4: 0 | J4: 0 | K4: 0 | L4: 0 | M4: 0 | N4: 0 | O4: 0 | P4: 0 | Q4: 0 | R4: 0 | S4: 0 | T4: 736 | U4: 0 | V4: 42.5
A5: 010474 | B5: M.Marape(a) | C5: MO | D5: 209 | E5: 331 | F5: 540 | G5: 4 | H5: 2.3 | I5: 0 | J5: 0 | K5: 0 | L5: 0 | M5: 0 | N5: 0 | O5: 0 | P5: 0 | Q5: 0 | R5: 0 | S5: 0 | T5: 540 | U5: 0 | V5: 34
A6: 010467 | B6: Cam.Marape | C6: MO | D6: 152 | E6: 349 | F6: 501 | G6: 4 | H6: 2.3 | I6: 0 | J6: 0 | K6: 0 | L6: 0 | M6: 0 | N6: 0 | O6: 0 | P6: 0 | Q6: 0 | R6: 0 | S6: 0 | T6: 501 | U6: 0 | V6: 34
A7: 010472 | B7: Vila Sapo | C7: UM | D7: 131 | E7: 162 | F7: 293 | G7: 2 | H7: 3 | I7: 0 | J7: 0 | K7: 0 | L7: 0 | M7: 0 | N7: 0 | O7: 0 | P7: 0 | Q7: 0 | R7: 0 | S7: 0 | T7: 293 | U7: 0 | V7: 17
A8: 010530 | B8: M.Marape(b) | C8: MO | D8: 104 | E8: 164 | F8: 268 | G8: 2 | H8: 2.3 | I8: 0 | J8: 0 | K8: 0 | L8: 0 | M8: 0 | N8: 0 | O8: 0 | P8: 0 | Q8: 0 | R8: 0 | S8: 0 | T8: 268 | U8: 0 | V8: 17
A9: 010531 | B9: M.Marape(c) | C9: MO | D9: 88 | E9: 138 | F9: 226 | G9: 2 | H9: 2.3 | I9: 0 | J9: 0 | K9: 0 | L9: 0 | M9: 0 | N9: 0 | O9: 0 | P9: 0 | Q9: 0 | R9: 0 | S9: 0 | T9: 226 | U9: 0 | V9: 17
A10: 010475 | B10: Aloj.StaCasa | C10: UM | D10: 76 | E10: 76 | F10: 152 | G10: 1 | H10: 3 | I10: 0 | J10: 0 | K10: 0 | L10: 0 | M10: 0 | N10: 0 | O10: 0 | P10: 0 | Q10: 0 | R10: 0 | S10: 0 | T10: 152 | U10: 0 | V10: 8.5
A11: 010466 | B11: Av.M.Fontes | C11: UM | D11: 45 | E11: 64 | F11: 109 | G11: 1 | H11: 3 | I11: 0 | J11: 0 | K11: 0 | L11: 0 | M11: 0 | N11: 0 | O11: 0 | P11: 0 | Q11: 0 | R11: 0 | S11: 0 | T11: 109 | U11: 0 | V11: 8.5
A12: 010470 | B12: NSRA Aparecida | C12: UM | D12: 27 | E12: 74 | F12: 101 | G12: 1 | H12: 3 | I12: 0 | J12: 0 | K12: 0 | L12: 0 | M12: 0 | N12: 0 | O12: 0 | P12: 0 | Q12: 0 | R12: 0 | S12: 0 | T12: 101 | U12: 0 | V12: 8.5
A13: 010532 | B13: Av.MF Pach | C13: UM | D13: 29 | E13: 41 | F13: 70 | G13: 1 | H13: 3 | I13: 0 | J13: 0 | K13: 0 | L13: 0 | M13: 0 | N13: 0 | O13: 0 | P13: 0 | Q13: 0 | R13: 0 | S13: 0 | T13: 70 | U13: 0 | V13: 8.5
A14: 010465 | B14: Cam.Maria Rosa | C14: MO | D14: 34 | E14: 34 | F14: 68 | G14: 1 | H14: 2.3 | I14: 0 | J14: 0 | K14: 0 | L14: 0 | M14: 0 | N14: 0 | O14: 0 | P14: 0 | Q14: 0 | R14: 0 | S14: 0 | T14: 68 | U14: 0 | V14: 8.5
B15: TOTAL | D15: 1284 | E15: 2456 | F15: 3740 | G15: 29 | I15: 0 | J15: 0 | K15: 0 | L15: 0 | M15: 0 | N15: 0 | O15: 0 | P15: 0 | Q15: 0 | R15: 0 | S15: 0 | T15: 3740 | U15: 0 | V15: 246.5
A16: MATERIAL
A17: Material | B17: Fator | C17: Total | D17: Abr | E17: Mai | F17: Jun | G17: Jul | H17: Ago | I17: Set | J17: Out | K17: Nov | L17: Dez | M17: Jan/27
A18: Tubo PVC ESG | B18: 0.55 | C18: 0 | D18: 0 | E18: 0 | F18: 0 | G18: 0 | H18: 0 | I18: 0 | J18: 0 | K18: 0 | L18: 0 | M18: 0
A19: Tubo PEAD Agua | B19: 0.65 | C19: 0 | D19: 0 | E19: 0 | F19: 0 | G19: 0 | H19: 0 | I19: 0 | J19: 0 | K19: 0 | L19: 0 | M19: 0
A20: Areia | B20: 0.27 | C20: 0 | D20: 0 | E20: 0 | F20: 0 | G20: 0 | H20: 0 | I20: 0 | J20: 0 | K20: 0 | L20: 0 | M20: 0
A21: Brita | B21: 0.12 | C21: 0 | D21: 0 | E21: 0 | F21: 0 | G21: 0 | H21: 0 | I21: 0 | J21: 0 | K21: 0 | L21: 0 | M21: 0
A22: Concreto | B22: 0.1 | C22: 0 | D22: 0 | E22: 0 | F22: 0 | G22: 0 | H22: 0 | I22: 0 | J22: 0 | K22: 0 | L22: 0 | M22: 0
A23: CBUQ | B23: 0.12 | C23: 0 | D23: 0 | E23: 0 | F23: 0 | G23: 0 | H23: 0 | I23: 0 | J23: 0 | K23: 0 | L23: 0 | M23: 0

Sheet N10_CONJUNTO
A1: N10 — Conjunto | 1.672 lig
A2: TAG | B2: NOME | C2: TIPO | D2: LA | E2: LE | F2: LIG | G2: EQ | H2: PROD | I2: Abr | J2: Mai | K2: Jun | L2: Jul | M2: Ago | N2: Set | O2: Out | P2: Nov | Q2: Dez | R2: Jan/27 | S2: PLAN | T2: SALDO | U2: CUSTO | V2: PESS
A3: 010486 | B3: M.Z.Menino(b) | C3: MO | D3: 195 | E3: 682 | F3: 877 | G3: 5 | H3: 2.3 | I3: 0 | J3: 0 | K3: 0 | L3: 0 | M3: 0 | N3: 0 | O3: 0 | P3: 0 | Q3: 0 | R3: 0 | S3: 0 | T3: 877 | U3: 0 | V3: 42.5
A4: 010480 | B4: Caneleira CDHU | C4: UR | D4: 264 | E4: 277 | F4: 541 | G4: 3 | H4: 4 | I4: 0 | J4: 0 | K4: 0 | L4: 0 | M4: 0 | N4: 0 | O4: 0 | P4: 0 | Q4: 0 | R4: 0 | S4: 0 | T4: 541 | U4: 0 | V4: 25.5
A5: 010485 | B5: M.Z.Menino(a) | C5: MO | D5: 194 | E5: 300 | F5: 494 | G5: 3 | H5: 2.3 | I5: 0 | J5: 0 | K5: 0 | L5: 0 | M5: 0 | N5: 0 | O5: 0 | P5: 0 | Q5: 0 | R5: 0 | S5: 0 | T5: 494 | U5: 0 | V5: 25.5
A6: 010490 | B6: Av.Bandeirantes | C6: UM | D6: 90 | E6: 197 | F6: 287 | G6: 2 | H6: 3 | I6: 0 | J6: 0 | K6: 0 | L6: 0 | M6: 0 | N6: 0 | O6: 0 | P6: 0 | Q6: 0 | R6: 0 | S6: 0 | T6: 287 | U6: 0 | V6: 17
A7: 010481 | B7: V.Ayrton Senna | C7: UR | D7: 70 | E7: 169 | F7: 239 | G7: 1 | H7: 4 | I7: 0 | J7: 0 | K7: 0 | L7: 0 | M7: 0 | N7: 0 | O7: 0 | P7: 0 | Q7: 0 | R7: 0 | S7: 0 | T7: 239 | U7: 0 | V7: 8.5
A8: 010484 | B8: V.Esperanca | C8: UR | D8: 52 | E8: 168 | F8: 220 | G8: 1 | H8: 4 | I8: 0 | J8: 0 | K8: 0 | L8: 0 | M8: 0 | N8: 0 | O8: 0 | P8: 0 | Q8: 0 | R8: 0 | S8: 0 | T8: 220 | U8: 0 | V8: 8.5
A9: 010494 | B9: Av.W.Leao | C9: UM | D9: 39 | E9: 64 | F9: 103 | G9: 1 | H9: 3 | I9: 0 | J9: 0 | K9: 0 | L9: 0 | M9: 0 | N9: 0 | O9: 0 | P9: 0 | Q9: 0 | R9: 0 | S9: 0 | T9: 103 | U9: 0 | V9: 8.5
A10: 010492 | B10: R.S.Geraldo | C10: UM | D10: 46 | E10: 46 | F10: 92 | G10: 1 | H10: 3 | I10: 0 | J10: 0 | K10: 0 | L10: 0 | M10: 0 | N10: 0 | O10: 0 | P10: 0 | Q10: 0 | R10: 0 | S10: 0 | T10: 92 | U10: 0 | V10: 8.5
A11: 010476 | B11: Fav.Piratininga | C11: UR | D11: 33 | E11: 33 | F11: 66 | G11: 1 | H11: 4 | I11: 0 | J11: 0 | K11: 0 | L11: 0 | M11: 0 | N11: 0 | O11: 0 | P11: 0 | Q11: 0 | R11: 0 | S11: 0 | T11: 66 | U11: 0 | V11: 8.5
A12: 010493 | B12: S.Bento II | C12: UM | D12: 27 | E12: 27 | F12: 54 | G12: 1 | H12: 3 | I12: 0 | J12: 0 | K12: 0 | L12: 0 | M12: 0 | N12: 0 | O12: 0 | P12: 0 | Q12: 0 | R12: 0 | S12: 0 | T12: 54 | U12: 0 | V12: 8.5
A13: 010495 | B13: Trav.Sta Casa | C13: UM | D13: 22 | E13: 22 | F13: 44 | G13: 1 | H13: 3 | I13: 0 | J13: 0 | K13: 0 | L13: 0 | M13: 0 | N13: 0 | O13: 0 | P13: 0 | Q13: 0 | R13: 0 | S13: 0 | T13: 44 | U13: 0 | V13: 8.5
A14: 010491 | B14: Av.Getulio | C14: UM | D14: 13 | E14: 13 | F14: 26 | G14: 1 | H14: 3 | I14: 0 | J14: 0 | K14: 0 | L14: 0 | M14: 0 | N14: 0 | O14: 0 | P14: 0 | Q14: 0 | R14: 0 | S14: 0 | T14: 26 | U14: 0 | V14: 8.5
B15: TOTAL | D15: 1045 | E15: 1998 | F15: 3043 | G15: 21 | I15: 0 | J15: 0 | K15: 0 | L15: 0 | M15: 0 | N15: 0 | O15: 0 | P15: 0 | Q15: 0 | R15: 0 | S15: 0 | T15: 3043 | U15: 0 | V15: 178.5
A16: MATERIAL
A17: Material | B17: Fator | C17: Total | D17: Abr | E17: Mai | F17: Jun | G17: Jul | H17: Ago | I17: Set | J17: Out | K17: Nov | L17: Dez | M17: Jan/27
A18: Tubo PVC ESG | B18: 0.55 | C18: 0 | D18: 0 | E18: 0 | F18: 0 | G18: 0 | H18: 0 | I18: 0 | J18: 0 | K18: 0 | L18: 0 | M18: 0
A19: Tubo PEAD Agua | B19: 0.65 | C19: 0 | D19: 0 | E19: 0 | F19: 0 | G19: 0 | H19: 0 | I19: 0 | J19: 0 | K19: 0 | L19: 0 | M19: 0
A20: Areia | B20: 0.27 | C20: 0 | D20: 0 | E20: 0 | F20: 0 | G20: 0 | H20: 0 | I20: 0 | J20: 0 | K20: 0 | L20: 0 | M20: 0
A21: Brita | B21: 0.12 | C21: 0 | D21: 0 | E21: 0 | F21: 0 | G21: 0 | H21: 0 | I21: 0 | J21: 0 | K21: 0 | L21: 0 | M21: 0
A22: Concreto | B22: 0.1 | C22: 0 | D22: 0 | E22: 0 | F22: 0 | G22: 0 | H22: 0 | I22: 0 | J22: 0 | K22: 0 | L22: 0 | M22: 0
A23: CBUQ | B23: 0.12 | C23: 0 | D23: 0 | E23: 0 | F23: 0 | G23: 0 | H23: 0 | I23: 0 | J23: 0 | K23: 0 | L23: 0 | M23: 0

Sheet N11_ALAGADO
A1: N11 — Alagado/Dique | 1.862 lig
A2: TAG | B2: NOME | C2: TIPO | D2: LA | E2: LE | F2: LIG | G2: EQ | H2: PROD | I2: Abr | J2: Mai | K2: Jun | L2: Jul | M2: Ago | N2: Set | O2: Out | P2: Nov | Q2: Dez | R2: Jan/27 | S2: PLAN | T2: SALDO | U2: CUSTO | V2: PESS
A3: 010519 | B3: Dique V.Gilda | C3: AL | D3: 634 | E3: 811 | F3: 1445 | G3: 8 | H3: 2.5 | I3: 0 | J3: 0 | K3: 0 | L3: 0 | M3: 0 | N3: 0 | O3: 0 | P3: 0 | Q3: 0 | R3: 0 | S3: 0 | T3: 1445 | U3: 0 | V3: 68
A4: 010497 | B4: Reg.AG Dique | C4: AL | D4: 0 | E4: 408 | F4: 408 | G4: 2 | H4: 2.5 | I4: 0 | J4: 0 | K4: 0 | L4: 0 | M4: 0 | N4: 0 | O4: 0 | P4: 0 | Q4: 0 | R4: 0 | S4: 0 | T4: 408 | U4: 0 | V4: 17
A5: 010516 | B5: Dique VG(c) | C5: AL | D5: 3 | E5: 4 | F5: 7 | G5: 1 | H5: 2.5 | I5: 0 | J5: 0 | K5: 0 | L5: 0 | M5: 0 | N5: 0 | O5: 0 | P5: 0 | Q5: 0 | R5: 0 | S5: 0 | T5: 7 | U5: 0 | V5: 8.5
A6: 010499 | B6: Dique S.Manoel | C6: AL | D6: 1 | E6: 1 | F6: 2 | G6: 1 | H6: 2.5 | I6: 0 | J6: 0 | K6: 0 | L6: 0 | M6: 0 | N6: 0 | O6: 0 | P6: 0 | Q6: 0 | R6: 0 | S6: 0 | T6: 2 | U6: 0 | V6: 8.5
B7: TOTAL | D7: 638 | E7: 1224 | F7: 1862 | G7: 12 | I7: 0 | J7: 0 | K7: 0 | L7: 0 | M7: 0 | N7: 0 | O7: 0 | P7: 0 | Q7: 0 | R7: 0 | S7: 0 | T7: 1862 | U7: 0 | V7: 102
A8: MATERIAL
A9: Material | B9: Fator | C9: Total | D9: Abr | E9: Mai | F9: Jun | G9: Jul | H9: Ago | I9: Set | J9: Out | K9: Nov | L9: Dez | M9: Jan/27
A10: Tubo PVC ESG | B10: 0.55 | C10: 0 | D10: 0 | E10: 0 | F10: 0 | G10: 0 | H10: 0 | I10: 0 | J10: 0 | K10: 0 | L10: 0 | M10: 0
A11: Tubo PEAD Agua | B11: 0.65 | C11: 0 | D11: 0 | E11: 0 | F11: 0 | G11: 0 | H11: 0 | I11: 0 | J11: 0 | K11: 0 | L11: 0 | M11: 0
A12: Areia | B12: 0.27 | C12: 0 | D12: 0 | E12: 0 | F12: 0 | G12: 0 | H12: 0 | I12: 0 | J12: 0 | K12: 0 | L12: 0 | M12: 0
A13: Brita | B13: 0.12 | C13: 0 | D13: 0 | E13: 0 | F13: 0 | G13: 0 | H13: 0 | I13: 0 | J13: 0 | K13: 0 | L13: 0 | M13: 0
A14: Concreto | B14: 0.1 | C14: 0 | D14: 0 | E14: 0 | F14: 0 | G14: 0 | H14: 0 | I14: 0 | J14: 0 | K14: 0 | L14: 0 | M14: 0
A15: CBUQ | B15: 0.12 | C15: 0 | D15: 0 | E15: 0 | F15: 0 | G15: 0 | H15: 0 | I15: 0 | J15: 0 | K15: 0 | L15: 0 | M15: 0

Sheet N12_MONTANHOSO
A1: N12 — Montanhoso | 10.511 lig
A2: TAG | B2: NOME | C2: TIPO | D2: LA | E2: LE | F2: LIG | G2: EQ | H2: PROD | I2: Abr | J2: Mai | K2: Jun | L2: Jul | M2: Ago | N2: Set | O2: Out | P2: Nov | Q2: Dez | R2: Jan/27 | S2: PLAN | T2: SALDO | U2: CUSTO | V2: PESS
A3: 010460 | B3: Pacheco AP | C3: MO | D3: 239 | E3: 687 | F3: 926 | G3: 1 | H3: 2.3 | I3: 0 | J3: 0 | K3: 0 | L3: 0 | M3: 0 | N3: 0 | O3: 0 | P3: 0 | Q3: 0 | R3: 0 | S3: 0 | T3: 926 | U3: 0 | V3: 8.5
A4: 010455 | B4: Sta Maria | C4: MO | D4: 237 | E4: 388 | F4: 625 | G4: 1 | H4: 2.3 | I4: 0 | J4: 0 | K4: 0 | L4: 0 | M4: 0 | N4: 0 | O4: 0 | P4: 0 | Q4: 0 | R4: 0 | S4: 0 | T4: 625 | U4: 0 | V4: 8.5
A5: 010457 | B5: S.Bento I | C5: MO | D5: 632 | E5: 1 | F5: 633 | G5: 1 | H5: 2.3 | I5: 0 | J5: 0 | K5: 0 | L5: 0 | M5: 0 | N5: 0 | O5: 0 | P5: 0 | Q5: 0 | R5: 0 | S5: 0 | T5: 633 | U5: 0 | V5: 8.5
A6: 010452 | B6: Lomba Penha | C6: MO | D6: 567 | E6: 1 | F6: 568 | G6: 1 | H6: 2.3 | I6: 0 | J6: 0 | K6: 0 | L6: 0 | M6: 0 | N6: 0 | O6: 0 | P6: 0 | Q6: 0 | R6: 0 | S6: 0 | T6: 568 | U6: 0 | V6: 8.5
A7: 010449 | B7: ZEIS S.Bento | C7: MO | D7: 199 | E7: 344 | F7: 543 | G7: 1 | H7: 2.3 | I7: 0 | J7: 0 | K7: 0 | L7: 0 | M7: 0 | N7: 0 | O7: 0 | P7: 0 | Q7: 0 | R7: 0 | S7: 0 | T7: 543 | U7: 0 | V7: 8.5
A8: 010464 | B8: GRusso-JGS | C8: MO | D8: 235 | E8: 473 | F8: 708 | G8: 1 | H8: 2.3 | I8: 0 | J8: 0 | K8: 0 | L8: 0 | M8: 0 | N8: 0 | O8: 0 | P8: 0 | Q8: 0 | R8: 0 | S8: 0 | T8: 708 | U8: 0 | V8: 8.5
A9: 010458 | B9: Torquato Dias | C9: MO | D9: 43 | E9: 342 | F9: 385 | G9: 1 | H9: 2.3 | I9: 0 | J9: 0 | K9: 0 | L9: 0 | M9: 0 | N9: 0 | O9: 0 | P9: 0 | Q9: 0 | R9: 0 | S9: 0 | T9: 385 | U9: 0 | V9: 8.5
A10: 010527 | B10: Area Tunel | C10: MO | D10: 95 | E10: 239 | F10: 334 | G10: 1 | H10: 2.3 | I10: 0 | J10: 0 | K10: 0 | L10: 0 | M10: 0 | N10: 0 | O10: 0 | P10: 0 | Q10: 0 | R10: 0 | S10: 0 | T10: 334 | U10: 0 | V10: 8.5
A11: 010489 | B11: M.Serrat II | C11: MO | D11: 136 | E11: 136 | F11: 272 | G11: 1 | H11: 2.3 | I11: 0 | J11: 0 | K11: 0 | L11: 0 | M11: 0 | N11: 0 | O11: 0 | P11: 0 | Q11: 0 | R11: 0 | S11: 0 | T11: 272 | U11: 0 | V11: 8.5
A12: 010461 | B12: V.Cesar | C12: MO | D12: 125 | E12: 125 | F12: 250 | G12: 1 | H12: 2.3 | I12: 0 | J12: 0 | K12: 0 | L12: 0 | M12: 0 | N12: 0 | O12: 0 | P12: 0 | Q12: 0 | R12: 0 | S12: 0 | T12: 250 | U12: 0 | V12: 8.5
A13: 010453 | B13: N.Cintra I | C13: MO | D13: 30 | E13: 195 | F13: 225 | G13: 1 | H13: 2.3 | I13: 0 | J13: 0 | K13: 0 | L13: 0 | M13: 0 | N13: 0 | O13: 0 | P13: 0 | Q13: 0 | R13: 0 | S13: 0 | T13: 225 | U13: 0 | V13: 8.5
A14: 010528 | B14: Av.Pref.Dr.A | C14: MO | D14: 108 | E14: 108 | F14: 216 | G14: 1 | H14: 2.3 | I14: 0 | J14: 0 | K14: 0 | L14: 0 | M14: 0 | N14: 0 | O14: 0 | P14: 0 | Q14: 0 | R14: 0 | S14: 0 | T14: 216 | U14: 0 | V14: 8.5
... A25: 010448 | B25: Caneleira III | C25: MO | D25: 1 | E25: 1 | F25: 2 | G25: 1 | H25: 2.3 | I25: 0 | J25: 0 | K25: 0 | L25: 0 | M25: 0 | N25: 0 | O25: 0 | P25: 0 | Q25: 0 | R25: 0 | S25: 0 | T25: 2 | U25: 0 | V25: 8.5
B26: TOTAL | D26: 3174 | E26: 3627 | F26: 6801 | G26: 23 | I26: 0 | J26: 0 | K26: 0 | L26: 0 | M26: 0 | N26: 0 | O26: 0 | P26: 0 | Q26: 0 | R26: 0 | S26: 0 | T26: 6801 | U26: 0 | V26: 195.5
A27: MATERIAL
A28: Material | B28: Fator | C28: Total | D28: Abr | E28: Mai | F28: Jun | G28: Jul | H28: Ago | I28: Set | J28: Out | K28: Nov | L28: Dez | M28: Jan/27
A29: Tubo PVC ESG | B29: 0.55 | C29: 0 | D29: 0 | E29: 0 | F29: 0 | G29: 0 | H29: 0 | I29: 0 | J29: 0 | K29: 0 | L29: 0 | M29: 0
A30: Tubo PEAD Agua | B30: 0.65 | C30: 0 | D30: 0 | E30: 0 | F30: 0 | G30: 0 | H30: 0 | I30: 0 | J30: 0 | K30: 0 | L30: 0 | M30: 0
A31: Areia | B31: 0.27 | C31: 0 | D31: 0 | E31: 0 | F31: 0 | G31: 0 | H31: 0 | I31: 0 | J31: 0 | K31: 0 | L31: 0 | M31: 0
A32: Brita | B32: 0.12 | C32: 0 | D32: 0 | E32: 0 | F32: 0 | G32: 0 | H32: 0 | I32: 0 | J32: 0 | K32: 0 | L32: 0 | M32: 0
A33: Concreto | B33: 0.1 | C33: 0 | D33: 0 | E33: 0 | F33: 0 | G33: 0 | H33: 0 | I33: 0 | J33: 0 | K33: 0 | L33: 0 | M33: 0
A34: CBUQ | B34: 0.12 | C34: 0 | D34: 0 | E34: 0 | F34: 0 | G34: 0 | H34: 0 | I34: 0 | J34: 0 | K34: 0 | L34: 0 | M34: 0

Sheet SD_JOAO_CARLOS
A1: SD — João Carlos | ESG 91% | AGU 5.759m restante
A3: EQ: | B3: 4 | C3: PROD: | D3: 6 | E3: INI: | F3: 1
A4: PROGRESSO: | B4: ESG: 867/955m (91%) | E4: AG: 930/93m (998%)
A5: TIPO | B5: ID | C5: PV INI | D5: PV FIM | E5: EXT(m) | F5: DN | G5: MATERIAL | H5: PROF(m) | I5: ESCAV(m3) | J5: STATUS
A6: ESGOTO | B6: T-001 | C6: PI 68 | D6: PI 64 | E6: 26.32 | F6: 300 | G6: Tubo PVC | H6: 1.59 | I6: 33.41 | J6: PENDENTE
A7: ESGOTO | B7: T-002 | C7: PI 62 | D7: PI 44 | E7: 10.45 | F7: 300 | G7: Tubo PVC | H7: 3.11 | I7: 26.01 | J7: PENDENTE
A8: ESGOTO | B8: T-003 | C8: PI 44 | D8: PI 02 | E8: 8.28 | F8: 300 | G8: Tubo PVC | H8: 4.32 | I8: 28.6 | J8: PENDENTE
A9: ESGOTO | B9: T-004 | C9: PI 06 | D9: PI 16 | E9: 35.86 | F9: 300 | G9: Tubo PVC | H9: 1.77 | I9: 50.66 | J9: PENDENTE
A10: ESGOTO | B10: T-005 | C10: PI 62 | D10: PI 63 | E10: 12.77 | F10: 300 | G10: Tubo PVC | H10: 1.87 | I10: 19.07 | J10: PENDENTE
A11: ESGOTO | B11: T-006 | C11: PI 64 | D11: PI 63 | E11: 9.35 | F11: 300 | G11: Tubo PVC | H11: 1.96 | I11: 14.69 | J11: PENDENTE
A12: ESGOTO | B12: T-007 | C12: PI 16 | D12: PI 19 | E12: 8.4 | F12: 200 | G12: Tubo PVC | H12: 2.6 | I12: 17.48 | J12: PENDENTE
A13: ESGOTO | B13: T-008 | C13: PI 118 | D13: PI 115 | E13: 13.75 | F13: 1000 | G13: Tubo de Concreto | H13: 0.73 | I13: 8.02 | J13: PENDENTE
A14: ESGOTO | B14: T-009 | C14: PI 115 | D14: PI 113 | E14: 11.52 | F14: 1000 | G14: Tubo de Concreto | H14: 0.98 | I14: 9.06 | J14: PENDENTE
A15: ESGOTO | B15: T-010 | C15: PI 68 | D15: PI 65 | E15: 10.76 | F15: 1000 | G15: Tubo de Concreto | H15: 0.69 | I15: 5.96 | J15: PENDENTE
A16: ESGOTO | B16: T-011 | C16: PI 65 | D16: PI 64 | E16: 10.69 | F16: 1000 | G16: Tubo de Concreto | H16: 1.19 | I16: 10.21 | J16: PENDENTE
A17: ESGOTO | B17: T-012 | C17: PI 64 | D17: PI 63 | E17: 9.38 | F17: 1000 | G17: Tubo de Concreto | H17: 1.96 | I17: 14.74 | J17: PENDENTE
... A95: AGUA | B95: T-045 | C95: PI 03 | D95: PI 04 | E95: 2 | F95: 200 | G95: Tubo PVC | H95: 0.3 | I95: 0.48 | J95: PENDENTE
A96: TOTAL | E96: 1047.95

Sheet SD_SAO_MANOEL
A1: SD — São Manoel | ESG >100% | AGU 3.769m executado
A3: EQ: | B3: 5 | C3: PROD: | D3: 6 | E3: INI: | F3: 1
A4: PROGRESSO: | B4: ESG: 1384/955m (145%) | E4: AG: 3769/93m (4046%)
A5: TIPO | B5: ID | C5: PV INI | D5: PV FIM | E5: EXT(m) | F5: DN | G5: MATERIAL | H5: PROF(m) | I5: ESCAV(m3) | J5: STATUS
A6: ESGOTO | B6: T-001 | C6: PI 68 | D6: PI 64 | E6: 26.32 | F6: 300 | G6: Tubo PVC | H6: 1.59 | I6: 33.41 | J6: PENDENTE
A7: ESGOTO | B7: T-002 | C7: PI 62 | D7: PI 44 | E7: 10.45 | F7: 300 | G7: Tubo PVC | H7: 3.11 | I7: 26.01 | J7: PENDENTE
A8: ESGOTO | B8: T-003 | C8: PI 44 | D8: PI 02 | E8: 8.28 | F8: 300 | G8: Tubo PVC | H8: 4.32 | I8: 28.6 | J8: PENDENTE
A9: ESGOTO | B9: T-004 | C9: PI 06 | D9: PI 16 | E9: 35.86 | F9: 300 | G9: Tubo PVC | H9: 1.77 | I9: 50.66 | J9: PENDENTE
A10: ESGOTO | B10: T-005 | C10: PI 62 | D10: PI 63 | E10: 12.77 | F10: 300 | G10: Tubo PVC | H10: 1.87 | I10: 19.07 | J10: PENDENTE
A11: ESGOTO | B11: T-006 | C11: PI 64 | D11: PI 63 | E11: 9.35 | F11: 300 | G11: Tubo PVC | H11: 1.96 | I11: 14.69 | J11: PENDENTE
A12: ESGOTO | B12: T-007 | C12: PI 16 | D12: PI 19 | E12: 8.4 | F12: 200 | G12: Tubo PVC | H12: 2.6 | I12: 17.48 | J12: PENDENTE
A13: ESGOTO | B13: T-008 | C13: PI 118 | D13: PI 115 | E13: 13.75 | F13: 1000 | G13: Tubo de Concreto | H13: 0.73 | I13: 8.02 | J13: PENDENTE
A14: ESGOTO | B14: T-009 | C14: PI 115 | D14: PI 113 | E14: 11.52 | F14: 1000 | G14: Tubo de Concreto | H14: 0.98 | I14: 9.06 | J14: PENDENTE
A15: ESGOTO | B15: T-010 | C15: PI 68 | D15: PI 65 | E15: 10.76 | F15: 1000 | G15: Tubo de Concreto | H15: 0.69 | I15: 5.96 | J15: PENDENTE
A16: ESGOTO | B16: T-011 | C16: PI 65 | D16: PI 64 | E16: 10.69 | F16: 1000 | G16: Tubo de Concreto | H16: 1.19 | I16: 10.21 | J16: PENDENTE
A17: ESGOTO | B17: T-012 | C17: PI 64 | D17: PI 63 | E17: 9.38 | F17: 1000 | G17: Tubo de Concreto | H17: 1.96 | I17: 14.74 | J17: PENDENTE
... A95: AGUA | B95: T-045 | C95: PI 03 | D95: PI 04 | E95: 2 | F95: 200 | G95: Tubo PVC | H95: 0.3 | I95: 0.48 | J95: PENDENTE
A96: TOTAL | E96: 1047.95

Sheet SD_VILA_ISRAEL
A1: SD — Vila Israel | ESG 66% | AGU sem projeto
A3: EQ: | B3: 4 | C3: PROD: | D3: 6 | E3: INI: | F3: 1
A4: PROGRESSO: | B4: ESG: 1406/2140m (66%) | E4: AG: sem projeto agua
A5: TIPO | B5: ID | C5: PV INI | D5: PV FIM | E5: EXT(m) | F5: DN | G5: MATERIAL | H5: PROF(m) | I5: ESCAV(m3) | J5: STATUS
A6: ESGOTO | B6: T-001 | C6: PI 194 | D6: PI 195 | E6: 6.9 | F6: 200 | G6: Tubo PVC | H6: 0.6 | I6: 3.31 | J6: PENDENTE
A7: ESGOTO | B7: T-002 | C7: PI 195 | D7: PI 196 | E7: 7.37 | F7: 200 | G7: Tubo PVC | H7: 0.6 | I7: 3.54 | J7: PENDENTE
A8: ESGOTO | B8: T-003 | C8: PI 196 | D8: PI 197 | E8: 5.41 | F8: 200 | G8: Tubo PVC | H8: 0.6 | I8: 2.6 | J8: PENDENTE
A9: ESGOTO | B9: T-004 | C9: PI 197 | D9: PI 196 | E9: 2.5 | F9: 200 | G9: Tubo PVC | H9: 0.6 | I9: 1.2 | J9: PENDENTE
A10: ESGOTO | B10: T-005 | C10: PI 196 | D10: PI 195 | E10: 2.5 | F10: 200 | G10: Tubo PVC | H10: 0.6 | I10: 1.2 | J10: PENDENTE
A11: ESGOTO | B11: T-006 | C11: PI 195 | D11: PI 194 | E11: 2.5 | F11: 200 | G11: Tubo PVC | H11: 0.6 | I11: 1.2 | J11: PENDENTE
A12: ESGOTO | B12: T-007 | C12: PI 195 | D12: PI 208 | E12: 4.99 | F12: 200 | G12: Tubo PVC | H12: 0.58 | I12: 2.32 | J12: PENDENTE
A13: ESGOTO | B13: T-008 | C13: PI 208 | D13: PI 209 | E13: 16.94 | F13: 200 | G13: Tubo PVC | H13: 1.18 | I13: 16.01 | J13: PENDENTE
A14: ESGOTO | B14: T-009 | C14: PI 209 | D14: PI 211 | E14: 3.32 | F14: 200 | G14: Tubo PVC | H14: 1.88 | I14: 4.98 | J14: PENDENTE
A15: ESGOTO | B15: T-010 | C15: PI 209 | D15: PI 212 | E15: 28.64 | F15: 200 | G15: Tubo PVC | H15: 1.2 | I15: 27.49 | J15: PENDENTE
A16: ESGOTO | B16: T-011 | C16: PI 212 | D16: PI 213 | E16: 22.87 | F16: 200 | G16: Tubo PVC | H16: 0.6 | I16: 10.98 | J16: PENDENTE
A17: ESGOTO | B17: T-012 | C17: PI 213 | D17: PI 214 | E17: 15.9 | F17: 200 | G17: Tubo PVC | H17: 0.6 | I17: 7.63 | J17: PENDENTE
... A265: ESGOTO | B265: T-260 | C265: PV 27 | D265: PI 211 | E265: 6.63 | F265: 200 | G265: Tubo PVC | H265: 1.27 | I265: 6.76 | J265: PENDENTE
A266: TOTAL | E266: 2140.41

Sheet SD_MORRO_TETEU
A1: SD — Morro do Tetéu | ESG 21% | AGU 74%
A3: EQ: | B3: 10 | C3: PROD: | D3: 6 | E3: INI: | F3: 1
A4: PROGRESSO: | B4: ESG: 1037/5034m (21%) | E4: AG: 338/457m (74%)
A5: TIPO | B5: ID | C5: PV INI | D5: PV FIM | E5: EXT(m) | F5: DN | G5: MATERIAL | H5: PROF(m) | I5: ESCAV(m3) | J5: STATUS
A6: ESGOTO | B6: T-001 | C6: PI 102 | D6: PI 103 | E6: 15.82 | F6: 200 | G6: Tubo PVC | H6: 0.6 | I6: 7.59 | J6: PENDENTE
A7: ESGOTO | B7: T-002 | C7: PI 103 | D7: PI 104 | E7: 10.57 | F7: 200 | G7: Tubo PVC | H7: 0.6 | I7: 5.07 | J7: PENDENTE
A8: ESGOTO | B8: T-003 | C8: PI 104 | D8: PI 105 | E8: 2.59 | F8: 200 | G8: Tubo PVC | H8: 0.6 | I8: 1.24 | J8: PENDENTE
A9: ESGOTO | B9: T-004 | C9: PI 105 | D9: PI 106 | E9: 8.88 | F9: 200 | G9: Tubo PVC | H9: 0.6 | I9: 4.26 | J9: PENDENTE
A10: ESGOTO | B10: T-005 | C10: PI 106 | D10: PI 107 | E10: 2.24 | F10: 200 | G10: Tubo PVC | H10: 0.6 | I10: 1.08 | J10: PENDENTE
A11: ESGOTO | B11: T-006 | C11: PI 107 | D11: PI 108 | E11: 4.35 | F11: 200 | G11: Tubo PVC | H11: 0.6 | I11: 2.09 | J11: PENDENTE
A12: ESGOTO | B12: T-007 | C12: PI 108 | D12: PI 109 | E12: 2.15 | F12: 200 | G12: Tubo PVC | H12: 0.6 | I12: 1.03 | J12: PENDENTE
A13: ESGOTO | B13: T-008 | C13: PI 109 | D13: PI 110 | E13: 10.67 | F13: 200 | G13: Tubo PVC | H13: 0.6 | I13: 5.12 | J13: PENDENTE
A14: ESGOTO | B14: T-009 | C14: PI 111 | D14: PI 112 | E14: 10.85 | F14: 200 | G14: Tubo PVC | H14: 0.6 | I14: 5.21 | J14: PENDENTE
A15: ESGOTO | B15: T-010 | C15: PI 112 | D15: PI 113 | E15: 3.91 | F15: 200 | G15: Tubo PVC | H15: 0.6 | I15: 1.88 | J15: PENDENTE
A16: ESGOTO | B16: T-011 | C16: PI 114 | D16: PI 115 | E16: 9.39 | F16: 200 | G16: Tubo PVC | H16: 1.2 | I16: 9.01 | J16: PENDENTE
A17: ESGOTO | B17: T-012 | C17: PI 115 | D17: PI 116 | E17: 9.76 | F17: 200 | G17: Tubo PVC | H17: 0.6 | I17: 4.68 | J17: PENDENTE
... A1338: AGUA | B1338: T-785 | C1338: PI 270 | D1338: PI 268 | E1338: 1.05 | F1338: 200 | G1338: Tubo PVC | H1338: 0.6 | I1338: 0.5 | J1338: PENDENTE
A1339: TOTAL | E1339: 5490.94

Sheet SD_VILA_CRIADORES
A1: SD — Vila Criadores | ESG 10% | AGU 3.147m exec.
A3: EQ: | B3: 8 | C3: PROD: | D3: 6 | E3: INI: | F3: 1
A4: PROGRESSO: | B4: ESG: 297/2930m (10%) | E4: AG: 3147/255m (1235%)
A5: TIPO | B5: ID | C5: PV INI | D5: PV FIM | E5: EXT(m) | F5: DN | G5: MATERIAL | H5: PROF(m) | I5: ESCAV(m3) | J5: STATUS
A6: ESGOTO | B6: T-001 | C6: PI 75 | D6: PI 76 | E6: 15.77 | F6: 200 | G6: Tubo PVC | H6: 0.6 | I6: 7.57 | J6: PENDENTE
A7: ESGOTO | B7: T-002 | C7: PI 76 | D7: PI 77 | E7: 32.88 | F7: 200 | G7: Tubo PVC | H7: 0.6 | I7: 15.78 | J7: PENDENTE
A8: ESGOTO | B8: T-003 | C8: PI 77 | D8: PI 79 | E8: 2.24 | F8: 200 | G8: Tubo PVC | H8: 0.6 | I8: 1.08 | J8: PENDENTE
A9: ESGOTO | B9: T-004 | C9: PI 79 | D9: PI 77 | E9: 1.34 | F9: 200 | G9: Tubo PVC | H9: 0.6 | I9: 0.64 | J9: PENDENTE
A10: ESGOTO | B10: T-005 | C10: PI 81 | D10: PI 82 | E10: 1.05 | F10: 200 | G10: Tubo PVC | H10: 0.6 | I10: 0.5 | J10: PENDENTE
A11: ESGOTO | B11: T-006 | C11: PI 81 | D11: PI 82 | E11: 0.63 | F11: 200 | G11: Tubo PVC | H11: 0.6 | I11: 0.3 | J11: PENDENTE
A12: ESGOTO | B12: T-007 | C12: PI 82 | D12: PI 83 | E12: 37.25 | F12: 200 | G12: Tubo PVC | H12: 0.6 | I12: 17.88 | J12: PENDENTE
A13: ESGOTO | B13: T-008 | C13: PI 84 | D13: PI 85 | E13: 30.91 | F13: 200 | G13: Tubo PVC | H13: 0.6 | I13: 14.84 | J13: PENDENTE
A14: ESGOTO | B14: T-009 | C14: PI 85 | D14: PI 86 | E14: 30.82 | F14: 200 | G14: Tubo PVC | H14: 0.6 | I14: 14.79 | J14: PENDENTE
A15: ESGOTO | B15: T-010 | C15: PI 86 | D15: PI 87 | E15: 27.48 | F15: 200 | G15: Tubo PVC | H15: 0.66 | I15: 14.52 | J15: PENDENTE
A16: ESGOTO | B16: T-011 | C16: PI 135 | D16: PI 136 | E16: 11.08 | F16: 200 | G16: Tubo PVC | H16: 0.69 | I16: 6.16 | J16: PENDENTE
A17: ESGOTO | B17: T-012 | C17: PI 136 | D17: PI 137 | E17: 32.92 | F17: 200 | G17: Tubo PVC | H17: 0.69 | I17: 18.31 | J17: PENDENTE
... A154: AGUA | B154: T-003 | C154: PI 01 | D154: PI 02 | E154: 3.72 | F154: 110 | G154: Tubo PE 80 NTS194 PN 12.5 | H154: 1.5 | I154: 4.46 | J154: PENDENTE
A155: TOTAL | E155: 3184.9

Sheet SD_PANTANAL_BAIXO
