Workbook

Sheet COMO_USAR
A1: COMO USAR ESTA PLANILHA
A2: ARQUITETURA | B2: DADOS → PROJETO (SUMIFS) → SALDO → MATERIAIS → PEDIDO → DASHBOARD
B3: Muda um número em DADOS → recalcula TUDO automaticamente.
A5: ABA DADOS | B5: 367 linhas de produção diária (6 núcleos, Jan-Mar/26). Colunas J e K são fórmulas (rede=LE+PRA, lig=LIE+LIA).
B6: FONTE PRIMÁRIA. Se adicionar dados novos aqui, tudo recalcula.
A8: ABA PROJETO | B8: Proj AG/ESG e Meses/EQ são EDITÁVEIS (azul). Exec AG/ESG puxa de DADOS com SUMIFS.
B9: Métricas: lig/mês, m/lig, GAP vs meta SABESP, fator multiplicador.
A11: ABA SALDO | B11: 100% fórmulas. Saldo = Proj - Exec. Status automático (PRONTO/FINALIZANDO/EXECUÇÃO).
A13: ABA ML_RESULTADOS | B13: XGBoost Feature Importance + dados Real vs Predito + gráficos Excel nativos.
B14: A explicação completa está na aba METODO_ML.
A16: ABA MATERIAIS | B16: Fatores EDITÁVEIS (amarelo). QTD = SALDO × Fator. Custo = QTD × P.Unit.
B17: Muda SALDO (que vem de PROJETO) → muda materiais → muda custos.
A19: ABA PEDIDO_URGENTE | B19: 100% fórmulas de MATERIAIS ÷ meses.
A21: ABA DASHBOARD | B21: 100% fórmulas. KPIs + tabela núcleos + resultado final.
A23: ABA METODO_ML | B23: Explicação passo a passo de: XGBoost, GridSearchCV, R², Seaborn, Feature Importance.
A25: GRÁFICOS | B25: Scatter Real vs Predito + Bar Feature Importance + Bar Produtividade por Núcleo = nativos Excel.
B26: Imagens Python (heatmaps, tendências, dashboard, violin) embutidas nas abas.
A28: EDITÁVEIS | B28: AZUL = inputs do projeto (proj AG/ESG, meses, equipes)
B29: AMARELO = fatores de composição de materiais
B30: TUDO MAIS = fórmula ou dado bruto

Sheet DADOS
A1: DADOS DE PRODUÇÃO DIÁRIA — Fonte primária | Tudo calcula a partir daqui
A2: DIA | B2: NÚCLEO | C2: EQUIPES | D2: LE (esg) | E2: PRA (ag) | F2: PRE | G2: PVs | H2: LIE | I2: LIA | J2: REDE | K2: LIG | L2: DIA_SEM | M2: MÊS | N2: REDE_ACUM
A3: 2026-01-12 | B3: João Carlos | C3: 3 | D3: 0 | E3: 48 | F3: 6 | G3: 0 | H3: 0 | I3: 0 | J3: =D3+E3 -> 48 | K3: =H3+I3 -> 0 | L3: =MOD(WEEKDAY(A3,2)-1,7) -> 0 | M3: =MONTH(A3) -> 1 | N3: =SUMIFS(J$3:J3,$B$3:$B3,B3) -> 48
A4: 2026-01-13 | B4: João Carlos | C4: 3 | D4: 0 | E4: 58 | F4: 6 | G4: 0 | H4: 0 | I4: 0 | J4: =D4+E4 -> 58 | K4: =H4+I4 -> 0 | L4: =MOD(WEEKDAY(A4,2)-1,7) -> 1 | M4: =MONTH(A4) -> 1 | N4: =SUMIFS(J$3:J4,$B$3:$B4,B4) -> 106
A5: 2026-01-14 | B5: João Carlos | C5: 3 | D5: 0 | E5: 40 | F5: 0 | G5: 1 | H5: 0 | I5: 0 | J5: =D5+E5 -> 40 | K5: =H5+I5 -> 0 | L5: =MOD(WEEKDAY(A5,2)-1,7) -> 2 | M5: =MONTH(A5) -> 1 | N5: =SUMIFS(J$3:J5,$B$3:$B5,B5) -> 146
A6: 2026-01-15 | B6: João Carlos | C6: 3 | D6: 0 | E6: 30 | F6: 0 | G6: 1 | H6: 0 | I6: 0 | J6: =D6+E6 -> 30 | K6: =H6+I6 -> 0 | L6: =MOD(WEEKDAY(A6,2)-1,7) -> 3 | M6: =MONTH(A6) -> 1 | N6: =SUMIFS(J$3:J6,$B$3:$B6,B6) -> 176
A7: 2026-01-17 | B7: João Carlos | C7: 3 | D7: 0 | E7: 6 | F7: 6 | G7: 1 | H7: 0 | I7: 0 | J7: =D7+E7 -> 6 | K7: =H7+I7 -> 0 | L7: =MOD(WEEKDAY(A7,2)-1,7) -> 5 | M7: =MONTH(A7) -> 1 | N7: =SUMIFS(J$3:J7,$B$3:$B7,B7) -> 182
A8: 2026-01-19 | B8: João Carlos | C8: 3 | D8: 0 | E8: 13 | F8: 0 | G8: 1 | H8: 0 | I8: 0 | J8: =D8+E8 -> 13 | K8: =H8+I8 -> 0 | L8: =MOD(WEEKDAY(A8,2)-1,7) -> 0 | M8: =MONTH(A8) -> 1 | N8: =SUMIFS(J$3:J8,$B$3:$B8,B8) -> 195
A9: 2026-01-20 | B9: João Carlos | C9: 3 | D9: 0 | E9: 15 | F9: 0 | G9: 0 | H9: 0 | I9: 0 | J9: =D9+E9 -> 15 | K9: =H9+I9 -> 0 | L9: =MOD(WEEKDAY(A9,2)-1,7) -> 1 | M9: =MONTH(A9) -> 1 | N9: =SUMIFS(J$3:J9,$B$3:$B9,B9) -> 210
A10: 2026-01-21 | B10: João Carlos | C10: 3 | D10: 0 | E10: 28 | F10: 0 | G10: 1 | H10: 0 | I10: 0 | J10: =D10+E10 -> 28 | K10: =H10+I10 -> 0 | L10: =MOD(WEEKDAY(A10,2)-1,7) -> 2 | M10: =MONTH(A10) -> 1 | N10: =SUMIFS(J$3:J10,$B$3:$B10,B10) -> 238
A11: 2026-01-22 | B11: João Carlos | C11: 3 | D11: 0 | E11: 12 | F11: 6 | G11: 0 | H11: 0 | I11: 0 | J11: =D11+E11 -> 12 | K11: =H11+I11 -> 0 | L11: =MOD(WEEKDAY(A11,2)-1,7) -> 3 | M11: =MONTH(A11) -> 1 | N11: =SUMIFS(J$3:J11,$B$3:$B11,B11) -> 250
A12: 2026-01-23 | B12: João Carlos | C12: 3 | D12: 0 | E12: 12 | F12: 6 | G12: 1 | H12: 0 | I12: 0 | J12: =D12+E12 -> 12 | K12: =H12+I12 -> 0 | L12: =MOD(WEEKDAY(A12,2)-1,7) -> 4 | M12: =MONTH(A12) -> 1 | N12: =SUMIFS(J$3:J12,$B$3:$B12,B12) -> 262
A13: 2026-01-24 | B13: João Carlos | C13: 3 | D13: 0 | E13: 12 | F13: 0 | G13: 2 | H13: 0 | I13: 0 | J13: =D13+E13 -> 12 | K13: =H13+I13 -> 0 | L13: =MOD(WEEKDAY(A13,2)-1,7) -> 5 | M13: =MONTH(A13) -> 1 | N13: =SUMIFS(J$3:J13,$B$3:$B13,B13) -> 274
A14: 2026-01-27 | B14: João Carlos | C14: 3 | D14: 0 | E14: 6 | F14: 6 | G14: 0 | H14: 0 | I14: 0 | J14: =D14+E14 -> 6 | K14: =H14+I14 -> 0 | L14: =MOD(WEEKDAY(A14,2)-1,7) -> 1 | M14: =MONTH(A14) -> 1 | N14: =SUMIFS(J$3:J14,$B$3:$B14,B14) -> 280
... A369: 2026-03-19 | B369: Vila Israel | C369: 6 | D369: 0 | E369: 0 | F369: 0 | G369: 0 | H369: 2 | I369: 1 | J369: =D369+E369 -> 0 | K369: =H369+I369 -> 3 | L369: =MOD(WEEKDAY(A369,2)-1,7) -> 3 | M369: =MONTH(A369) -> 3 | N369: =SUMIFS(J$3:J369,$B$3:$B369,B369) -> 464
A370: TOTAL | D370: =SUM(D3:D369) -> 802 | E370: =SUM(E3:E369) -> 5116.26 | F370: =SUM(F3:F369) -> 3128.77 | G370: =SUM(G3:G369) -> 105 | H370: =SUM(H3:H369) -> 98 | I370: =SUM(I3:I369) -> 799 | J370: =D370+E370 -> 5918.26 | K370: =H370+I370 -> 897 | N370: =SUMIFS(J$3:J370,$B$3:$B370,B370) -> 0

Sheet PROJETO
A1: PROJETO — AZUL = editável | Executado puxa de DADOS com SUMIFS
A3: NÚCLEO | B3: PROJ AG | C3: PROJ ESG | D3: PROJ TOTAL | E3: EXEC AG | F3: EXEC ESG | G3: EXEC TOTAL | H3: MESES | I3: EQ | J3: FONTE
A4: SM+JC | B4: 6000 | C4: 6000 | D4: =B4+C4 -> 12000 | E4: =SUMIFS(DADOS!E3:E369,DADOS!B3:B369,"São Manoel")+SUMIFS(DADOS!E3:E369,DADOS!B3:B369,"João Carlos") -> 2145.16 | F4: =SUMIFS(DADOS!D3:D369,DADOS!B3:B369,"São Manoel")+SUMIFS(DADOS!D3:D369,DADOS!B3:B369,"João Carlos") -> 300 | G4: =E4+F4 -> 2445.16 | H4: 4 | I4: 9 | J4: SUMIFS de DADOS
A5: ISRAEL | B5: 1900 | C5: 1900 | D5: =B5+C5 -> 3800 | E5: =SUMIFS(DADOS!E3:E369,DADOS!B3:B369,"Vila Israel") -> 416 | F5: =SUMIFS(DADOS!D3:D369,DADOS!B3:B369,"Vila Israel") -> 48 | G5: =E5+F5 -> 464 | H5: 0 | I5: 4 | J5: SUMIFS de DADOS
A6: TETEU | B6: 5000 | C6: 5000 | D6: =B6+C6 -> 10000 | E6: =SUMIFS(DADOS!E3:E369,DADOS!B3:B369,"Morro Tetéu") -> 1029.1 | F6: =SUMIFS(DADOS!D3:D369,DADOS!B3:B369,"Morro Tetéu") -> 226 | G6: =E6+F6 -> 1255.1 | H6: 5 | I6: 10 | J6: SUMIFS de DADOS
A7: CRIADORES | B7: 5000 | C7: 5000 | D7: =B7+C7 -> 10000 | E7: =SUMIFS(DADOS!E3:E369,DADOS!B3:B369,"Vila Criadores") -> 822 | F7: =SUMIFS(DADOS!D3:D369,DADOS!B3:B369,"Vila Criadores") -> 58 | G7: =E7+F7 -> 880 | H7: 5 | I7: 8 | J7: SUMIFS de DADOS
A8: PANTANAL | B8: 4000 | C8: 4000 | D8: =B8+C8 -> 8000 | E8: =SUMIFS(DADOS!E3:E369,DADOS!B3:B369,"Pantanal Baixo") -> 704 | F8: =SUMIFS(DADOS!D3:D369,DADOS!B3:B369,"Pantanal Baixo") -> 170 | G8: =E8+F8 -> 874 | H8: 5 | I8: 8 | J8: SUMIFS de DADOS
A9: TOTAL | B9: =SUM(B4:B8) -> 21900 | C9: =SUM(C4:C8) -> 21900 | D9: =SUM(D4:D8) -> 43800 | E9: =SUM(E4:E8) -> 5116.26 | F9: =SUM(F4:F8) -> 802 | G9: =SUM(G4:G8) -> 5918.26
A11: MÉTRICAS DERIVADAS (fórmulas)
A12: Total ligações | B12: =SUM(B5:B11) -> 37800 | C12: =SUM(C5:C11) -> 37800 | D12: =SUM(D5:D11) -> 75600 | E12: =SUM(E5:E11) -> 8087.36 | F12: =SUM(F5:F11) -> 1304 | G12: =SUM(G5:G11) -> 9391.36
A13: Dias produtivos | B13: =COUNTA(DADOS!A3:A369) -> 367
A14: Lig/dia médio | B14: =B12/B13 -> 102.99728
A15: Rede/dia médio | B15: =PROJETO!G9/B13 -> 16.126049
A16: m/ligação | B16: =IF(B12>0,PROJETO!G9/B12,0) -> 0.15656772
A17: Lig/mês (÷2.5) | B17: =ROUND(B12/2.5,0) -> 15120
A18: Meta SABESP | B18: 1044
A19: GAP | B19: =B18-B17 -> -14076
A20: GAP % | B20: =IF(B18>0,B19/B18,0) -> -13.482759
A21: Fator multiplicador | B21: =IF(B17>0,B18/B17,0) -> 0.069047619

Sheet SALDO
A1: SALDO — 100% fórmulas de PROJETO
A3: NÚCLEO | B3: SALDO AG | C3: SALDO ESG | D3: SALDO TOTAL | E3: % AG | F3: % ESG | G3: % TOTAL | H3: STATUS AG | I3: STATUS ESG | J3: MESES | K3: RITMO AG/mês | L3: RITMO ESG/mês
A4: =PROJETO!A4 -> SM+JC | B4: =MAX(0,PROJETO!B4-PROJETO!E4) -> 3854.84 | C4: =MAX(0,PROJETO!C4-PROJETO!F4) -> 5700 | D4: =B4+C4 -> 9554.84 | E4: =IF(PROJETO!B4>0,PROJETO!E4/PROJETO!B4,0) -> 0.35752667 | F4: =IF(PROJETO!C4>0,PROJETO!F4/PROJETO!C4,0) -> 0.05 | G4: =IF(PROJETO!D4>0,PROJETO!G4/PROJETO!D4,0) -> 0.20376333 | H4: =IF(E4>=1,"PRONTO",IF(E4>=0.8,"FINALIZANDO","EM EXECUÇÃO")) -> EM EXECUÇÃO | I4: =IF(F4>=1,"PRONTO",IF(F4>=0.8,"FINALIZANDO","EM EXECUÇÃO")) -> EM EXECUÇÃO | J4: =PROJETO!H4 -> 4 | K4: =IF(H4="PRONTO",0,IF(J4>0,B4/J4,0)) -> 963.71 | L4: =IF(I4="PRONTO",0,IF(J4>0,C4/J4,0)) -> 1425
A5: =PROJETO!A5 -> ISRAEL | B5: =MAX(0,PROJETO!B5-PROJETO!E5) -> 1484 | C5: =MAX(0,PROJETO!C5-PROJETO!F5) -> 1852 | D5: =B5+C5 -> 3336 | E5: =IF(PROJETO!B5>0,PROJETO!E5/PROJETO!B5,0) -> 0.21894737 | F5: =IF(PROJETO!C5>0,PROJETO!F5/PROJETO!C5,0) -> 0.025263158 | G5: =IF(PROJETO!D5>0,PROJETO!G5/PROJETO!D5,0) -> 0.12210526 | H5: =IF(E5>=1,"PRONTO",IF(E5>=0.8,"FINALIZANDO","EM EXECUÇÃO")) -> EM EXECUÇÃO | I5: =IF(F5>=1,"PRONTO",IF(F5>=0.8,"FINALIZANDO","EM EXECUÇÃO")) -> EM EXECUÇÃO | J5: =PROJETO!H5 -> 0 | K5: =IF(H5="PRONTO",0,IF(J5>0,B5/J5,0)) -> 0 | L5: =IF(I5="PRONTO",0,IF(J5>0,C5/J5,0)) -> 0
A6: =PROJETO!A6 -> TETEU | B6: =MAX(0,PROJETO!B6-PROJETO!E6) -> 3970.9 | C6: =MAX(0,PROJETO!C6-PROJETO!F6) -> 4774 | D6: =B6+C6 -> 8744.9 | E6: =IF(PROJETO!B6>0,PROJETO!E6/PROJETO!B6,0) -> 0.20582 | F6: =IF(PROJETO!C6>0,PROJETO!F6/PROJETO!C6,0) -> 0.0452 | G6: =IF(PROJETO!D6>0,PROJETO!G6/PROJETO!D6,0) -> 0.12551 | H6: =IF(E6>=1,"PRONTO",IF(E6>=0.8,"FINALIZANDO","EM EXECUÇÃO")) -> EM EXECUÇÃO | I6: =IF(F6>=1,"PRONTO",IF(F6>=0.8,"FINALIZANDO","EM EXECUÇÃO")) -> EM EXECUÇÃO | J6: =PROJETO!H6 -> 5 | K6: =IF(H6="PRONTO",0,IF(J6>0,B6/J6,0)) -> 794.18 | L6: =IF(I6="PRONTO",0,IF(J6>0,C6/J6,0)) -> 954.8
A7: =PROJETO!A7 -> CRIADORES | B7: =MAX(0,PROJETO!B7-PROJETO!E7) -> 4178 | C7: =MAX(0,PROJETO!C7-PROJETO!F7) -> 4942 | D7: =B7+C7 -> 9120 | E7: =IF(PROJETO!B7>0,PROJETO!E7/PROJETO!B7,0) -> 0.1644 | F7: =IF(PROJETO!C7>0,PROJETO!F7/PROJETO!C7,0) -> 0.0116 | G7: =IF(PROJETO!D7>0,PROJETO!G7/PROJETO!D7,0) -> 0.088 | H7: =IF(E7>=1,"PRONTO",IF(E7>=0.8,"FINALIZANDO","EM EXECUÇÃO")) -> EM EXECUÇÃO | I7: =IF(F7>=1,"PRONTO",IF(F7>=0.8,"FINALIZANDO","EM EXECUÇÃO")) -> EM EXECUÇÃO | J7: =PROJETO!H7 -> 5 | K7: =IF(H7="PRONTO",0,IF(J7>0,B7/J7,0)) -> 835.6 | L7: =IF(I7="PRONTO",0,IF(J7>0,C7/J7,0)) -> 988.4
A8: =PROJETO!A8 -> PANTANAL | B8: =MAX(0,PROJETO!B8-PROJETO!E8) -> 3296 | C8: =MAX(0,PROJETO!C8-PROJETO!F8) -> 3830 | D8: =B8+C8 -> 7126 | E8: =IF(PROJETO!B8>0,PROJETO!E8/PROJETO!B8,0) -> 0.176 | F8: =IF(PROJETO!C8>0,PROJETO!F8/PROJETO!C8,0) -> 0.0425 | G8: =IF(PROJETO!D8>0,PROJETO!G8/PROJETO!D8,0) -> 0.10925 | H8: =IF(E8>=1,"PRONTO",IF(E8>=0.8,"FINALIZANDO","EM EXECUÇÃO")) -> EM EXECUÇÃO | I8: =IF(F8>=1,"PRONTO",IF(F8>=0.8,"FINALIZANDO","EM EXECUÇÃO")) -> EM EXECUÇÃO | J8: =PROJETO!H8 -> 5 | K8: =IF(H8="PRONTO",0,IF(J8>0,B8/J8,0)) -> 659.2 | L8: =IF(I8="PRONTO",0,IF(J8>0,C8/J8,0)) -> 766
A9: TOTAL | B9: =SUM(B4:B8) -> 16783.74 | C9: =SUM(C4:C8) -> 21098 | D9: =SUM(D4:D8) -> 37881.74 | E9: =IF(PROJETO!B9>0,PROJETO!E9/PROJETO!B9,0) -> 0.23361918 | F9: =IF(PROJETO!C9>0,PROJETO!F9/PROJETO!C9,0) -> 0.036621005 | G9: =IF(PROJETO!D9>0,PROJETO!G9/PROJETO!D9,0) -> 0.13512009

Sheet ML_RESULTADOS
A1: XGBOOST RESULTADOS — R²=0.228 | 142 amostras | GridSearchCV 324 modelos
A3: FEATURE IMPORTANCE (o que mais importa pra gerar ligações)
A4: FEATURE | B4: IMPORTÂNCIA | C4: % | D4: BARRA | E4: INTERPRETAÇÃO
A5: lig_r3 | B5: 0.2845 | C5: =IF(SUM(B5:B15)>0,B5/SUM(B5:B15)*100,0) -> 28.452846 | D5: ██████████████ | E5: Momentum ligações 3d — FATOR #1. Manter ritmo > ter mais gente.
A6: rede_r3 | B6: 0.102 | C6: =IF(SUM(B5:B15)>0,B6/SUM(B5:B15)*100,0) -> 10.20102 | D6: █████ | E6: Ritmo de rede últimos 3 dias.
A7: rede_acum | B7: 0.1013 | C7: =IF(SUM(B5:B15)>0,B7/SUM(B5:B15)*100,0) -> 10.131013 | D7: █████ | E7: Rede acumulada pronta. Mais rede → mais potencial de ligação.
A8: PRE | B8: 0.087099999 | C8: =IF(SUM(B5:B15)>0,B8/SUM(B5:B15)*100,0) -> 8.710871 | D8: ████ | E8: Pré-assentamento. Preparação do terreno.
A9: lig_r7 | B9: 0.086499996 | C9: =IF(SUM(B5:B15)>0,B9/SUM(B5:B15)*100,0) -> 8.6508647 | D9: ████ | E9: Ritmo de ligações 7 dias. Estabilidade.
A10: rede_r7 | B10: 0.072999999 | C10: =IF(SUM(B5:B15)>0,B10/SUM(B5:B15)*100,0) -> 7.30073 | D10: ███ | E10: Ritmo de rede últimos 7 dias.
A11: equipes | B11: 0.071800001 | C11: =IF(SUM(B5:B15)>0,B11/SUM(B5:B15)*100,0) -> 7.1807182 | D11: ███ | E11: Equipes em campo. APENAS 5% — NÃO é o fator principal!
A12: dia_sem | B12: 0.070900001 | C12: =IF(SUM(B5:B15)>0,B12/SUM(B5:B15)*100,0) -> 7.0907091 | D12: ███ | E12: Dia da semana. Produção cai sexta/sábado.
A13: PVs | B13: 0.046 | C13: =IF(SUM(B5:B15)>0,B13/SUM(B5:B15)*100,0) -> 4.6004601 | D13: ██ | E13: PVs executados. Indicador de rede pronta.
A14: nuc_enc | B14: 0.042399999 | C14: =IF(SUM(B5:B15)>0,B14/SUM(B5:B15)*100,0) -> 4.2404239 | D14: ██ | E14: Qual núcleo. Pouca diferença (bom!)
A15: mes | B15: 0.034400001 | C15: =IF(SUM(B5:B15)>0,B15/SUM(B5:B15)*100,0) -> 3.4403442 | D15: █ | E15: Mês do ano. Janeiro fraco, fevereiro melhora.
A18: REAL vs PREDITO (dados para gráfico)
A19: Real | B19: Predito | C19: Núcleo | D19: Erro
A20: 7 | B20: 5.4 | C20: João Carlos | D20: =ABS(A20-B20) -> 1.6
A21: 15 | B21: 14.2 | C21: João Carlos | D21: =ABS(A21-B21) -> 0.8
A22: 12 | B22: 15.1 | C22: João Carlos | D22: =ABS(A22-B22) -> 3.1
A23: 23 | B23: 15.9 | C23: João Carlos | D23: =ABS(A23-B23) -> 7.1
A24: 16 | B24: 14.2 | C24: João Carlos | D24: =ABS(A24-B24) -> 1.8
A25: 13 | B25: 13.2 | C25: João Carlos | D25: =ABS(A25-B25) -> 0.2
A26: 14 | B26: 8.1 | C26: João Carlos | D26: =ABS(A26-B26) -> 5.9
A27: 4 | B27: 5.8 | C27: João Carlos | D27: =ABS(A27-B27) -> 1.8
A28: 9 | B28: 8.9 | C28: João Carlos | D28: =ABS(A28-B28) -> 0.1
A29: 4 | B29: 6.4 | C29: João Carlos | D29: =ABS(A29-B29) -> 2.4
A30: 7 | B30: 7.9 | C30: João Carlos | D30: =ABS(A30-B30) -> 0.9
A31: 6 | B31: 6.8 | C31: João Carlos | D31: =ABS(A31-B31) -> 0.8
... A161: 3 | B161: 2.9 | C161: Vila Israel | D161: =ABS(A161-B161) -> 0.1
A163: MAE | B163: =AVERAGE(D20:D161) -> 1.9809859
A164: RMSE | B164: =SQRT(SUMPRODUCT((A20:A161-B20:B161)^2)/COUNT(A20:A161)) -> 2.5739075
A165: R² | B165: =1-SUMPRODUCT((A20:A161-B20:B161)^2)/SUMPRODUCT((A20:A161-AVERAGE(A20:A161))^2) -> 0.75882778 | C165: REDE TOTAL | D165: LIG TOTAL | E165: REDE/DIA | F165: LIG/DIA | G165: EQUIPES | H165: m/eq/dia
A166: João Carlos | B166: 67 | C166: 943 | D166: 166 | E166: 14.1 | F166: 2.5 | G166: 3 | H166: =E166/G166 -> 4.7
A167: Morro Tetéu | B167: 72 | C167: 1255 | D167: 196 | E167: 17.4 | F167: 2.7 | G167: 4 | H167: =E167/G167 -> 4.35
A168: Pantanal Baixo | B168: 72 | C168: 874 | D168: 91 | E168: 12.1 | F168: 1.3 | G168: 8 | H168: =E168/G168 -> 1.5125
A169: São Manoel | B169: 62 | C169: 1502 | D169: 127 | E169: 24.2 | F169: 2 | G169: 8 | H169: =E169/G169 -> 3.025
A170: Vila Criadores | B170: 56 | C170: 880 | D170: 212 | E170: 15.7 | F170: 3.8 | G170: 7 | H170: =E170/G170 -> 2.2428571
A171: Vila Israel | B171: 38 | C171: 464 | D171: 105 | E171: 12.2 | F171: 2.8 | G171: 6 | H171: =E171/G171 -> 2.0333333

Sheet MATERIAIS
A1: MATERIAIS — AMARELO = fatores editáveis | Calcula de SALDO automaticamente
A3: MATERIAL | B3: UN | C3: REDE | D3: FATOR | E3: P.UNIT | F3: LEAD
A4: Tubo PVC DN200 | B4: m | C4: ESG | D4: 0.6 | E4: 200.12 | F4: 3 sem
A5: Tubo PVC DN300 | B5: m | C5: ESG | D5: 0.4 | E5: 310 | F5: =D5*E5 -> 124
A6: Tubo PEAD DN63 | B6: m | C6: AG | D6: 0.7 | E6: 85 | F6: =D6*E6 -> 59.5
A7: Tubo PEAD DN110 | B7: m | C7: AG | D7: 0.3 | E7: 101.8 | F7: =D7*E7 -> 30.54
A8: PV concreto DN1200 | B8: un | C8: ESG | D8: 0.068 | E8: 3686 | F8: =D8*E8 -> 250.648
A9: PI plástico DN600 | B9: un | C9: ESG | D9: 0.022 | E9: 1412 | F9: =D9*E9 -> 31.064
A10: Caixa inspeção | B10: un | C10: ESG | D10: 0.055 | E10: 1034 | F10: =D10*E10 -> 56.87
A11: Sela eletrofusão | B11: un | C11: AG | D11: 0.022 | E11: 660 | F11: =D11*E11 -> 14.52
A12: Cavalete/hidrom. | B12: un | C12: AG | D12: 0.017 | E12: 490 | F12: =D12*E12 -> 8.33
A13: Areia berço | B13: m³ | C13: AMB | D13: 0.49 | E13: 160 | F13: =D13*E13 -> 78.4
A14: Brita base | B14: m³ | C14: AMB | D14: 0.22 | E14: 210 | F14: =D14*E14 -> 46.2
A15: Concreto | B15: m³ | C15: AMB | D15: 0.18 | E15: 720 | F15: =D15*E15 -> 129.6
A16: CBUQ repavim. | B16: t | C16: AMB | D16: 0.22 | E16: 820 | F16: =D16*E16 -> 180.4
A17: Conexões diversas | B17: vb | C17: AMB | D17: 0.011 | E17: 120 | F17: =D17*E17 -> 1.32
A20: QTD = SALDO × FATOR (tudo fórmula)
A21: MATERIAL | B21: REDE | C21: SM+JC | D21: ISRAEL | E21: TETEU | F21: CRIADORES | G21: PANTANAL | H21: TOTAL | I21: CUSTO
A22: =A4 -> Tubo PVC DN200 | B22: =C4 -> ESG | C22: =MAX(0,SALDO!C4)*$D$4 -> 3420 | D22: =MAX(0,SALDO!C5)*$D$4 -> 1111.2 | E22: =MAX(0,SALDO!C6)*$D$4 -> 2864.4 | F22: =MAX(0,SALDO!C7)*$D$4 -> 2965.2 | G22: =MAX(0,SALDO!C8)*$D$4 -> 2298 | H22: =SUM(C22:G22) -> 12658.8 | I22: =H22*$E$4 -> 2533279.1
A23: =A5 -> Tubo PVC DN300 | B23: =C5 -> ESG | C23: =MAX(0,SALDO!C4)*$D$5 -> 2280 | D23: =MAX(0,SALDO!C5)*$D$5 -> 740.8 | E23: =MAX(0,SALDO!C6)*$D$5 -> 1909.6 | F23: =MAX(0,SALDO!C7)*$D$5 -> 1976.8 | G23: =MAX(0,SALDO!C8)*$D$5 -> 1532 | H23: =SUM(C23:G23) -> 8439.2 | I23: =H23*$E$5 -> 2616152
A24: =A6 -> Tubo PEAD DN63 | B24: =C6 -> AG | C24: =MAX(0,SALDO!B4)*$D$6 -> 2698.388 | D24: =MAX(0,SALDO!B5)*$D$6 -> 1038.8 | E24: =MAX(0,SALDO!B6)*$D$6 -> 2779.63 | F24: =MAX(0,SALDO!B7)*$D$6 -> 2924.6 | G24: =MAX(0,SALDO!B8)*$D$6 -> 2307.2 | H24: =SUM(C24:G24) -> 11748.618 | I24: =H24*$E$6 -> 998632.53
A25: =A7 -> Tubo PEAD DN110 | B25: =C7 -> AG | C25: =MAX(0,SALDO!B4)*$D$7 -> 1156.452 | D25: =MAX(0,SALDO!B5)*$D$7 -> 445.2 | E25: =MAX(0,SALDO!B6)*$D$7 -> 1191.27 | F25: =MAX(0,SALDO!B7)*$D$7 -> 1253.4 | G25: =MAX(0,SALDO!B8)*$D$7 -> 988.8 | H25: =SUM(C25:G25) -> 5035.122 | I25: =H25*$E$7 -> 512575.42
A26: =A8 -> PV concreto DN1200 | B26: =C8 -> ESG | C26: =MAX(0,SALDO!C4)*$D$8 -> 387.6 | D26: =MAX(0,SALDO!C5)*$D$8 -> 125.936 | E26: =MAX(0,SALDO!C6)*$D$8 -> 324.632 | F26: =MAX(0,SALDO!C7)*$D$8 -> 336.056 | G26: =MAX(0,SALDO!C8)*$D$8 -> 260.44 | H26: =SUM(C26:G26) -> 1434.664 | I26: =H26*$E$8 -> 5288171.5
A27: =A9 -> PI plástico DN600 | B27: =C9 -> ESG | C27: =MAX(0,SALDO!C4)*$D$9 -> 125.4 | D27: =MAX(0,SALDO!C5)*$D$9 -> 40.744 | E27: =MAX(0,SALDO!C6)*$D$9 -> 105.028 | F27: =MAX(0,SALDO!C7)*$D$9 -> 108.724 | G27: =MAX(0,SALDO!C8)*$D$9 -> 84.26 | H27: =SUM(C27:G27) -> 464.156 | I27: =H27*$E$9 -> 655388.27
A28: =A10 -> Caixa inspeção | B28: =C10 -> ESG | C28: =MAX(0,SALDO!C4)*$D$10 -> 313.5 | D28: =MAX(0,SALDO!C5)*$D$10 -> 101.86 | E28: =MAX(0,SALDO!C6)*$D$10 -> 262.57 | F28: =MAX(0,SALDO!C7)*$D$10 -> 271.81 | G28: =MAX(0,SALDO!C8)*$D$10 -> 210.65 | H28: =SUM(C28:G28) -> 1160.39 | I28: =H28*$E$10 -> 1199843.3
A29: =A11 -> Sela eletrofusão | B29: =C11 -> AG | C29: =MAX(0,SALDO!B4)*$D$11 -> 84.80648 | D29: =MAX(0,SALDO!B5)*$D$11 -> 32.648 | E29: =MAX(0,SALDO!B6)*$D$11 -> 87.3598 | F29: =MAX(0,SALDO!B7)*$D$11 -> 91.916 | G29: =MAX(0,SALDO!B8)*$D$11 -> 72.512 | H29: =SUM(C29:G29) -> 369.24228 | I29: =H29*$E$11 -> 243699.9
A30: =A12 -> Cavalete/hidrom. | B30: =C12 -> AG | C30: =MAX(0,SALDO!B4)*$D$12 -> 65.53228 | D30: =MAX(0,SALDO!B5)*$D$12 -> 25.228 | E30: =MAX(0,SALDO!B6)*$D$12 -> 67.5053 | F30: =MAX(0,SALDO!B7)*$D$12 -> 71.026 | G30: =MAX(0,SALDO!B8)*$D$12 -> 56.032 | H30: =SUM(C30:G30) -> 285.32358 | I30: =H30*$E$12 -> 139808.55
A31: =A13 -> Areia berço | B31: =C13 -> AMB | C31: =MAX(0,SALDO!D4)*$D$13 -> 4681.8716 | D31: =MAX(0,SALDO!D5)*$D$13 -> 1634.64 | E31: =MAX(0,SALDO!D6)*$D$13 -> 4285.001 | F31: =MAX(0,SALDO!D7)*$D$13 -> 4468.8 | G31: =MAX(0,SALDO!D8)*$D$13 -> 3491.74 | H31: =SUM(C31:G31) -> 18562.053 | I31: =H31*$E$13 -> 2969928.4
A32: =A14 -> Brita base | B32: =C14 -> AMB | C32: =MAX(0,SALDO!D4)*$D$14 -> 2102.0648 | D32: =MAX(0,SALDO!D5)*$D$14 -> 733.92 | E32: =MAX(0,SALDO!D6)*$D$14 -> 1923.878 | F32: =MAX(0,SALDO!D7)*$D$14 -> 2006.4 | G32: =MAX(0,SALDO!D8)*$D$14 -> 1567.72 | H32: =SUM(C32:G32) -> 8333.9828 | I32: =H32*$E$14 -> 1750136.4
A33: =A15 -> Concreto | B33: =C15 -> AMB | C33: =MAX(0,SALDO!D4)*$D$15 -> 1719.8712 | D33: =MAX(0,SALDO!D5)*$D$15 -> 600.48 | E33: =MAX(0,SALDO!D6)*$D$15 -> 1574.082 | F33: =MAX(0,SALDO!D7)*$D$15 -> 1641.6 | G33: =MAX(0,SALDO!D8)*$D$15 -> 1282.68 | H33: =SUM(C33:G33) -> 6818.7132 | I33: =H33*$E$15 -> 4909473.5
A34: =A16 -> CBUQ repavim. | B34: =C16 -> AMB | C34: =MAX(0,SALDO!D4)*$D$16 -> 2102.0648 | D34: =MAX(0,SALDO!D5)*$D$16 -> 733.92 | E34: =MAX(0,SALDO!D6)*$D$16 -> 1923.878 | F34: =MAX(0,SALDO!D7)*$D$16 -> 2006.4 | G34: =MAX(0,SALDO!D8)*$D$16 -> 1567.72 | H34: =SUM(C34:G34) -> 8333.9828 | I34: =H34*$E$16 -> 6833865.9
A35: =A17 -> Conexões diversas | B35: =C17 -> AMB | C35: =MAX(0,SALDO!D4)*$D$17 -> 105.10324 | D35: =MAX(0,SALDO!D5)*$D$17 -> 36.696 | E35: =MAX(0,SALDO!D6)*$D$17 -> 96.1939 | F35: =MAX(0,SALDO!D7)*$D$17 -> 100.32 | G35: =MAX(0,SALDO!D8)*$D$17 -> 78.386 | H35: =SUM(C35:G35) -> 416.69914 | I35: =H35*$E$17 -> 50003.897
A36: TOTAL | I36: =SUM(I22:I35) -> 30700959

Sheet PEDIDO_URGENTE
A1: PEDIDO URGENTE — Próximos 30 dias | Fórmulas de MATERIAIS÷meses
A3: MATERIAL | B3: UN | C3: QTD/MÊS | D3: P.UNIT | E3: CUSTO/MÊS | F3: LEAD
A4: =MATERIAIS!A22 -> Tubo PVC DN200 | B4: =MATERIAIS!B4 -> m | C4: =IF(MAX(PROJETO!H4:H8)>0,MATERIAIS!H22/MAX(PROJETO!H4:H8),0) -> 2531.76 | D4: =MATERIAIS!E4 -> 200.12 | E4: =C4*D4 -> 506655.81 | F4: =MATERIAIS!F4 -> 3 sem
A5: =MATERIAIS!A23 -> Tubo PVC DN300 | B5: =MATERIAIS!B5 -> m | C5: =IF(MAX(PROJETO!H4:H8)>0,MATERIAIS!H23/MAX(PROJETO!H4:H8),0) -> 1687.84 | D5: =MATERIAIS!E5 -> 310 | E5: =C5*D5 -> 523230.4 | F5: =MATERIAIS!F5 -> 124
A6: =MATERIAIS!A24 -> Tubo PEAD DN63 | B6: =MATERIAIS!B6 -> m | C6: =IF(MAX(PROJETO!H4:H8)>0,MATERIAIS!H24/MAX(PROJETO!H4:H8),0) -> 2349.7236 | D6: =MATERIAIS!E6 -> 85 | E6: =C6*D6 -> 199726.51 | F6: =MATERIAIS!F6 -> 59.5
A7: =MATERIAIS!A25 -> Tubo PEAD DN110 | B7: =MATERIAIS!B7 -> m | C7: =IF(MAX(PROJETO!H4:H8)>0,MATERIAIS!H25/MAX(PROJETO!H4:H8),0) -> 1007.0244 | D7: =MATERIAIS!E7 -> 101.8 | E7: =C7*D7 -> 102515.08 | F7: =MATERIAIS!F7 -> 30.54
A8: =MATERIAIS!A26 -> PV concreto DN1200 | B8: =MATERIAIS!B8 -> un | C8: =IF(MAX(PROJETO!H4:H8)>0,MATERIAIS!H26/MAX(PROJETO!H4:H8),0) -> 286.9328 | D8: =MATERIAIS!E8 -> 3686 | E8: =C8*D8 -> 1057634.3 | F8: =MATERIAIS!F8 -> 250.648
A9: =MATERIAIS!A27 -> PI plástico DN600 | B9: =MATERIAIS!B9 -> un | C9: =IF(MAX(PROJETO!H4:H8)>0,MATERIAIS!H27/MAX(PROJETO!H4:H8),0) -> 92.8312 | D9: =MATERIAIS!E9 -> 1412 | E9: =C9*D9 -> 131077.65 | F9: =MATERIAIS!F9 -> 31.064
A10: =MATERIAIS!A28 -> Caixa inspeção | B10: =MATERIAIS!B10 -> un | C10: =IF(MAX(PROJETO!H4:H8)>0,MATERIAIS!H28/MAX(PROJETO!H4:H8),0) -> 232.078 | D10: =MATERIAIS!E10 -> 1034 | E10: =C10*D10 -> 239968.65 | F10: =MATERIAIS!F10 -> 56.87
A11: =MATERIAIS!A29 -> Sela eletrofusão | B11: =MATERIAIS!B11 -> un | C11: =IF(MAX(PROJETO!H4:H8)>0,MATERIAIS!H29/MAX(PROJETO!H4:H8),0) -> 73.848456 | D11: =MATERIAIS!E11 -> 660 | E11: =C11*D11 -> 48739.981 | F11: =MATERIAIS!F11 -> 14.52
A12: =MATERIAIS!A30 -> Cavalete/hidrom. | B12: =MATERIAIS!B12 -> un | C12: =IF(MAX(PROJETO!H4:H8)>0,MATERIAIS!H30/MAX(PROJETO!H4:H8),0) -> 57.064716 | D12: =MATERIAIS!E12 -> 490 | E12: =C12*D12 -> 27961.711 | F12: =MATERIAIS!F12 -> 8.33
A13: =MATERIAIS!A31 -> Areia berço | B13: =MATERIAIS!B13 -> m³ | C13: =IF(MAX(PROJETO!H4:H8)>0,MATERIAIS!H31/MAX(PROJETO!H4:H8),0) -> 3712.4105 | D13: =MATERIAIS!E13 -> 160 | E13: =C13*D13 -> 593985.68 | F13: =MATERIAIS!F13 -> 78.4
A14: =MATERIAIS!A32 -> Brita base | B14: =MATERIAIS!B14 -> m³ | C14: =IF(MAX(PROJETO!H4:H8)>0,MATERIAIS!H32/MAX(PROJETO!H4:H8),0) -> 1666.7966 | D14: =MATERIAIS!E14 -> 210 | E14: =C14*D14 -> 350027.28 | F14: =MATERIAIS!F14 -> 46.2
A15: =MATERIAIS!A33 -> Concreto | B15: =MATERIAIS!B15 -> m³ | C15: =IF(MAX(PROJETO!H4:H8)>0,MATERIAIS!H33/MAX(PROJETO!H4:H8),0) -> 1363.7426 | D15: =MATERIAIS!E15 -> 720 | E15: =C15*D15 -> 981894.7 | F15: =MATERIAIS!F15 -> 129.6
A16: =MATERIAIS!A34 -> CBUQ repavim. | B16: =MATERIAIS!B16 -> t | C16: =IF(MAX(PROJETO!H4:H8)>0,MATERIAIS!H34/MAX(PROJETO!H4:H8),0) -> 1666.7966 | D16: =MATERIAIS!E16 -> 820 | E16: =C16*D16 -> 1366773.2 | F16: =MATERIAIS!F16 -> 180.4
A17: =MATERIAIS!A35 -> Conexões diversas | B17: =MATERIAIS!B17 -> vb | C17: =IF(MAX(PROJETO!H4:H8)>0,MATERIAIS!H35/MAX(PROJETO!H4:H8),0) -> 83.339828 | D17: =MATERIAIS!E17 -> 120 | E17: =C17*D17 -> 10000.779 | F17: =MATERIAIS!F17 -> 1.32
A18: TOTAL | E18: =SUM(E4:E17) -> 6140191.7

Sheet DASHBOARD
A1: DASHBOARD — 100% FÓRMULAS | Muda DADOS → muda TUDO
A3: =PROJETO!B17 -> 15120 | D3: =SALDO!G9 -> 0.13512009 | G3: =SALDO!D9 -> 37881.74 | J3: =MATERIAIS!I36 -> 30700959
A4: LIG/MÊS (meta: 1.044) | D4: % EXECUÇÃO | G4: SALDO (m) | J4: COMPRAS MAT.
A6: PROGRESSO (fórmulas de PROJETO → SALDO)
A7: NÚCLEO | B7: PROJ | C7: EXEC | D7: SALDO | E7: % | F7: STATUS AG | G7: STATUS ESG | H7: RITMO AG | I7: RITMO ESG | J7: EQ | K7: CUSTO SALDO
A8: =PROJETO!A4 -> SM+JC | B8: =PROJETO!D4 -> 12000 | C8: =PROJETO!G4 -> 2445.16 | D8: =SALDO!D4 -> 9554.84 | E8: =SALDO!G4 -> 0.20376333 | F8: =SALDO!H4 -> EM EXECUÇÃO | G8: =SALDO!I4 -> EM EXECUÇÃO | H8: =SALDO!K4 -> 963.71 | I8: =SALDO!L4 -> 1425 | J8: =PROJETO!I4 -> 9 | K8: =SALDO!D4*910 -> 8694904.4
A9: =PROJETO!A5 -> ISRAEL | B9: =PROJETO!D5 -> 3800 | C9: =PROJETO!G5 -> 464 | D9: =SALDO!D5 -> 3336 | E9: =SALDO!G5 -> 0.12210526 | F9: =SALDO!H5 -> EM EXECUÇÃO | G9: =SALDO!I5 -> EM EXECUÇÃO | H9: =SALDO!K5 -> 0 | I9: =SALDO!L5 -> 0 | J9: =PROJETO!I5 -> 4 | K9: =SALDO!D5*910 -> 3035760
A10: =PROJETO!A6 -> TETEU | B10: =PROJETO!D6 -> 10000 | C10: =PROJETO!G6 -> 1255.1 | D10: =SALDO!D6 -> 8744.9 | E10: =SALDO!G6 -> 0.12551 | F10: =SALDO!H6 -> EM EXECUÇÃO | G10: =SALDO!I6 -> EM EXECUÇÃO | H10: =SALDO!K6 -> 794.18 | I10: =SALDO!L6 -> 954.8 | J10: =PROJETO!I6 -> 10 | K10: =SALDO!D6*910 -> 7957859
A11: =PROJETO!A7 -> CRIADORES | B11: =PROJETO!D7 -> 10000 | C11: =PROJETO!G7 -> 880 | D11: =SALDO!D7 -> 9120 | E11: =SALDO!G7 -> 0.088 | F11: =SALDO!H7 -> EM EXECUÇÃO | G11: =SALDO!I7 -> EM EXECUÇÃO | H11: =SALDO!K7 -> 835.6 | I11: =SALDO!L7 -> 988.4 | J11: =PROJETO!I7 -> 8 | K11: =SALDO!D7*910 -> 8299200
A12: =PROJETO!A8 -> PANTANAL | B12: =PROJETO!D8 -> 8000 | C12: =PROJETO!G8 -> 874 | D12: =SALDO!D8 -> 7126 | E12: =SALDO!G8 -> 0.10925 | F12: =SALDO!H8 -> EM EXECUÇÃO | G12: =SALDO!I8 -> EM EXECUÇÃO | H12: =SALDO!K8 -> 659.2 | I12: =SALDO!L8 -> 766 | J12: =PROJETO!I8 -> 8 | K12: =SALDO!D8*910 -> 6484660
A13: TOTAL | B13: =SUM(B8:B12) -> 43800 | C13: =SUM(C8:C12) -> 5918.26 | D13: =SUM(D8:D12) -> 37881.74 | E13: =IF(B13>0,C13/B13,0) -> 0.13512009 | J13: =SUM(J8:J12) -> 39 | K13: =SUM(K8:K12) -> 34472383
A15: ="Saldo: "&TEXT(SALDO!D9,"#,##0")&"m | Faturamento: R$ "&TEXT(SALDO!D9*910,"#,##0")&" | Compras: "&TEXT(MATERIAIS!I36,"R$ #,##0")&" | Urgente/mês: "&TEXT(PEDIDO_URGENTE!E18,"R$ #,##0") -> Saldo: 37,882m | Faturamento: R$ 34,472,383 | Compras: R$ 30,700,959 | Urgente/mês: R$ 6,140,192

Sheet METODO_ML
A1: MÉTODO ML — XGBoost + GridSearchCV + Seaborn | Como funciona
A3: 1. VISÃO GERAL — O que fizemos e por quê
A4: OBJETIVO: | B4: Descobrir o que MAIS INFLUENCIA a quantidade de ligações/dia em cada núcleo.
A5: POR QUÊ: | B5: Para saber ONDE investir — se o gargalo é equipe, material, ritmo, dia da semana etc.
A6: MÉTODO: | B6: Pegamos 367 dias de produção real (aba DADOS), criamos features (variáveis), e treinamos um
B7: modelo de Machine Learning (XGBoost) para prever ligações/dia a partir dessas variáveis.
A8: RESULTADO: | B8: O modelo nos mostra o RANKING de importância de cada variável (Feature Importance).
B9: Esse ranking é o produto mais valioso — mais que a predição em si.
A11: 2. XGBOOST — eXtreme Gradient Boosting
A12: O que é: | B12: Algoritmo de ML que cria CENTENAS de árvores de decisão, cada uma corrigindo erros da anterior.
A13: Analogia: | B13: Imagine 50 engenheiros juniores. O 1o faz uma estimativa grosseira. O 2o olha onde o 1o errou
B14: e corrige. O 3o corrige os erros do 2o. E assim por diante, até chegar numa predição muito boa.
A15: Vantagem: | B15: É o algoritmo mais vencedor em competições de dados (Kaggle). Funciona muito bem com dados
B16: de planilha (tabulares), lida bem com dados ruidosos, e nos dá o Feature Importance de graça.
A17: Na prática: | B17: Alimentamos com: núcleo, dia da semana, mês, equipes, média móvel de rede (3d e 7d),
B18: média móvel de ligações (3d e 7d), PVs, PRE, rede acumulada = 11 variáveis.
A19: Saída: | B19: Predição de ligações/dia + RANKING de importância de cada variável.
A21: 3. GRIDSEARCHCV — Busca Exaustiva de Parâmetros
A22: O que é: | B22: O XGBoost tem "botões" para ajustar (hiperparâmetros). O GridSearchCV testa TODAS as combinações.
A23: Parâmetros: | B23: n_estimators (qtas árvores): 50, 100, 200 = 3 opções
B24: max_depth (profundidade): 3, 5, 7 = 3 opções
B25: learning_rate (velocidade de aprendizado): 0.05, 0.1, 0.2 = 3 opções
B26: subsample (% dos dados por árvore): 0.8, 1.0 = 2 opções
A27: Total: | B27: 3 × 3 × 3 × 2 = 108 combinações de parâmetros
A28: Validação: | B28: Para cada combinação, faz Cross-Validation 3-fold: divide os dados em 3 partes,
B29: treina em 2, testa na 3a, repete 3 vezes. Isso evita overfitting (decorar os dados).
A30: Modelos: | B30: 108 combinações × 3 folds = 324 modelos treinados e avaliados automaticamente.
A31: Melhor: | B31: n_estimators=50, max_depth=3, learning_rate=0.05, subsample=0.8
A32: Significa: | B32: Modelo conservador (poucas árvores rasas) — adequado para dados ruidosos como obra.
A34: 4. O GRÁFICO "REAL vs PREDITO" E O R²
A35: O gráfico: | B35: Cada PONTO AZUL = 1 dia de produção. Eixo X = ligações reais. Eixo Y = o que o modelo previu.
A36: Linha vermelha: | B36: Se o modelo fosse perfeito, todos os pontos estariam EXATAMENTE na linha vermelha (y=x).
A37: R²=0.23: | B37: O modelo explica 23% da variação. Parece pouco, mas tem motivo:
B38: • Obra é EXTREMAMENTE ruidosa (chuva, falta de material, equipe faltou, trecho difícil, SABESP atrasou)
B39: • Apenas 142 dias com ligações registradas (amostra pequena)
B40: • Muitos fatores externos que NÃO estão nos dados (clima, acesso ao morro, reunião atrasou)
A41: MAS: | B41: O FEATURE IMPORTANCE É CONFIÁVEL mesmo com R² baixo. O ranking nos diz COM CONFIANÇA que:
B42: → Momentum (manter o ritmo) é 6x mais importante que número de equipes
B43: → Rede acumulada pronta é 2x mais importante que equipes
B44: → O gargalo está no FLUXO DO PIPELINE, não na capacidade de campo
...
