Workbook
Name SegmentaçãodeDados_Núcleo: #N/A

Sheet GERAL
B2: Dia | C2: Dia Semana | D2: Mês | E2: Dia Útil | F2: Equipe | G2: Rua | H2: LA | I2: LE | J2: PRA | K2: PRE | L2: PV's | M2: LIE | N2: LIA | O2: IHM | P2: RHM | Q2: Núcleo
A3: =_xlfn.XLOOKUP(GERAL[[#This Row],[Dia]],U:U,T:T,"") | B3: 45962 | C3: sábado | D3: 45962 | E3: NÃO | Q3: Morro do Tetéu | R3: =_xlfn.XLOOKUP(GERAL[[#This Row],[Dia]],U:U,V:V,"") | T3: Semana 1 | U3: 46052 | V3: Prazo_30
A4: =_xlfn.XLOOKUP(GERAL[[#This Row],[Dia]],U:U,T:T,"") | B4: 45963 | C4: domingo | D4: 45963 | E4: NÃO | Q4: Morro do Tetéu | R4: =_xlfn.XLOOKUP(GERAL[[#This Row],[Dia]],U:U,V:V,"") | T4: Semana 1 | U4: 46053 | V4: Prazo_30
A5: =_xlfn.XLOOKUP(GERAL[[#This Row],[Dia]],U:U,T:T,"") | B5: 45964 | C5: segunda-feira | D5: 45964 | Q5: Morro do Tetéu | R5: =_xlfn.XLOOKUP(GERAL[[#This Row],[Dia]],U:U,V:V,"") | T5: Semana 1 | U5: 46054 | V5: Prazo_30
A6: =_xlfn.XLOOKUP(GERAL[[#This Row],[Dia]],U:U,T:T,"") | B6: 45965 | C6: terça-feira | D6: 45965 | Q6: Morro do Tetéu | R6: =_xlfn.XLOOKUP(GERAL[[#This Row],[Dia]],U:U,V:V,"") | T6: Semana 1 | U6: 46055 | V6: Prazo_30
A7: =_xlfn.XLOOKUP(GERAL[[#This Row],[Dia]],U:U,T:T,"") | B7: 45966 | C7: quarta-feira | D7: 45966 | Q7: Morro do Tetéu | R7: =_xlfn.XLOOKUP(GERAL[[#This Row],[Dia]],U:U,V:V,"") | T7: Semana 1 | U7: 46056 | V7: Prazo_30
A8: =_xlfn.XLOOKUP(GERAL[[#This Row],[Dia]],U:U,T:T,"") | B8: 45967 | C8: quinta-feira | D8: 45967 | Q8: Morro do Tetéu | R8: =_xlfn.XLOOKUP(GERAL[[#This Row],[Dia]],U:U,V:V,"") | T8: Semana 1 | U8: 46057 | V8: Prazo_30
A9: =_xlfn.XLOOKUP(GERAL[[#This Row],[Dia]],U:U,T:T,"") | B9: 45968 | C9: sexta-feira | D9: 45968 | Q9: Morro do Tetéu | R9: =_xlfn.XLOOKUP(GERAL[[#This Row],[Dia]],U:U,V:V,"") | T9: Semana 1 | U9: 46058 | V9: Prazo_30
A10: =_xlfn.XLOOKUP(GERAL[[#This Row],[Dia]],U:U,T:T,"") | B10: 45969 | C10: sábado | D10: 45969 | E10: NÃO | Q10: Morro do Tetéu | R10: =_xlfn.XLOOKUP(GERAL[[#This Row],[Dia]],U:U,V:V,"") | T10: Semana 1 | U10: 46059 | V10: Prazo_30
A11: =_xlfn.XLOOKUP(GERAL[[#This Row],[Dia]],U:U,T:T,"") | B11: 45970 | C11: domingo | D11: 45970 | E11: NÃO | Q11: Morro do Tetéu | R11: =_xlfn.XLOOKUP(GERAL[[#This Row],[Dia]],U:U,V:V,"") | T11: Semana 1 | U11: 46060 | V11: Prazo_30
A12: =_xlfn.XLOOKUP(GERAL[[#This Row],[Dia]],U:U,T:T,"") | B12: 45971 | C12: segunda-feira | D12: 45971 | Q12: Morro do Tetéu | R12: =_xlfn.XLOOKUP(GERAL[[#This Row],[Dia]],U:U,V:V,"") | T12: Semana 2 | U12: 46061 | V12: Prazo_30
A13: =_xlfn.XLOOKUP(GERAL[[#This Row],[Dia]],U:U,T:T,"") | B13: 45972 | C13: terça-feira | D13: 45972 | Q13: Morro do Tetéu | R13: =_xlfn.XLOOKUP(GERAL[[#This Row],[Dia]],U:U,V:V,"") | T13: Semana 2 | U13: 46062 | V13: Prazo_30
A14: =_xlfn.XLOOKUP(GERAL[[#This Row],[Dia]],U:U,T:T,"") | B14: 45973 | C14: quarta-feira | D14: 45973 | Q14: Morro do Tetéu | R14: =_xlfn.XLOOKUP(GERAL[[#This Row],[Dia]],U:U,V:V,"") | T14: Semana 2 | U14: 46063 | V14: Prazo_30
A15: =_xlfn.XLOOKUP(GERAL[[#This Row],[Dia]],U:U,T:T,"") | B15: 45974 | C15: quinta-feira | D15: 45974 | Q15: Morro do Tetéu | R15: =_xlfn.XLOOKUP(GERAL[[#This Row],[Dia]],U:U,V:V,"") | T15: Semana 2 | U15: 46064 | V15: Prazo_30
A16: =_xlfn.XLOOKUP(GERAL[[#This Row],[Dia]],U:U,T:T,"") | B16: 45975 | C16: sexta-feira | D16: 45975 | Q16: Morro do Tetéu | R16: =_xlfn.XLOOKUP(GERAL[[#This Row],[Dia]],U:U,V:V,"") | T16: Semana 2 | U16: 46065 | V16: Prazo_30
A17: =_xlfn.XLOOKUP(GERAL[[#This Row],[Dia]],U:U,T:T,"") | B17: 45976 | C17: sábado | D17: 45976 | E17: NÃO | Q17: Morro do Tetéu | R17: =_xlfn.XLOOKUP(GERAL[[#This Row],[Dia]],U:U,V:V,"") | T17: Semana 2 | U17: 46066 | V17: Prazo_30
A18: =_xlfn.XLOOKUP(GERAL[[#This Row],[Dia]],U:U,T:T,"") | B18: 45977 | C18: domingo | D18: 45977 | E18: NÃO | Q18: Morro do Tetéu | R18: =_xlfn.XLOOKUP(GERAL[[#This Row],[Dia]],U:U,V:V,"") | T18: Semana 2 | U18: 46067 | V18: Prazo_30
A19: =_xlfn.XLOOKUP(GERAL[[#This Row],[Dia]],U:U,T:T,"") | B19: 45978 | C19: segunda-feira | D19: 45978 | Q19: Morro do Tetéu | R19: =_xlfn.XLOOKUP(GERAL[[#This Row],[Dia]],U:U,V:V,"") | T19: Semana 3 | U19: 46068 | V19: Prazo_30
A20: =_xlfn.XLOOKUP(GERAL[[#This Row],[Dia]],U:U,T:T,"") | B20: 45979 | C20: terça-feira | D20: 45979 | Q20: Morro do Tetéu | R20: =_xlfn.XLOOKUP(GERAL[[#This Row],[Dia]],U:U,V:V,"") | T20: Semana 3 | U20: 46069 | V20: Prazo_30
A21: =_xlfn.XLOOKUP(GERAL[[#This Row],[Dia]],U:U,T:T,"") | B21: 45980 | C21: quarta-feira | D21: 45980 | Q21: Morro do Tetéu | R21: =_xlfn.XLOOKUP(GERAL[[#This Row],[Dia]],U:U,V:V,"") | T21: Semana 3 | U21: 46070 | V21: Prazo_30
A22: =_xlfn.XLOOKUP(GERAL[[#This Row],[Dia]],U:U,T:T,"") | B22: 45981 | C22: quinta-feira | D22: 45981 | Q22: Morro do Tetéu | R22: =_xlfn.XLOOKUP(GERAL[[#This Row],[Dia]],U:U,V:V,"") | T22: Semana 3 | U22: 46071 | V22: Prazo_30
A23: =_xlfn.XLOOKUP(GERAL[[#This Row],[Dia]],U:U,T:T,"") | B23: 45982 | C23: sexta-feira | D23: 45982 | Q23: Morro do Tetéu | R23: =_xlfn.XLOOKUP(GERAL[[#This Row],[Dia]],U:U,V:V,"") | T23: Semana 3 | U23: 46072 | V23: Prazo_30
A24: =_xlfn.XLOOKUP(GERAL[[#This Row],[Dia]],U:U,T:T,"") | B24: 45983 | C24: sábado | D24: 45983 | E24: NÃO | Q24: Morro do Tetéu | R24: =_xlfn.XLOOKUP(GERAL[[#This Row],[Dia]],U:U,V:V,"") | T24: Semana 3 | U24: 46073 | V24: Prazo_30
A25: =_xlfn.XLOOKUP(GERAL[[#This Row],[Dia]],U:U,T:T,"") | B25: 45984 | C25: domingo | D25: 45984 | E25: NÃO | Q25: Morro do Tetéu | R25: =_xlfn.XLOOKUP(GERAL[[#This Row],[Dia]],U:U,V:V,"") | T25: Semana 3 | U25: 46074 | V25: Prazo_30
A26: =_xlfn.XLOOKUP(GERAL[[#This Row],[Dia]],U:U,T:T,"") | B26: 45985 | C26: segunda-feira | D26: 45985 | Q26: Morro do Tetéu | R26: =_xlfn.XLOOKUP(GERAL[[#This Row],[Dia]],U:U,V:V,"") | T26: Semana 4 | U26: 46075 | V26: Prazo_30
A27: =_xlfn.XLOOKUP(GERAL[[#This Row],[Dia]],U:U,T:T,"") | B27: 45986 | C27: terça-feira | D27: 45986 | Q27: Morro do Tetéu | R27: =_xlfn.XLOOKUP(GERAL[[#This Row],[Dia]],U:U,V:V,"") | T27: Semana 4 | U27: 46076 | V27: Prazo_30
A28: =_xlfn.XLOOKUP(GERAL[[#This Row],[Dia]],U:U,T:T,"") | B28: 45987 | C28: quarta-feira | D28: 45987 | Q28: Morro do Tetéu | R28: =_xlfn.XLOOKUP(GERAL[[#This Row],[Dia]],U:U,V:V,"") | T28: Semana 4 | U28: 46077 | V28: Prazo_30
A29: =_xlfn.XLOOKUP(GERAL[[#This Row],[Dia]],U:U,T:T,"") | B29: 45988 | C29: quinta-feira | D29: 45988 | Q29: Morro do Tetéu | R29: =_xlfn.XLOOKUP(GERAL[[#This Row],[Dia]],U:U,V:V,"") | T29: Semana 4 | U29: 46078 | V29: Prazo_30
A30: =_xlfn.XLOOKUP(GERAL[[#This Row],[Dia]],U:U,T:T,"") | B30: 45989 | C30: sexta-feira | D30: 45989 | Q30: Morro do Tetéu | R30: =_xlfn.XLOOKUP(GERAL[[#This Row],[Dia]],U:U,V:V,"") | T30: Semana 4 | U30: 46079 | V30: Prazo_30
A31: =_xlfn.XLOOKUP(GERAL[[#This Row],[Dia]],U:U,T:T,"") | B31: 45990 | C31: sábado | D31: 45990 | E31: NÃO | Q31: Morro do Tetéu | R31: =_xlfn.XLOOKUP(GERAL[[#This Row],[Dia]],U:U,V:V,"") | T31: Semana 4 | U31: 46080 | V31: Prazo_30
A32: =_xlfn.XLOOKUP(GERAL[[#This Row],[Dia]],U:U,T:T,"") | B32: 45991 | C32: domingo | D32: 45991 | E32: NÃO | Q32: Morro do Tetéu | R32: =_xlfn.XLOOKUP(GERAL[[#This Row],[Dia]],U:U,V:V,"") | T32: Semana 4 | U32: 46081 | V32: Prazo_30
A33: =_xlfn.XLOOKUP(GERAL[[#This Row],[Dia]],U:U,T:T,"") | B33: 45992 | C33: segunda-feira | D33: 45992 | Q33: Morro do Tetéu | R33: =_xlfn.XLOOKUP(GERAL[[#This Row],[Dia]],U:U,V:V,"") | T33: Semana 5 | U33: 46082 | V33: Prazo_30
A34: =_xlfn.XLOOKUP(GERAL[[#This Row],[Dia]],U:U,T:T,"") | B34: 45993 | C34: terça-feira | D34: 45993 | Q34: Morro do Tetéu | R34: =_xlfn.XLOOKUP(GERAL[[#This Row],[Dia]],U:U,V:V,"") | T34: Semana 5 | U34: 46083 | V34: Prazo_30
A35: =_xlfn.XLOOKUP(GERAL[[#This Row],[Dia]],U:U,T:T,"") | B35: 45994 | C35: quarta-feira | D35: 45994 | Q35: Morro do Tetéu | R35: =_xlfn.XLOOKUP(GERAL[[#This Row],[Dia]],U:U,V:V,"") | T35: Semana 5 | U35: 46083 | V35: Prazo_30
A36: =_xlfn.XLOOKUP(GERAL[[#This Row],[Dia]],U:U,T:T,"") | B36: 45995 | C36: quinta-feira | D36: 45995 | Q36: Morro do Tetéu | R36: =_xlfn.XLOOKUP(GERAL[[#This Row],[Dia]],U:U,V:V,"") | T36: Semana 5 | U36: 46083 | V36: Prazo_30
A37: =_xlfn.XLOOKUP(GERAL[[#This Row],[Dia]],U:U,T:T,"") | B37: 45996 | C37: sexta-feira | D37: 45996 | Q37: Morro do Tetéu | R37: =_xlfn.XLOOKUP(GERAL[[#This Row],[Dia]],U:U,V:V,"") | T37: Semana 5 | U37: 46083 | V37: Prazo_30
A38: =_xlfn.XLOOKUP(GERAL[[#This Row],[Dia]],U:U,T:T,"") | B38: 45997 | C38: sábado | D38: 45997 | E38: NÃO | Q38: Morro do Tetéu | R38: =_xlfn.XLOOKUP(GERAL[[#This Row],[Dia]],U:U,V:V,"") | T38: Semana 5 | U38: 46083 | V38: Prazo_30
A39: =_xlfn.XLOOKUP(GERAL[[#This Row],[Dia]],U:U,T:T,"") | B39: 45998 | C39: domingo | D39: 45998 | E39: NÃO | Q39: Morro do Tetéu | R39: =_xlfn.XLOOKUP(GERAL[[#This Row],[Dia]],U:U,V:V,"") | T39: Semana 5 | U39: 46083 | V39: Prazo_30
A40: =_xlfn.XLOOKUP(GERAL[[#This Row],[Dia]],U:U,T:T,"") | B40: 45999 | C40: segunda-feira | D40: 45999 | Q40: Morro do Tetéu | R40: =_xlfn.XLOOKUP(GERAL[[#This Row],[Dia]],U:U,V:V,"") | T40: Semana 6 | U40: 46083 | V40: Prazo_30
A41: =_xlfn.XLOOKUP(GERAL[[#This Row],[Dia]],U:U,T:T,"") | B41: 46000 | C41: terça-feira | D41: 46000 | Q41: Morro do Tetéu | R41: =_xlfn.XLOOKUP(GERAL[[#This Row],[Dia]],U:U,V:V,"") | T41: Semana 6 | U41: 46084 | V41: Prazo_30
...

Sheet PROD_EQUIPE
S2: Informar período
E3: SE LIGA NA REDE - SANTOS
E4: PRODUÇÃO POR EQUIPE
Q7: DE | R7: ATÉ
P8: PERÍODO | Q8: 46052 | R8: =TODAY()-1 -> 46133
B10: RUA | C10: DIAS ÚTEIS | D10: LA | E10: LE | F10: PRA | G10: PRE | H10: PV's | I10: LIE | J10: LIA | K10: IHM | L10: RHM | M10: Ind. Prod. LA | N10: Ind Prod LE | O10: Ind Prod PRA | P10: Ind Prod PRE | Q10: IND. PROD REDE | R10: IND. PROD LIG
B11: ∑ Equipe até 28/02 - MT | C11: =COUNTIFS(GERAL[Dia Útil],"SIM",GERAL[Equipe],PROD_EQUIPE!B11,GERAL[Dia],">=" &PROD_EQUIPE!$Q$8,GERAL[Dia],"<=" &PROD_EQUIPE!$R$8) -> 21 | D11: =SUMIFS(GERAL[LA],GERAL[Equipe],PROD_EQUIPE!B11,GERAL[Dia],">=" &PROD_EQUIPE!$Q$8,GERAL[Dia],"<=" &PROD_EQUIPE!$R$8) -> 70 | E11: =SUMIFS(GERAL[LE],GERAL[Equipe],PROD_EQUIPE!B11,GERAL[Dia],">=" &PROD_EQUIPE!$Q$8,GERAL[Dia],"<=" &PROD_EQUIPE!$R$8) -> 82 | F11: =SUMIFS(GERAL[PRA],GERAL[Equipe],PROD_EQUIPE!B11,GERAL[Dia],">=" &PROD_EQUIPE!$Q$8,GERAL[Dia],"<=" &PROD_EQUIPE!$R$8) -> 555.1 | G11: =SUMIFS(GERAL[PRE],GERAL[Equipe],PROD_EQUIPE!B11,GERAL[Dia],">=" &PROD_EQUIPE!$Q$8,GERAL[Dia],"<=" &PROD_EQUIPE!$R$8) -> 142 | H11: =SUMIFS(GERAL[PV''s],GERAL[Equipe],PROD_EQUIPE!B11,GERAL[Dia],">=" &PROD_EQUIPE!$Q$8,GERAL[Dia],"<=" &PROD_EQUIPE!$R$8) -> 7 | I11: =SUMIFS(GERAL[LIE],GERAL[Equipe],PROD_EQUIPE!B11,GERAL[Dia],">=" &PROD_EQUIPE!$Q$8,GERAL[Dia],"<=" &PROD_EQUIPE!$R$8) -> 9 | J11: =SUMIFS(GERAL[LIA],GERAL[Equipe],PROD_EQUIPE!B11,GERAL[Dia],">=" &PROD_EQUIPE!$Q$8,GERAL[Dia],"<=" &PROD_EQUIPE!$R$8) -> 97 | K11: =SUMIFS(GERAL[IHM],GERAL[Equipe],PROD_EQUIPE!B11,GERAL[Dia],">=" &PROD_EQUIPE!$Q$8,GERAL[Dia],"<=" &PROD_EQUIPE!$R$8) -> 59 | L11: =SUMIFS(GERAL[RHM],GERAL[Equipe],PROD_EQUIPE!B11,GERAL[Dia],">=" &PROD_EQUIPE!$Q$8,GERAL[Dia],"<=" &PROD_EQUIPE!$R$8) -> 0 | M11: =IFERROR(D11/C11,"") -> 3.3333333 | N11: =IFERROR(E11/C11,"") -> 3.9047619 | O11: =IFERROR(F11/C11,"") -> 26.433333 | P11: =IFERROR(G11/C11,"") -> 6.7619048 | Q11: =IFERROR(SUM(F11:G11)/C11,"") -> 33.195238 | R11: =IFERROR(SUM(D11:E11)/C11,"") -> 7.2380952
B12: JOÃO | C12: =COUNTIFS(GERAL[Dia Útil],"SIM",GERAL[Equipe],PROD_EQUIPE!B12,GERAL[Dia],">=" &PROD_EQUIPE!$Q$8,GERAL[Dia],"<=" &PROD_EQUIPE!$R$8) -> 18 | D12: =SUMIFS(GERAL[LA],GERAL[Equipe],PROD_EQUIPE!B12,GERAL[Dia],">=" &PROD_EQUIPE!$Q$8,GERAL[Dia],"<=" &PROD_EQUIPE!$R$8) -> 44 | E12: =SUMIFS(GERAL[LE],GERAL[Equipe],PROD_EQUIPE!B12,GERAL[Dia],">=" &PROD_EQUIPE!$Q$8,GERAL[Dia],"<=" &PROD_EQUIPE!$R$8) -> 0 | F12: =SUMIFS(GERAL[PRA],GERAL[Equipe],PROD_EQUIPE!B12,GERAL[Dia],">=" &PROD_EQUIPE!$Q$8,GERAL[Dia],"<=" &PROD_EQUIPE!$R$8) -> 400 | G12: =SUMIFS(GERAL[PRE],GERAL[Equipe],PROD_EQUIPE!B12,GERAL[Dia],">=" &PROD_EQUIPE!$Q$8,GERAL[Dia],"<=" &PROD_EQUIPE!$R$8) -> 103 | H12: =SUMIFS(GERAL[PV''s],GERAL[Equipe],PROD_EQUIPE!B12,GERAL[Dia],">=" &PROD_EQUIPE!$Q$8,GERAL[Dia],"<=" &PROD_EQUIPE!$R$8) -> 4 | I12: =SUMIFS(GERAL[LIE],GERAL[Equipe],PROD_EQUIPE!B12,GERAL[Dia],">=" &PROD_EQUIPE!$Q$8,GERAL[Dia],"<=" &PROD_EQUIPE!$R$8) -> 0 | J12: =SUMIFS(GERAL[LIA],GERAL[Equipe],PROD_EQUIPE!B12,GERAL[Dia],">=" &PROD_EQUIPE!$Q$8,GERAL[Dia],"<=" &PROD_EQUIPE!$R$8) -> 7 | K12: =SUMIFS(GERAL[IHM],GERAL[Equipe],PROD_EQUIPE!B12,GERAL[Dia],">=" &PROD_EQUIPE!$Q$8,GERAL[Dia],"<=" &PROD_EQUIPE!$R$8) -> 0 | L12: =SUMIFS(GERAL[RHM],GERAL[Equipe],PROD_EQUIPE!B12,GERAL[Dia],">=" &PROD_EQUIPE!$Q$8,GERAL[Dia],"<=" &PROD_EQUIPE!$R$8) -> 0 | M12: =IFERROR(D12/C12,"") -> 2.4444444 | N12: =IFERROR(E12/C12,"") -> 0 | O12: =IFERROR(F12/C12,"") -> 22.222222 | P12: =IFERROR(G12/C12,"") -> 5.7222222 | Q12: =IFERROR(SUM(F12:G12)/C12,"") -> 27.944444 | R12: =IFERROR(SUM(D12:E12)/C12,"") -> 2.4444444
B13: PITBULL | C13: =COUNTIFS(GERAL[Dia Útil],"SIM",GERAL[Equipe],PROD_EQUIPE!B13,GERAL[Dia],">=" &PROD_EQUIPE!$Q$8,GERAL[Dia],"<=" &PROD_EQUIPE!$R$8) -> 23 | D13: =SUMIFS(GERAL[LA],GERAL[Equipe],PROD_EQUIPE!B13,GERAL[Dia],">=" &PROD_EQUIPE!$Q$8,GERAL[Dia],"<=" &PROD_EQUIPE!$R$8) -> 14 | E13: =SUMIFS(GERAL[LE],GERAL[Equipe],PROD_EQUIPE!B13,GERAL[Dia],">=" &PROD_EQUIPE!$Q$8,GERAL[Dia],"<=" &PROD_EQUIPE!$R$8) -> 40 | F13: =SUMIFS(GERAL[PRA],GERAL[Equipe],PROD_EQUIPE!B13,GERAL[Dia],">=" &PROD_EQUIPE!$Q$8,GERAL[Dia],"<=" &PROD_EQUIPE!$R$8) -> 121 | G13: =SUMIFS(GERAL[PRE],GERAL[Equipe],PROD_EQUIPE!B13,GERAL[Dia],">=" &PROD_EQUIPE!$Q$8,GERAL[Dia],"<=" &PROD_EQUIPE!$R$8) -> 172.4 | H13: =SUMIFS(GERAL[PV''s],GERAL[Equipe],PROD_EQUIPE!B13,GERAL[Dia],">=" &PROD_EQUIPE!$Q$8,GERAL[Dia],"<=" &PROD_EQUIPE!$R$8) -> 1 | I13: =SUMIFS(GERAL[LIE],GERAL[Equipe],PROD_EQUIPE!B13,GERAL[Dia],">=" &PROD_EQUIPE!$Q$8,GERAL[Dia],"<=" &PROD_EQUIPE!$R$8) -> 0 | J13: =SUMIFS(GERAL[LIA],GERAL[Equipe],PROD_EQUIPE!B13,GERAL[Dia],">=" &PROD_EQUIPE!$Q$8,GERAL[Dia],"<=" &PROD_EQUIPE!$R$8) -> 21 | K13: =SUMIFS(GERAL[IHM],GERAL[Equipe],PROD_EQUIPE!B13,GERAL[Dia],">=" &PROD_EQUIPE!$Q$8,GERAL[Dia],"<=" &PROD_EQUIPE!$R$8) -> 17 | L13: =SUMIFS(GERAL[RHM],GERAL[Equipe],PROD_EQUIPE!B13,GERAL[Dia],">=" &PROD_EQUIPE!$Q$8,GERAL[Dia],"<=" &PROD_EQUIPE!$R$8) -> 0 | M13: =IFERROR(D13/C13,"") -> 0.60869565 | N13: =IFERROR(E13/C13,"") -> 1.7391304 | O13: =IFERROR(F13/C13,"") -> 5.2608696 | P13: =IFERROR(G13/C13,"") -> 7.4956522 | Q13: =IFERROR(SUM(F13:G13)/C13,"") -> 12.756522 | R13: =IFERROR(SUM(D13:E13)/C13,"") -> 2.3478261
B14: TIM MAIA | C14: =COUNTIFS(GERAL[Dia Útil],"SIM",GERAL[Equipe],PROD_EQUIPE!B14,GERAL[Dia],">=" &PROD_EQUIPE!$Q$8,GERAL[Dia],"<=" &PROD_EQUIPE!$R$8) -> 8 | D14: =SUMIFS(GERAL[LA],GERAL[Equipe],PROD_EQUIPE!B14,GERAL[Dia],">=" &PROD_EQUIPE!$Q$8,GERAL[Dia],"<=" &PROD_EQUIPE!$R$8) -> 0 | E14: =SUMIFS(GERAL[LE],GERAL[Equipe],PROD_EQUIPE!B14,GERAL[Dia],">=" &PROD_EQUIPE!$Q$8,GERAL[Dia],"<=" &PROD_EQUIPE!$R$8) -> 0 | F14: =SUMIFS(GERAL[PRA],GERAL[Equipe],PROD_EQUIPE!B14,GERAL[Dia],">=" &PROD_EQUIPE!$Q$8,GERAL[Dia],"<=" &PROD_EQUIPE!$R$8) -> 0 | G14: =SUMIFS(GERAL[PRE],GERAL[Equipe],PROD_EQUIPE!B14,GERAL[Dia],">=" &PROD_EQUIPE!$Q$8,GERAL[Dia],"<=" &PROD_EQUIPE!$R$8) -> 0 | H14: =SUMIFS(GERAL[PV''s],GERAL[Equipe],PROD_EQUIPE!B14,GERAL[Dia],">=" &PROD_EQUIPE!$Q$8,GERAL[Dia],"<=" &PROD_EQUIPE!$R$8) -> 0 | I14: =SUMIFS(GERAL[LIE],GERAL[Equipe],PROD_EQUIPE!B14,GERAL[Dia],">=" &PROD_EQUIPE!$Q$8,GERAL[Dia],"<=" &PROD_EQUIPE!$R$8) -> 0 | J14: =SUMIFS(GERAL[LIA],GERAL[Equipe],PROD_EQUIPE!B14,GERAL[Dia],">=" &PROD_EQUIPE!$Q$8,GERAL[Dia],"<=" &PROD_EQUIPE!$R$8) -> 42 | K14: =SUMIFS(GERAL[IHM],GERAL[Equipe],PROD_EQUIPE!B14,GERAL[Dia],">=" &PROD_EQUIPE!$Q$8,GERAL[Dia],"<=" &PROD_EQUIPE!$R$8) -> 0 | L14: =SUMIFS(GERAL[RHM],GERAL[Equipe],PROD_EQUIPE!B14,GERAL[Dia],">=" &PROD_EQUIPE!$Q$8,GERAL[Dia],"<=" &PROD_EQUIPE!$R$8) -> 0 | M14: =IFERROR(D14/C14,"") -> 0 | N14: =IFERROR(E14/C14,"") -> 0 | O14: =IFERROR(F14/C14,"") -> 0 | P14: =IFERROR(G14/C14,"") -> 0 | Q14: =IFERROR(SUM(F14:G14)/C14,"") -> 0 | R14: =IFERROR(SUM(D14:E14)/C14,"") -> 0
B15: ZULU | C15: =COUNTIFS(GERAL[Dia Útil],"SIM",GERAL[Equipe],PROD_EQUIPE!B15,GERAL[Dia],">=" &PROD_EQUIPE!$Q$8,GERAL[Dia],"<=" &PROD_EQUIPE!$R$8) -> 29 | D15: =SUMIFS(GERAL[LA],GERAL[Equipe],PROD_EQUIPE!B15,GERAL[Dia],">=" &PROD_EQUIPE!$Q$8,GERAL[Dia],"<=" &PROD_EQUIPE!$R$8) -> 48 | E15: =SUMIFS(GERAL[LE],GERAL[Equipe],PROD_EQUIPE!B15,GERAL[Dia],">=" &PROD_EQUIPE!$Q$8,GERAL[Dia],"<=" &PROD_EQUIPE!$R$8) -> 18 | F15: =SUMIFS(GERAL[PRA],GERAL[Equipe],PROD_EQUIPE!B15,GERAL[Dia],">=" &PROD_EQUIPE!$Q$8,GERAL[Dia],"<=" &PROD_EQUIPE!$R$8) -> 268 | G15: =SUMIFS(GERAL[PRE],GERAL[Equipe],PROD_EQUIPE!B15,GERAL[Dia],">=" &PROD_EQUIPE!$Q$8,GERAL[Dia],"<=" &PROD_EQUIPE!$R$8) -> 27 | H15: =SUMIFS(GERAL[PV''s],GERAL[Equipe],PROD_EQUIPE!B15,GERAL[Dia],">=" &PROD_EQUIPE!$Q$8,GERAL[Dia],"<=" &PROD_EQUIPE!$R$8) -> 0 | I15: =SUMIFS(GERAL[LIE],GERAL[Equipe],PROD_EQUIPE!B15,GERAL[Dia],">=" &PROD_EQUIPE!$Q$8,GERAL[Dia],"<=" &PROD_EQUIPE!$R$8) -> 2 | J15: =SUMIFS(GERAL[LIA],GERAL[Equipe],PROD_EQUIPE!B15,GERAL[Dia],">=" &PROD_EQUIPE!$Q$8,GERAL[Dia],"<=" &PROD_EQUIPE!$R$8) -> 32 | K15: =SUMIFS(GERAL[IHM],GERAL[Equipe],PROD_EQUIPE!B15,GERAL[Dia],">=" &PROD_EQUIPE!$Q$8,GERAL[Dia],"<=" &PROD_EQUIPE!$R$8) -> 31 | L15: =SUMIFS(GERAL[RHM],GERAL[Equipe],PROD_EQUIPE!B15,GERAL[Dia],">=" &PROD_EQUIPE!$Q$8,GERAL[Dia],"<=" &PROD_EQUIPE!$R$8) -> 0 | M15: =IFERROR(D15/C15,"") -> 1.6551724 | N15: =IFERROR(E15/C15,"") -> 0.62068966 | O15: =IFERROR(F15/C15,"") -> 9.2413793 | P15: =IFERROR(G15/C15,"") -> 0.93103448 | Q15: =IFERROR(SUM(F15:G15)/C15,"") -> 10.172414 | R15: =IFERROR(SUM(D15:E15)/C15,"") -> 2.2758621
B16: (vazio) | C16: =COUNTIFS(GERAL[Dia Útil],"SIM",GERAL[Equipe],PROD_EQUIPE!B16,GERAL[Dia],">=" &PROD_EQUIPE!$Q$8,GERAL[Dia],"<=" &PROD_EQUIPE!$R$8) -> 0 | D16: =SUMIFS(GERAL[LA],GERAL[Equipe],PROD_EQUIPE!B16,GERAL[Dia],">=" &PROD_EQUIPE!$Q$8,GERAL[Dia],"<=" &PROD_EQUIPE!$R$8) -> 0 | E16: =SUMIFS(GERAL[LE],GERAL[Equipe],PROD_EQUIPE!B16,GERAL[Dia],">=" &PROD_EQUIPE!$Q$8,GERAL[Dia],"<=" &PROD_EQUIPE!$R$8) -> 0 | F16: =SUMIFS(GERAL[PRA],GERAL[Equipe],PROD_EQUIPE!B16,GERAL[Dia],">=" &PROD_EQUIPE!$Q$8,GERAL[Dia],"<=" &PROD_EQUIPE!$R$8) -> 0 | G16: =SUMIFS(GERAL[PRE],GERAL[Equipe],PROD_EQUIPE!B16,GERAL[Dia],">=" &PROD_EQUIPE!$Q$8,GERAL[Dia],"<=" &PROD_EQUIPE!$R$8) -> 0 | H16: =SUMIFS(GERAL[PV''s],GERAL[Equipe],PROD_EQUIPE!B16,GERAL[Dia],">=" &PROD_EQUIPE!$Q$8,GERAL[Dia],"<=" &PROD_EQUIPE!$R$8) -> 0 | I16: =SUMIFS(GERAL[LIE],GERAL[Equipe],PROD_EQUIPE!B16,GERAL[Dia],">=" &PROD_EQUIPE!$Q$8,GERAL[Dia],"<=" &PROD_EQUIPE!$R$8) -> 0 | J16: =SUMIFS(GERAL[LIA],GERAL[Equipe],PROD_EQUIPE!B16,GERAL[Dia],">=" &PROD_EQUIPE!$Q$8,GERAL[Dia],"<=" &PROD_EQUIPE!$R$8) -> 0 | K16: =SUMIFS(GERAL[IHM],GERAL[Equipe],PROD_EQUIPE!B16,GERAL[Dia],">=" &PROD_EQUIPE!$Q$8,GERAL[Dia],"<=" &PROD_EQUIPE!$R$8) -> 0 | L16: =SUMIFS(GERAL[RHM],GERAL[Equipe],PROD_EQUIPE!B16,GERAL[Dia],">=" &PROD_EQUIPE!$Q$8,GERAL[Dia],"<=" &PROD_EQUIPE!$R$8) -> 0 | M16: =IFERROR(D16/C16,"") | N16: =IFERROR(E16/C16,"") | O16: =IFERROR(F16/C16,"") | P16: =IFERROR(G16/C16,"") | Q16: =IFERROR(SUM(F16:G16)/C16,"") | R16: =IFERROR(SUM(D16:E16)/C16,"")
C17: =COUNTIFS(GERAL[Dia Útil],"SIM",GERAL[Equipe],PROD_EQUIPE!B17,GERAL[Dia],">=" &PROD_EQUIPE!$Q$8,GERAL[Dia],"<=" &PROD_EQUIPE!$R$8) -> 0 | D17: =SUMIFS(GERAL[LA],GERAL[Equipe],PROD_EQUIPE!B17,GERAL[Dia],">=" &PROD_EQUIPE!$Q$8,GERAL[Dia],"<=" &PROD_EQUIPE!$R$8) -> 0 | E17: =SUMIFS(GERAL[LE],GERAL[Equipe],PROD_EQUIPE!B17,GERAL[Dia],">=" &PROD_EQUIPE!$Q$8,GERAL[Dia],"<=" &PROD_EQUIPE!$R$8) -> 0 | F17: =SUMIFS(GERAL[PRA],GERAL[Equipe],PROD_EQUIPE!B17,GERAL[Dia],">=" &PROD_EQUIPE!$Q$8,GERAL[Dia],"<=" &PROD_EQUIPE!$R$8) -> 0 | G17: =SUMIFS(GERAL[PRE],GERAL[Equipe],PROD_EQUIPE!B17,GERAL[Dia],">=" &PROD_EQUIPE!$Q$8,GERAL[Dia],"<=" &PROD_EQUIPE!$R$8) -> 0 | H17: =SUMIFS(GERAL[PV''s],GERAL[Equipe],PROD_EQUIPE!B17,GERAL[Dia],">=" &PROD_EQUIPE!$Q$8,GERAL[Dia],"<=" &PROD_EQUIPE!$R$8) -> 0 | I17: =SUMIFS(GERAL[LIE],GERAL[Equipe],PROD_EQUIPE!B17,GERAL[Dia],">=" &PROD_EQUIPE!$Q$8,GERAL[Dia],"<=" &PROD_EQUIPE!$R$8) -> 0 | J17: =SUMIFS(GERAL[LIA],GERAL[Equipe],PROD_EQUIPE!B17,GERAL[Dia],">=" &PROD_EQUIPE!$Q$8,GERAL[Dia],"<=" &PROD_EQUIPE!$R$8) -> 0 | K17: =SUMIFS(GERAL[IHM],GERAL[Equipe],PROD_EQUIPE!B17,GERAL[Dia],">=" &PROD_EQUIPE!$Q$8,GERAL[Dia],"<=" &PROD_EQUIPE!$R$8) -> 0 | L17: =SUMIFS(GERAL[RHM],GERAL[Equipe],PROD_EQUIPE!B17,GERAL[Dia],">=" &PROD_EQUIPE!$Q$8,GERAL[Dia],"<=" &PROD_EQUIPE!$R$8) -> 0 | M17: =IFERROR(D17/C17,"") | N17: =IFERROR(E17/C17,"") | O17: =IFERROR(F17/C17,"") | P17: =IFERROR(G17/C17,"") | Q17: =IFERROR(SUM(F17:G17)/C17,"") | R17: =IFERROR(SUM(D17:E17)/C17,"")
C18: =COUNTIFS(GERAL[Dia Útil],"SIM",GERAL[Equipe],PROD_EQUIPE!B18,GERAL[Dia],">=" &PROD_EQUIPE!$Q$8,GERAL[Dia],"<=" &PROD_EQUIPE!$R$8) -> 0 | D18: =SUMIFS(GERAL[LA],GERAL[Equipe],PROD_EQUIPE!B18,GERAL[Dia],">=" &PROD_EQUIPE!$Q$8,GERAL[Dia],"<=" &PROD_EQUIPE!$R$8) -> 0 | E18: =SUMIFS(GERAL[LE],GERAL[Equipe],PROD_EQUIPE!B18,GERAL[Dia],">=" &PROD_EQUIPE!$Q$8,GERAL[Dia],"<=" &PROD_EQUIPE!$R$8) -> 0 | F18: =SUMIFS(GERAL[PRA],GERAL[Equipe],PROD_EQUIPE!B18,GERAL[Dia],">=" &PROD_EQUIPE!$Q$8,GERAL[Dia],"<=" &PROD_EQUIPE!$R$8) -> 0 | G18: =SUMIFS(GERAL[PRE],GERAL[Equipe],PROD_EQUIPE!B18,GERAL[Dia],">=" &PROD_EQUIPE!$Q$8,GERAL[Dia],"<=" &PROD_EQUIPE!$R$8) -> 0 | H18: =SUMIFS(GERAL[PV''s],GERAL[Equipe],PROD_EQUIPE!B18,GERAL[Dia],">=" &PROD_EQUIPE!$Q$8,GERAL[Dia],"<=" &PROD_EQUIPE!$R$8) -> 0 | I18: =SUMIFS(GERAL[LIE],GERAL[Equipe],PROD_EQUIPE!B18,GERAL[Dia],">=" &PROD_EQUIPE!$Q$8,GERAL[Dia],"<=" &PROD_EQUIPE!$R$8) -> 0 | J18: =SUMIFS(GERAL[LIA],GERAL[Equipe],PROD_EQUIPE!B18,GERAL[Dia],">=" &PROD_EQUIPE!$Q$8,GERAL[Dia],"<=" &PROD_EQUIPE!$R$8) -> 0 | K18: =SUMIFS(GERAL[IHM],GERAL[Equipe],PROD_EQUIPE!B18,GERAL[Dia],">=" &PROD_EQUIPE!$Q$8,GERAL[Dia],"<=" &PROD_EQUIPE!$R$8) -> 0 | L18: =SUMIFS(GERAL[RHM],GERAL[Equipe],PROD_EQUIPE!B18,GERAL[Dia],">=" &PROD_EQUIPE!$Q$8,GERAL[Dia],"<=" &PROD_EQUIPE!$R$8) -> 0 | M18: =IFERROR(D18/C18,"") | N18: =IFERROR(E18/C18,"") | O18: =IFERROR(F18/C18,"") | P18: =IFERROR(G18/C18,"") | Q18: =IFERROR(SUM(F18:G18)/C18,"") | R18: =IFERROR(SUM(D18:E18)/C18,"")
C19: =COUNTIFS(GERAL[Dia Útil],"SIM",GERAL[Equipe],PROD_EQUIPE!B19,GERAL[Dia],">=" &PROD_EQUIPE!$Q$8,GERAL[Dia],"<=" &PROD_EQUIPE!$R$8) -> 0 | D19: =SUMIFS(GERAL[LA],GERAL[Equipe],PROD_EQUIPE!B19,GERAL[Dia],">=" &PROD_EQUIPE!$Q$8,GERAL[Dia],"<=" &PROD_EQUIPE!$R$8) -> 0 | E19: =SUMIFS(GERAL[LE],GERAL[Equipe],PROD_EQUIPE!B19,GERAL[Dia],">=" &PROD_EQUIPE!$Q$8,GERAL[Dia],"<=" &PROD_EQUIPE!$R$8) -> 0 | F19: =SUMIFS(GERAL[PRA],GERAL[Equipe],PROD_EQUIPE!B19,GERAL[Dia],">=" &PROD_EQUIPE!$Q$8,GERAL[Dia],"<=" &PROD_EQUIPE!$R$8) -> 0 | G19: =SUMIFS(GERAL[PRE],GERAL[Equipe],PROD_EQUIPE!B19,GERAL[Dia],">=" &PROD_EQUIPE!$Q$8,GERAL[Dia],"<=" &PROD_EQUIPE!$R$8) -> 0 | H19: =SUMIFS(GERAL[PV''s],GERAL[Equipe],PROD_EQUIPE!B19,GERAL[Dia],">=" &PROD_EQUIPE!$Q$8,GERAL[Dia],"<=" &PROD_EQUIPE!$R$8) -> 0 | I19: =SUMIFS(GERAL[LIE],GERAL[Equipe],PROD_EQUIPE!B19,GERAL[Dia],">=" &PROD_EQUIPE!$Q$8,GERAL[Dia],"<=" &PROD_EQUIPE!$R$8) -> 0 | J19: =SUMIFS(GERAL[LIA],GERAL[Equipe],PROD_EQUIPE!B19,GERAL[Dia],">=" &PROD_EQUIPE!$Q$8,GERAL[Dia],"<=" &PROD_EQUIPE!$R$8) -> 0 | K19: =SUMIFS(GERAL[IHM],GERAL[Equipe],PROD_EQUIPE!B19,GERAL[Dia],">=" &PROD_EQUIPE!$Q$8,GERAL[Dia],"<=" &PROD_EQUIPE!$R$8) -> 0 | L19: =SUMIFS(GERAL[RHM],GERAL[Equipe],PROD_EQUIPE!B19,GERAL[Dia],">=" &PROD_EQUIPE!$Q$8,GERAL[Dia],"<=" &PROD_EQUIPE!$R$8) -> 0 | M19: =IFERROR(D19/C19,"") | N19: =IFERROR(E19/C19,"") | O19: =IFERROR(F19/C19,"") | P19: =IFERROR(G19/C19,"") | Q19: =IFERROR(SUM(F19:G19)/C19,"") | R19: =IFERROR(SUM(D19:E19)/C19,"")
C20: =COUNTIFS(GERAL[Dia Útil],"SIM",GERAL[Equipe],PROD_EQUIPE!B20,GERAL[Dia],">=" &PROD_EQUIPE!$Q$8,GERAL[Dia],"<=" &PROD_EQUIPE!$R$8) -> 0 | D20: =SUMIFS(GERAL[LA],GERAL[Equipe],PROD_EQUIPE!B20,GERAL[Dia],">=" &PROD_EQUIPE!$Q$8,GERAL[Dia],"<=" &PROD_EQUIPE!$R$8) -> 0 | E20: =SUMIFS(GERAL[LE],GERAL[Equipe],PROD_EQUIPE!B20,GERAL[Dia],">=" &PROD_EQUIPE!$Q$8,GERAL[Dia],"<=" &PROD_EQUIPE!$R$8) -> 0 | F20: =SUMIFS(GERAL[PRA],GERAL[Equipe],PROD_EQUIPE!B20,GERAL[Dia],">=" &PROD_EQUIPE!$Q$8,GERAL[Dia],"<=" &PROD_EQUIPE!$R$8) -> 0 | G20: =SUMIFS(GERAL[PRE],GERAL[Equipe],PROD_EQUIPE!B20,GERAL[Dia],">=" &PROD_EQUIPE!$Q$8,GERAL[Dia],"<=" &PROD_EQUIPE!$R$8) -> 0 | H20: =SUMIFS(GERAL[PV''s],GERAL[Equipe],PROD_EQUIPE!B20,GERAL[Dia],">=" &PROD_EQUIPE!$Q$8,GERAL[Dia],"<=" &PROD_EQUIPE!$R$8) -> 0 | I20: =SUMIFS(GERAL[LIE],GERAL[Equipe],PROD_EQUIPE!B20,GERAL[Dia],">=" &PROD_EQUIPE!$Q$8,GERAL[Dia],"<=" &PROD_EQUIPE!$R$8) -> 0 | J20: =SUMIFS(GERAL[LIA],GERAL[Equipe],PROD_EQUIPE!B20,GERAL[Dia],">=" &PROD_EQUIPE!$Q$8,GERAL[Dia],"<=" &PROD_EQUIPE!$R$8) -> 0 | K20: =SUMIFS(GERAL[IHM],GERAL[Equipe],PROD_EQUIPE!B20,GERAL[Dia],">=" &PROD_EQUIPE!$Q$8,GERAL[Dia],"<=" &PROD_EQUIPE!$R$8) -> 0 | L20: =SUMIFS(GERAL[RHM],GERAL[Equipe],PROD_EQUIPE!B20,GERAL[Dia],">=" &PROD_EQUIPE!$Q$8,GERAL[Dia],"<=" &PROD_EQUIPE!$R$8) -> 0 | M20: =IFERROR(D20/C20,"") | N20: =IFERROR(E20/C20,"") | O20: =IFERROR(F20/C20,"") | P20: =IFERROR(G20/C20,"") | Q20: =IFERROR(SUM(F20:G20)/C20,"") | R20: =IFERROR(SUM(D20:E20)/C20,"")
C21: =COUNTIFS(GERAL[Dia Útil],"SIM",GERAL[Equipe],PROD_EQUIPE!B21,GERAL[Dia],">=" &PROD_EQUIPE!$Q$8,GERAL[Dia],"<=" &PROD_EQUIPE!$R$8) -> 0 | D21: =SUMIFS(GERAL[LA],GERAL[Equipe],PROD_EQUIPE!B21,GERAL[Dia],">=" &PROD_EQUIPE!$Q$8,GERAL[Dia],"<=" &PROD_EQUIPE!$R$8) -> 0 | E21: =SUMIFS(GERAL[LE],GERAL[Equipe],PROD_EQUIPE!B21,GERAL[Dia],">=" &PROD_EQUIPE!$Q$8,GERAL[Dia],"<=" &PROD_EQUIPE!$R$8) -> 0 | F21: =SUMIFS(GERAL[PRA],GERAL[Equipe],PROD_EQUIPE!B21,GERAL[Dia],">=" &PROD_EQUIPE!$Q$8,GERAL[Dia],"<=" &PROD_EQUIPE!$R$8) -> 0 | G21: =SUMIFS(GERAL[PRE],GERAL[Equipe],PROD_EQUIPE!B21,GERAL[Dia],">=" &PROD_EQUIPE!$Q$8,GERAL[Dia],"<=" &PROD_EQUIPE!$R$8) -> 0 | H21: =SUMIFS(GERAL[PV''s],GERAL[Equipe],PROD_EQUIPE!B21,GERAL[Dia],">=" &PROD_EQUIPE!$Q$8,GERAL[Dia],"<=" &PROD_EQUIPE!$R$8) -> 0 | I21: =SUMIFS(GERAL[LIE],GERAL[Equipe],PROD_EQUIPE!B21,GERAL[Dia],">=" &PROD_EQUIPE!$Q$8,GERAL[Dia],"<=" &PROD_EQUIPE!$R$8) -> 0 | J21: =SUMIFS(GERAL[LIA],GERAL[Equipe],PROD_EQUIPE!B21,GERAL[Dia],">=" &PROD_EQUIPE!$Q$8,GERAL[Dia],"<=" &PROD_EQUIPE!$R$8) -> 0 | K21: =SUMIFS(GERAL[IHM],GERAL[Equipe],PROD_EQUIPE!B21,GERAL[Dia],">=" &PROD_EQUIPE!$Q$8,GERAL[Dia],"<=" &PROD_EQUIPE!$R$8) -> 0 | L21: =SUMIFS(GERAL[RHM],GERAL[Equipe],PROD_EQUIPE!B21,GERAL[Dia],">=" &PROD_EQUIPE!$Q$8,GERAL[Dia],"<=" &PROD_EQUIPE!$R$8) -> 0 | M21: =IFERROR(D21/C21,"") | N21: =IFERROR(E21/C21,"") | O21: =IFERROR(F21/C21,"") | P21: =IFERROR(G21/C21,"") | Q21: =IFERROR(SUM(F21:G21)/C21,"") | R21: =IFERROR(SUM(D21:E21)/C21,"")
C22: =COUNTIFS(GERAL[Dia Útil],"SIM",GERAL[Equipe],PROD_EQUIPE!B22,GERAL[Dia],">=" &PROD_EQUIPE!$Q$8,GERAL[Dia],"<=" &PROD_EQUIPE!$R$8) -> 0 | D22: =SUMIFS(GERAL[LA],GERAL[Equipe],PROD_EQUIPE!B22,GERAL[Dia],">=" &PROD_EQUIPE!$Q$8,GERAL[Dia],"<=" &PROD_EQUIPE!$R$8) -> 0 | E22: =SUMIFS(GERAL[LE],GERAL[Equipe],PROD_EQUIPE!B22,GERAL[Dia],">=" &PROD_EQUIPE!$Q$8,GERAL[Dia],"<=" &PROD_EQUIPE!$R$8) -> 0 | F22: =SUMIFS(GERAL[PRA],GERAL[Equipe],PROD_EQUIPE!B22,GERAL[Dia],">=" &PROD_EQUIPE!$Q$8,GERAL[Dia],"<=" &PROD_EQUIPE!$R$8) -> 0 | G22: =SUMIFS(GERAL[PRE],GERAL[Equipe],PROD_EQUIPE!B22,GERAL[Dia],">=" &PROD_EQUIPE!$Q$8,GERAL[Dia],"<=" &PROD_EQUIPE!$R$8) -> 0 | H22: =SUMIFS(GERAL[PV''s],GERAL[Equipe],PROD_EQUIPE!B22,GERAL[Dia],">=" &PROD_EQUIPE!$Q$8,GERAL[Dia],"<=" &PROD_EQUIPE!$R$8) -> 0 | I22: =SUMIFS(GERAL[LIE],GERAL[Equipe],PROD_EQUIPE!B22,GERAL[Dia],">=" &PROD_EQUIPE!$Q$8,GERAL[Dia],"<=" &PROD_EQUIPE!$R$8) -> 0 | J22: =SUMIFS(GERAL[LIA],GERAL[Equipe],PROD_EQUIPE!B22,GERAL[Dia],">=" &PROD_EQUIPE!$Q$8,GERAL[Dia],"<=" &PROD_EQUIPE!$R$8) -> 0 | K22: =SUMIFS(GERAL[IHM],GERAL[Equipe],PROD_EQUIPE!B22,GERAL[Dia],">=" &PROD_EQUIPE!$Q$8,GERAL[Dia],"<=" &PROD_EQUIPE!$R$8) -> 0 | L22: =SUMIFS(GERAL[RHM],GERAL[Equipe],PROD_EQUIPE!B22,GERAL[Dia],">=" &PROD_EQUIPE!$Q$8,GERAL[Dia],"<=" &PROD_EQUIPE!$R$8) -> 0 | M22: =IFERROR(D22/C22,"") | N22: =IFERROR(E22/C22,"") | O22: =IFERROR(F22/C22,"") | P22: =IFERROR(G22/C22,"") | Q22: =IFERROR(SUM(F22:G22)/C22,"") | R22: =IFERROR(SUM(D22:E22)/C22,"")
C23: =COUNTIFS(GERAL[Dia Útil],"SIM",GERAL[Equipe],PROD_EQUIPE!B23,GERAL[Dia],">=" &PROD_EQUIPE!$Q$8,GERAL[Dia],"<=" &PROD_EQUIPE!$R$8) -> 0 | D23: =SUMIFS(GERAL[LA],GERAL[Equipe],PROD_EQUIPE!B23,GERAL[Dia],">=" &PROD_EQUIPE!$Q$8,GERAL[Dia],"<=" &PROD_EQUIPE!$R$8) -> 0 | E23: =SUMIFS(GERAL[LE],GERAL[Equipe],PROD_EQUIPE!B23,GERAL[Dia],">=" &PROD_EQUIPE!$Q$8,GERAL[Dia],"<=" &PROD_EQUIPE!$R$8) -> 0 | F23: =SUMIFS(GERAL[PRA],GERAL[Equipe],PROD_EQUIPE!B23,GERAL[Dia],">=" &PROD_EQUIPE!$Q$8,GERAL[Dia],"<=" &PROD_EQUIPE!$R$8) -> 0 | G23: =SUMIFS(GERAL[PRE],GERAL[Equipe],PROD_EQUIPE!B23,GERAL[Dia],">=" &PROD_EQUIPE!$Q$8,GERAL[Dia],"<=" &PROD_EQUIPE!$R$8) -> 0 | H23: =SUMIFS(GERAL[PV''s],GERAL[Equipe],PROD_EQUIPE!B23,GERAL[Dia],">=" &PROD_EQUIPE!$Q$8,GERAL[Dia],"<=" &PROD_EQUIPE!$R$8) -> 0 | I23: =SUMIFS(GERAL[LIE],GERAL[Equipe],PROD_EQUIPE!B23,GERAL[Dia],">=" &PROD_EQUIPE!$Q$8,GERAL[Dia],"<=" &PROD_EQUIPE!$R$8) -> 0 | J23: =SUMIFS(GERAL[LIA],GERAL[Equipe],PROD_EQUIPE!B23,GERAL[Dia],">=" &PROD_EQUIPE!$Q$8,GERAL[Dia],"<=" &PROD_EQUIPE!$R$8) -> 0 | K23: =SUMIFS(GERAL[IHM],GERAL[Equipe],PROD_EQUIPE!B23,GERAL[Dia],">=" &PROD_EQUIPE!$Q$8,GERAL[Dia],"<=" &PROD_EQUIPE!$R$8) -> 0 | L23: =SUMIFS(GERAL[RHM],GERAL[Equipe],PROD_EQUIPE!B23,GERAL[Dia],">=" &PROD_EQUIPE!$Q$8,GERAL[Dia],"<=" &PROD_EQUIPE!$R$8) -> 0 | M23: =IFERROR(D23/C23,"") | N23: =IFERROR(E23/C23,"") | O23: =IFERROR(F23/C23,"") | P23: =IFERROR(G23/C23,"") | Q23: =IFERROR(SUM(F23:G23)/C23,"") | R23: =IFERROR(SUM(D23:E23)/C23,"")
C24: =COUNTIFS(GERAL[Dia Útil],"SIM",GERAL[Equipe],PROD_EQUIPE!B24,GERAL[Dia],">=" &PROD_EQUIPE!$Q$8,GERAL[Dia],"<=" &PROD_EQUIPE!$R$8) -> 0 | D24: =SUMIFS(GERAL[LA],GERAL[Equipe],PROD_EQUIPE!B24,GERAL[Dia],">=" &PROD_EQUIPE!$Q$8,GERAL[Dia],"<=" &PROD_EQUIPE!$R$8) -> 0 | E24: =SUMIFS(GERAL[LE],GERAL[Equipe],PROD_EQUIPE!B24,GERAL[Dia],">=" &PROD_EQUIPE!$Q$8,GERAL[Dia],"<=" &PROD_EQUIPE!$R$8) -> 0 | F24: =SUMIFS(GERAL[PRA],GERAL[Equipe],PROD_EQUIPE!B24,GERAL[Dia],">=" &PROD_EQUIPE!$Q$8,GERAL[Dia],"<=" &PROD_EQUIPE!$R$8) -> 0 | G24: =SUMIFS(GERAL[PRE],GERAL[Equipe],PROD_EQUIPE!B24,GERAL[Dia],">=" &PROD_EQUIPE!$Q$8,GERAL[Dia],"<=" &PROD_EQUIPE!$R$8) -> 0 | H24: =SUMIFS(GERAL[PV''s],GERAL[Equipe],PROD_EQUIPE!B24,GERAL[Dia],">=" &PROD_EQUIPE!$Q$8,GERAL[Dia],"<=" &PROD_EQUIPE!$R$8) -> 0 | I24: =SUMIFS(GERAL[LIE],GERAL[Equipe],PROD_EQUIPE!B24,GERAL[Dia],">=" &PROD_EQUIPE!$Q$8,GERAL[Dia],"<=" &PROD_EQUIPE!$R$8) -> 0 | J24: =SUMIFS(GERAL[LIA],GERAL[Equipe],PROD_EQUIPE!B24,GERAL[Dia],">=" &PROD_EQUIPE!$Q$8,GERAL[Dia],"<=" &PROD_EQUIPE!$R$8) -> 0 | K24: =SUMIFS(GERAL[IHM],GERAL[Equipe],PROD_EQUIPE!B24,GERAL[Dia],">=" &PROD_EQUIPE!$Q$8,GERAL[Dia],"<=" &PROD_EQUIPE!$R$8) -> 0 | L24: =SUMIFS(GERAL[RHM],GERAL[Equipe],PROD_EQUIPE!B24,GERAL[Dia],">=" &PROD_EQUIPE!$Q$8,GERAL[Dia],"<=" &PROD_EQUIPE!$R$8) -> 0 | M24: =IFERROR(D24/C24,"") | N24: =IFERROR(E24/C24,"") | O24: =IFERROR(F24/C24,"") | P24: =IFERROR(G24/C24,"") | Q24: =IFERROR(SUM(F24:G24)/C24,"") | R24: =IFERROR(SUM(D24:E24)/C24,"")
C25: =COUNTIFS(GERAL[Dia Útil],"SIM",GERAL[Equipe],PROD_EQUIPE!B25,GERAL[Dia],">=" &PROD_EQUIPE!$Q$8,GERAL[Dia],"<=" &PROD_EQUIPE!$R$8) -> 0 | D25: =SUMIFS(GERAL[LA],GERAL[Equipe],PROD_EQUIPE!B25,GERAL[Dia],">=" &PROD_EQUIPE!$Q$8,GERAL[Dia],"<=" &PROD_EQUIPE!$R$8) -> 0 | E25: =SUMIFS(GERAL[LE],GERAL[Equipe],PROD_EQUIPE!B25,GERAL[Dia],">=" &PROD_EQUIPE!$Q$8,GERAL[Dia],"<=" &PROD_EQUIPE!$R$8) -> 0 | F25: =SUMIFS(GERAL[PRA],GERAL[Equipe],PROD_EQUIPE!B25,GERAL[Dia],">=" &PROD_EQUIPE!$Q$8,GERAL[Dia],"<=" &PROD_EQUIPE!$R$8) -> 0 | G25: =SUMIFS(GERAL[PRE],GERAL[Equipe],PROD_EQUIPE!B25,GERAL[Dia],">=" &PROD_EQUIPE!$Q$8,GERAL[Dia],"<=" &PROD_EQUIPE!$R$8) -> 0 | H25: =SUMIFS(GERAL[PV''s],GERAL[Equipe],PROD_EQUIPE!B25,GERAL[Dia],">=" &PROD_EQUIPE!$Q$8,GERAL[Dia],"<=" &PROD_EQUIPE!$R$8) -> 0 | I25: =SUMIFS(GERAL[LIE],GERAL[Equipe],PROD_EQUIPE!B25,GERAL[Dia],">=" &PROD_EQUIPE!$Q$8,GERAL[Dia],"<=" &PROD_EQUIPE!$R$8) -> 0 | J25: =SUMIFS(GERAL[LIA],GERAL[Equipe],PROD_EQUIPE!B25,GERAL[Dia],">=" &PROD_EQUIPE!$Q$8,GERAL[Dia],"<=" &PROD_EQUIPE!$R$8) -> 0 | K25: =SUMIFS(GERAL[IHM],GERAL[Equipe],PROD_EQUIPE!B25,GERAL[Dia],">=" &PROD_EQUIPE!$Q$8,GERAL[Dia],"<=" &PROD_EQUIPE!$R$8) -> 0 | L25: =SUMIFS(GERAL[RHM],GERAL[Equipe],PROD_EQUIPE!B25,GERAL[Dia],">=" &PROD_EQUIPE!$Q$8,GERAL[Dia],"<=" &PROD_EQUIPE!$R$8) -> 0 | M25: =IFERROR(D25/C25,"") | N25: =IFERROR(E25/C25,"") | O25: =IFERROR(F25/C25,"") | P25: =IFERROR(G25/C25,"") | Q25: =IFERROR(SUM(F25:G25)/C25,"") | R25: =IFERROR(SUM(D25:E25)/C25,"")
C26: =COUNTIFS(GERAL[Dia Útil],"SIM",GERAL[Equipe],PROD_EQUIPE!B26,GERAL[Dia],">=" &PROD_EQUIPE!$Q$8,GERAL[Dia],"<=" &PROD_EQUIPE!$R$8) -> 0 | D26: =SUMIFS(GERAL[LA],GERAL[Equipe],PROD_EQUIPE!B26,GERAL[Dia],">=" &PROD_EQUIPE!$Q$8,GERAL[Dia],"<=" &PROD_EQUIPE!$R$8) -> 0 | E26: =SUMIFS(GERAL[LE],GERAL[Equipe],PROD_EQUIPE!B26,GERAL[Dia],">=" &PROD_EQUIPE!$Q$8,GERAL[Dia],"<=" &PROD_EQUIPE!$R$8) -> 0 | F26: =SUMIFS(GERAL[PRA],GERAL[Equipe],PROD_EQUIPE!B26,GERAL[Dia],">=" &PROD_EQUIPE!$Q$8,GERAL[Dia],"<=" &PROD_EQUIPE!$R$8) -> 0 | G26: =SUMIFS(GERAL[PRE],GERAL[Equipe],PROD_EQUIPE!B26,GERAL[Dia],">=" &PROD_EQUIPE!$Q$8,GERAL[Dia],"<=" &PROD_EQUIPE!$R$8) -> 0 | H26: =SUMIFS(GERAL[PV''s],GERAL[Equipe],PROD_EQUIPE!B26,GERAL[Dia],">=" &PROD_EQUIPE!$Q$8,GERAL[Dia],"<=" &PROD_EQUIPE!$R$8) -> 0 | I26: =SUMIFS(GERAL[LIE],GERAL[Equipe],PROD_EQUIPE!B26,GERAL[Dia],">=" &PROD_EQUIPE!$Q$8,GERAL[Dia],"<=" &PROD_EQUIPE!$R$8) -> 0 | J26: =SUMIFS(GERAL[LIA],GERAL[Equipe],PROD_EQUIPE!B26,GERAL[Dia],">=" &PROD_EQUIPE!$Q$8,GERAL[Dia],"<=" &PROD_EQUIPE!$R$8) -> 0 | K26: =SUMIFS(GERAL[IHM],GERAL[Equipe],PROD_EQUIPE!B26,GERAL[Dia],">=" &PROD_EQUIPE!$Q$8,GERAL[Dia],"<=" &PROD_EQUIPE!$R$8) -> 0 | L26: =SUMIFS(GERAL[RHM],GERAL[Equipe],PROD_EQUIPE!B26,GERAL[Dia],">=" &PROD_EQUIPE!$Q$8,GERAL[Dia],"<=" &PROD_EQUIPE!$R$8) -> 0 | M26: =IFERROR(D26/C26,"") | N26: =IFERROR(E26/C26,"") | O26: =IFERROR(F26/C26,"") | P26: =IFERROR(G26/C26,"") | Q26: =IFERROR(SUM(F26:G26)/C26,"") | R26: =IFERROR(SUM(D26:E26)/C26,"")
C27: =COUNTIFS(GERAL[Dia Útil],"SIM",GERAL[Equipe],PROD_EQUIPE!B27,GERAL[Dia],">=" &PROD_EQUIPE!$Q$8,GERAL[Dia],"<=" &PROD_EQUIPE!$R$8) -> 0 | D27: =SUMIFS(GERAL[LA],GERAL[Equipe],PROD_EQUIPE!B27,GERAL[Dia],">=" &PROD_EQUIPE!$Q$8,GERAL[Dia],"<=" &PROD_EQUIPE!$R$8) -> 0 | E27: =SUMIFS(GERAL[LE],GERAL[Equipe],PROD_EQUIPE!B27,GERAL[Dia],">=" &PROD_EQUIPE!$Q$8,GERAL[Dia],"<=" &PROD_EQUIPE!$R$8) -> 0 | F27: =SUMIFS(GERAL[PRA],GERAL[Equipe],PROD_EQUIPE!B27,GERAL[Dia],">=" &PROD_EQUIPE!$Q$8,GERAL[Dia],"<=" &PROD_EQUIPE!$R$8) -> 0 | G27: =SUMIFS(GERAL[PRE],GERAL[Equipe],PROD_EQUIPE!B27,GERAL[Dia],">=" &PROD_EQUIPE!$Q$8,GERAL[Dia],"<=" &PROD_EQUIPE!$R$8) -> 0 | H27: =SUMIFS(GERAL[PV''s],GERAL[Equipe],PROD_EQUIPE!B27,GERAL[Dia],">=" &PROD_EQUIPE!$Q$8,GERAL[Dia],"<=" &PROD_EQUIPE!$R$8) -> 0 | I27: =SUMIFS(GERAL[LIE],GERAL[Equipe],PROD_EQUIPE!B27,GERAL[Dia],">=" &PROD_EQUIPE!$Q$8,GERAL[Dia],"<=" &PROD_EQUIPE!$R$8) -> 0 | J27: =SUMIFS(GERAL[LIA],GERAL[Equipe],PROD_EQUIPE!B27,GERAL[Dia],">=" &PROD_EQUIPE!$Q$8,GERAL[Dia],"<=" &PROD_EQUIPE!$R$8) -> 0 | K27: =SUMIFS(GERAL[IHM],GERAL[Equipe],PROD_EQUIPE!B27,GERAL[Dia],">=" &PROD_EQUIPE!$Q$8,GERAL[Dia],"<=" &PROD_EQUIPE!$R$8) -> 0 | L27: =SUMIFS(GERAL[RHM],GERAL[Equipe],PROD_EQUIPE!B27,GERAL[Dia],">=" &PROD_EQUIPE!$Q$8,GERAL[Dia],"<=" &PROD_EQUIPE!$R$8) -> 0 | M27: =IFERROR(D27/C27,"") | N27: =IFERROR(E27/C27,"") | O27: =IFERROR(F27/C27,"") | P27: =IFERROR(G27/C27,"") | Q27: =IFERROR(SUM(F27:G27)/C27,"") | R27: =IFERROR(SUM(D27:E27)/C27,"")
C28: =COUNTIFS(GERAL[Dia Útil],"SIM",GERAL[Equipe],PROD_EQUIPE!B28,GERAL[Dia],">=" &PROD_EQUIPE!$Q$8,GERAL[Dia],"<=" &PROD_EQUIPE!$R$8) -> 0 | D28: =SUMIFS(GERAL[LA],GERAL[Equipe],PROD_EQUIPE!B28,GERAL[Dia],">=" &PROD_EQUIPE!$Q$8,GERAL[Dia],"<=" &PROD_EQUIPE!$R$8) -> 0 | E28: =SUMIFS(GERAL[LE],GERAL[Equipe],PROD_EQUIPE!B28,GERAL[Dia],">=" &PROD_EQUIPE!$Q$8,GERAL[Dia],"<=" &PROD_EQUIPE!$R$8) -> 0 | F28: =SUMIFS(GERAL[PRA],GERAL[Equipe],PROD_EQUIPE!B28,GERAL[Dia],">=" &PROD_EQUIPE!$Q$8,GERAL[Dia],"<=" &PROD_EQUIPE!$R$8) -> 0 | G28: =SUMIFS(GERAL[PRE],GERAL[Equipe],PROD_EQUIPE!B28,GERAL[Dia],">=" &PROD_EQUIPE!$Q$8,GERAL[Dia],"<=" &PROD_EQUIPE!$R$8) -> 0 | H28: =SUMIFS(GERAL[PV''s],GERAL[Equipe],PROD_EQUIPE!B28,GERAL[Dia],">=" &PROD_EQUIPE!$Q$8,GERAL[Dia],"<=" &PROD_EQUIPE!$R$8) -> 0 | I28: =SUMIFS(GERAL[LIE],GERAL[Equipe],PROD_EQUIPE!B28,GERAL[Dia],">=" &PROD_EQUIPE!$Q$8,GERAL[Dia],"<=" &PROD_EQUIPE!$R$8) -> 0 | J28: =SUMIFS(GERAL[LIA],GERAL[Equipe],PROD_EQUIPE!B28,GERAL[Dia],">=" &PROD_EQUIPE!$Q$8,GERAL[Dia],"<=" &PROD_EQUIPE!$R$8) -> 0 | K28: =SUMIFS(GERAL[IHM],GERAL[Equipe],PROD_EQUIPE!B28,GERAL[Dia],">=" &PROD_EQUIPE!$Q$8,GERAL[Dia],"<=" &PROD_EQUIPE!$R$8) -> 0 | L28: =SUMIFS(GERAL[RHM],GERAL[Equipe],PROD_EQUIPE!B28,GERAL[Dia],">=" &PROD_EQUIPE!$Q$8,GERAL[Dia],"<=" &PROD_EQUIPE!$R$8) -> 0 | M28: =IFERROR(D28/C28,"") | N28: =IFERROR(E28/C28,"") | O28: =IFERROR(F28/C28,"") | P28: =IFERROR(G28/C28,"") | Q28: =IFERROR(SUM(F28:G28)/C28,"") | R28: =IFERROR(SUM(D28:E28)/C28,"")
... C31: =COUNTIFS(GERAL[Dia Útil],"SIM",GERAL[Equipe],PROD_EQUIPE!B31,GERAL[Dia],">=" &PROD_EQUIPE!$Q$8,GERAL[Dia],"<=" &PROD_EQUIPE!$R$8) -> 0 | D31: =SUMIFS(GERAL[LA],GERAL[Equipe],PROD_EQUIPE!B31,GERAL[Dia],">=" &PROD_EQUIPE!$Q$8,GERAL[Dia],"<=" &PROD_EQUIPE!$R$8) -> 0 | E31: =SUMIFS(GERAL[LE],GERAL[Equipe],PROD_EQUIPE!B31,GERAL[Dia],">=" &PROD_EQUIPE!$Q$8,GERAL[Dia],"<=" &PROD_EQUIPE!$R$8) -> 0 | F31: =SUMIFS(GERAL[PRA],GERAL[Equipe],PROD_EQUIPE!B31,GERAL[Dia],">=" &PROD_EQUIPE!$Q$8,GERAL[Dia],"<=" &PROD_EQUIPE!$R$8) -> 0 | G31: =SUMIFS(GERAL[PRE],GERAL[Equipe],PROD_EQUIPE!B31,GERAL[Dia],">=" &PROD_EQUIPE!$Q$8,GERAL[Dia],"<=" &PROD_EQUIPE!$R$8) -> 0 | H31: =SUMIFS(GERAL[PV''s],GERAL[Equipe],PROD_EQUIPE!B31,GERAL[Dia],">=" &PROD_EQUIPE!$Q$8,GERAL[Dia],"<=" &PROD_EQUIPE!$R$8) -> 0 | I31: =SUMIFS(GERAL[LIE],GERAL[Equipe],PROD_EQUIPE!B31,GERAL[Dia],">=" &PROD_EQUIPE!$Q$8,GERAL[Dia],"<=" &PROD_EQUIPE!$R$8) -> 0 | J31: =SUMIFS(GERAL[LIA],GERAL[Equipe],PROD_EQUIPE!B31,GERAL[Dia],">=" &PROD_EQUIPE!$Q$8,GERAL[Dia],"<=" &PROD_EQUIPE!$R$8) -> 0 | K31: =SUMIFS(GERAL[IHM],GERAL[Equipe],PROD_EQUIPE!B31,GERAL[Dia],">=" &PROD_EQUIPE!$Q$8,GERAL[Dia],"<=" &PROD_EQUIPE!$R$8) -> 0 | L31: =SUMIFS(GERAL[RHM],GERAL[Equipe],PROD_EQUIPE!B31,GERAL[Dia],">=" &PROD_EQUIPE!$Q$8,GERAL[Dia],"<=" &PROD_EQUIPE!$R$8) -> 0 | M31: =IFERROR(D31/C31,"") | N31: =IFERROR(E31/C31,"") | O31: =IFERROR(F31/C31,"") | P31: =IFERROR(G31/C31,"") | Q31: =IFERROR(SUM(F31:G31)/C31,"") | R31: =IFERROR(SUM(D31:E31)/C31,"")
C32: =SUM(C11:C31) -> 99 | D32: =SUM(D11:D31) -> 176 | E32: =SUM(E11:E31) -> 140 | F32: =SUM(F11:F31) -> 1344.1 | G32: =SUM(G11:G31) -> 444.4 | H32: =SUM(H11:H31) -> 12 | I32: =SUM(I11:I31) -> 11 | J32: =SUM(J11:J31) -> 199 | ... L32: =SUM(L11:L31) -> 0
J34: PRODUTIVIDADE MÉDIA | M34: =IFERROR(AVERAGE(M11:M31),"") -> 1.6083292 | N34: =IFERROR(AVERAGE(N11:N31),"") -> 1.2529164 | O34: =IFERROR(AVERAGE(O11:O31),"") -> 12.631561 | P34: =IFERROR(AVERAGE(P11:P31),"") -> 4.1821627 | Q34: =IFERROR(AVERAGE(Q11:Q31),"") -> 16.813724 | R34: =IFERROR(AVERAGE(R11:R31),"") -> 2.8612456
J35: MÉDIA INTERNA | M35: {=IFERROR(TRIMMEAN(IF(M11:M31>0.01,M11:M31),40%),"")} -> 2.0104115 | N35: {=IFERROR(TRIMMEAN(IF(N11:N31>0.01,N11:N31),40%),"")} -> 2.088194 | O35: {=IFERROR(TRIMMEAN(IF(O11:O31>0.01,O11:O31),40%),"")} -> 15.789451 | P35: {=IFERROR(TRIMMEAN(IF(P11:P31>0.01,P11:P31),40%),"")} -> 5.2277034 | Q35: {=IFERROR(TRIMMEAN(IF(Q11:Q31>0.01,Q11:Q31),40%),"")} -> 21.017155 | R35: {=IFERROR(TRIMMEAN(IF(R11:R31>0.01,R11:R31),40%),"")} -> 3.576557

Sheet PROD_NÚCLEO
S2: Informar período
E3: SE LIGA NA REDE - SANTOS
E4: PRODUÇÃO POR NÚCLEO - RUA
Q7: DE | R7: ATÉ
P8: PERÍODO | Q8: 46052 | R8: =TODAY()-1 -> 46133
B10: RUA | C10: DIAS ÚTEIS | D10: LA | E10: LE | F10: PRA | G10: PRE | H10: PV's | I10: LIE | J10: LIA | K10: IHM | L10: RHM | M10: Ind. Prod. LA | N10: Ind Prod LE | O10: Ind Prod PRA | P10: Ind Prod PRE | Q10: IND. PROD REDE | R10: IND. PROD LIG
B11: BECO 3 | C11: =COUNTIFS(GERAL[Dia Útil],"SIM",GERAL[Rua],B11,GERAL[Dia],">=" &$Q$8,GERAL[Dia],"<=" &$R$8) -> 5 | D11: =SUMIFS(GERAL[LA],GERAL[Rua],B11,GERAL[Dia],">=" &$Q$8,GERAL[Dia],"<=" &$R$8) -> 11 | E11: =SUMIFS(GERAL[LE],GERAL[Rua],B11,GERAL[Dia],">=" &$Q$8,GERAL[Dia],"<=" &$R$8) -> 12 | F11: =SUMIFS(GERAL[PRA],GERAL[Rua],B11,GERAL[Dia],">=" &$Q$8,GERAL[Dia],"<=" &$R$8) -> 0 | G11: =SUMIFS(GERAL[PRE],GERAL[Rua],B11,GERAL[Dia],">=" &$Q$8,GERAL[Dia],"<=" &$R$8) -> 0 | H11: =SUMIFS(GERAL[PV''s],GERAL[Rua],B11,GERAL[Dia],">=" &$Q$8,GERAL[Dia],"<=" &$R$8) -> 0 | I11: =SUMIFS(GERAL[LIE],GERAL[Rua],B11,GERAL[Dia],">=" &$Q$8,GERAL[Dia],"<=" &$R$8) -> 0 | J11: =SUMIFS(GERAL[LIA],GERAL[Rua],B11,GERAL[Dia],">=" &$Q$8,GERAL[Dia],"<=" &$R$8) -> 0 | K11: =SUMIFS(GERAL[IHM],GERAL[Rua],B11,GERAL[Dia],">=" &$Q$8,GERAL[Dia],"<=" &$R$8) -> 15 | L11: =SUMIFS(GERAL[RHM],GERAL[Rua],B11,GERAL[Dia],">=" &$Q$8,GERAL[Dia],"<=" &$R$8) -> 0 | M11: =IFERROR(D11/C11,"") -> 2.2 | N11: =IFERROR(E11/C11,"") -> 2.4 | O11: =IFERROR(F11/C11,"") -> 0 | P11: =IFERROR(G11/C11,"") -> 0 | Q11: =IFERROR(SUM(F11:G11)/C11,"") -> 0 | R11: =IFERROR(SUM(D11:E11)/C11,"") -> 4.6
B12: BECO 3 | C12: =COUNTIFS(GERAL[Dia Útil],"SIM",GERAL[Rua],B12,GERAL[Dia],">=" &$Q$8,GERAL[Dia],"<=" &$R$8) -> 1 | D12: =SUMIFS(GERAL[LA],GERAL[Rua],B12,GERAL[Dia],">=" &$Q$8,GERAL[Dia],"<=" &$R$8) -> 0 | E12: =SUMIFS(GERAL[LE],GERAL[Rua],B12,GERAL[Dia],">=" &$Q$8,GERAL[Dia],"<=" &$R$8) -> 0 | F12: =SUMIFS(GERAL[PRA],GERAL[Rua],B12,GERAL[Dia],">=" &$Q$8,GERAL[Dia],"<=" &$R$8) -> 30 | G12: =SUMIFS(GERAL[PRE],GERAL[Rua],B12,GERAL[Dia],">=" &$Q$8,GERAL[Dia],"<=" &$R$8) -> 0 | H12: =SUMIFS(GERAL[PV''s],GERAL[Rua],B12,GERAL[Dia],">=" &$Q$8,GERAL[Dia],"<=" &$R$8) -> 0 | I12: =SUMIFS(GERAL[LIE],GERAL[Rua],B12,GERAL[Dia],">=" &$Q$8,GERAL[Dia],"<=" &$R$8) -> 0 | J12: =SUMIFS(GERAL[LIA],GERAL[Rua],B12,GERAL[Dia],">=" &$Q$8,GERAL[Dia],"<=" &$R$8) -> 0 | K12: =SUMIFS(GERAL[IHM],GERAL[Rua],B12,GERAL[Dia],">=" &$Q$8,GERAL[Dia],"<=" &$R$8) -> 0 | L12: =SUMIFS(GERAL[RHM],GERAL[Rua],B12,GERAL[Dia],">=" &$Q$8,GERAL[Dia],"<=" &$R$8) -> 0 | M12: =IFERROR(D12/C12,"") -> 0 | N12: =IFERROR(E12/C12,"") -> 0 | O12: =IFERROR(F12/C12,"") -> 30 | P12: =IFERROR(G12/C12,"") -> 0 | Q12: =IFERROR(SUM(F12:G12)/C12,"") -> 30 | R12: =IFERROR(SUM(D12:E12)/C12,"") -> 0
B13: BECO 62 | C13: =COUNTIFS(GERAL[Dia Útil],"SIM",GERAL[Rua],B13,GERAL[Dia],">=" &$Q$8,GERAL[Dia],"<=" &$R$8) -> 1 | D13: =SUMIFS(GERAL[LA],GERAL[Rua],B13,GERAL[Dia],">=" &$Q$8,GERAL[Dia],"<=" &$R$8) -> 0 | E13: =SUMIFS(GERAL[LE],GERAL[Rua],B13,GERAL[Dia],">=" &$Q$8,GERAL[Dia],"<=" &$R$8) -> 0 | F13: =SUMIFS(GERAL[PRA],GERAL[Rua],B13,GERAL[Dia],">=" &$Q$8,GERAL[Dia],"<=" &$R$8) -> 0 | G13: =SUMIFS(GERAL[PRE],GERAL[Rua],B13,GERAL[Dia],">=" &$Q$8,GERAL[Dia],"<=" &$R$8) -> 0 | H13: =SUMIFS(GERAL[PV''s],GERAL[Rua],B13,GERAL[Dia],">=" &$Q$8,GERAL[Dia],"<=" &$R$8) -> 0 | I13: =SUMIFS(GERAL[LIE],GERAL[Rua],B13,GERAL[Dia],">=" &$Q$8,GERAL[Dia],"<=" &$R$8) -> 0 | J13: =SUMIFS(GERAL[LIA],GERAL[Rua],B13,GERAL[Dia],">=" &$Q$8,GERAL[Dia],"<=" &$R$8) -> 0 | K13: =SUMIFS(GERAL[IHM],GERAL[Rua],B13,GERAL[Dia],">=" &$Q$8,GERAL[Dia],"<=" &$R$8) -> 10 | L13: =SUMIFS(GERAL[RHM],GERAL[Rua],B13,GERAL[Dia],">=" &$Q$8,GERAL[Dia],"<=" &$R$8) -> 0 | M13: =IFERROR(D13/C13,"") -> 0 | N13: =IFERROR(E13/C13,"") -> 0 | O13: =IFERROR(F13/C13,"") -> 0 | P13: =IFERROR(G13/C13,"") -> 0 | Q13: =IFERROR(SUM(F13:G13)/C13,"") -> 0 | R13: =IFERROR(SUM(D13:E13)/C13,"") -> 0
B14: BECO 72 | C14: =COUNTIFS(GERAL[Dia Útil],"SIM",GERAL[Rua],B14,GERAL[Dia],">=" &$Q$8,GERAL[Dia],"<=" &$R$8) -> 1 | D14: =SUMIFS(GERAL[LA],GERAL[Rua],B14,GERAL[Dia],">=" &$Q$8,GERAL[Dia],"<=" &$R$8) -> 0 | E14: =SUMIFS(GERAL[LE],GERAL[Rua],B14,GERAL[Dia],">=" &$Q$8,GERAL[Dia],"<=" &$R$8) -> 0 | F14: =SUMIFS(GERAL[PRA],GERAL[Rua],B14,GERAL[Dia],">=" &$Q$8,GERAL[Dia],"<=" &$R$8) -> 0 | G14: =SUMIFS(GERAL[PRE],GERAL[Rua],B14,GERAL[Dia],">=" &$Q$8,GERAL[Dia],"<=" &$R$8) -> 0 | H14: =SUMIFS(GERAL[PV''s],GERAL[Rua],B14,GERAL[Dia],">=" &$Q$8,GERAL[Dia],"<=" &$R$8) -> 0 | I14: =SUMIFS(GERAL[LIE],GERAL[Rua],B14,GERAL[Dia],">=" &$Q$8,GERAL[Dia],"<=" &$R$8) -> 0 | J14: =SUMIFS(GERAL[LIA],GERAL[Rua],B14,GERAL[Dia],">=" &$Q$8,GERAL[Dia],"<=" &$R$8) -> 0 | K14: =SUMIFS(GERAL[IHM],GERAL[Rua],B14,GERAL[Dia],">=" &$Q$8,GERAL[Dia],"<=" &$R$8) -> 4 | L14: =SUMIFS(GERAL[RHM],GERAL[Rua],B14,GERAL[Dia],">=" &$Q$8,GERAL[Dia],"<=" &$R$8) -> 0 | M14: =IFERROR(D14/C14,"") -> 0 | N14: =IFERROR(E14/C14,"") -> 0 | O14: =IFERROR(F14/C14,"") -> 0 | P14: =IFERROR(G14/C14,"") -> 0 | Q14: =IFERROR(SUM(F14:G14)/C14,"") -> 0 | R14: =IFERROR(SUM(D14:E14)/C14,"") -> 0
B15: BECO DO MOACIR | C15: =COUNTIFS(GERAL[Dia Útil],"SIM",GERAL[Rua],B15,GERAL[Dia],">=" &$Q$8,GERAL[Dia],"<=" &$R$8) -> 2 | D15: =SUMIFS(GERAL[LA],GERAL[Rua],B15,GERAL[Dia],">=" &$Q$8,GERAL[Dia],"<=" &$R$8) -> 0 | E15: =SUMIFS(GERAL[LE],GERAL[Rua],B15,GERAL[Dia],">=" &$Q$8,GERAL[Dia],"<=" &$R$8) -> 0 | F15: =SUMIFS(GERAL[PRA],GERAL[Rua],B15,GERAL[Dia],">=" &$Q$8,GERAL[Dia],"<=" &$R$8) -> 0 | G15: =SUMIFS(GERAL[PRE],GERAL[Rua],B15,GERAL[Dia],">=" &$Q$8,GERAL[Dia],"<=" &$R$8) -> 0 | H15: =SUMIFS(GERAL[PV''s],GERAL[Rua],B15,GERAL[Dia],">=" &$Q$8,GERAL[Dia],"<=" &$R$8) -> 0 | I15: =SUMIFS(GERAL[LIE],GERAL[Rua],B15,GERAL[Dia],">=" &$Q$8,GERAL[Dia],"<=" &$R$8) -> 0 | J15: =SUMIFS(GERAL[LIA],GERAL[Rua],B15,GERAL[Dia],">=" &$Q$8,GERAL[Dia],"<=" &$R$8) -> 4 | K15: =SUMIFS(GERAL[IHM],GERAL[Rua],B15,GERAL[Dia],">=" &$Q$8,GERAL[Dia],"<=" &$R$8) -> 1 | L15: =SUMIFS(GERAL[RHM],GERAL[Rua],B15,GERAL[Dia],">=" &$Q$8,GERAL[Dia],"<=" &$R$8) -> 0 | M15: =IFERROR(D15/C15,"") -> 0 | N15: =IFERROR(E15/C15,"") -> 0 | O15: =IFERROR(F15/C15,"") -> 0 | P15: =IFERROR(G15/C15,"") -> 0 | Q15: =IFERROR(SUM(F15:G15)/C15,"") -> 0 | R15: =IFERROR(SUM(D15:E15)/C15,"") -> 0
B16: BEIRA RIO | C16: =COUNTIFS(GERAL[Dia Útil],"SIM",GERAL[Rua],B16,GERAL[Dia],">=" &$Q$8,GERAL[Dia],"<=" &$R$8) -> 2 | D16: =SUMIFS(GERAL[LA],GERAL[Rua],B16,GERAL[Dia],">=" &$Q$8,GERAL[Dia],"<=" &$R$8) -> 0 | E16: =SUMIFS(GERAL[LE],GERAL[Rua],B16,GERAL[Dia],">=" &$Q$8,GERAL[Dia],"<=" &$R$8) -> 0 | F16: =SUMIFS(GERAL[PRA],GERAL[Rua],B16,GERAL[Dia],">=" &$Q$8,GERAL[Dia],"<=" &$R$8) -> 0 | G16: =SUMIFS(GERAL[PRE],GERAL[Rua],B16,GERAL[Dia],">=" &$Q$8,GERAL[Dia],"<=" &$R$8) -> 13 | H16: =SUMIFS(GERAL[PV''s],GERAL[Rua],B16,GERAL[Dia],">=" &$Q$8,GERAL[Dia],"<=" &$R$8) -> 3 | I16: =SUMIFS(GERAL[LIE],GERAL[Rua],B16,GERAL[Dia],">=" &$Q$8,GERAL[Dia],"<=" &$R$8) -> 0 | J16: =SUMIFS(GERAL[LIA],GERAL[Rua],B16,GERAL[Dia],">=" &$Q$8,GERAL[Dia],"<=" &$R$8) -> 0 | K16: =SUMIFS(GERAL[IHM],GERAL[Rua],B16,GERAL[Dia],">=" &$Q$8,GERAL[Dia],"<=" &$R$8) -> 0 | L16: =SUMIFS(GERAL[RHM],GERAL[Rua],B16,GERAL[Dia],">=" &$Q$8,GERAL[Dia],"<=" &$R$8) -> 0 | M16: =IFERROR(D16/C16,"") -> 0 | N16: =IFERROR(E16/C16,"") -> 0 | O16: =IFERROR(F16/C16,"") -> 0 | P16: =IFERROR(G16/C16,"") -> 6.5 | Q16: =IFERROR(SUM(F16:G16)/C16,"") -> 6.5 | R16: =IFERROR(SUM(D16:E16)/C16,"") -> 0
B17: CAMINHO DA ESPERANÇA | C17: =COUNTIFS(GERAL[Dia Útil],"SIM",GERAL[Rua],B17,GERAL[Dia],">=" &$Q$8,GERAL[Dia],"<=" &$R$8) -> 13 | D17: =SUMIFS(GERAL[LA],GERAL[Rua],B17,GERAL[Dia],">=" &$Q$8,GERAL[Dia],"<=" &$R$8) -> 1 | E17: =SUMIFS(GERAL[LE],GERAL[Rua],B17,GERAL[Dia],">=" &$Q$8,GERAL[Dia],"<=" &$R$8) -> 26 | F17: =SUMIFS(GERAL[PRA],GERAL[Rua],B17,GERAL[Dia],">=" &$Q$8,GERAL[Dia],"<=" &$R$8) -> 0 | G17: =SUMIFS(GERAL[PRE],GERAL[Rua],B17,GERAL[Dia],">=" &$Q$8,GERAL[Dia],"<=" &$R$8) -> 92.4 | H17: =SUMIFS(GERAL[PV''s],GERAL[Rua],B17,GERAL[Dia],">=" &$Q$8,GERAL[Dia],"<=" &$R$8) -> 1 | I17: =SUMIFS(GERAL[LIE],GERAL[Rua],B17,GERAL[Dia],">=" &$Q$8,GERAL[Dia],"<=" &$R$8) -> 0 | J17: =SUMIFS(GERAL[LIA],GERAL[Rua],B17,GERAL[Dia],">=" &$Q$8,GERAL[Dia],"<=" &$R$8) -> 22 | K17: =SUMIFS(GERAL[IHM],GERAL[Rua],B17,GERAL[Dia],">=" &$Q$8,GERAL[Dia],"<=" &$R$8) -> 0 | L17: =SUMIFS(GERAL[RHM],GERAL[Rua],B17,GERAL[Dia],">=" &$Q$8,GERAL[Dia],"<=" &$R$8) -> 0 | M17: =IFERROR(D17/C17,"") -> 0.076923077 | N17: =IFERROR(E17/C17,"") -> 2 | O17: =IFERROR(F17/C17,"") -> 0 | P17: =IFERROR(G17/C17,"") -> 7.1076923 | Q17: =IFERROR(SUM(F17:G17)/C17,"") -> 7.1076923 | R17: =IFERROR(SUM(D17:E17)/C17,"") -> 2.0769231
B18: CAMINHO PARTICULAR SÃO JORGE | C18: =COUNTIFS(GERAL[Dia Útil],"SIM",GERAL[Rua],B18,GERAL[Dia],">=" &$Q$8,GERAL[Dia],"<=" &$R$8) -> 7 | D18: =SUMIFS(GERAL[LA],GERAL[Rua],B18,GERAL[Dia],">=" &$Q$8,GERAL[Dia],"<=" &$R$8) -> 6 | E18: =SUMIFS(GERAL[LE],GERAL[Rua],B18,GERAL[Dia],">=" &$Q$8,GERAL[Dia],"<=" &$R$8) -> 8 | F18: =SUMIFS(GERAL[PRA],GERAL[Rua],B18,GERAL[Dia],">=" &$Q$8,GERAL[Dia],"<=" &$R$8) -> 95 | G18: =SUMIFS(GERAL[PRE],GERAL[Rua],B18,GERAL[Dia],">=" &$Q$8,GERAL[Dia],"<=" &$R$8) -> 68 | H18: =SUMIFS(GERAL[PV''s],GERAL[Rua],B18,GERAL[Dia],">=" &$Q$8,GERAL[Dia],"<=" &$R$8) -> 1 | I18: =SUMIFS(GERAL[LIE],GERAL[Rua],B18,GERAL[Dia],">=" &$Q$8,GERAL[Dia],"<=" &$R$8) -> 0 | J18: =SUMIFS(GERAL[LIA],GERAL[Rua],B18,GERAL[Dia],">=" &$Q$8,GERAL[Dia],"<=" &$R$8) -> 0 | K18: =SUMIFS(GERAL[IHM],GERAL[Rua],B18,GERAL[Dia],">=" &$Q$8,GERAL[Dia],"<=" &$R$8) -> 0 | L18: =SUMIFS(GERAL[RHM],GERAL[Rua],B18,GERAL[Dia],">=" &$Q$8,GERAL[Dia],"<=" &$R$8) -> 0 | M18: =IFERROR(D18/C18,"") -> 0.85714286 | N18: =IFERROR(E18/C18,"") -> 1.1428571 | O18: =IFERROR(F18/C18,"") -> 13.571429 | P18: =IFERROR(G18/C18,"") -> 9.7142857 | Q18: =IFERROR(SUM(F18:G18)/C18,"") -> 23.285714 | R18: =IFERROR(SUM(D18:E18)/C18,"") -> 2
B19: CHUVA | C19: =COUNTIFS(GERAL[Dia Útil],"SIM",GERAL[Rua],B19,GERAL[Dia],">=" &$Q$8,GERAL[Dia],"<=" &$R$8) -> 0 | D19: =SUMIFS(GERAL[LA],GERAL[Rua],B19,GERAL[Dia],">=" &$Q$8,GERAL[Dia],"<=" &$R$8) -> 0 | E19: =SUMIFS(GERAL[LE],GERAL[Rua],B19,GERAL[Dia],">=" &$Q$8,GERAL[Dia],"<=" &$R$8) -> 0 | F19: =SUMIFS(GERAL[PRA],GERAL[Rua],B19,GERAL[Dia],">=" &$Q$8,GERAL[Dia],"<=" &$R$8) -> 0 | G19: =SUMIFS(GERAL[PRE],GERAL[Rua],B19,GERAL[Dia],">=" &$Q$8,GERAL[Dia],"<=" &$R$8) -> 0 | H19: =SUMIFS(GERAL[PV''s],GERAL[Rua],B19,GERAL[Dia],">=" &$Q$8,GERAL[Dia],"<=" &$R$8) -> 0 | I19: =SUMIFS(GERAL[LIE],GERAL[Rua],B19,GERAL[Dia],">=" &$Q$8,GERAL[Dia],"<=" &$R$8) -> 0 | J19: =SUMIFS(GERAL[LIA],GERAL[Rua],B19,GERAL[Dia],">=" &$Q$8,GERAL[Dia],"<=" &$R$8) -> 0 | K19: =SUMIFS(GERAL[IHM],GERAL[Rua],B19,GERAL[Dia],">=" &$Q$8,GERAL[Dia],"<=" &$R$8) -> 0 | L19: =SUMIFS(GERAL[RHM],GERAL[Rua],B19,GERAL[Dia],">=" &$Q$8,GERAL[Dia],"<=" &$R$8) -> 0 | M19: =IFERROR(D19/C19,"") | N19: =IFERROR(E19/C19,"") | O19: =IFERROR(F19/C19,"") | P19: =IFERROR(G19/C19,"") | Q19: =IFERROR(SUM(F19:G19)/C19,"") | R19: =IFERROR(SUM(D19:E19)/C19,"")
B20: Diversas até 28/02 - MT | C20: =COUNTIFS(GERAL[Dia Útil],"SIM",GERAL[Rua],B20,GERAL[Dia],">=" &$Q$8,GERAL[Dia],"<=" &$R$8) -> 21 | D20: =SUMIFS(GERAL[LA],GERAL[Rua],B20,GERAL[Dia],">=" &$Q$8,GERAL[Dia],"<=" &$R$8) -> 70 | E20: =SUMIFS(GERAL[LE],GERAL[Rua],B20,GERAL[Dia],">=" &$Q$8,GERAL[Dia],"<=" &$R$8) -> 82 | F20: =SUMIFS(GERAL[PRA],GERAL[Rua],B20,GERAL[Dia],">=" &$Q$8,GERAL[Dia],"<=" &$R$8) -> 555.1 | G20: =SUMIFS(GERAL[PRE],GERAL[Rua],B20,GERAL[Dia],">=" &$Q$8,GERAL[Dia],"<=" &$R$8) -> 142 | H20: =SUMIFS(GERAL[PV''s],GERAL[Rua],B20,GERAL[Dia],">=" &$Q$8,GERAL[Dia],"<=" &$R$8) -> 7 | I20: =SUMIFS(GERAL[LIE],GERAL[Rua],B20,GERAL[Dia],">=" &$Q$8,GERAL[Dia],"<=" &$R$8) -> 9 | J20: =SUMIFS(GERAL[LIA],GERAL[Rua],B20,GERAL[Dia],">=" &$Q$8,GERAL[Dia],"<=" &$R$8) -> 97 | K20: =SUMIFS(GERAL[IHM],GERAL[Rua],B20,GERAL[Dia],">=" &$Q$8,GERAL[Dia],"<=" &$R$8) -> 59 | L20: =SUMIFS(GERAL[RHM],GERAL[Rua],B20,GERAL[Dia],">=" &$Q$8,GERAL[Dia],"<=" &$R$8) -> 0 | M20: =IFERROR(D20/C20,"") -> 3.3333333 | N20: =IFERROR(E20/C20,"") -> 3.9047619 | O20: =IFERROR(F20/C20,"") -> 26.433333 | P20: =IFERROR(G20/C20,"") -> 6.7619048 | Q20: =IFERROR(SUM(F20:G20)/C20,"") -> 33.195238 | R20: =IFERROR(SUM(D20:E20)/C20,"") -> 7.2380952
B21: RUA DAS PEDRAS | C21: =COUNTIFS(GERAL[Dia Útil],"SIM",GERAL[Rua],B21,GERAL[Dia],">=" &$Q$8,GERAL[Dia],"<=" &$R$8) -> 3 | D21: =SUMIFS(GERAL[LA],GERAL[Rua],B21,GERAL[Dia],">=" &$Q$8,GERAL[Dia],"<=" &$R$8) -> 9 | E21: =SUMIFS(GERAL[LE],GERAL[Rua],B21,GERAL[Dia],">=" &$Q$8,GERAL[Dia],"<=" &$R$8) -> 1 | F21: =SUMIFS(GERAL[PRA],GERAL[Rua],B21,GERAL[Dia],">=" &$Q$8,GERAL[Dia],"<=" &$R$8) -> 15 | G21: =SUMIFS(GERAL[PRE],GERAL[Rua],B21,GERAL[Dia],">=" &$Q$8,GERAL[Dia],"<=" &$R$8) -> 0 | H21: =SUMIFS(GERAL[PV''s],GERAL[Rua],B21,GERAL[Dia],">=" &$Q$8,GERAL[Dia],"<=" &$R$8) -> 0 | I21: =SUMIFS(GERAL[LIE],GERAL[Rua],B21,GERAL[Dia],">=" &$Q$8,GERAL[Dia],"<=" &$R$8) -> 0 | J21: =SUMIFS(GERAL[LIA],GERAL[Rua],B21,GERAL[Dia],">=" &$Q$8,GERAL[Dia],"<=" &$R$8) -> 1 | K21: =SUMIFS(GERAL[IHM],GERAL[Rua],B21,GERAL[Dia],">=" &$Q$8,GERAL[Dia],"<=" &$R$8) -> 1 | L21: =SUMIFS(GERAL[RHM],GERAL[Rua],B21,GERAL[Dia],">=" &$Q$8,GERAL[Dia],"<=" &$R$8) -> 0 | M21: =IFERROR(D21/C21,"") -> 3 | N21: =IFERROR(E21/C21,"") -> 0.33333333 | O21: =IFERROR(F21/C21,"") -> 5 | P21: =IFERROR(G21/C21,"") -> 0 | Q21: =IFERROR(SUM(F21:G21)/C21,"") -> 5 | R21: =IFERROR(SUM(D21:E21)/C21,"") -> 3.3333333
B22: RUA DAS PEDRAS | C22: =COUNTIFS(GERAL[Dia Útil],"SIM",GERAL[Rua],B22,GERAL[Dia],">=" &$Q$8,GERAL[Dia],"<=" &$R$8) -> 8 | D22: =SUMIFS(GERAL[LA],GERAL[Rua],B22,GERAL[Dia],">=" &$Q$8,GERAL[Dia],"<=" &$R$8) -> 20 | E22: =SUMIFS(GERAL[LE],GERAL[Rua],B22,GERAL[Dia],">=" &$Q$8,GERAL[Dia],"<=" &$R$8) -> 10 | F22: =SUMIFS(GERAL[PRA],GERAL[Rua],B22,GERAL[Dia],">=" &$Q$8,GERAL[Dia],"<=" &$R$8) -> 25 | G22: =SUMIFS(GERAL[PRE],GERAL[Rua],B22,GERAL[Dia],">=" &$Q$8,GERAL[Dia],"<=" &$R$8) -> 18 | H22: =SUMIFS(GERAL[PV''s],GERAL[Rua],B22,GERAL[Dia],">=" &$Q$8,GERAL[Dia],"<=" &$R$8) -> 0 | I22: =SUMIFS(GERAL[LIE],GERAL[Rua],B22,GERAL[Dia],">=" &$Q$8,GERAL[Dia],"<=" &$R$8) -> 2 | J22: =SUMIFS(GERAL[LIA],GERAL[Rua],B22,GERAL[Dia],">=" &$Q$8,GERAL[Dia],"<=" &$R$8) -> 14 | K22: =SUMIFS(GERAL[IHM],GERAL[Rua],B22,GERAL[Dia],">=" &$Q$8,GERAL[Dia],"<=" &$R$8) -> 4 | L22: =SUMIFS(GERAL[RHM],GERAL[Rua],B22,GERAL[Dia],">=" &$Q$8,GERAL[Dia],"<=" &$R$8) -> 0 | M22: =IFERROR(D22/C22,"") -> 2.5 | N22: =IFERROR(E22/C22,"") -> 1.25 | O22: =IFERROR(F22/C22,"") -> 3.125 | P22: =IFERROR(G22/C22,"") -> 2.25 | Q22: =IFERROR(SUM(F22:G22)/C22,"") -> 5.375 | R22: =IFERROR(SUM(D22:E22)/C22,"") -> 3.75
... B32: (vazio) | C32: =COUNTIFS(GERAL[Dia Útil],"SIM",GERAL[Rua],B32,GERAL[Dia],">=" &$Q$8,GERAL[Dia],"<=" &$R$8) -> 0 | D32: =SUMIFS(GERAL[LA],GERAL[Rua],B32,GERAL[Dia],">=" &$Q$8,GERAL[Dia],"<=" &$R$8) -> 0 | E32: =SUMIFS(GERAL[LE],GERAL[Rua],B32,GERAL[Dia],">=" &$Q$8,GERAL[Dia],"<=" &$R$8) -> 0 | F32: =SUMIFS(GERAL[PRA],GERAL[Rua],B32,GERAL[Dia],">=" &$Q$8,GERAL[Dia],"<=" &$R$8) -> 0 | G32: =SUMIFS(GERAL[PRE],GERAL[Rua],B32,GERAL[Dia],">=" &$Q$8,GERAL[Dia],"<=" &$R$8) -> 0 | H32: =SUMIFS(GERAL[PV''s],GERAL[Rua],B32,GERAL[Dia],">=" &$Q$8,GERAL[Dia],"<=" &$R$8) -> 0 | I32: =SUMIFS(GERAL[LIE],GERAL[Rua],B32,GERAL[Dia],">=" &$Q$8,GERAL[Dia],"<=" &$R$8) -> 0 | J32: =SUMIFS(GERAL[LIA],GERAL[Rua],B32,GERAL[Dia],">=" &$Q$8,GERAL[Dia],"<=" &$R$8) -> 0 | K32: =SUMIFS(GERAL[IHM],GERAL[Rua],B32,GERAL[Dia],">=" &$Q$8,GERAL[Dia],"<=" &$R$8) -> 0 | L32: =SUMIFS(GERAL[RHM],GERAL[Rua],B32,GERAL[Dia],">=" &$Q$8,GERAL[Dia],"<=" &$R$8) -> 0 | M32: =IFERROR(D32/C32,"") | N32: =IFERROR(E32/C32,"") | O32: =IFERROR(F32/C32,"") | P32: =IFERROR(G32/C32,"") | Q32: =IFERROR(SUM(F32:G32)/C32,"") | R32: =IFERROR(SUM(D32:E32)/C32,"")
C33: =COUNTIFS(GERAL[Dia Útil],"SIM",GERAL[Rua],B33,GERAL[Dia],">=" &$Q$8,GERAL[Dia],"<=" &$R$8) -> 0 | D33: =SUMIFS(GERAL[LA],GERAL[Rua],B33,GERAL[Dia],">=" &$Q$8,GERAL[Dia],"<=" &$R$8) -> 0 | E33: =SUMIFS(GERAL[LE],GERAL[Rua],B33,GERAL[Dia],">=" &$Q$8,GERAL[Dia],"<=" &$R$8) -> 0 | F33: =SUMIFS(GERAL[PRA],GERAL[Rua],B33,GERAL[Dia],">=" &$Q$8,GERAL[Dia],"<=" &$R$8) -> 0 | G33: =SUMIFS(GERAL[PRE],GERAL[Rua],B33,GERAL[Dia],">=" &$Q$8,GERAL[Dia],"<=" &$R$8) -> 0 | H33: =SUMIFS(GERAL[PV''s],GERAL[Rua],B33,GERAL[Dia],">=" &$Q$8,GERAL[Dia],"<=" &$R$8) -> 0 | I33: =SUMIFS(GERAL[LIE],GERAL[Rua],B33,GERAL[Dia],">=" &$Q$8,GERAL[Dia],"<=" &$R$8) -> 0 | J33: =SUMIFS(GERAL[LIA],GERAL[Rua],B33,GERAL[Dia],">=" &$Q$8,GERAL[Dia],"<=" &$R$8) -> 0 | K33: =SUMIFS(GERAL[IHM],GERAL[Rua],B33,GERAL[Dia],">=" &$Q$8,GERAL[Dia],"<=" &$R$8) -> 0 | L33: =SUMIFS(GERAL[RHM],GERAL[Rua],B33,GERAL[Dia],">=" &$Q$8,GERAL[Dia],"<=" &$R$8) -> 0 | M33: =IFERROR(D33/C33,"") | N33: =IFERROR(E33/C33,"") | O33: =IFERROR(F33/C33,"") | P33: =IFERROR(G33/C33,"") | Q33: =IFERROR(SUM(F33:G33)/C33,"") | R33: =IFERROR(SUM(D33:E33)/C33,"")
C34: =COUNTIFS(GERAL[Dia Útil],"SIM",GERAL[Rua],B34,GERAL[Dia],">=" &$Q$8,GERAL[Dia],"<=" &$R$8) -> 0 | D34: =SUMIFS(GERAL[LA],GERAL[Rua],B34,GERAL[Dia],">=" &$Q$8,GERAL[Dia],"<=" &$R$8) -> 0 | E34: =SUMIFS(GERAL[LE],GERAL[Rua],B34,GERAL[Dia],">=" &$Q$8,GERAL[Dia],"<=" &$R$8) -> 0 | F34: =SUMIFS(GERAL[PRA],GERAL[Rua],B34,GERAL[Dia],">=" &$Q$8,GERAL[Dia],"<=" &$R$8) -> 0 | G34: =SUMIFS(GERAL[PRE],GERAL[Rua],B34,GERAL[Dia],">=" &$Q$8,GERAL[Dia],"<=" &$R$8) -> 0 | H34: =SUMIFS(GERAL[PV''s],GERAL[Rua],B34,GERAL[Dia],">=" &$Q$8,GERAL[Dia],"<=" &$R$8) -> 0 | I34: =SUMIFS(GERAL[LIE],GERAL[Rua],B34,GERAL[Dia],">=" &$Q$8,GERAL[Dia],"<=" &$R$8) -> 0 | J34: =SUMIFS(GERAL[LIA],GERAL[Rua],B34,GERAL[Dia],">=" &$Q$8,GERAL[Dia],"<=" &$R$8) -> 0 | K34: =SUMIFS(GERAL[IHM],GERAL[Rua],B34,GERAL[Dia],">=" &$Q$8,GERAL[Dia],"<=" &$R$8) -> 0 | L34: =SUMIFS(GERAL[RHM],GERAL[Rua],B34,GERAL[Dia],">=" &$Q$8,GERAL[Dia],"<=" &$R$8) -> 0 | M34: =IFERROR(D34/C34,"") | N34: =IFERROR(E34/C34,"") | O34: =IFERROR(F34/C34,"") | P34: =IFERROR(G34/C34,"") | Q34: =IFERROR(SUM(F34:G34)/C34,"") | R34: =IFERROR(SUM(D34:E34)/C34,"")
C35: =COUNTIFS(GERAL[Dia Útil],"SIM",GERAL[Rua],B35,GERAL[Dia],">=" &$Q$8,GERAL[Dia],"<=" &$R$8) -> 0 | D35: =SUMIFS(GERAL[LA],GERAL[Rua],B35,GERAL[Dia],">=" &$Q$8,GERAL[Dia],"<=" &$R$8) -> 0 | E35: =SUMIFS(GERAL[LE],GERAL[Rua],B35,GERAL[Dia],">=" &$Q$8,GERAL[Dia],"<=" &$R$8) -> 0 | F35: =SUMIFS(GERAL[PRA],GERAL[Rua],B35,GERAL[Dia],">=" &$Q$8,GERAL[Dia],"<=" &$R$8) -> 0 | G35: =SUMIFS(GERAL[PRE],GERAL[Rua],B35,GERAL[Dia],">=" &$Q$8,GERAL[Dia],"<=" &$R$8) -> 0 | H35: =SUMIFS(GERAL[PV''s],GERAL[Rua],B35,GERAL[Dia],">=" &$Q$8,GERAL[Dia],"<=" &$R$8) -> 0 | I35: =SUMIFS(GERAL[LIE],GERAL[Rua],B35,GERAL[Dia],">=" &$Q$8,GERAL[Dia],"<=" &$R$8) -> 0 | J35: =SUMIFS(GERAL[LIA],GERAL[Rua],B35,GERAL[Dia],">=" &$Q$8,GERAL[Dia],"<=" &$R$8) -> 0 | K35: =SUMIFS(GERAL[IHM],GERAL[Rua],B35,GERAL[Dia],">=" &$Q$8,GERAL[Dia],"<=" &$R$8) -> 0 | L35: =SUMIFS(GERAL[RHM],GERAL[Rua],B35,GERAL[Dia],">=" &$Q$8,GERAL[Dia],"<=" &$R$8) -> 0 | M35: =IFERROR(D35/C35,"") | N35: =IFERROR(E35/C35,"") | O35: =IFERROR(F35/C35,"") | P35: =IFERROR(G35/C35,"") | Q35: =IFERROR(SUM(F35:G35)/C35,"") | R35: =IFERROR(SUM(D35:E35)/C35,"")
C36: =COUNTIFS(GERAL[Dia Útil],"SIM",GERAL[Rua],B36,GERAL[Dia],">=" &$Q$8,GERAL[Dia],"<=" &$R$8) -> 0 | D36: =SUMIFS(GERAL[LA],GERAL[Rua],B36,GERAL[Dia],">=" &$Q$8,GERAL[Dia],"<=" &$R$8) -> 0 | E36: =SUMIFS(GERAL[LE],GERAL[Rua],B36,GERAL[Dia],">=" &$Q$8,GERAL[Dia],"<=" &$R$8) -> 0 | F36: =SUMIFS(GERAL[PRA],GERAL[Rua],B36,GERAL[Dia],">=" &$Q$8,GERAL[Dia],"<=" &$R$8) -> 0 | G36: =SUMIFS(GERAL[PRE],GERAL[Rua],B36,GERAL[Dia],">=" &$Q$8,GERAL[Dia],"<=" &$R$8) -> 0 | H36: =SUMIFS(GERAL[PV''s],GERAL[Rua],B36,GERAL[Dia],">=" &$Q$8,GERAL[Dia],"<=" &$R$8) -> 0 | I36: =SUMIFS(GERAL[LIE],GERAL[Rua],B36,GERAL[Dia],">=" &$Q$8,GERAL[Dia],"<=" &$R$8) -> 0 | J36: =SUMIFS(GERAL[LIA],GERAL[Rua],B36,GERAL[Dia],">=" &$Q$8,GERAL[Dia],"<=" &$R$8) -> 0 | K36: =SUMIFS(GERAL[IHM],GERAL[Rua],B36,GERAL[Dia],">=" &$Q$8,GERAL[Dia],"<=" &$R$8) -> 0 | L36: =SUMIFS(GERAL[RHM],GERAL[Rua],B36,GERAL[Dia],">=" &$Q$8,GERAL[Dia],"<=" &$R$8) -> 0 | M36: =IFERROR(D36/C36,"") | N36: =IFERROR(E36/C36,"") | O36: =IFERROR(F36/C36,"") | P36: =IFERROR(G36/C36,"") | Q36: =IFERROR(SUM(F36:G36)/C36,"") | R36: =IFERROR(SUM(D36:E36)/C36,"")
