Workbook

Sheet APOIO
B2: Dias Úteis
B3: SIM
B4: NÃO

Sheet S_MANOEL
B1: LOCAL: | C1: SÃO MANOEL
B2: PREENCHIMENTO DE EXECUÇÃO DIÁRIA | H2: GERAL - PRODUÇÃO
B4: Não alterar | C4: Não alterar | D4: Não alterar | E4: Unidade | H4: Unidade | I4: Unidade | J4: Metros | K4: DN | L4: Unidade | M4: Metros | N4: DN | O4: Unidade | P4: Unidade | Q4: Unidade | R4: Unidade | S4: Unidade | T4: Unidade | U4: Unidade | V4: DN
B5: Dia | C5: Dia Semana | D5: Mês | E5: Dia Útil | F5: Equipe | G5: Rua | H5: LA | I5: LE | J5: PRA | K5: DN | L5: C.UMA | M5: PRE | N5: DN2 | O5: C. INSP | P5: PV's | Q5: PI's | R5: LIE | S5: LIA | T5: IHM | U5: INT | V5: DN3
B6: 45962 | C6: sábado | D6: 45962 | E6: NÃO
B7: 45963 | C7: domingo | D7: 45963 | E7: NÃO
B8: 45964 | C8: segunda-feira | D8: 45964
B9: 45965 | C9: terça-feira | D9: 45965
B10: 45966 | C10: quarta-feira | D10: 45966
B11: 45967 | C11: quinta-feira | D11: 45967
B12: 45968 | C12: sexta-feira | D12: 45968
B13: 45969 | C13: sábado | D13: 45969 | E13: NÃO
B14: 45970 | C14: domingo | D14: 45970 | E14: NÃO
B15: 45971 | C15: segunda-feira | D15: 45971
B16: 45972 | C16: terça-feira | D16: 45972
B17: 45973 | C17: quarta-feira | D17: 45973
B18: 45974 | C18: quinta-feira | D18: 45974
B19: 45975 | C19: sexta-feira | D19: 45975
B20: 45976 | C20: sábado | D20: 45976 | E20: NÃO
B21: 45977 | C21: domingo | D21: 45977 | E21: NÃO
B22: 45978 | C22: segunda-feira | D22: 45978
B23: 45979 | C23: terça-feira | D23: 45979
B24: 45980 | C24: quarta-feira | D24: 45980
B25: 45981 | C25: quinta-feira | D25: 45981
B26: 45982 | C26: sexta-feira | D26: 45982
B27: 45983 | C27: sábado | D27: 45983 | E27: NÃO
B28: 45984 | C28: domingo | D28: 45984 | E28: NÃO
B29: 45985 | C29: segunda-feira | D29: 45985
B30: 45986 | C30: terça-feira | D30: 45986
B31: 45987 | C31: quarta-feira | D31: 45987
B32: 45988 | C32: quinta-feira | D32: 45988
B33: 45989 | C33: sexta-feira | D33: 45989
B34: 45990 | C34: sábado | D34: 45990 | E34: NÃO
B35: 45991 | C35: domingo | D35: 45991 | E35: NÃO
B36: 45992 | C36: segunda-feira | D36: 45992
B37: 45993 | C37: terça-feira | D37: 45993
B38: 45994 | C38: quarta-feira | D38: 45994
B39: 45995 | C39: quinta-feira | D39: 45995
B40: 45996 | C40: sexta-feira | D40: 45996
B41: 45997 | C41: sábado | D41: 45997 | E41: NÃO
...

Sheet J_CARLOS
B1: LOCAL: | C1: JOÃO CARLOS
B2: PREENCHIMENTO DE EXECUÇÃO DIÁRIA | H2: GERAL - PRODUÇÃO
B4: Não alterar | C4: Não alterar | D4: Não alterar | E4: Unidade | H4: Unidade | I4: Unidade | J4: Metros | K4: DN | L4: Unidade | M4: Metros | N4: DN | O4: Unidade | P4: Unidade | Q4: Unidade | R4: Unidade | S4: Unidade | T4: Unidade | U4: Unidade | V4: DN
B5: Dia | C5: Dia Semana | D5: Mês | E5: Dia Útil | F5: Equipe | G5: Rua | H5: LA | I5: LE | J5: PRA | K5: DN | L5: C.UMA | M5: PRE | N5: DN2 | O5: C. INSP | P5: PV's | Q5: PI's | R5: LIE | S5: LIA | T5: IHM | U5: INT | V5: DN3
B6: 45962 | C6: sábado | D6: 45962 | E6: NÃO
B7: 45963 | C7: domingo | D7: 45963 | E7: NÃO
B8: 45964 | C8: segunda-feira | D8: 45964
B9: 45965 | C9: terça-feira | D9: 45965
B10: 45966 | C10: quarta-feira | D10: 45966
B11: 45967 | C11: quinta-feira | D11: 45967
B12: 45968 | C12: sexta-feira | D12: 45968
B13: 45969 | C13: sábado | D13: 45969 | E13: NÃO
B14: 45970 | C14: domingo | D14: 45970 | E14: NÃO
B15: 45971 | C15: segunda-feira | D15: 45971
B16: 45972 | C16: terça-feira | D16: 45972
B17: 45973 | C17: quarta-feira | D17: 45973
B18: 45974 | C18: quinta-feira | D18: 45974
B19: 45975 | C19: sexta-feira | D19: 45975
B20: 45976 | C20: sábado | D20: 45976 | E20: NÃO
B21: 45977 | C21: domingo | D21: 45977 | E21: NÃO
B22: 45978 | C22: segunda-feira | D22: 45978
B23: 45979 | C23: terça-feira | D23: 45979
B24: 45980 | C24: quarta-feira | D24: 45980
B25: 45981 | C25: quinta-feira | D25: 45981
B26: 45982 | C26: sexta-feira | D26: 45982
B27: 45983 | C27: sábado | D27: 45983 | E27: NÃO
B28: 45984 | C28: domingo | D28: 45984 | E28: NÃO
B29: 45985 | C29: segunda-feira | D29: 45985
B30: 45986 | C30: terça-feira | D30: 45986
B31: 45987 | C31: quarta-feira | D31: 45987
B32: 45988 | C32: quinta-feira | D32: 45988
B33: 45989 | C33: sexta-feira | D33: 45989
B34: 45990 | C34: sábado | D34: 45990 | E34: NÃO
B35: 45991 | C35: domingo | D35: 45991 | E35: NÃO
B36: 45992 | C36: segunda-feira | D36: 45992
B37: 45993 | C37: terça-feira | D37: 45993
B38: 45994 | C38: quarta-feira | D38: 45994
B39: 45995 | C39: quinta-feira | D39: 45995
B40: 45996 | C40: sexta-feira | D40: 45996
B41: 45997 | C41: sábado | D41: 45997 | E41: NÃO
...

Sheet V_ISRAEL
B1: LOCAL: | C1: VILA ISRAEL
B2: PREENCHIMENTO DE EXECUÇÃO DIÁRIA | H2: GERAL - PRODUÇÃO
B4: Não alterar | C4: Não alterar | D4: Não alterar | E4: Unidade | H4: Unidade | I4: Unidade | J4: Metros | K4: DN | L4: Unidade | M4: Metros | N4: DN | O4: Unidade | P4: Unidade | Q4: Unidade | R4: Unidade | S4: Unidade | T4: Unidade | U4: Unidade | V4: DN
B5: Dia | C5: Dia Semana | D5: Mês | E5: Dia Útil | F5: Equipe | G5: Rua | H5: LA | I5: LE | J5: PRA | K5: DN | L5: C.UMA | M5: PRE | N5: DN2 | O5: C.INS | P5: PV's | Q5: PI's | R5: LIE | S5: LIA | T5: IHM | U5: INT | V5: DN3
B6: 45962 | C6: sábado | D6: 45962 | E6: NÃO
B7: 45963 | C7: domingo | D7: 45963 | E7: NÃO
B8: 45964 | C8: segunda-feira | D8: 45964
B9: 45965 | C9: terça-feira | D9: 45965
B10: 45966 | C10: quarta-feira | D10: 45966
B11: 45967 | C11: quinta-feira | D11: 45967
B12: 45968 | C12: sexta-feira | D12: 45968
B13: 45969 | C13: sábado | D13: 45969 | E13: NÃO
B14: 45970 | C14: domingo | D14: 45970 | E14: NÃO
B15: 45971 | C15: segunda-feira | D15: 45971
B16: 45972 | C16: terça-feira | D16: 45972
B17: 45973 | C17: quarta-feira | D17: 45973
B18: 45974 | C18: quinta-feira | D18: 45974
B19: 45975 | C19: sexta-feira | D19: 45975
B20: 45976 | C20: sábado | D20: 45976 | E20: NÃO
B21: 45977 | C21: domingo | D21: 45977 | E21: NÃO
B22: 45978 | C22: segunda-feira | D22: 45978
B23: 45979 | C23: terça-feira | D23: 45979
B24: 45980 | C24: quarta-feira | D24: 45980
B25: 45981 | C25: quinta-feira | D25: 45981
B26: 45982 | C26: sexta-feira | D26: 45982
B27: 45983 | C27: sábado | D27: 45983 | E27: NÃO
B28: 45984 | C28: domingo | D28: 45984 | E28: NÃO
B29: 45985 | C29: segunda-feira | D29: 45985
B30: 45986 | C30: terça-feira | D30: 45986
B31: 45987 | C31: quarta-feira | D31: 45987
B32: 45988 | C32: quinta-feira | D32: 45988
B33: 45989 | C33: sexta-feira | D33: 45989
B34: 45990 | C34: sábado | D34: 45990 | E34: NÃO
B35: 45991 | C35: domingo | D35: 45991 | E35: NÃO
B36: 45992 | C36: segunda-feira | D36: 45992
B37: 45993 | C37: terça-feira | D37: 45993
B38: 45994 | C38: quarta-feira | D38: 45994
B39: 45995 | C39: quinta-feira | D39: 45995
B40: 45996 | C40: sexta-feira | D40: 45996
B41: 45997 | C41: sábado | D41: 45997 | E41: NÃO
...

Sheet M_TETEU
B1: LOCAL: | C1: MORRO DO TETÉU E VALE VERDE
B2: PREENCHIMENTO DE EXECUÇÃO DIÁRIA | H2: GERAL - PRODUÇÃO
B4: Não alterar | C4: Não alterar | D4: Não alterar | E4: Unidade | H4: Unidade | I4: Metros | J4: Metros | K4: DN | L4: Unidade | M4: Metros | N4: DN | O4: Unidade | P4: Unidade | Q4: Unidade | R4: Unidade | S4: Unidade | T4: Unidade | U4: Unidade | V4: DN
B5: Dia | C5: Dia Semana | D5: Mês | E5: Dia Útil | F5: Equipe | G5: Rua | H5: LA | I5: LE | J5: PRA | K5: DN | L5: C.UMA | M5: PRE | N5: DN | O5: C. Insp | P5: PV's | Q5: PI's | R5: LIE | S5: LIA | T5: IHM | U5: INT. | V5: DN2
B6: 45962 | C6: sábado | D6: 45962 | E6: NÃO
B7: 45963 | C7: domingo | D7: 45963 | E7: NÃO
B8: 45964 | C8: segunda-feira | D8: 45964
B9: 45965 | C9: terça-feira | D9: 45965
B10: 45966 | C10: quarta-feira | D10: 45966
B11: 45967 | C11: quinta-feira | D11: 45967
B12: 45968 | C12: sexta-feira | D12: 45968
B13: 45969 | C13: sábado | D13: 45969 | E13: NÃO
B14: 45970 | C14: domingo | D14: 45970 | E14: NÃO
B15: 45971 | C15: segunda-feira | D15: 45971
B16: 45972 | C16: terça-feira | D16: 45972
B17: 45973 | C17: quarta-feira | D17: 45973
B18: 45974 | C18: quinta-feira | D18: 45974
B19: 45975 | C19: sexta-feira | D19: 45975
B20: 45976 | C20: sábado | D20: 45976 | E20: NÃO
B21: 45977 | C21: domingo | D21: 45977 | E21: NÃO
B22: 45978 | C22: segunda-feira | D22: 45978
B23: 45979 | C23: terça-feira | D23: 45979
B24: 45980 | C24: quarta-feira | D24: 45980
B25: 45981 | C25: quinta-feira | D25: 45981
B26: 45982 | C26: sexta-feira | D26: 45982
B27: 45983 | C27: sábado | D27: 45983 | E27: NÃO
B28: 45984 | C28: domingo | D28: 45984 | E28: NÃO
B29: 45985 | C29: segunda-feira | D29: 45985
B30: 45986 | C30: terça-feira | D30: 45986
B31: 45987 | C31: quarta-feira | D31: 45987
B32: 45988 | C32: quinta-feira | D32: 45988
B33: 45989 | C33: sexta-feira | D33: 45989
B34: 45990 | C34: sábado | D34: 45990 | E34: NÃO
B35: 45991 | C35: domingo | D35: 45991 | E35: NÃO
B36: 45992 | C36: segunda-feira | D36: 45992
B37: 45993 | C37: terça-feira | D37: 45993
B38: 45994 | C38: quarta-feira | D38: 45994
B39: 45995 | C39: quinta-feira | D39: 45995
B40: 45996 | C40: sexta-feira | D40: 45996
B41: 45997 | C41: sábado | D41: 45997 | E41: NÃO
...

Sheet V_CRIADORES
B1: LOCAL: | C1: VILA DOS CRIADORES
B2: PREENCHIMENTO DE EXECUÇÃO DIÁRIA | H2: GERAL - PRODUÇÃO
B4: Não alterar | C4: Não alterar | D4: Não alterar | E4: Unidade | H4: Unidade | I4: Unidade | J4: Metros | K4: DN | L4: Unidade | M4: Metros | N4: DN | O4: Unidade | P4: Unidade | Q4: Unidade | R4: Unidade | S4: Unidade | T4: Unidade | U4: Unidade | V4: DN
B5: Dia | C5: Dia Semana | D5: Mês | E5: Dia Útil | F5: Equipe | G5: Rua | H5: LA | I5: LE | J5: PRA | K5: DN | L5: C.UMA | M5: PRE | N5: DN2 | O5: C. INSP | P5: PV's | Q5: PI's | R5: LIE | S5: LIA | T5: IHM | U5: INT | V5: DN3
B6: 45962 | C6: sábado | D6: 45962 | E6: NÃO
B7: 45963 | C7: domingo | D7: 45963 | E7: NÃO
B8: 45964 | C8: segunda-feira | D8: 45964
B9: 45965 | C9: terça-feira | D9: 45965
B10: 45966 | C10: quarta-feira | D10: 45966
B11: 45967 | C11: quinta-feira | D11: 45967
B12: 45968 | C12: sexta-feira | D12: 45968
B13: 45969 | C13: sábado | D13: 45969 | E13: NÃO
B14: 45970 | C14: domingo | D14: 45970 | E14: NÃO
B15: 45971 | C15: segunda-feira | D15: 45971
B16: 45972 | C16: terça-feira | D16: 45972
B17: 45973 | C17: quarta-feira | D17: 45973
B18: 45974 | C18: quinta-feira | D18: 45974
B19: 45975 | C19: sexta-feira | D19: 45975
B20: 45976 | C20: sábado | D20: 45976 | E20: NÃO
B21: 45977 | C21: domingo | D21: 45977 | E21: NÃO
B22: 45978 | C22: segunda-feira | D22: 45978
B23: 45979 | C23: terça-feira | D23: 45979
B24: 45980 | C24: quarta-feira | D24: 45980
B25: 45981 | C25: quinta-feira | D25: 45981
B26: 45982 | C26: sexta-feira | D26: 45982
B27: 45983 | C27: sábado | D27: 45983 | E27: NÃO
B28: 45984 | C28: domingo | D28: 45984 | E28: NÃO
B29: 45985 | C29: segunda-feira | D29: 45985
B30: 45986 | C30: terça-feira | D30: 45986
B31: 45987 | C31: quarta-feira | D31: 45987
B32: 45988 | C32: quinta-feira | D32: 45988
B33: 45989 | C33: sexta-feira | D33: 45989
B34: 45990 | C34: sábado | D34: 45990 | E34: NÃO
B35: 45991 | C35: domingo | D35: 45991 | E35: NÃO
B36: 45992 | C36: segunda-feira | D36: 45992
B37: 45993 | C37: terça-feira | D37: 45993
B38: 45994 | C38: quarta-feira | D38: 45994
B39: 45995 | C39: quinta-feira | D39: 45995
B40: 45996 | C40: sexta-feira | D40: 45996
B41: 45997 | C41: sábado | D41: 45997 | E41: NÃO
...

Sheet P_BAIXO
B1: LOCAL: | C1: PANTANAL BAIXO
B2: PREENCHIMENTO DE EXECUÇÃO DIÁRIA | H2: GERAL - PRODUÇÃO
B4: Não alterar | C4: Não alterar | D4: Não alterar | E4: Unidade | H4: Unidade | I4: Unidade | J4: Metros | K4: DN | L4: Unidade | M4: Metros | N4: DN | O4: Unidade | P4: Unidade | Q4: Unidade | R4: Unidade | S4: Unidade | T4: Unidade | U4: Unidade | V4: DN
B5: Dia | C5: Dia Semana | D5: Mês | E5: Dia Útil | F5: Equipe | G5: Rua | H5: LA | I5: LE | J5: PRA | K5: DN | L5: C.UMA | M5: PRE | N5: DN2 | O5: C. INP | P5: PV's | Q5: PI's | R5: LIE | S5: LIA | T5: IHM | U5: INT | V5: DN
B6: 45962 | C6: sábado | D6: 45962 | E6: NÃO
B7: 45963 | C7: domingo | D7: 45963 | E7: NÃO
B8: 45964 | C8: segunda-feira | D8: 45964
B9: 45965 | C9: terça-feira | D9: 45965
B10: 45966 | C10: quarta-feira | D10: 45966
B11: 45967 | C11: quinta-feira | D11: 45967
B12: 45968 | C12: sexta-feira | D12: 45968
B13: 45969 | C13: sábado | D13: 45969 | E13: NÃO
B14: 45970 | C14: domingo | D14: 45970 | E14: NÃO
B15: 45971 | C15: segunda-feira | D15: 45971
B16: 45972 | C16: terça-feira | D16: 45972
B17: 45973 | C17: quarta-feira | D17: 45973
B18: 45974 | C18: quinta-feira | D18: 45974
B19: 45975 | C19: sexta-feira | D19: 45975
B20: 45976 | C20: sábado | D20: 45976 | E20: NÃO
B21: 45977 | C21: domingo | D21: 45977 | E21: NÃO
B22: 45978 | C22: segunda-feira | D22: 45978
B23: 45979 | C23: terça-feira | D23: 45979
B24: 45980 | C24: quarta-feira | D24: 45980
B25: 45981 | C25: quinta-feira | D25: 45981
B26: 45982 | C26: sexta-feira | D26: 45982
B27: 45983 | C27: sábado | D27: 45983 | E27: NÃO
B28: 45984 | C28: domingo | D28: 45984 | E28: NÃO
B29: 45985 | C29: segunda-feira | D29: 45985
B30: 45986 | C30: terça-feira | D30: 45986
B31: 45987 | C31: quarta-feira | D31: 45987
B32: 45988 | C32: quinta-feira | D32: 45988
B33: 45989 | C33: sexta-feira | D33: 45989
B34: 45990 | C34: sábado | D34: 45990 | E34: NÃO
B35: 45991 | C35: domingo | D35: 45991 | E35: NÃO
B36: 45992 | C36: segunda-feira | D36: 45992
B37: 45993 | C37: terça-feira | D37: 45993
B38: 45994 | C38: quarta-feira | D38: 45994
B39: 45995 | C39: quinta-feira | D39: 45995
B40: 45996 | C40: sexta-feira | D40: 45996
B41: 45997 | C41: sábado | D41: 45997 | E41: NÃO
...

Sheet Planilha1
B2: Equipes por Núcleo
B3: NÚCLEO | C3: Equipes Atual | E3: Em Prospecção | F3: TOTAL
B4: São Manoel | C4: 6 | D4: 2 | E4: 2 | F4: =SUM(C4:E4) -> 10
B5: João Carlos | C5: 3 | E5: 1 | F5: =SUM(C5:E5) -> 4
B6: Vila Israel | C6: 4 | D6: 2 | F6: =SUM(C6:E6) -> 6
B7: Teteu | C7: 4 | F7: =SUM(C7:E7) -> 4
B8: Vila dos Criadores | C8: 5 | D8: 2 | F8: =SUM(C8:E8) -> 7
B9: Pantanal Baixo | C9: 6 | D9: 2 | F9: =SUM(C9:E9) -> 8
B10: TOTAL => | C10: =SUM(C4:C9) -> 28 | D10: =SUM(D4:D9) -> 8 | E10: =SUM(E4:E9) -> 3 | F10: =SUM(F4:F9) -> 39
B13: Equipes por Núcleo
B14: NÚCLEO | C14: Equipes Atual | E14: Em Prospecção | F14: TOTAL
B15: São Manoel | C15: 8 | E15: 2 | F15: =SUM(C15:E15) -> 10
B16: João Carlos | C16: 3 | E16: 1 | F16: =SUM(C16:E16) -> 4
B17: Vila Israel | C17: 6 | F17: =SUM(C17:E17) -> 6
B18: Teteu | C18: 4 | F18: =SUM(C18:E18) -> 4
B19: Vila dos Criadores | C19: 7 | F19: =SUM(C19:E19) -> 7
B20: Pantanal Baixo | C20: 8 | F20: =SUM(C20:E20) -> 8
B21: TOTAL => | C21: =SUM(C15:C20) -> 36 | D21: =SUM(D15:D20) -> 0 | E21: =SUM(E15:E20) -> 3 | F21: =SUM(F15:F20) -> 39

Sheet RESUMO
A1: ITEM | B1: MORRO TETEU | C1: PANTANAL BAIXO | D1: JOÃO CARLOS | E1: SÃO MANOEL | F1: VILA ISRAEL | G1: VILA CRIADORES | H1: Total
A2: LE - Ligação de Esgoto | B2: =M_TETEU!$I530 -> 4 | C2: =P_BAIXO!$I601 -> 0 | D2: =J_CARLOS!$I525 -> 12 | E2: =S_MANOEL!$I556 -> 223 | F2: =V_ISRAEL!$I508 -> 4 | G2: =V_CRIADORES!$I549 -> 15 | H2: =SUM(B2:G2) -> 258
A3: PRE - Prolongamento Rede de Esgoto | B3: =M_TETEU!$N530 -> 218 | C3: =P_BAIXO!$N601 -> 3084 | D3: =J_CARLOS!$N525 -> 0 | E3: =S_MANOEL!$O556 -> 1455.77 | F3: =V_ISRAEL!$N508 -> 1000 | G3: =V_CRIADORES!$M549 -> 142 | H3: =SUM(B3:G3) -> 5899.77
A4: PV - Poço de Visita | B4: =M_TETEU!$P530 -> 2 | C4: =P_BAIXO!$P601 -> 2 | D4: =J_CARLOS!$P525 -> 0 | E4: =S_MANOEL!$P556 -> 23 | F4: =V_ISRAEL!$P508 -> 1 | G4: =V_CRIADORES!$P549 -> 3 | H4: =SUM(B4:G4) -> 31
A5: LIE - Ligação Intradomiciliar de Esgoto | B5: =M_TETEU!$R530 -> 0 | C5: =P_BAIXO!$R601 -> 0 | D5: =J_CARLOS!$R525 -> 0 | E5: =S_MANOEL!$R556 -> 27 | F5: =V_ISRAEL!$R508 -> 0 | G5: =V_CRIADORES!$R549 -> 0 | H5: =SUM(B5:G5) -> 27
A6: LA - Ligação de Água | B6: =M_TETEU!$H530 -> 3 | C6: =P_BAIXO!$H601 -> 2 | D6: =J_CARLOS!$H525 -> 6 | E6: =S_MANOEL!$H556 -> 172 | F6: =V_ISRAEL!$H508 -> 5 | G6: =V_CRIADORES!$H549 -> 3 | H6: =SUM(B6:G6) -> 191
A7: PRA - Prolongamento Rede de Água | B7: =M_TETEU!$M530 -> 61 | C7: =P_BAIXO!$M601 -> 84 | D7: =J_CARLOS!$M525 -> 0 | E7: =S_MANOEL!$M556 -> 1576.16 | F7: =V_ISRAEL!$M508 -> 60 | G7: =V_CRIADORES!$J549 -> 28 | H7: =SUM(B7:G7) -> 1809.16
A8: LIA - Ligação Intradomiciliar de Água | B8: =M_TETEU!$S530 -> 98 | C8: =P_BAIXO!$S601 -> 72 | D8: =J_CARLOS!$S525 -> 71 | E8: =S_MANOEL!$S556 -> 130 | F8: =V_ISRAEL!$S508 -> 2 | G8: =V_CRIADORES!$S549 -> 21 | H8: =SUM(B8:G8) -> 394
A9: IHM - Instalação de Hidrometro | B9: =M_TETEU!$T530 -> 30 | C9: =P_BAIXO!$T601 -> 0 | D9: =J_CARLOS!$T525 -> 5 | E9: =S_MANOEL!$T556 -> 0 | F9: =V_ISRAEL!$T508 -> 0 | G9: =V_CRIADORES!$T549 -> 16 | H9: =SUM(B9:G9) -> 51
A10: RHM - Reposição de Hidrometro | B10: =M_TETEU!$V530 -> 189 | C10: =P_BAIXO!$V601 -> 0 | D10: =J_CARLOS!$V525 -> 0 | E10: =S_MANOEL!$V556 -> 383 | F10: =V_ISRAEL!$V508 -> 0 | G10: =V_CRIADORES!$V549 -> 110 | H10: =SUM(B10:G10) -> 682
