Workbook
Name SegmentaçãodeDados_Núcleo: #N/A

Sheet GERAL
B2: Dia | C2: Dia Semana | D2: Mês | E2: Dia Útil | F2: Equipe | G2: Rua | H2: LA | I2: LE | J2: PRA | K2: DN | L2: C.UMA | M2: PRE | N2: DN2 | O2: C. INSP | P2: PV's | Q2: PI's | R2: LIE | S2: LIA | T2: IHM | U2: INT | V2: DN3 | W2: Núcleo
A3: =_xlfn.XLOOKUP(GERAL[[#This Row],[Dia]],AA:AA,Z:Z,"") | B3: 45962 | C3: sábado | D3: 45962 | E3: NÃO | W3: Morro do Tetéu | X3: =_xlfn.XLOOKUP(GERAL[[#This Row],[Dia]],AA:AA,AB:AB,"") | Z3: Semana 1 | AA3: 46052 | AB3: Prazo_30 | AC3: =_xlfn.XLOOKUP(GERAL[[#This Row],[Dia]],AI:AI,AJ:AJ,"")
A4: =_xlfn.XLOOKUP(GERAL[[#This Row],[Dia]],AA:AA,Z:Z,"") | B4: 45963 | C4: domingo | D4: 45963 | E4: NÃO | W4: Morro do Tetéu | X4: =_xlfn.XLOOKUP(GERAL[[#This Row],[Dia]],AA:AA,AB:AB,"") | Z4: Semana 1 | AA4: 46053 | AB4: Prazo_30 | AC4: =_xlfn.XLOOKUP(GERAL[[#This Row],[Dia]],AI:AI,AJ:AJ,"")
A5: =_xlfn.XLOOKUP(GERAL[[#This Row],[Dia]],AA:AA,Z:Z,"") | B5: 45964 | C5: segunda-feira | D5: 45964 | W5: Morro do Tetéu | X5: =_xlfn.XLOOKUP(GERAL[[#This Row],[Dia]],AA:AA,AB:AB,"") | Z5: Semana 1 | AA5: 46054 | AB5: Prazo_30 | AC5: =_xlfn.XLOOKUP(GERAL[[#This Row],[Dia]],AI:AI,AJ:AJ,"")
A6: =_xlfn.XLOOKUP(GERAL[[#This Row],[Dia]],AA:AA,Z:Z,"") | B6: 45965 | C6: terça-feira | D6: 45965 | W6: Morro do Tetéu | X6: =_xlfn.XLOOKUP(GERAL[[#This Row],[Dia]],AA:AA,AB:AB,"") | Z6: Semana 1 | AA6: 46055 | AB6: Prazo_30 | AC6: =_xlfn.XLOOKUP(GERAL[[#This Row],[Dia]],AI:AI,AJ:AJ,"")
A7: =_xlfn.XLOOKUP(GERAL[[#This Row],[Dia]],AA:AA,Z:Z,"") | B7: 45966 | C7: quarta-feira | D7: 45966 | W7: Morro do Tetéu | X7: =_xlfn.XLOOKUP(GERAL[[#This Row],[Dia]],AA:AA,AB:AB,"") | Z7: Semana 1 | AA7: 46056 | AB7: Prazo_30 | AC7: =_xlfn.XLOOKUP(GERAL[[#This Row],[Dia]],AI:AI,AJ:AJ,"")
A8: =_xlfn.XLOOKUP(GERAL[[#This Row],[Dia]],AA:AA,Z:Z,"") | B8: 45967 | C8: quinta-feira | D8: 45967 | W8: Morro do Tetéu | X8: =_xlfn.XLOOKUP(GERAL[[#This Row],[Dia]],AA:AA,AB:AB,"") | Z8: Semana 1 | AA8: 46057 | AB8: Prazo_30 | AC8: =_xlfn.XLOOKUP(GERAL[[#This Row],[Dia]],AI:AI,AJ:AJ,"")
A9: =_xlfn.XLOOKUP(GERAL[[#This Row],[Dia]],AA:AA,Z:Z,"") | B9: 45968 | C9: sexta-feira | D9: 45968 | W9: Morro do Tetéu | X9: =_xlfn.XLOOKUP(GERAL[[#This Row],[Dia]],AA:AA,AB:AB,"") | Z9: Semana 1 | AA9: 46058 | AB9: Prazo_30 | AC9: =_xlfn.XLOOKUP(GERAL[[#This Row],[Dia]],AI:AI,AJ:AJ,"")
A10: =_xlfn.XLOOKUP(GERAL[[#This Row],[Dia]],AA:AA,Z:Z,"") | B10: 45969 | C10: sábado | D10: 45969 | E10: NÃO | W10: Morro do Tetéu | X10: =_xlfn.XLOOKUP(GERAL[[#This Row],[Dia]],AA:AA,AB:AB,"") | Z10: Semana 1 | AA10: 46059 | AB10: Prazo_30 | AC10: =_xlfn.XLOOKUP(GERAL[[#This Row],[Dia]],AI:AI,AJ:AJ,"")
A11: =_xlfn.XLOOKUP(GERAL[[#This Row],[Dia]],AA:AA,Z:Z,"") | B11: 45970 | C11: domingo | D11: 45970 | E11: NÃO | W11: Morro do Tetéu | X11: =_xlfn.XLOOKUP(GERAL[[#This Row],[Dia]],AA:AA,AB:AB,"") | Z11: Semana 1 | AA11: 46060 | AB11: Prazo_30 | AC11: =_xlfn.XLOOKUP(GERAL[[#This Row],[Dia]],AI:AI,AJ:AJ,"")
A12: =_xlfn.XLOOKUP(GERAL[[#This Row],[Dia]],AA:AA,Z:Z,"") | B12: 45971 | C12: segunda-feira | D12: 45971 | W12: Morro do Tetéu | X12: =_xlfn.XLOOKUP(GERAL[[#This Row],[Dia]],AA:AA,AB:AB,"") | Z12: Semana 2 | AA12: 46061 | AB12: Prazo_30 | AC12: =_xlfn.XLOOKUP(GERAL[[#This Row],[Dia]],AI:AI,AJ:AJ,"")
A13: =_xlfn.XLOOKUP(GERAL[[#This Row],[Dia]],AA:AA,Z:Z,"") | B13: 45972 | C13: terça-feira | D13: 45972 | W13: Morro do Tetéu | X13: =_xlfn.XLOOKUP(GERAL[[#This Row],[Dia]],AA:AA,AB:AB,"") | Z13: Semana 2 | AA13: 46062 | AB13: Prazo_30 | AC13: =_xlfn.XLOOKUP(GERAL[[#This Row],[Dia]],AI:AI,AJ:AJ,"")
A14: =_xlfn.XLOOKUP(GERAL[[#This Row],[Dia]],AA:AA,Z:Z,"") | B14: 45973 | C14: quarta-feira | D14: 45973 | W14: Morro do Tetéu | X14: =_xlfn.XLOOKUP(GERAL[[#This Row],[Dia]],AA:AA,AB:AB,"") | Z14: Semana 2 | AA14: 46063 | AB14: Prazo_30 | AC14: =_xlfn.XLOOKUP(GERAL[[#This Row],[Dia]],AI:AI,AJ:AJ,"")
A15: =_xlfn.XLOOKUP(GERAL[[#This Row],[Dia]],AA:AA,Z:Z,"") | B15: 45974 | C15: quinta-feira | D15: 45974 | W15: Morro do Tetéu | X15: =_xlfn.XLOOKUP(GERAL[[#This Row],[Dia]],AA:AA,AB:AB,"") | Z15: Semana 2 | AA15: 46064 | AB15: Prazo_30 | AC15: =_xlfn.XLOOKUP(GERAL[[#This Row],[Dia]],AI:AI,AJ:AJ,"")
A16: =_xlfn.XLOOKUP(GERAL[[#This Row],[Dia]],AA:AA,Z:Z,"") | B16: 45975 | C16: sexta-feira | D16: 45975 | W16: Morro do Tetéu | X16: =_xlfn.XLOOKUP(GERAL[[#This Row],[Dia]],AA:AA,AB:AB,"") | Z16: Semana 2 | AA16: 46065 | AB16: Prazo_30 | AC16: =_xlfn.XLOOKUP(GERAL[[#This Row],[Dia]],AI:AI,AJ:AJ,"")
A17: =_xlfn.XLOOKUP(GERAL[[#This Row],[Dia]],AA:AA,Z:Z,"") | B17: 45976 | C17: sábado | D17: 45976 | E17: NÃO | W17: Morro do Tetéu | X17: =_xlfn.XLOOKUP(GERAL[[#This Row],[Dia]],AA:AA,AB:AB,"") | Z17: Semana 2 | AA17: 46066 | AB17: Prazo_30 | AC17: =_xlfn.XLOOKUP(GERAL[[#This Row],[Dia]],AI:AI,AJ:AJ,"")
A18: =_xlfn.XLOOKUP(GERAL[[#This Row],[Dia]],AA:AA,Z:Z,"") | B18: 45977 | C18: domingo | D18: 45977 | E18: NÃO | W18: Morro do Tetéu | X18: =_xlfn.XLOOKUP(GERAL[[#This Row],[Dia]],AA:AA,AB:AB,"") | Z18: Semana 2 | AA18: 46067 | AB18: Prazo_30 | AC18: =_xlfn.XLOOKUP(GERAL[[#This Row],[Dia]],AI:AI,AJ:AJ,"")
A19: =_xlfn.XLOOKUP(GERAL[[#This Row],[Dia]],AA:AA,Z:Z,"") | B19: 45978 | C19: segunda-feira | D19: 45978 | W19: Morro do Tetéu | X19: =_xlfn.XLOOKUP(GERAL[[#This Row],[Dia]],AA:AA,AB:AB,"") | Z19: Semana 3 | AA19: 46068 | AB19: Prazo_30 | AC19: =_xlfn.XLOOKUP(GERAL[[#This Row],[Dia]],AI:AI,AJ:AJ,"")
A20: =_xlfn.XLOOKUP(GERAL[[#This Row],[Dia]],AA:AA,Z:Z,"") | B20: 45979 | C20: terça-feira | D20: 45979 | W20: Morro do Tetéu | X20: =_xlfn.XLOOKUP(GERAL[[#This Row],[Dia]],AA:AA,AB:AB,"") | Z20: Semana 3 | AA20: 46069 | AB20: Prazo_30 | AC20: =_xlfn.XLOOKUP(GERAL[[#This Row],[Dia]],AI:AI,AJ:AJ,"")
A21: =_xlfn.XLOOKUP(GERAL[[#This Row],[Dia]],AA:AA,Z:Z,"") | B21: 45980 | C21: quarta-feira | D21: 45980 | W21: Morro do Tetéu | X21: =_xlfn.XLOOKUP(GERAL[[#This Row],[Dia]],AA:AA,AB:AB,"") | Z21: Semana 3 | AA21: 46070 | AB21: Prazo_30 | AC21: =_xlfn.XLOOKUP(GERAL[[#This Row],[Dia]],AI:AI,AJ:AJ,"")
A22: =_xlfn.XLOOKUP(GERAL[[#This Row],[Dia]],AA:AA,Z:Z,"") | B22: 45981 | C22: quinta-feira | D22: 45981 | W22: Morro do Tetéu | X22: =_xlfn.XLOOKUP(GERAL[[#This Row],[Dia]],AA:AA,AB:AB,"") | Z22: Semana 3 | AA22: 46071 | AB22: Prazo_30 | AC22: =_xlfn.XLOOKUP(GERAL[[#This Row],[Dia]],AI:AI,AJ:AJ,"")
A23: =_xlfn.XLOOKUP(GERAL[[#This Row],[Dia]],AA:AA,Z:Z,"") | B23: 45982 | C23: sexta-feira | D23: 45982 | W23: Morro do Tetéu | X23: =_xlfn.XLOOKUP(GERAL[[#This Row],[Dia]],AA:AA,AB:AB,"") | Z23: Semana 3 | AA23: 46072 | AB23: Prazo_30 | AC23: =_xlfn.XLOOKUP(GERAL[[#This Row],[Dia]],AI:AI,AJ:AJ,"")
A24: =_xlfn.XLOOKUP(GERAL[[#This Row],[Dia]],AA:AA,Z:Z,"") | B24: 45983 | C24: sábado | D24: 45983 | E24: NÃO | W24: Morro do Tetéu | X24: =_xlfn.XLOOKUP(GERAL[[#This Row],[Dia]],AA:AA,AB:AB,"") | Z24: Semana 3 | AA24: 46073 | AB24: Prazo_30 | AC24: =_xlfn.XLOOKUP(GERAL[[#This Row],[Dia]],AI:AI,AJ:AJ,"")
A25: =_xlfn.XLOOKUP(GERAL[[#This Row],[Dia]],AA:AA,Z:Z,"") | B25: 45984 | C25: domingo | D25: 45984 | E25: NÃO | W25: Morro do Tetéu | X25: =_xlfn.XLOOKUP(GERAL[[#This Row],[Dia]],AA:AA,AB:AB,"") | Z25: Semana 3 | AA25: 46074 | AB25: Prazo_30 | AC25: =_xlfn.XLOOKUP(GERAL[[#This Row],[Dia]],AI:AI,AJ:AJ,"")
A26: =_xlfn.XLOOKUP(GERAL[[#This Row],[Dia]],AA:AA,Z:Z,"") | B26: 45985 | C26: segunda-feira | D26: 45985 | W26: Morro do Tetéu | X26: =_xlfn.XLOOKUP(GERAL[[#This Row],[Dia]],AA:AA,AB:AB,"") | Z26: Semana 4 | AA26: 46075 | AB26: Prazo_30 | AC26: =_xlfn.XLOOKUP(GERAL[[#This Row],[Dia]],AI:AI,AJ:AJ,"")
A27: =_xlfn.XLOOKUP(GERAL[[#This Row],[Dia]],AA:AA,Z:Z,"") | B27: 45986 | C27: terça-feira | D27: 45986 | W27: Morro do Tetéu | X27: =_xlfn.XLOOKUP(GERAL[[#This Row],[Dia]],AA:AA,AB:AB,"") | Z27: Semana 4 | AA27: 46076 | AB27: Prazo_30 | AC27: =_xlfn.XLOOKUP(GERAL[[#This Row],[Dia]],AI:AI,AJ:AJ,"")
A28: =_xlfn.XLOOKUP(GERAL[[#This Row],[Dia]],AA:AA,Z:Z,"") | B28: 45987 | C28: quarta-feira | D28: 45987 | W28: Morro do Tetéu | X28: =_xlfn.XLOOKUP(GERAL[[#This Row],[Dia]],AA:AA,AB:AB,"") | Z28: Semana 4 | AA28: 46077 | AB28: Prazo_30 | AC28: =_xlfn.XLOOKUP(GERAL[[#This Row],[Dia]],AI:AI,AJ:AJ,"")
A29: =_xlfn.XLOOKUP(GERAL[[#This Row],[Dia]],AA:AA,Z:Z,"") | B29: 45988 | C29: quinta-feira | D29: 45988 | W29: Morro do Tetéu | X29: =_xlfn.XLOOKUP(GERAL[[#This Row],[Dia]],AA:AA,AB:AB,"") | Z29: Semana 4 | AA29: 46078 | AB29: Prazo_30 | AC29: =_xlfn.XLOOKUP(GERAL[[#This Row],[Dia]],AI:AI,AJ:AJ,"")
A30: =_xlfn.XLOOKUP(GERAL[[#This Row],[Dia]],AA:AA,Z:Z,"") | B30: 45989 | C30: sexta-feira | D30: 45989 | W30: Morro do Tetéu | X30: =_xlfn.XLOOKUP(GERAL[[#This Row],[Dia]],AA:AA,AB:AB,"") | Z30: Semana 4 | AA30: 46079 | AB30: Prazo_30 | AC30: =_xlfn.XLOOKUP(GERAL[[#This Row],[Dia]],AI:AI,AJ:AJ,"")
A31: =_xlfn.XLOOKUP(GERAL[[#This Row],[Dia]],AA:AA,Z:Z,"") | B31: 45990 | C31: sábado | D31: 45990 | E31: NÃO | W31: Morro do Tetéu | X31: =_xlfn.XLOOKUP(GERAL[[#This Row],[Dia]],AA:AA,AB:AB,"") | Z31: Semana 4 | AA31: 46080 | AB31: Prazo_30 | AC31: =_xlfn.XLOOKUP(GERAL[[#This Row],[Dia]],AI:AI,AJ:AJ,"")
A32: =_xlfn.XLOOKUP(GERAL[[#This Row],[Dia]],AA:AA,Z:Z,"") | B32: 45991 | C32: domingo | D32: 45991 | E32: NÃO | W32: Morro do Tetéu | X32: =_xlfn.XLOOKUP(GERAL[[#This Row],[Dia]],AA:AA,AB:AB,"") | Z32: Semana 4 | AA32: 46081 | AB32: Prazo_30 | AC32: =_xlfn.XLOOKUP(GERAL[[#This Row],[Dia]],AI:AI,AJ:AJ,"")
A33: =_xlfn.XLOOKUP(GERAL[[#This Row],[Dia]],AA:AA,Z:Z,"") | B33: 45992 | C33: segunda-feira | D33: 45992 | W33: Morro do Tetéu | X33: =_xlfn.XLOOKUP(GERAL[[#This Row],[Dia]],AA:AA,AB:AB,"") | Z33: Semana 5 | AA33: 46082 | AB33: Prazo_30 | AC33: =_xlfn.XLOOKUP(GERAL[[#This Row],[Dia]],AI:AI,AJ:AJ,"")
A34: =_xlfn.XLOOKUP(GERAL[[#This Row],[Dia]],AA:AA,Z:Z,"") | B34: 45993 | C34: terça-feira | D34: 45993 | W34: Morro do Tetéu | X34: =_xlfn.XLOOKUP(GERAL[[#This Row],[Dia]],AA:AA,AB:AB,"") | Z34: Semana 5 | AA34: 46083 | AB34: Prazo_30 | AC34: =_xlfn.XLOOKUP(GERAL[[#This Row],[Dia]],AI:AI,AJ:AJ,"")
A35: =_xlfn.XLOOKUP(GERAL[[#This Row],[Dia]],AA:AA,Z:Z,"") | B35: 45994 | C35: quarta-feira | D35: 45994 | W35: Morro do Tetéu | X35: =_xlfn.XLOOKUP(GERAL[[#This Row],[Dia]],AA:AA,AB:AB,"") | Z35: Semana 5 | AA35: 46083 | AB35: Prazo_30 | AC35: =_xlfn.XLOOKUP(GERAL[[#This Row],[Dia]],AI:AI,AJ:AJ,"")
A36: =_xlfn.XLOOKUP(GERAL[[#This Row],[Dia]],AA:AA,Z:Z,"") | B36: 45995 | C36: quinta-feira | D36: 45995 | W36: Morro do Tetéu | X36: =_xlfn.XLOOKUP(GERAL[[#This Row],[Dia]],AA:AA,AB:AB,"") | Z36: Semana 5 | AA36: 46083 | AB36: Prazo_30 | AC36: =_xlfn.XLOOKUP(GERAL[[#This Row],[Dia]],AI:AI,AJ:AJ,"")
A37: =_xlfn.XLOOKUP(GERAL[[#This Row],[Dia]],AA:AA,Z:Z,"") | B37: 45996 | C37: sexta-feira | D37: 45996 | W37: Morro do Tetéu | X37: =_xlfn.XLOOKUP(GERAL[[#This Row],[Dia]],AA:AA,AB:AB,"") | Z37: Semana 5 | AA37: 46083 | AB37: Prazo_30 | AC37: =_xlfn.XLOOKUP(GERAL[[#This Row],[Dia]],AI:AI,AJ:AJ,"")
A38: =_xlfn.XLOOKUP(GERAL[[#This Row],[Dia]],AA:AA,Z:Z,"") | B38: 45997 | C38: sábado | D38: 45997 | E38: NÃO | W38: Morro do Tetéu | X38: =_xlfn.XLOOKUP(GERAL[[#This Row],[Dia]],AA:AA,AB:AB,"") | Z38: Semana 5 | AA38: 46083 | AB38: Prazo_30 | AC38: =_xlfn.XLOOKUP(GERAL[[#This Row],[Dia]],AI:AI,AJ:AJ,"")
A39: =_xlfn.XLOOKUP(GERAL[[#This Row],[Dia]],AA:AA,Z:Z,"") | B39: 45998 | C39: domingo | D39: 45998 | E39: NÃO | W39: Morro do Tetéu | X39: =_xlfn.XLOOKUP(GERAL[[#This Row],[Dia]],AA:AA,AB:AB,"") | Z39: Semana 5 | AA39: 46083 | AB39: Prazo_30 | AC39: =_xlfn.XLOOKUP(GERAL[[#This Row],[Dia]],AI:AI,AJ:AJ,"")
A40: =_xlfn.XLOOKUP(GERAL[[#This Row],[Dia]],AA:AA,Z:Z,"") | B40: 45999 | C40: segunda-feira | D40: 45999 | W40: Morro do Tetéu | X40: =_xlfn.XLOOKUP(GERAL[[#This Row],[Dia]],AA:AA,AB:AB,"") | Z40: Semana 6 | AA40: 46083 | AB40: Prazo_30 | AC40: =_xlfn.XLOOKUP(GERAL[[#This Row],[Dia]],AI:AI,AJ:AJ,"")
A41: =_xlfn.XLOOKUP(GERAL[[#This Row],[Dia]],AA:AA,Z:Z,"") | B41: 46000 | C41: terça-feira | D41: 46000 | W41: Morro do Tetéu | X41: =_xlfn.XLOOKUP(GERAL[[#This Row],[Dia]],AA:AA,AB:AB,"") | Z41: Semana 6 | AA41: 46084 | AB41: Prazo_30 | AC41: =_xlfn.XLOOKUP(GERAL[[#This Row],[Dia]],AI:AI,AJ:AJ,"")
...

Sheet PROD_EQUIPE
R2: Informar período
E3: SE LIGA NA REDE - SANTOS
E4: PRODUÇÃO POR EQUIPE
J7: PRODUTIVIDADE MÉDIA | L7: =IFERROR(AVERAGE(L13:L33),"") -> 1.814339 | M7: =IFERROR(AVERAGE(M13:M33),"") -> 0.69187214 | N7: =IFERROR(AVERAGE(N13:N33),"") -> 4.334447 | O7: =IFERROR(AVERAGE(O13:O33),"") -> 1.0586298 | P7: =IFERROR(AVERAGE(P13:P33),"") -> 5.3930767 | Q7: =IFERROR(AVERAGE(Q13:Q33),"") -> 2.5062112
J8: MÉDIA INTERNA | L8: {=IFERROR(TRIMMEAN(IF(L13:L33>0.01,L13:L33),40%),"")} -> 1.6305995 | M8: {=IFERROR(TRIMMEAN(IF(M13:M33>0.01,M13:M33),40%),"")} -> 1.0378082 | N8: {=IFERROR(TRIMMEAN(IF(N13:N33>0.01,N13:N33),40%),"")} -> 8.6688939 | O8: {=IFERROR(TRIMMEAN(IF(O13:O33>0.01,O13:O33),40%),"")} -> 3.1758893 | P8: {=IFERROR(TRIMMEAN(IF(P13:P33>0.01,P13:P33),40%),"")} -> 8.0896151 | Q8: {=IFERROR(TRIMMEAN(IF(Q13:Q33>0.01,Q13:Q33),40%),"")} -> 2.3571429
P9: DE | Q9: ATÉ
O10: PERÍODO | P10: 46052 | Q10: =TODAY()-1 -> 46135
C11: =SUM(C13:C1000) -> 102 | D11: =SUM(D13:D1000) -> 142 | E11: =SUM(E13:E1000) -> 113 | F11: =SUM(F13:F1000) -> 571 | G11: =SUM(G13:G1000) -> 147 | H11: =SUM(H13:H1000) -> 21 | I11: =SUM(I13:I1000) -> 28 | J11: =SUM(J13:J1000) -> 274 | K11: =SUM(K13:K1000) -> 57
B12: RUA | C12: DIAS ÚTEIS | D12: LA | E12: LE | F12: PRA | G12: PRE | H12: PV's | I12: LIE | J12: LIA | K12: IHM | L12: Ind. Prod. LA | M12: Ind Prod LE | N12: Ind Prod PRA | O12: Ind Prod PRE | P12: IND. PROD REDE | Q12: IND. PROD LIG
B13: ∑ Equipe até 28/02 - JC | C13: =COUNTIFS(GERAL[Dia Útil],"SIM",GERAL[Equipe],PROD_EQUIPE!B13,GERAL[Dia],">=" &PROD_EQUIPE!$P$10,GERAL[Dia],"<=" &PROD_EQUIPE!$Q$10) -> 23 | D13: =SUMIFS(GERAL[LA],GERAL[Equipe],PROD_EQUIPE!B13,GERAL[Dia],">=" &PROD_EQUIPE!$P$10,GERAL[Dia],"<=" &PROD_EQUIPE!$Q$10) -> 73 | E13: =SUMIFS(GERAL[LE],GERAL[Equipe],PROD_EQUIPE!B13,GERAL[Dia],">=" &PROD_EQUIPE!$P$10,GERAL[Dia],"<=" &PROD_EQUIPE!$Q$10) -> 33 | F13: =SUMIFS(GERAL[PRA],GERAL[Equipe],PROD_EQUIPE!B13,GERAL[Dia],">=" &PROD_EQUIPE!$P$10,GERAL[Dia],"<=" &PROD_EQUIPE!$Q$10) -> 231 | G13: =SUMIFS(GERAL[PRE],GERAL[Equipe],PROD_EQUIPE!B13,GERAL[Dia],">=" &PROD_EQUIPE!$P$10,GERAL[Dia],"<=" &PROD_EQUIPE!$Q$10) -> 144 | H13: =SUMIFS(GERAL[PV''s],GERAL[Equipe],PROD_EQUIPE!B13,GERAL[Dia],">=" &PROD_EQUIPE!$P$10,GERAL[Dia],"<=" &PROD_EQUIPE!$Q$10) -> 12 | I13: =SUMIFS(GERAL[LIE],GERAL[Equipe],PROD_EQUIPE!B13,GERAL[Dia],">=" &PROD_EQUIPE!$P$10,GERAL[Dia],"<=" &PROD_EQUIPE!$Q$10) -> 4 | J13: =SUMIFS(GERAL[LIA],GERAL[Equipe],PROD_EQUIPE!B13,GERAL[Dia],">=" &PROD_EQUIPE!$P$10,GERAL[Dia],"<=" &PROD_EQUIPE!$Q$10) -> 127 | K13: =SUMIFS(GERAL[IHM],GERAL[Equipe],PROD_EQUIPE!B13,GERAL[Dia],">=" &PROD_EQUIPE!$P$10,GERAL[Dia],"<=" &PROD_EQUIPE!$Q$10) -> 26 | L13: =IFERROR(D13/C13,"") -> 3.173913 | M13: =IFERROR(E13/C13,"") -> 1.4347826 | N13: =IFERROR(F13/C13,"") -> 10.043478 | O13: =IFERROR(G13/C13,"") -> 6.2608696 | P13: =IFERROR(SUM(F13:G13)/C13,"") -> 16.304348 | Q13: =IFERROR(SUM(D13:E13)/C13,"") -> 4.6086957
B14: DOUGLAS | C14: =COUNTIFS(GERAL[Dia Útil],"SIM",GERAL[Equipe],PROD_EQUIPE!B14,GERAL[Dia],">=" &PROD_EQUIPE!$P$10,GERAL[Dia],"<=" &PROD_EQUIPE!$Q$10) -> 33 | D14: =SUMIFS(GERAL[LA],GERAL[Equipe],PROD_EQUIPE!B14,GERAL[Dia],">=" &PROD_EQUIPE!$P$10,GERAL[Dia],"<=" &PROD_EQUIPE!$Q$10) -> 12 | E14: =SUMIFS(GERAL[LE],GERAL[Equipe],PROD_EQUIPE!B14,GERAL[Dia],">=" &PROD_EQUIPE!$P$10,GERAL[Dia],"<=" &PROD_EQUIPE!$Q$10) -> 62 | F14: =SUMIFS(GERAL[PRA],GERAL[Equipe],PROD_EQUIPE!B14,GERAL[Dia],">=" &PROD_EQUIPE!$P$10,GERAL[Dia],"<=" &PROD_EQUIPE!$Q$10) -> 0 | G14: =SUMIFS(GERAL[PRE],GERAL[Equipe],PROD_EQUIPE!B14,GERAL[Dia],">=" &PROD_EQUIPE!$P$10,GERAL[Dia],"<=" &PROD_EQUIPE!$Q$10) -> 3 | H14: =SUMIFS(GERAL[PV''s],GERAL[Equipe],PROD_EQUIPE!B14,GERAL[Dia],">=" &PROD_EQUIPE!$P$10,GERAL[Dia],"<=" &PROD_EQUIPE!$Q$10) -> 5 | I14: =SUMIFS(GERAL[LIE],GERAL[Equipe],PROD_EQUIPE!B14,GERAL[Dia],">=" &PROD_EQUIPE!$P$10,GERAL[Dia],"<=" &PROD_EQUIPE!$Q$10) -> 0 | J14: =SUMIFS(GERAL[LIA],GERAL[Equipe],PROD_EQUIPE!B14,GERAL[Dia],">=" &PROD_EQUIPE!$P$10,GERAL[Dia],"<=" &PROD_EQUIPE!$Q$10) -> 48 | K14: =SUMIFS(GERAL[IHM],GERAL[Equipe],PROD_EQUIPE!B14,GERAL[Dia],">=" &PROD_EQUIPE!$P$10,GERAL[Dia],"<=" &PROD_EQUIPE!$Q$10) -> 3 | L14: =IFERROR(D14/C14,"") -> 0.36363636 | M14: =IFERROR(E14/C14,"") -> 1.8787879 | N14: =IFERROR(F14/C14,"") -> 0 | O14: =IFERROR(G14/C14,"") -> 0.090909091 | P14: =IFERROR(SUM(F14:G14)/C14,"") -> 0.090909091 | Q14: =IFERROR(SUM(D14:E14)/C14,"") -> 2.2424242
B15: DOUGLAS/ SANDRO | C15: =COUNTIFS(GERAL[Dia Útil],"SIM",GERAL[Equipe],PROD_EQUIPE!B15,GERAL[Dia],">=" &PROD_EQUIPE!$P$10,GERAL[Dia],"<=" &PROD_EQUIPE!$Q$10) -> 2 | D15: =SUMIFS(GERAL[LA],GERAL[Equipe],PROD_EQUIPE!B15,GERAL[Dia],">=" &PROD_EQUIPE!$P$10,GERAL[Dia],"<=" &PROD_EQUIPE!$Q$10) -> 2 | E15: =SUMIFS(GERAL[LE],GERAL[Equipe],PROD_EQUIPE!B15,GERAL[Dia],">=" &PROD_EQUIPE!$P$10,GERAL[Dia],"<=" &PROD_EQUIPE!$Q$10) -> 0 | F15: =SUMIFS(GERAL[PRA],GERAL[Equipe],PROD_EQUIPE!B15,GERAL[Dia],">=" &PROD_EQUIPE!$P$10,GERAL[Dia],"<=" &PROD_EQUIPE!$Q$10) -> 0 | G15: =SUMIFS(GERAL[PRE],GERAL[Equipe],PROD_EQUIPE!B15,GERAL[Dia],">=" &PROD_EQUIPE!$P$10,GERAL[Dia],"<=" &PROD_EQUIPE!$Q$10) -> 0 | H15: =SUMIFS(GERAL[PV''s],GERAL[Equipe],PROD_EQUIPE!B15,GERAL[Dia],">=" &PROD_EQUIPE!$P$10,GERAL[Dia],"<=" &PROD_EQUIPE!$Q$10) -> 0 | I15: =SUMIFS(GERAL[LIE],GERAL[Equipe],PROD_EQUIPE!B15,GERAL[Dia],">=" &PROD_EQUIPE!$P$10,GERAL[Dia],"<=" &PROD_EQUIPE!$Q$10) -> 0 | J15: =SUMIFS(GERAL[LIA],GERAL[Equipe],PROD_EQUIPE!B15,GERAL[Dia],">=" &PROD_EQUIPE!$P$10,GERAL[Dia],"<=" &PROD_EQUIPE!$Q$10) -> 32 | K15: =SUMIFS(GERAL[IHM],GERAL[Equipe],PROD_EQUIPE!B15,GERAL[Dia],">=" &PROD_EQUIPE!$P$10,GERAL[Dia],"<=" &PROD_EQUIPE!$Q$10) -> 2 | L15: =IFERROR(D15/C15,"") -> 1 | M15: =IFERROR(E15/C15,"") -> 0 | N15: =IFERROR(F15/C15,"") -> 0 | O15: =IFERROR(G15/C15,"") -> 0 | P15: =IFERROR(SUM(F15:G15)/C15,"") -> 0 | Q15: =IFERROR(SUM(D15:E15)/C15,"") -> 1
B16: JAMILTON | C16: =COUNTIFS(GERAL[Dia Útil],"SIM",GERAL[Equipe],PROD_EQUIPE!B16,GERAL[Dia],">=" &PROD_EQUIPE!$P$10,GERAL[Dia],"<=" &PROD_EQUIPE!$Q$10) -> 21 | D16: =SUMIFS(GERAL[LA],GERAL[Equipe],PROD_EQUIPE!B16,GERAL[Dia],">=" &PROD_EQUIPE!$P$10,GERAL[Dia],"<=" &PROD_EQUIPE!$Q$10) -> 14 | E16: =SUMIFS(GERAL[LE],GERAL[Equipe],PROD_EQUIPE!B16,GERAL[Dia],">=" &PROD_EQUIPE!$P$10,GERAL[Dia],"<=" &PROD_EQUIPE!$Q$10) -> 9 | F16: =SUMIFS(GERAL[PRA],GERAL[Equipe],PROD_EQUIPE!B16,GERAL[Dia],">=" &PROD_EQUIPE!$P$10,GERAL[Dia],"<=" &PROD_EQUIPE!$Q$10) -> 235 | G16: =SUMIFS(GERAL[PRE],GERAL[Equipe],PROD_EQUIPE!B16,GERAL[Dia],">=" &PROD_EQUIPE!$P$10,GERAL[Dia],"<=" &PROD_EQUIPE!$Q$10) -> 0 | H16: =SUMIFS(GERAL[PV''s],GERAL[Equipe],PROD_EQUIPE!B16,GERAL[Dia],">=" &PROD_EQUIPE!$P$10,GERAL[Dia],"<=" &PROD_EQUIPE!$Q$10) -> 2 | I16: =SUMIFS(GERAL[LIE],GERAL[Equipe],PROD_EQUIPE!B16,GERAL[Dia],">=" &PROD_EQUIPE!$P$10,GERAL[Dia],"<=" &PROD_EQUIPE!$Q$10) -> 8 | J16: =SUMIFS(GERAL[LIA],GERAL[Equipe],PROD_EQUIPE!B16,GERAL[Dia],">=" &PROD_EQUIPE!$P$10,GERAL[Dia],"<=" &PROD_EQUIPE!$Q$10) -> 27 | K16: =SUMIFS(GERAL[IHM],GERAL[Equipe],PROD_EQUIPE!B16,GERAL[Dia],">=" &PROD_EQUIPE!$P$10,GERAL[Dia],"<=" &PROD_EQUIPE!$Q$10) -> 8 | L16: =IFERROR(D16/C16,"") -> 0.66666667 | M16: =IFERROR(E16/C16,"") -> 0.42857143 | N16: =IFERROR(F16/C16,"") -> 11.190476 | O16: =IFERROR(G16/C16,"") -> 0 | P16: =IFERROR(SUM(F16:G16)/C16,"") -> 11.190476 | Q16: =IFERROR(SUM(D16:E16)/C16,"") -> 1.0952381
B17: SANDRO | C17: =COUNTIFS(GERAL[Dia Útil],"SIM",GERAL[Equipe],PROD_EQUIPE!B17,GERAL[Dia],">=" &PROD_EQUIPE!$P$10,GERAL[Dia],"<=" &PROD_EQUIPE!$Q$10) -> 22 | D17: =SUMIFS(GERAL[LA],GERAL[Equipe],PROD_EQUIPE!B17,GERAL[Dia],">=" &PROD_EQUIPE!$P$10,GERAL[Dia],"<=" &PROD_EQUIPE!$Q$10) -> 37 | E17: =SUMIFS(GERAL[LE],GERAL[Equipe],PROD_EQUIPE!B17,GERAL[Dia],">=" &PROD_EQUIPE!$P$10,GERAL[Dia],"<=" &PROD_EQUIPE!$Q$10) -> 9 | F17: =SUMIFS(GERAL[PRA],GERAL[Equipe],PROD_EQUIPE!B17,GERAL[Dia],">=" &PROD_EQUIPE!$P$10,GERAL[Dia],"<=" &PROD_EQUIPE!$Q$10) -> 105 | G17: =SUMIFS(GERAL[PRE],GERAL[Equipe],PROD_EQUIPE!B17,GERAL[Dia],">=" &PROD_EQUIPE!$P$10,GERAL[Dia],"<=" &PROD_EQUIPE!$Q$10) -> 0 | H17: =SUMIFS(GERAL[PV''s],GERAL[Equipe],PROD_EQUIPE!B17,GERAL[Dia],">=" &PROD_EQUIPE!$P$10,GERAL[Dia],"<=" &PROD_EQUIPE!$Q$10) -> 2 | I17: =SUMIFS(GERAL[LIE],GERAL[Equipe],PROD_EQUIPE!B17,GERAL[Dia],">=" &PROD_EQUIPE!$P$10,GERAL[Dia],"<=" &PROD_EQUIPE!$Q$10) -> 16 | J17: =SUMIFS(GERAL[LIA],GERAL[Equipe],PROD_EQUIPE!B17,GERAL[Dia],">=" &PROD_EQUIPE!$P$10,GERAL[Dia],"<=" &PROD_EQUIPE!$Q$10) -> 36 | K17: =SUMIFS(GERAL[IHM],GERAL[Equipe],PROD_EQUIPE!B17,GERAL[Dia],">=" &PROD_EQUIPE!$P$10,GERAL[Dia],"<=" &PROD_EQUIPE!$Q$10) -> 14 | L17: =IFERROR(D17/C17,"") -> 1.6818182 | M17: =IFERROR(E17/C17,"") -> 0.40909091 | N17: =IFERROR(F17/C17,"") -> 4.7727273 | O17: =IFERROR(G17/C17,"") -> 0 | P17: =IFERROR(SUM(F17:G17)/C17,"") -> 4.7727273 | Q17: =IFERROR(SUM(D17:E17)/C17,"") -> 2.0909091
B18: SANDRO | C18: =COUNTIFS(GERAL[Dia Útil],"SIM",GERAL[Equipe],PROD_EQUIPE!B18,GERAL[Dia],">=" &PROD_EQUIPE!$P$10,GERAL[Dia],"<=" &PROD_EQUIPE!$Q$10) -> 1 | D18: =SUMIFS(GERAL[LA],GERAL[Equipe],PROD_EQUIPE!B18,GERAL[Dia],">=" &PROD_EQUIPE!$P$10,GERAL[Dia],"<=" &PROD_EQUIPE!$Q$10) -> 4 | E18: =SUMIFS(GERAL[LE],GERAL[Equipe],PROD_EQUIPE!B18,GERAL[Dia],">=" &PROD_EQUIPE!$P$10,GERAL[Dia],"<=" &PROD_EQUIPE!$Q$10) -> 0 | F18: =SUMIFS(GERAL[PRA],GERAL[Equipe],PROD_EQUIPE!B18,GERAL[Dia],">=" &PROD_EQUIPE!$P$10,GERAL[Dia],"<=" &PROD_EQUIPE!$Q$10) -> 0 | G18: =SUMIFS(GERAL[PRE],GERAL[Equipe],PROD_EQUIPE!B18,GERAL[Dia],">=" &PROD_EQUIPE!$P$10,GERAL[Dia],"<=" &PROD_EQUIPE!$Q$10) -> 0 | H18: =SUMIFS(GERAL[PV''s],GERAL[Equipe],PROD_EQUIPE!B18,GERAL[Dia],">=" &PROD_EQUIPE!$P$10,GERAL[Dia],"<=" &PROD_EQUIPE!$Q$10) -> 0 | I18: =SUMIFS(GERAL[LIE],GERAL[Equipe],PROD_EQUIPE!B18,GERAL[Dia],">=" &PROD_EQUIPE!$P$10,GERAL[Dia],"<=" &PROD_EQUIPE!$Q$10) -> 0 | J18: =SUMIFS(GERAL[LIA],GERAL[Equipe],PROD_EQUIPE!B18,GERAL[Dia],">=" &PROD_EQUIPE!$P$10,GERAL[Dia],"<=" &PROD_EQUIPE!$Q$10) -> 4 | K18: =SUMIFS(GERAL[IHM],GERAL[Equipe],PROD_EQUIPE!B18,GERAL[Dia],">=" &PROD_EQUIPE!$P$10,GERAL[Dia],"<=" &PROD_EQUIPE!$Q$10) -> 4 | L18: =IFERROR(D18/C18,"") -> 4 | M18: =IFERROR(E18/C18,"") -> 0 | N18: =IFERROR(F18/C18,"") -> 0 | O18: =IFERROR(G18/C18,"") -> 0 | P18: =IFERROR(SUM(F18:G18)/C18,"") -> 0 | Q18: =IFERROR(SUM(D18:E18)/C18,"") -> 4
B19: (vazio) | C19: =COUNTIFS(GERAL[Dia Útil],"SIM",GERAL[Equipe],PROD_EQUIPE!B19,GERAL[Dia],">=" &PROD_EQUIPE!$P$10,GERAL[Dia],"<=" &PROD_EQUIPE!$Q$10) -> 0 | D19: =SUMIFS(GERAL[LA],GERAL[Equipe],PROD_EQUIPE!B19,GERAL[Dia],">=" &PROD_EQUIPE!$P$10,GERAL[Dia],"<=" &PROD_EQUIPE!$Q$10) -> 0 | E19: =SUMIFS(GERAL[LE],GERAL[Equipe],PROD_EQUIPE!B19,GERAL[Dia],">=" &PROD_EQUIPE!$P$10,GERAL[Dia],"<=" &PROD_EQUIPE!$Q$10) -> 0 | F19: =SUMIFS(GERAL[PRA],GERAL[Equipe],PROD_EQUIPE!B19,GERAL[Dia],">=" &PROD_EQUIPE!$P$10,GERAL[Dia],"<=" &PROD_EQUIPE!$Q$10) -> 0 | G19: =SUMIFS(GERAL[PRE],GERAL[Equipe],PROD_EQUIPE!B19,GERAL[Dia],">=" &PROD_EQUIPE!$P$10,GERAL[Dia],"<=" &PROD_EQUIPE!$Q$10) -> 0 | H19: =SUMIFS(GERAL[PV''s],GERAL[Equipe],PROD_EQUIPE!B19,GERAL[Dia],">=" &PROD_EQUIPE!$P$10,GERAL[Dia],"<=" &PROD_EQUIPE!$Q$10) -> 0 | I19: =SUMIFS(GERAL[LIE],GERAL[Equipe],PROD_EQUIPE!B19,GERAL[Dia],">=" &PROD_EQUIPE!$P$10,GERAL[Dia],"<=" &PROD_EQUIPE!$Q$10) -> 0 | J19: =SUMIFS(GERAL[LIA],GERAL[Equipe],PROD_EQUIPE!B19,GERAL[Dia],">=" &PROD_EQUIPE!$P$10,GERAL[Dia],"<=" &PROD_EQUIPE!$Q$10) -> 0 | K19: =SUMIFS(GERAL[IHM],GERAL[Equipe],PROD_EQUIPE!B19,GERAL[Dia],">=" &PROD_EQUIPE!$P$10,GERAL[Dia],"<=" &PROD_EQUIPE!$Q$10) -> 0 | L19: =IFERROR(D19/C19,"") | M19: =IFERROR(E19/C19,"") | N19: =IFERROR(F19/C19,"") | O19: =IFERROR(G19/C19,"") | P19: =IFERROR(SUM(F19:G19)/C19,"") | Q19: =IFERROR(SUM(D19:E19)/C19,"")
C20: =COUNTIFS(GERAL[Dia Útil],"SIM",GERAL[Equipe],PROD_EQUIPE!B20,GERAL[Dia],">=" &PROD_EQUIPE!$P$10,GERAL[Dia],"<=" &PROD_EQUIPE!$Q$10) -> 0 | D20: =SUMIFS(GERAL[LA],GERAL[Equipe],PROD_EQUIPE!B20,GERAL[Dia],">=" &PROD_EQUIPE!$P$10,GERAL[Dia],"<=" &PROD_EQUIPE!$Q$10) -> 0 | E20: =SUMIFS(GERAL[LE],GERAL[Equipe],PROD_EQUIPE!B20,GERAL[Dia],">=" &PROD_EQUIPE!$P$10,GERAL[Dia],"<=" &PROD_EQUIPE!$Q$10) -> 0 | F20: =SUMIFS(GERAL[PRA],GERAL[Equipe],PROD_EQUIPE!B20,GERAL[Dia],">=" &PROD_EQUIPE!$P$10,GERAL[Dia],"<=" &PROD_EQUIPE!$Q$10) -> 0 | G20: =SUMIFS(GERAL[PRE],GERAL[Equipe],PROD_EQUIPE!B20,GERAL[Dia],">=" &PROD_EQUIPE!$P$10,GERAL[Dia],"<=" &PROD_EQUIPE!$Q$10) -> 0 | H20: =SUMIFS(GERAL[PV''s],GERAL[Equipe],PROD_EQUIPE!B20,GERAL[Dia],">=" &PROD_EQUIPE!$P$10,GERAL[Dia],"<=" &PROD_EQUIPE!$Q$10) -> 0 | I20: =SUMIFS(GERAL[LIE],GERAL[Equipe],PROD_EQUIPE!B20,GERAL[Dia],">=" &PROD_EQUIPE!$P$10,GERAL[Dia],"<=" &PROD_EQUIPE!$Q$10) -> 0 | J20: =SUMIFS(GERAL[LIA],GERAL[Equipe],PROD_EQUIPE!B20,GERAL[Dia],">=" &PROD_EQUIPE!$P$10,GERAL[Dia],"<=" &PROD_EQUIPE!$Q$10) -> 0 | K20: =SUMIFS(GERAL[IHM],GERAL[Equipe],PROD_EQUIPE!B20,GERAL[Dia],">=" &PROD_EQUIPE!$P$10,GERAL[Dia],"<=" &PROD_EQUIPE!$Q$10) -> 0 | L20: =IFERROR(D20/C20,"") | M20: =IFERROR(E20/C20,"") | N20: =IFERROR(F20/C20,"") | O20: =IFERROR(G20/C20,"") | P20: =IFERROR(SUM(F20:G20)/C20,"") | Q20: =IFERROR(SUM(D20:E20)/C20,"")
C21: =COUNTIFS(GERAL[Dia Útil],"SIM",GERAL[Equipe],PROD_EQUIPE!B21,GERAL[Dia],">=" &PROD_EQUIPE!$P$10,GERAL[Dia],"<=" &PROD_EQUIPE!$Q$10) -> 0 | D21: =SUMIFS(GERAL[LA],GERAL[Equipe],PROD_EQUIPE!B21,GERAL[Dia],">=" &PROD_EQUIPE!$P$10,GERAL[Dia],"<=" &PROD_EQUIPE!$Q$10) -> 0 | E21: =SUMIFS(GERAL[LE],GERAL[Equipe],PROD_EQUIPE!B21,GERAL[Dia],">=" &PROD_EQUIPE!$P$10,GERAL[Dia],"<=" &PROD_EQUIPE!$Q$10) -> 0 | F21: =SUMIFS(GERAL[PRA],GERAL[Equipe],PROD_EQUIPE!B21,GERAL[Dia],">=" &PROD_EQUIPE!$P$10,GERAL[Dia],"<=" &PROD_EQUIPE!$Q$10) -> 0 | G21: =SUMIFS(GERAL[PRE],GERAL[Equipe],PROD_EQUIPE!B21,GERAL[Dia],">=" &PROD_EQUIPE!$P$10,GERAL[Dia],"<=" &PROD_EQUIPE!$Q$10) -> 0 | H21: =SUMIFS(GERAL[PV''s],GERAL[Equipe],PROD_EQUIPE!B21,GERAL[Dia],">=" &PROD_EQUIPE!$P$10,GERAL[Dia],"<=" &PROD_EQUIPE!$Q$10) -> 0 | I21: =SUMIFS(GERAL[LIE],GERAL[Equipe],PROD_EQUIPE!B21,GERAL[Dia],">=" &PROD_EQUIPE!$P$10,GERAL[Dia],"<=" &PROD_EQUIPE!$Q$10) -> 0 | J21: =SUMIFS(GERAL[LIA],GERAL[Equipe],PROD_EQUIPE!B21,GERAL[Dia],">=" &PROD_EQUIPE!$P$10,GERAL[Dia],"<=" &PROD_EQUIPE!$Q$10) -> 0 | K21: =SUMIFS(GERAL[IHM],GERAL[Equipe],PROD_EQUIPE!B21,GERAL[Dia],">=" &PROD_EQUIPE!$P$10,GERAL[Dia],"<=" &PROD_EQUIPE!$Q$10) -> 0 | L21: =IFERROR(D21/C21,"") | M21: =IFERROR(E21/C21,"") | N21: =IFERROR(F21/C21,"") | O21: =IFERROR(G21/C21,"") | P21: =IFERROR(SUM(F21:G21)/C21,"") | Q21: =IFERROR(SUM(D21:E21)/C21,"")
C22: =COUNTIFS(GERAL[Dia Útil],"SIM",GERAL[Equipe],PROD_EQUIPE!B22,GERAL[Dia],">=" &PROD_EQUIPE!$P$10,GERAL[Dia],"<=" &PROD_EQUIPE!$Q$10) -> 0 | D22: =SUMIFS(GERAL[LA],GERAL[Equipe],PROD_EQUIPE!B22,GERAL[Dia],">=" &PROD_EQUIPE!$P$10,GERAL[Dia],"<=" &PROD_EQUIPE!$Q$10) -> 0 | E22: =SUMIFS(GERAL[LE],GERAL[Equipe],PROD_EQUIPE!B22,GERAL[Dia],">=" &PROD_EQUIPE!$P$10,GERAL[Dia],"<=" &PROD_EQUIPE!$Q$10) -> 0 | F22: =SUMIFS(GERAL[PRA],GERAL[Equipe],PROD_EQUIPE!B22,GERAL[Dia],">=" &PROD_EQUIPE!$P$10,GERAL[Dia],"<=" &PROD_EQUIPE!$Q$10) -> 0 | G22: =SUMIFS(GERAL[PRE],GERAL[Equipe],PROD_EQUIPE!B22,GERAL[Dia],">=" &PROD_EQUIPE!$P$10,GERAL[Dia],"<=" &PROD_EQUIPE!$Q$10) -> 0 | H22: =SUMIFS(GERAL[PV''s],GERAL[Equipe],PROD_EQUIPE!B22,GERAL[Dia],">=" &PROD_EQUIPE!$P$10,GERAL[Dia],"<=" &PROD_EQUIPE!$Q$10) -> 0 | I22: =SUMIFS(GERAL[LIE],GERAL[Equipe],PROD_EQUIPE!B22,GERAL[Dia],">=" &PROD_EQUIPE!$P$10,GERAL[Dia],"<=" &PROD_EQUIPE!$Q$10) -> 0 | J22: =SUMIFS(GERAL[LIA],GERAL[Equipe],PROD_EQUIPE!B22,GERAL[Dia],">=" &PROD_EQUIPE!$P$10,GERAL[Dia],"<=" &PROD_EQUIPE!$Q$10) -> 0 | K22: =SUMIFS(GERAL[IHM],GERAL[Equipe],PROD_EQUIPE!B22,GERAL[Dia],">=" &PROD_EQUIPE!$P$10,GERAL[Dia],"<=" &PROD_EQUIPE!$Q$10) -> 0 | L22: =IFERROR(D22/C22,"") | M22: =IFERROR(E22/C22,"") | N22: =IFERROR(F22/C22,"") | O22: =IFERROR(G22/C22,"") | P22: =IFERROR(SUM(F22:G22)/C22,"") | Q22: =IFERROR(SUM(D22:E22)/C22,"")
C23: =COUNTIFS(GERAL[Dia Útil],"SIM",GERAL[Equipe],PROD_EQUIPE!B23,GERAL[Dia],">=" &PROD_EQUIPE!$P$10,GERAL[Dia],"<=" &PROD_EQUIPE!$Q$10) -> 0 | D23: =SUMIFS(GERAL[LA],GERAL[Equipe],PROD_EQUIPE!B23,GERAL[Dia],">=" &PROD_EQUIPE!$P$10,GERAL[Dia],"<=" &PROD_EQUIPE!$Q$10) -> 0 | E23: =SUMIFS(GERAL[LE],GERAL[Equipe],PROD_EQUIPE!B23,GERAL[Dia],">=" &PROD_EQUIPE!$P$10,GERAL[Dia],"<=" &PROD_EQUIPE!$Q$10) -> 0 | F23: =SUMIFS(GERAL[PRA],GERAL[Equipe],PROD_EQUIPE!B23,GERAL[Dia],">=" &PROD_EQUIPE!$P$10,GERAL[Dia],"<=" &PROD_EQUIPE!$Q$10) -> 0 | G23: =SUMIFS(GERAL[PRE],GERAL[Equipe],PROD_EQUIPE!B23,GERAL[Dia],">=" &PROD_EQUIPE!$P$10,GERAL[Dia],"<=" &PROD_EQUIPE!$Q$10) -> 0 | H23: =SUMIFS(GERAL[PV''s],GERAL[Equipe],PROD_EQUIPE!B23,GERAL[Dia],">=" &PROD_EQUIPE!$P$10,GERAL[Dia],"<=" &PROD_EQUIPE!$Q$10) -> 0 | I23: =SUMIFS(GERAL[LIE],GERAL[Equipe],PROD_EQUIPE!B23,GERAL[Dia],">=" &PROD_EQUIPE!$P$10,GERAL[Dia],"<=" &PROD_EQUIPE!$Q$10) -> 0 | J23: =SUMIFS(GERAL[LIA],GERAL[Equipe],PROD_EQUIPE!B23,GERAL[Dia],">=" &PROD_EQUIPE!$P$10,GERAL[Dia],"<=" &PROD_EQUIPE!$Q$10) -> 0 | K23: =SUMIFS(GERAL[IHM],GERAL[Equipe],PROD_EQUIPE!B23,GERAL[Dia],">=" &PROD_EQUIPE!$P$10,GERAL[Dia],"<=" &PROD_EQUIPE!$Q$10) -> 0 | L23: =IFERROR(D23/C23,"") | M23: =IFERROR(E23/C23,"") | N23: =IFERROR(F23/C23,"") | O23: =IFERROR(G23/C23,"") | P23: =IFERROR(SUM(F23:G23)/C23,"") | Q23: =IFERROR(SUM(D23:E23)/C23,"")
C24: =COUNTIFS(GERAL[Dia Útil],"SIM",GERAL[Equipe],PROD_EQUIPE!B24,GERAL[Dia],">=" &PROD_EQUIPE!$P$10,GERAL[Dia],"<=" &PROD_EQUIPE!$Q$10) -> 0 | D24: =SUMIFS(GERAL[LA],GERAL[Equipe],PROD_EQUIPE!B24,GERAL[Dia],">=" &PROD_EQUIPE!$P$10,GERAL[Dia],"<=" &PROD_EQUIPE!$Q$10) -> 0 | E24: =SUMIFS(GERAL[LE],GERAL[Equipe],PROD_EQUIPE!B24,GERAL[Dia],">=" &PROD_EQUIPE!$P$10,GERAL[Dia],"<=" &PROD_EQUIPE!$Q$10) -> 0 | F24: =SUMIFS(GERAL[PRA],GERAL[Equipe],PROD_EQUIPE!B24,GERAL[Dia],">=" &PROD_EQUIPE!$P$10,GERAL[Dia],"<=" &PROD_EQUIPE!$Q$10) -> 0 | G24: =SUMIFS(GERAL[PRE],GERAL[Equipe],PROD_EQUIPE!B24,GERAL[Dia],">=" &PROD_EQUIPE!$P$10,GERAL[Dia],"<=" &PROD_EQUIPE!$Q$10) -> 0 | H24: =SUMIFS(GERAL[PV''s],GERAL[Equipe],PROD_EQUIPE!B24,GERAL[Dia],">=" &PROD_EQUIPE!$P$10,GERAL[Dia],"<=" &PROD_EQUIPE!$Q$10) -> 0 | I24: =SUMIFS(GERAL[LIE],GERAL[Equipe],PROD_EQUIPE!B24,GERAL[Dia],">=" &PROD_EQUIPE!$P$10,GERAL[Dia],"<=" &PROD_EQUIPE!$Q$10) -> 0 | J24: =SUMIFS(GERAL[LIA],GERAL[Equipe],PROD_EQUIPE!B24,GERAL[Dia],">=" &PROD_EQUIPE!$P$10,GERAL[Dia],"<=" &PROD_EQUIPE!$Q$10) -> 0 | K24: =SUMIFS(GERAL[IHM],GERAL[Equipe],PROD_EQUIPE!B24,GERAL[Dia],">=" &PROD_EQUIPE!$P$10,GERAL[Dia],"<=" &PROD_EQUIPE!$Q$10) -> 0 | L24: =IFERROR(D24/C24,"") | M24: =IFERROR(E24/C24,"") | N24: =IFERROR(F24/C24,"") | O24: =IFERROR(G24/C24,"") | P24: =IFERROR(SUM(F24:G24)/C24,"") | Q24: =IFERROR(SUM(D24:E24)/C24,"")
C25: =COUNTIFS(GERAL[Dia Útil],"SIM",GERAL[Equipe],PROD_EQUIPE!B25,GERAL[Dia],">=" &PROD_EQUIPE!$P$10,GERAL[Dia],"<=" &PROD_EQUIPE!$Q$10) -> 0 | D25: =SUMIFS(GERAL[LA],GERAL[Equipe],PROD_EQUIPE!B25,GERAL[Dia],">=" &PROD_EQUIPE!$P$10,GERAL[Dia],"<=" &PROD_EQUIPE!$Q$10) -> 0 | E25: =SUMIFS(GERAL[LE],GERAL[Equipe],PROD_EQUIPE!B25,GERAL[Dia],">=" &PROD_EQUIPE!$P$10,GERAL[Dia],"<=" &PROD_EQUIPE!$Q$10) -> 0 | F25: =SUMIFS(GERAL[PRA],GERAL[Equipe],PROD_EQUIPE!B25,GERAL[Dia],">=" &PROD_EQUIPE!$P$10,GERAL[Dia],"<=" &PROD_EQUIPE!$Q$10) -> 0 | G25: =SUMIFS(GERAL[PRE],GERAL[Equipe],PROD_EQUIPE!B25,GERAL[Dia],">=" &PROD_EQUIPE!$P$10,GERAL[Dia],"<=" &PROD_EQUIPE!$Q$10) -> 0 | H25: =SUMIFS(GERAL[PV''s],GERAL[Equipe],PROD_EQUIPE!B25,GERAL[Dia],">=" &PROD_EQUIPE!$P$10,GERAL[Dia],"<=" &PROD_EQUIPE!$Q$10) -> 0 | I25: =SUMIFS(GERAL[LIE],GERAL[Equipe],PROD_EQUIPE!B25,GERAL[Dia],">=" &PROD_EQUIPE!$P$10,GERAL[Dia],"<=" &PROD_EQUIPE!$Q$10) -> 0 | J25: =SUMIFS(GERAL[LIA],GERAL[Equipe],PROD_EQUIPE!B25,GERAL[Dia],">=" &PROD_EQUIPE!$P$10,GERAL[Dia],"<=" &PROD_EQUIPE!$Q$10) -> 0 | K25: =SUMIFS(GERAL[IHM],GERAL[Equipe],PROD_EQUIPE!B25,GERAL[Dia],">=" &PROD_EQUIPE!$P$10,GERAL[Dia],"<=" &PROD_EQUIPE!$Q$10) -> 0 | L25: =IFERROR(D25/C25,"") | M25: =IFERROR(E25/C25,"") | N25: =IFERROR(F25/C25,"") | O25: =IFERROR(G25/C25,"") | P25: =IFERROR(SUM(F25:G25)/C25,"") | Q25: =IFERROR(SUM(D25:E25)/C25,"")
C26: =COUNTIFS(GERAL[Dia Útil],"SIM",GERAL[Equipe],PROD_EQUIPE!B26,GERAL[Dia],">=" &PROD_EQUIPE!$P$10,GERAL[Dia],"<=" &PROD_EQUIPE!$Q$10) -> 0 | D26: =SUMIFS(GERAL[LA],GERAL[Equipe],PROD_EQUIPE!B26,GERAL[Dia],">=" &PROD_EQUIPE!$P$10,GERAL[Dia],"<=" &PROD_EQUIPE!$Q$10) -> 0 | E26: =SUMIFS(GERAL[LE],GERAL[Equipe],PROD_EQUIPE!B26,GERAL[Dia],">=" &PROD_EQUIPE!$P$10,GERAL[Dia],"<=" &PROD_EQUIPE!$Q$10) -> 0 | F26: =SUMIFS(GERAL[PRA],GERAL[Equipe],PROD_EQUIPE!B26,GERAL[Dia],">=" &PROD_EQUIPE!$P$10,GERAL[Dia],"<=" &PROD_EQUIPE!$Q$10) -> 0 | G26: =SUMIFS(GERAL[PRE],GERAL[Equipe],PROD_EQUIPE!B26,GERAL[Dia],">=" &PROD_EQUIPE!$P$10,GERAL[Dia],"<=" &PROD_EQUIPE!$Q$10) -> 0 | H26: =SUMIFS(GERAL[PV''s],GERAL[Equipe],PROD_EQUIPE!B26,GERAL[Dia],">=" &PROD_EQUIPE!$P$10,GERAL[Dia],"<=" &PROD_EQUIPE!$Q$10) -> 0 | I26: =SUMIFS(GERAL[LIE],GERAL[Equipe],PROD_EQUIPE!B26,GERAL[Dia],">=" &PROD_EQUIPE!$P$10,GERAL[Dia],"<=" &PROD_EQUIPE!$Q$10) -> 0 | J26: =SUMIFS(GERAL[LIA],GERAL[Equipe],PROD_EQUIPE!B26,GERAL[Dia],">=" &PROD_EQUIPE!$P$10,GERAL[Dia],"<=" &PROD_EQUIPE!$Q$10) -> 0 | K26: =SUMIFS(GERAL[IHM],GERAL[Equipe],PROD_EQUIPE!B26,GERAL[Dia],">=" &PROD_EQUIPE!$P$10,GERAL[Dia],"<=" &PROD_EQUIPE!$Q$10) -> 0 | L26: =IFERROR(D26/C26,"") | M26: =IFERROR(E26/C26,"") | N26: =IFERROR(F26/C26,"") | O26: =IFERROR(G26/C26,"") | P26: =IFERROR(SUM(F26:G26)/C26,"") | Q26: =IFERROR(SUM(D26:E26)/C26,"")
C27: =COUNTIFS(GERAL[Dia Útil],"SIM",GERAL[Equipe],PROD_EQUIPE!B27,GERAL[Dia],">=" &PROD_EQUIPE!$P$10,GERAL[Dia],"<=" &PROD_EQUIPE!$Q$10) -> 0 | D27: =SUMIFS(GERAL[LA],GERAL[Equipe],PROD_EQUIPE!B27,GERAL[Dia],">=" &PROD_EQUIPE!$P$10,GERAL[Dia],"<=" &PROD_EQUIPE!$Q$10) -> 0 | E27: =SUMIFS(GERAL[LE],GERAL[Equipe],PROD_EQUIPE!B27,GERAL[Dia],">=" &PROD_EQUIPE!$P$10,GERAL[Dia],"<=" &PROD_EQUIPE!$Q$10) -> 0 | F27: =SUMIFS(GERAL[PRA],GERAL[Equipe],PROD_EQUIPE!B27,GERAL[Dia],">=" &PROD_EQUIPE!$P$10,GERAL[Dia],"<=" &PROD_EQUIPE!$Q$10) -> 0 | G27: =SUMIFS(GERAL[PRE],GERAL[Equipe],PROD_EQUIPE!B27,GERAL[Dia],">=" &PROD_EQUIPE!$P$10,GERAL[Dia],"<=" &PROD_EQUIPE!$Q$10) -> 0 | H27: =SUMIFS(GERAL[PV''s],GERAL[Equipe],PROD_EQUIPE!B27,GERAL[Dia],">=" &PROD_EQUIPE!$P$10,GERAL[Dia],"<=" &PROD_EQUIPE!$Q$10) -> 0 | I27: =SUMIFS(GERAL[LIE],GERAL[Equipe],PROD_EQUIPE!B27,GERAL[Dia],">=" &PROD_EQUIPE!$P$10,GERAL[Dia],"<=" &PROD_EQUIPE!$Q$10) -> 0 | J27: =SUMIFS(GERAL[LIA],GERAL[Equipe],PROD_EQUIPE!B27,GERAL[Dia],">=" &PROD_EQUIPE!$P$10,GERAL[Dia],"<=" &PROD_EQUIPE!$Q$10) -> 0 | K27: =SUMIFS(GERAL[IHM],GERAL[Equipe],PROD_EQUIPE!B27,GERAL[Dia],">=" &PROD_EQUIPE!$P$10,GERAL[Dia],"<=" &PROD_EQUIPE!$Q$10) -> 0 | L27: =IFERROR(D27/C27,"") | M27: =IFERROR(E27/C27,"") | N27: =IFERROR(F27/C27,"") | O27: =IFERROR(G27/C27,"") | P27: =IFERROR(SUM(F27:G27)/C27,"") | Q27: =IFERROR(SUM(D27:E27)/C27,"")
C28: =COUNTIFS(GERAL[Dia Útil],"SIM",GERAL[Equipe],PROD_EQUIPE!B28,GERAL[Dia],">=" &PROD_EQUIPE!$P$10,GERAL[Dia],"<=" &PROD_EQUIPE!$Q$10) -> 0 | D28: =SUMIFS(GERAL[LA],GERAL[Equipe],PROD_EQUIPE!B28,GERAL[Dia],">=" &PROD_EQUIPE!$P$10,GERAL[Dia],"<=" &PROD_EQUIPE!$Q$10) -> 0 | E28: =SUMIFS(GERAL[LE],GERAL[Equipe],PROD_EQUIPE!B28,GERAL[Dia],">=" &PROD_EQUIPE!$P$10,GERAL[Dia],"<=" &PROD_EQUIPE!$Q$10) -> 0 | F28: =SUMIFS(GERAL[PRA],GERAL[Equipe],PROD_EQUIPE!B28,GERAL[Dia],">=" &PROD_EQUIPE!$P$10,GERAL[Dia],"<=" &PROD_EQUIPE!$Q$10) -> 0 | G28: =SUMIFS(GERAL[PRE],GERAL[Equipe],PROD_EQUIPE!B28,GERAL[Dia],">=" &PROD_EQUIPE!$P$10,GERAL[Dia],"<=" &PROD_EQUIPE!$Q$10) -> 0 | H28: =SUMIFS(GERAL[PV''s],GERAL[Equipe],PROD_EQUIPE!B28,GERAL[Dia],">=" &PROD_EQUIPE!$P$10,GERAL[Dia],"<=" &PROD_EQUIPE!$Q$10) -> 0 | I28: =SUMIFS(GERAL[LIE],GERAL[Equipe],PROD_EQUIPE!B28,GERAL[Dia],">=" &PROD_EQUIPE!$P$10,GERAL[Dia],"<=" &PROD_EQUIPE!$Q$10) -> 0 | J28: =SUMIFS(GERAL[LIA],GERAL[Equipe],PROD_EQUIPE!B28,GERAL[Dia],">=" &PROD_EQUIPE!$P$10,GERAL[Dia],"<=" &PROD_EQUIPE!$Q$10) -> 0 | K28: =SUMIFS(GERAL[IHM],GERAL[Equipe],PROD_EQUIPE!B28,GERAL[Dia],">=" &PROD_EQUIPE!$P$10,GERAL[Dia],"<=" &PROD_EQUIPE!$Q$10) -> 0 | L28: =IFERROR(D28/C28,"") | M28: =IFERROR(E28/C28,"") | N28: =IFERROR(F28/C28,"") | O28: =IFERROR(G28/C28,"") | P28: =IFERROR(SUM(F28:G28)/C28,"") | Q28: =IFERROR(SUM(D28:E28)/C28,"")
C29: =COUNTIFS(GERAL[Dia Útil],"SIM",GERAL[Equipe],PROD_EQUIPE!B29,GERAL[Dia],">=" &PROD_EQUIPE!$P$10,GERAL[Dia],"<=" &PROD_EQUIPE!$Q$10) -> 0 | D29: =SUMIFS(GERAL[LA],GERAL[Equipe],PROD_EQUIPE!B29,GERAL[Dia],">=" &PROD_EQUIPE!$P$10,GERAL[Dia],"<=" &PROD_EQUIPE!$Q$10) -> 0 | E29: =SUMIFS(GERAL[LE],GERAL[Equipe],PROD_EQUIPE!B29,GERAL[Dia],">=" &PROD_EQUIPE!$P$10,GERAL[Dia],"<=" &PROD_EQUIPE!$Q$10) -> 0 | F29: =SUMIFS(GERAL[PRA],GERAL[Equipe],PROD_EQUIPE!B29,GERAL[Dia],">=" &PROD_EQUIPE!$P$10,GERAL[Dia],"<=" &PROD_EQUIPE!$Q$10) -> 0 | G29: =SUMIFS(GERAL[PRE],GERAL[Equipe],PROD_EQUIPE!B29,GERAL[Dia],">=" &PROD_EQUIPE!$P$10,GERAL[Dia],"<=" &PROD_EQUIPE!$Q$10) -> 0 | H29: =SUMIFS(GERAL[PV''s],GERAL[Equipe],PROD_EQUIPE!B29,GERAL[Dia],">=" &PROD_EQUIPE!$P$10,GERAL[Dia],"<=" &PROD_EQUIPE!$Q$10) -> 0 | I29: =SUMIFS(GERAL[LIE],GERAL[Equipe],PROD_EQUIPE!B29,GERAL[Dia],">=" &PROD_EQUIPE!$P$10,GERAL[Dia],"<=" &PROD_EQUIPE!$Q$10) -> 0 | J29: =SUMIFS(GERAL[LIA],GERAL[Equipe],PROD_EQUIPE!B29,GERAL[Dia],">=" &PROD_EQUIPE!$P$10,GERAL[Dia],"<=" &PROD_EQUIPE!$Q$10) -> 0 | K29: =SUMIFS(GERAL[IHM],GERAL[Equipe],PROD_EQUIPE!B29,GERAL[Dia],">=" &PROD_EQUIPE!$P$10,GERAL[Dia],"<=" &PROD_EQUIPE!$Q$10) -> 0 | L29: =IFERROR(D29/C29,"") | M29: =IFERROR(E29/C29,"") | N29: =IFERROR(F29/C29,"") | O29: =IFERROR(G29/C29,"") | P29: =IFERROR(SUM(F29:G29)/C29,"") | Q29: =IFERROR(SUM(D29:E29)/C29,"")
C30: =COUNTIFS(GERAL[Dia Útil],"SIM",GERAL[Equipe],PROD_EQUIPE!B30,GERAL[Dia],">=" &PROD_EQUIPE!$P$10,GERAL[Dia],"<=" &PROD_EQUIPE!$Q$10) -> 0 | D30: =SUMIFS(GERAL[LA],GERAL[Equipe],PROD_EQUIPE!B30,GERAL[Dia],">=" &PROD_EQUIPE!$P$10,GERAL[Dia],"<=" &PROD_EQUIPE!$Q$10) -> 0 | E30: =SUMIFS(GERAL[LE],GERAL[Equipe],PROD_EQUIPE!B30,GERAL[Dia],">=" &PROD_EQUIPE!$P$10,GERAL[Dia],"<=" &PROD_EQUIPE!$Q$10) -> 0 | F30: =SUMIFS(GERAL[PRA],GERAL[Equipe],PROD_EQUIPE!B30,GERAL[Dia],">=" &PROD_EQUIPE!$P$10,GERAL[Dia],"<=" &PROD_EQUIPE!$Q$10) -> 0 | G30: =SUMIFS(GERAL[PRE],GERAL[Equipe],PROD_EQUIPE!B30,GERAL[Dia],">=" &PROD_EQUIPE!$P$10,GERAL[Dia],"<=" &PROD_EQUIPE!$Q$10) -> 0 | H30: =SUMIFS(GERAL[PV''s],GERAL[Equipe],PROD_EQUIPE!B30,GERAL[Dia],">=" &PROD_EQUIPE!$P$10,GERAL[Dia],"<=" &PROD_EQUIPE!$Q$10) -> 0 | I30: =SUMIFS(GERAL[LIE],GERAL[Equipe],PROD_EQUIPE!B30,GERAL[Dia],">=" &PROD_EQUIPE!$P$10,GERAL[Dia],"<=" &PROD_EQUIPE!$Q$10) -> 0 | J30: =SUMIFS(GERAL[LIA],GERAL[Equipe],PROD_EQUIPE!B30,GERAL[Dia],">=" &PROD_EQUIPE!$P$10,GERAL[Dia],"<=" &PROD_EQUIPE!$Q$10) -> 0 | K30: =SUMIFS(GERAL[IHM],GERAL[Equipe],PROD_EQUIPE!B30,GERAL[Dia],">=" &PROD_EQUIPE!$P$10,GERAL[Dia],"<=" &PROD_EQUIPE!$Q$10) -> 0 | L30: =IFERROR(D30/C30,"") | M30: =IFERROR(E30/C30,"") | N30: =IFERROR(F30/C30,"") | O30: =IFERROR(G30/C30,"") | P30: =IFERROR(SUM(F30:G30)/C30,"") | Q30: =IFERROR(SUM(D30:E30)/C30,"")
C31: =COUNTIFS(GERAL[Dia Útil],"SIM",GERAL[Equipe],PROD_EQUIPE!B31,GERAL[Dia],">=" &PROD_EQUIPE!$P$10,GERAL[Dia],"<=" &PROD_EQUIPE!$Q$10) -> 0 | D31: =SUMIFS(GERAL[LA],GERAL[Equipe],PROD_EQUIPE!B31,GERAL[Dia],">=" &PROD_EQUIPE!$P$10,GERAL[Dia],"<=" &PROD_EQUIPE!$Q$10) -> 0 | E31: =SUMIFS(GERAL[LE],GERAL[Equipe],PROD_EQUIPE!B31,GERAL[Dia],">=" &PROD_EQUIPE!$P$10,GERAL[Dia],"<=" &PROD_EQUIPE!$Q$10) -> 0 | F31: =SUMIFS(GERAL[PRA],GERAL[Equipe],PROD_EQUIPE!B31,GERAL[Dia],">=" &PROD_EQUIPE!$P$10,GERAL[Dia],"<=" &PROD_EQUIPE!$Q$10) -> 0 | G31: =SUMIFS(GERAL[PRE],GERAL[Equipe],PROD_EQUIPE!B31,GERAL[Dia],">=" &PROD_EQUIPE!$P$10,GERAL[Dia],"<=" &PROD_EQUIPE!$Q$10) -> 0 | H31: =SUMIFS(GERAL[PV''s],GERAL[Equipe],PROD_EQUIPE!B31,GERAL[Dia],">=" &PROD_EQUIPE!$P$10,GERAL[Dia],"<=" &PROD_EQUIPE!$Q$10) -> 0 | I31: =SUMIFS(GERAL[LIE],GERAL[Equipe],PROD_EQUIPE!B31,GERAL[Dia],">=" &PROD_EQUIPE!$P$10,GERAL[Dia],"<=" &PROD_EQUIPE!$Q$10) -> 0 | J31: =SUMIFS(GERAL[LIA],GERAL[Equipe],PROD_EQUIPE!B31,GERAL[Dia],">=" &PROD_EQUIPE!$P$10,GERAL[Dia],"<=" &PROD_EQUIPE!$Q$10) -> 0 | K31: =SUMIFS(GERAL[IHM],GERAL[Equipe],PROD_EQUIPE!B31,GERAL[Dia],">=" &PROD_EQUIPE!$P$10,GERAL[Dia],"<=" &PROD_EQUIPE!$Q$10) -> 0 | L31: =IFERROR(D31/C31,"") | M31: =IFERROR(E31/C31,"") | N31: =IFERROR(F31/C31,"") | O31: =IFERROR(G31/C31,"") | P31: =IFERROR(SUM(F31:G31)/C31,"") | Q31: =IFERROR(SUM(D31:E31)/C31,"")
... C33: =COUNTIFS(GERAL[Dia Útil],"SIM",GERAL[Equipe],PROD_EQUIPE!B33,GERAL[Dia],">=" &PROD_EQUIPE!$P$10,GERAL[Dia],"<=" &PROD_EQUIPE!$Q$10) -> 0 | D33: =SUMIFS(GERAL[LA],GERAL[Equipe],PROD_EQUIPE!B33,GERAL[Dia],">=" &PROD_EQUIPE!$P$10,GERAL[Dia],"<=" &PROD_EQUIPE!$Q$10) -> 0 | E33: =SUMIFS(GERAL[LE],GERAL[Equipe],PROD_EQUIPE!B33,GERAL[Dia],">=" &PROD_EQUIPE!$P$10,GERAL[Dia],"<=" &PROD_EQUIPE!$Q$10) -> 0 | F33: =SUMIFS(GERAL[PRA],GERAL[Equipe],PROD_EQUIPE!B33,GERAL[Dia],">=" &PROD_EQUIPE!$P$10,GERAL[Dia],"<=" &PROD_EQUIPE!$Q$10) -> 0 | G33: =SUMIFS(GERAL[PRE],GERAL[Equipe],PROD_EQUIPE!B33,GERAL[Dia],">=" &PROD_EQUIPE!$P$10,GERAL[Dia],"<=" &PROD_EQUIPE!$Q$10) -> 0 | H33: =SUMIFS(GERAL[PV''s],GERAL[Equipe],PROD_EQUIPE!B33,GERAL[Dia],">=" &PROD_EQUIPE!$P$10,GERAL[Dia],"<=" &PROD_EQUIPE!$Q$10) -> 0 | I33: =SUMIFS(GERAL[LIE],GERAL[Equipe],PROD_EQUIPE!B33,GERAL[Dia],">=" &PROD_EQUIPE!$P$10,GERAL[Dia],"<=" &PROD_EQUIPE!$Q$10) -> 0 | J33: =SUMIFS(GERAL[LIA],GERAL[Equipe],PROD_EQUIPE!B33,GERAL[Dia],">=" &PROD_EQUIPE!$P$10,GERAL[Dia],"<=" &PROD_EQUIPE!$Q$10) -> 0 | K33: =SUMIFS(GERAL[IHM],GERAL[Equipe],PROD_EQUIPE!B33,GERAL[Dia],">=" &PROD_EQUIPE!$P$10,GERAL[Dia],"<=" &PROD_EQUIPE!$Q$10) -> 0 | L33: =IFERROR(D33/C33,"") | M33: =IFERROR(E33/C33,"") | N33: =IFERROR(F33/C33,"") | O33: =IFERROR(G33/C33,"") | P33: =IFERROR(SUM(F33:G33)/C33,"") | Q33: =IFERROR(SUM(D33:E33)/C33,"")

Sheet PROD_NÚCLEO
R2: Informar período
E3: SE LIGA NA REDE - SANTOS
E4: PRODUÇÃO POR NÚCLEO - RUA
J7: PRODUTIVIDADE MÉDIA | L7: =IFERROR(AVERAGE(L14:L46),"") -> 0.57727938 | M7: =IFERROR(AVERAGE(M14:M46),"") -> 1.7684503 | N7: =IFERROR(AVERAGE(N14:N46),"") -> 2.8331813 | O7: =IFERROR(AVERAGE(O14:O46),"") -> 1.7282698 | P7: =IFERROR(AVERAGE(P14:P46),"") -> 4.5614511 | Q7: =IFERROR(AVERAGE(Q14:Q46),"") -> 2.3457297
J8: MÉDIA INTERNA | L8: {=IFERROR(TRIMMEAN(IF(L14:L46>0.01,L14:L46),40%),"")} -> 1.876158 | M8: {=IFERROR(TRIMMEAN(IF(M14:M46>0.01,M14:M46),40%),"")} -> 1.8946937 | N8: {=IFERROR(TRIMMEAN(IF(N14:N46>0.01,N14:N46),40%),"")} -> 7.1111111 | O8: {=IFERROR(TRIMMEAN(IF(O14:O46>0.01,O14:O46),40%),"")} -> 2.5582492 | P8: {=IFERROR(TRIMMEAN(IF(P14:P46>0.01,P14:P46),40%),"")} -> 5.9992167 | Q8: {=IFERROR(TRIMMEAN(IF(Q14:Q46>0.01,Q14:Q46),40%),"")} -> 2.1799027
P10: DE | Q10: ATÉ
O11: PERÍODO | P11: 46052 | Q11: =TODAY()-1 -> 46135
C12: =SUM(C14:C996) -> 127 | D12: =SUM(D14:D996) -> 160 | E12: =SUM(E14:E996) -> 144 | F12: =SUM(F14:F996) -> 747 | G12: =SUM(G14:G996) -> 244 | H12: =SUM(H14:H996) -> 27 | I12: =SUM(I14:I996) -> 28 | J12: =SUM(J14:J996) -> 274 | K12: =SUM(K14:K996) -> 72
B13: RUA | C13: DIAS ÚTEIS | D13: LA | E13: LE | F13: PRA | G13: PRE | H13: PV's | I13: LIE | J13: LIA | K13: IHM | L13: Ind. Prod. LA | M13: Ind Prod LE | N13: Ind Prod PRA | O13: Ind Prod PRE | P13: IND. PROD REDE | Q13: IND. PROD LIG
B14: BECO 10 | C14: =COUNTIFS(GERAL[Dia Útil],"SIM",GERAL[Rua],B14,GERAL[Dia],">=" &$P$11,GERAL[Dia],"<=" &$Q$11) -> 6 | D14: =SUMIFS(GERAL[LA],GERAL[Rua],B14,GERAL[Dia],">=" &$P$11,GERAL[Dia],"<=" &$Q$11) -> 0 | E14: =SUMIFS(GERAL[LE],GERAL[Rua],B14,GERAL[Dia],">=" &$P$11,GERAL[Dia],"<=" &$Q$11) -> 4 | F14: =SUMIFS(GERAL[PRA],GERAL[Rua],B14,GERAL[Dia],">=" &$P$11,GERAL[Dia],"<=" &$Q$11) -> 0 | G14: =SUMIFS(GERAL[PRE],GERAL[Rua],B14,GERAL[Dia],">=" &$P$11,GERAL[Dia],"<=" &$Q$11) -> 26 | H14: =SUMIFS(GERAL[PV''s],GERAL[Rua],B14,GERAL[Dia],">=" &$P$11,GERAL[Dia],"<=" &$Q$11) -> 0 | I14: =SUMIFS(GERAL[LIE],GERAL[Rua],B14,GERAL[Dia],">=" &$P$11,GERAL[Dia],"<=" &$Q$11) -> 0 | J14: =SUMIFS(GERAL[LIA],GERAL[Rua],B14,GERAL[Dia],">=" &$P$11,GERAL[Dia],"<=" &$Q$11) -> 0 | K14: =SUMIFS(GERAL[IHM],GERAL[Rua],B14,GERAL[Dia],">=" &$P$11,GERAL[Dia],"<=" &$Q$11) -> 0 | L14: =IFERROR(D14/C14,"") -> 0 | M14: =IFERROR(E14/C14,"") -> 0.66666667 | N14: =IFERROR(F14/C14,"") -> 0 | O14: =IFERROR(G14/C14,"") -> 4.3333333 | P14: =IFERROR(SUM(F14:G14)/C14,"") -> 4.3333333 | Q14: =IFERROR(SUM(D14:E14)/C14,"") -> 0.66666667
B15: BECO 11 | C15: =COUNTIFS(GERAL[Dia Útil],"SIM",GERAL[Rua],B15,GERAL[Dia],">=" &$P$11,GERAL[Dia],"<=" &$Q$11) -> 9 | D15: =SUMIFS(GERAL[LA],GERAL[Rua],B15,GERAL[Dia],">=" &$P$11,GERAL[Dia],"<=" &$Q$11) -> 7 | E15: =SUMIFS(GERAL[LE],GERAL[Rua],B15,GERAL[Dia],">=" &$P$11,GERAL[Dia],"<=" &$Q$11) -> 14 | F15: =SUMIFS(GERAL[PRA],GERAL[Rua],B15,GERAL[Dia],">=" &$P$11,GERAL[Dia],"<=" &$Q$11) -> 60 | G15: =SUMIFS(GERAL[PRE],GERAL[Rua],B15,GERAL[Dia],">=" &$P$11,GERAL[Dia],"<=" &$Q$11) -> 17 | H15: =SUMIFS(GERAL[PV''s],GERAL[Rua],B15,GERAL[Dia],">=" &$P$11,GERAL[Dia],"<=" &$Q$11) -> 2 | I15: =SUMIFS(GERAL[LIE],GERAL[Rua],B15,GERAL[Dia],">=" &$P$11,GERAL[Dia],"<=" &$Q$11) -> 0 | J15: =SUMIFS(GERAL[LIA],GERAL[Rua],B15,GERAL[Dia],">=" &$P$11,GERAL[Dia],"<=" &$Q$11) -> 0 | K15: =SUMIFS(GERAL[IHM],GERAL[Rua],B15,GERAL[Dia],">=" &$P$11,GERAL[Dia],"<=" &$Q$11) -> 0 | L15: =IFERROR(D15/C15,"") -> 0.77777778 | M15: =IFERROR(E15/C15,"") -> 1.5555556 | N15: =IFERROR(F15/C15,"") -> 6.6666667 | O15: =IFERROR(G15/C15,"") -> 1.8888889 | P15: =IFERROR(SUM(F15:G15)/C15,"") -> 8.5555556 | Q15: =IFERROR(SUM(D15:E15)/C15,"") -> 2.3333333
B16: BECO 11 | C16: =COUNTIFS(GERAL[Dia Útil],"SIM",GERAL[Rua],B16,GERAL[Dia],">=" &$P$11,GERAL[Dia],"<=" &$Q$11) -> 2 | D16: =SUMIFS(GERAL[LA],GERAL[Rua],B16,GERAL[Dia],">=" &$P$11,GERAL[Dia],"<=" &$Q$11) -> 0 | E16: =SUMIFS(GERAL[LE],GERAL[Rua],B16,GERAL[Dia],">=" &$P$11,GERAL[Dia],"<=" &$Q$11) -> 3 | F16: =SUMIFS(GERAL[PRA],GERAL[Rua],B16,GERAL[Dia],">=" &$P$11,GERAL[Dia],"<=" &$Q$11) -> 0 | G16: =SUMIFS(GERAL[PRE],GERAL[Rua],B16,GERAL[Dia],">=" &$P$11,GERAL[Dia],"<=" &$Q$11) -> 6 | H16: =SUMIFS(GERAL[PV''s],GERAL[Rua],B16,GERAL[Dia],">=" &$P$11,GERAL[Dia],"<=" &$Q$11) -> 0 | I16: =SUMIFS(GERAL[LIE],GERAL[Rua],B16,GERAL[Dia],">=" &$P$11,GERAL[Dia],"<=" &$Q$11) -> 0 | J16: =SUMIFS(GERAL[LIA],GERAL[Rua],B16,GERAL[Dia],">=" &$P$11,GERAL[Dia],"<=" &$Q$11) -> 0 | K16: =SUMIFS(GERAL[IHM],GERAL[Rua],B16,GERAL[Dia],">=" &$P$11,GERAL[Dia],"<=" &$Q$11) -> 0 | L16: =IFERROR(D16/C16,"") -> 0 | M16: =IFERROR(E16/C16,"") -> 1.5 | N16: =IFERROR(F16/C16,"") -> 0 | O16: =IFERROR(G16/C16,"") -> 3 | P16: =IFERROR(SUM(F16:G16)/C16,"") -> 3 | Q16: =IFERROR(SUM(D16:E16)/C16,"") -> 1.5
B17: BECO 12 | C17: =COUNTIFS(GERAL[Dia Útil],"SIM",GERAL[Rua],B17,GERAL[Dia],">=" &$P$11,GERAL[Dia],"<=" &$Q$11) -> 3 | D17: =SUMIFS(GERAL[LA],GERAL[Rua],B17,GERAL[Dia],">=" &$P$11,GERAL[Dia],"<=" &$Q$11) -> 0 | E17: =SUMIFS(GERAL[LE],GERAL[Rua],B17,GERAL[Dia],">=" &$P$11,GERAL[Dia],"<=" &$Q$11) -> 7 | F17: =SUMIFS(GERAL[PRA],GERAL[Rua],B17,GERAL[Dia],">=" &$P$11,GERAL[Dia],"<=" &$Q$11) -> 0 | G17: =SUMIFS(GERAL[PRE],GERAL[Rua],B17,GERAL[Dia],">=" &$P$11,GERAL[Dia],"<=" &$Q$11) -> 3 | H17: =SUMIFS(GERAL[PV''s],GERAL[Rua],B17,GERAL[Dia],">=" &$P$11,GERAL[Dia],"<=" &$Q$11) -> 2 | I17: =SUMIFS(GERAL[LIE],GERAL[Rua],B17,GERAL[Dia],">=" &$P$11,GERAL[Dia],"<=" &$Q$11) -> 0 | J17: =SUMIFS(GERAL[LIA],GERAL[Rua],B17,GERAL[Dia],">=" &$P$11,GERAL[Dia],"<=" &$Q$11) -> 0 | K17: =SUMIFS(GERAL[IHM],GERAL[Rua],B17,GERAL[Dia],">=" &$P$11,GERAL[Dia],"<=" &$Q$11) -> 0 | L17: =IFERROR(D17/C17,"") -> 0 | M17: =IFERROR(E17/C17,"") -> 2.3333333 | N17: =IFERROR(F17/C17,"") -> 0 | O17: =IFERROR(G17/C17,"") -> 1 | P17: =IFERROR(SUM(F17:G17)/C17,"") -> 1 | Q17: =IFERROR(SUM(D17:E17)/C17,"") -> 2.3333333
B18: BECO 14 | C18: =COUNTIFS(GERAL[Dia Útil],"SIM",GERAL[Rua],B18,GERAL[Dia],">=" &$P$11,GERAL[Dia],"<=" &$Q$11) -> 7 | D18: =SUMIFS(GERAL[LA],GERAL[Rua],B18,GERAL[Dia],">=" &$P$11,GERAL[Dia],"<=" &$Q$11) -> 0 | E18: =SUMIFS(GERAL[LE],GERAL[Rua],B18,GERAL[Dia],">=" &$P$11,GERAL[Dia],"<=" &$Q$11) -> 17 | F18: =SUMIFS(GERAL[PRA],GERAL[Rua],B18,GERAL[Dia],">=" &$P$11,GERAL[Dia],"<=" &$Q$11) -> 56 | G18: =SUMIFS(GERAL[PRE],GERAL[Rua],B18,GERAL[Dia],">=" &$P$11,GERAL[Dia],"<=" &$Q$11) -> 6 | H18: =SUMIFS(GERAL[PV''s],GERAL[Rua],B18,GERAL[Dia],">=" &$P$11,GERAL[Dia],"<=" &$Q$11) -> 1 | I18: =SUMIFS(GERAL[LIE],GERAL[Rua],B18,GERAL[Dia],">=" &$P$11,GERAL[Dia],"<=" &$Q$11) -> 0 | J18: =SUMIFS(GERAL[LIA],GERAL[Rua],B18,GERAL[Dia],">=" &$P$11,GERAL[Dia],"<=" &$Q$11) -> 0 | K18: =SUMIFS(GERAL[IHM],GERAL[Rua],B18,GERAL[Dia],">=" &$P$11,GERAL[Dia],"<=" &$Q$11) -> 0 | L18: =IFERROR(D18/C18,"") -> 0 | M18: =IFERROR(E18/C18,"") -> 2.4285714 | N18: =IFERROR(F18/C18,"") -> 8 | O18: =IFERROR(G18/C18,"") -> 0.85714286 | P18: =IFERROR(SUM(F18:G18)/C18,"") -> 8.8571429 | Q18: =IFERROR(SUM(D18:E18)/C18,"") -> 2.4285714
B19: BECO 16 | C19: =COUNTIFS(GERAL[Dia Útil],"SIM",GERAL[Rua],B19,GERAL[Dia],">=" &$P$11,GERAL[Dia],"<=" &$Q$11) -> 11 | D19: =SUMIFS(GERAL[LA],GERAL[Rua],B19,GERAL[Dia],">=" &$P$11,GERAL[Dia],"<=" &$Q$11) -> 0 | E19: =SUMIFS(GERAL[LE],GERAL[Rua],B19,GERAL[Dia],">=" &$P$11,GERAL[Dia],"<=" &$Q$11) -> 28 | F19: =SUMIFS(GERAL[PRA],GERAL[Rua],B19,GERAL[Dia],">=" &$P$11,GERAL[Dia],"<=" &$Q$11) -> 60 | G19: =SUMIFS(GERAL[PRE],GERAL[Rua],B19,GERAL[Dia],">=" &$P$11,GERAL[Dia],"<=" &$Q$11) -> 30 | H19: =SUMIFS(GERAL[PV''s],GERAL[Rua],B19,GERAL[Dia],">=" &$P$11,GERAL[Dia],"<=" &$Q$11) -> 3 | I19: =SUMIFS(GERAL[LIE],GERAL[Rua],B19,GERAL[Dia],">=" &$P$11,GERAL[Dia],"<=" &$Q$11) -> 0 | J19: =SUMIFS(GERAL[LIA],GERAL[Rua],B19,GERAL[Dia],">=" &$P$11,GERAL[Dia],"<=" &$Q$11) -> 0 | K19: =SUMIFS(GERAL[IHM],GERAL[Rua],B19,GERAL[Dia],">=" &$P$11,GERAL[Dia],"<=" &$Q$11) -> 0 | L19: =IFERROR(D19/C19,"") -> 0 | M19: =IFERROR(E19/C19,"") -> 2.5454545 | N19: =IFERROR(F19/C19,"") -> 5.4545455 | O19: =IFERROR(G19/C19,"") -> 2.7272727 | P19: =IFERROR(SUM(F19:G19)/C19,"") -> 8.1818182 | Q19: =IFERROR(SUM(D19:E19)/C19,"") -> 2.5454545
B20: BECO 17 | C20: =COUNTIFS(GERAL[Dia Útil],"SIM",GERAL[Rua],B20,GERAL[Dia],">=" &$P$11,GERAL[Dia],"<=" &$Q$11) -> 1 | D20: =SUMIFS(GERAL[LA],GERAL[Rua],B20,GERAL[Dia],">=" &$P$11,GERAL[Dia],"<=" &$Q$11) -> 0 | E20: =SUMIFS(GERAL[LE],GERAL[Rua],B20,GERAL[Dia],">=" &$P$11,GERAL[Dia],"<=" &$Q$11) -> 2 | F20: =SUMIFS(GERAL[PRA],GERAL[Rua],B20,GERAL[Dia],">=" &$P$11,GERAL[Dia],"<=" &$Q$11) -> 0 | G20: =SUMIFS(GERAL[PRE],GERAL[Rua],B20,GERAL[Dia],">=" &$P$11,GERAL[Dia],"<=" &$Q$11) -> 0 | H20: =SUMIFS(GERAL[PV''s],GERAL[Rua],B20,GERAL[Dia],">=" &$P$11,GERAL[Dia],"<=" &$Q$11) -> 0 | I20: =SUMIFS(GERAL[LIE],GERAL[Rua],B20,GERAL[Dia],">=" &$P$11,GERAL[Dia],"<=" &$Q$11) -> 0 | J20: =SUMIFS(GERAL[LIA],GERAL[Rua],B20,GERAL[Dia],">=" &$P$11,GERAL[Dia],"<=" &$Q$11) -> 0 | K20: =SUMIFS(GERAL[IHM],GERAL[Rua],B20,GERAL[Dia],">=" &$P$11,GERAL[Dia],"<=" &$Q$11) -> 0 | L20: =IFERROR(D20/C20,"") -> 0 | M20: =IFERROR(E20/C20,"") -> 2 | N20: =IFERROR(F20/C20,"") -> 0 | O20: =IFERROR(G20/C20,"") -> 0 | P20: =IFERROR(SUM(F20:G20)/C20,"") -> 0 | Q20: =IFERROR(SUM(D20:E20)/C20,"") -> 2
B21: BECO 17 | C21: =COUNTIFS(GERAL[Dia Útil],"SIM",GERAL[Rua],B21,GERAL[Dia],">=" &$P$11,GERAL[Dia],"<=" &$Q$11) -> 5 | D21: =SUMIFS(GERAL[LA],GERAL[Rua],B21,GERAL[Dia],">=" &$P$11,GERAL[Dia],"<=" &$Q$11) -> 0 | E21: =SUMIFS(GERAL[LE],GERAL[Rua],B21,GERAL[Dia],">=" &$P$11,GERAL[Dia],"<=" &$Q$11) -> 12 | F21: =SUMIFS(GERAL[PRA],GERAL[Rua],B21,GERAL[Dia],">=" &$P$11,GERAL[Dia],"<=" &$Q$11) -> 0 | G21: =SUMIFS(GERAL[PRE],GERAL[Rua],B21,GERAL[Dia],">=" &$P$11,GERAL[Dia],"<=" &$Q$11) -> 12 | H21: =SUMIFS(GERAL[PV''s],GERAL[Rua],B21,GERAL[Dia],">=" &$P$11,GERAL[Dia],"<=" &$Q$11) -> 0 | I21: =SUMIFS(GERAL[LIE],GERAL[Rua],B21,GERAL[Dia],">=" &$P$11,GERAL[Dia],"<=" &$Q$11) -> 0 | J21: =SUMIFS(GERAL[LIA],GERAL[Rua],B21,GERAL[Dia],">=" &$P$11,GERAL[Dia],"<=" &$Q$11) -> 0 | K21: =SUMIFS(GERAL[IHM],GERAL[Rua],B21,GERAL[Dia],">=" &$P$11,GERAL[Dia],"<=" &$Q$11) -> 0 | L21: =IFERROR(D21/C21,"") -> 0 | M21: =IFERROR(E21/C21,"") -> 2.4 | N21: =IFERROR(F21/C21,"") -> 0 | O21: =IFERROR(G21/C21,"") -> 2.4 | P21: =IFERROR(SUM(F21:G21)/C21,"") -> 2.4 | Q21: =IFERROR(SUM(D21:E21)/C21,"") -> 2.4
B22: BECO 3 | C22: =COUNTIFS(GERAL[Dia Útil],"SIM",GERAL[Rua],B22,GERAL[Dia],">=" &$P$11,GERAL[Dia],"<=" &$Q$11) -> 5 | D22: =SUMIFS(GERAL[LA],GERAL[Rua],B22,GERAL[Dia],">=" &$P$11,GERAL[Dia],"<=" &$Q$11) -> 11 | E22: =SUMIFS(GERAL[LE],GERAL[Rua],B22,GERAL[Dia],">=" &$P$11,GERAL[Dia],"<=" &$Q$11) -> 12 | F22: =SUMIFS(GERAL[PRA],GERAL[Rua],B22,GERAL[Dia],">=" &$P$11,GERAL[Dia],"<=" &$Q$11) -> 0 | G22: =SUMIFS(GERAL[PRE],GERAL[Rua],B22,GERAL[Dia],">=" &$P$11,GERAL[Dia],"<=" &$Q$11) -> 0 | H22: =SUMIFS(GERAL[PV''s],GERAL[Rua],B22,GERAL[Dia],">=" &$P$11,GERAL[Dia],"<=" &$Q$11) -> 0 | I22: =SUMIFS(GERAL[LIE],GERAL[Rua],B22,GERAL[Dia],">=" &$P$11,GERAL[Dia],"<=" &$Q$11) -> 0 | J22: =SUMIFS(GERAL[LIA],GERAL[Rua],B22,GERAL[Dia],">=" &$P$11,GERAL[Dia],"<=" &$Q$11) -> 0 | K22: =SUMIFS(GERAL[IHM],GERAL[Rua],B22,GERAL[Dia],">=" &$P$11,GERAL[Dia],"<=" &$Q$11) -> 15 | L22: =IFERROR(D22/C22,"") -> 2.2 | M22: =IFERROR(E22/C22,"") -> 2.4 | N22: =IFERROR(F22/C22,"") -> 0 | O22: =IFERROR(G22/C22,"") -> 0 | P22: =IFERROR(SUM(F22:G22)/C22,"") -> 0 | Q22: =IFERROR(SUM(D22:E22)/C22,"") -> 4.6
B23: BECO 8 | C23: =COUNTIFS(GERAL[Dia Útil],"SIM",GERAL[Rua],B23,GERAL[Dia],">=" &$P$11,GERAL[Dia],"<=" &$Q$11) -> 1 | D23: =SUMIFS(GERAL[LA],GERAL[Rua],B23,GERAL[Dia],">=" &$P$11,GERAL[Dia],"<=" &$Q$11) -> 0 | E23: =SUMIFS(GERAL[LE],GERAL[Rua],B23,GERAL[Dia],">=" &$P$11,GERAL[Dia],"<=" &$Q$11) -> 1 | F23: =SUMIFS(GERAL[PRA],GERAL[Rua],B23,GERAL[Dia],">=" &$P$11,GERAL[Dia],"<=" &$Q$11) -> 0 | G23: =SUMIFS(GERAL[PRE],GERAL[Rua],B23,GERAL[Dia],">=" &$P$11,GERAL[Dia],"<=" &$Q$11) -> 0 | H23: =SUMIFS(GERAL[PV''s],GERAL[Rua],B23,GERAL[Dia],">=" &$P$11,GERAL[Dia],"<=" &$Q$11) -> 0 | I23: =SUMIFS(GERAL[LIE],GERAL[Rua],B23,GERAL[Dia],">=" &$P$11,GERAL[Dia],"<=" &$Q$11) -> 0 | J23: =SUMIFS(GERAL[LIA],GERAL[Rua],B23,GERAL[Dia],">=" &$P$11,GERAL[Dia],"<=" &$Q$11) -> 0 | K23: =SUMIFS(GERAL[IHM],GERAL[Rua],B23,GERAL[Dia],">=" &$P$11,GERAL[Dia],"<=" &$Q$11) -> 0 | L23: =IFERROR(D23/C23,"") -> 0 | M23: =IFERROR(E23/C23,"") -> 1 | N23: =IFERROR(F23/C23,"") -> 0 | O23: =IFERROR(G23/C23,"") -> 0 | P23: =IFERROR(SUM(F23:G23)/C23,"") -> 0 | Q23: =IFERROR(SUM(D23:E23)/C23,"") -> 1
B24: BECO 9 | C24: =COUNTIFS(GERAL[Dia Útil],"SIM",GERAL[Rua],B24,GERAL[Dia],">=" &$P$11,GERAL[Dia],"<=" &$Q$11) -> 3 | D24: =SUMIFS(GERAL[LA],GERAL[Rua],B24,GERAL[Dia],">=" &$P$11,GERAL[Dia],"<=" &$Q$11) -> 0 | E24: =SUMIFS(GERAL[LE],GERAL[Rua],B24,GERAL[Dia],">=" &$P$11,GERAL[Dia],"<=" &$Q$11) -> 8 | F24: =SUMIFS(GERAL[PRA],GERAL[Rua],B24,GERAL[Dia],">=" &$P$11,GERAL[Dia],"<=" &$Q$11) -> 0 | G24: =SUMIFS(GERAL[PRE],GERAL[Rua],B24,GERAL[Dia],">=" &$P$11,GERAL[Dia],"<=" &$Q$11) -> 0 | H24: =SUMIFS(GERAL[PV''s],GERAL[Rua],B24,GERAL[Dia],">=" &$P$11,GERAL[Dia],"<=" &$Q$11) -> 0 | I24: =SUMIFS(GERAL[LIE],GERAL[Rua],B24,GERAL[Dia],">=" &$P$11,GERAL[Dia],"<=" &$Q$11) -> 0 | J24: =SUMIFS(GERAL[LIA],GERAL[Rua],B24,GERAL[Dia],">=" &$P$11,GERAL[Dia],"<=" &$Q$11) -> 0 | K24: =SUMIFS(GERAL[IHM],GERAL[Rua],B24,GERAL[Dia],">=" &$P$11,GERAL[Dia],"<=" &$Q$11) -> 0 | L24: =IFERROR(D24/C24,"") -> 0 | M24: =IFERROR(E24/C24,"") -> 2.6666667 | N24: =IFERROR(F24/C24,"") -> 0 | O24: =IFERROR(G24/C24,"") -> 0 | P24: =IFERROR(SUM(F24:G24)/C24,"") -> 0 | Q24: =IFERROR(SUM(D24:E24)/C24,"") -> 2.6666667
B25: CHUVA | C25: =COUNTIFS(GERAL[Dia Útil],"SIM",GERAL[Rua],B25,GERAL[Dia],">=" &$P$11,GERAL[Dia],"<=" &$Q$11) -> 0 | D25: =SUMIFS(GERAL[LA],GERAL[Rua],B25,GERAL[Dia],">=" &$P$11,GERAL[Dia],"<=" &$Q$11) -> 0 | E25: =SUMIFS(GERAL[LE],GERAL[Rua],B25,GERAL[Dia],">=" &$P$11,GERAL[Dia],"<=" &$Q$11) -> 0 | F25: =SUMIFS(GERAL[PRA],GERAL[Rua],B25,GERAL[Dia],">=" &$P$11,GERAL[Dia],"<=" &$Q$11) -> 0 | G25: =SUMIFS(GERAL[PRE],GERAL[Rua],B25,GERAL[Dia],">=" &$P$11,GERAL[Dia],"<=" &$Q$11) -> 0 | H25: =SUMIFS(GERAL[PV''s],GERAL[Rua],B25,GERAL[Dia],">=" &$P$11,GERAL[Dia],"<=" &$Q$11) -> 0 | I25: =SUMIFS(GERAL[LIE],GERAL[Rua],B25,GERAL[Dia],">=" &$P$11,GERAL[Dia],"<=" &$Q$11) -> 0 | J25: =SUMIFS(GERAL[LIA],GERAL[Rua],B25,GERAL[Dia],">=" &$P$11,GERAL[Dia],"<=" &$Q$11) -> 0 | K25: =SUMIFS(GERAL[IHM],GERAL[Rua],B25,GERAL[Dia],">=" &$P$11,GERAL[Dia],"<=" &$Q$11) -> 0 | L25: =IFERROR(D25/C25,"") | M25: =IFERROR(E25/C25,"") | N25: =IFERROR(F25/C25,"") | O25: =IFERROR(G25/C25,"") | P25: =IFERROR(SUM(F25:G25)/C25,"") | Q25: =IFERROR(SUM(D25:E25)/C25,"")
... B28: (vazio) | C28: =COUNTIFS(GERAL[Dia Útil],"SIM",GERAL[Rua],B28,GERAL[Dia],">=" &$P$11,GERAL[Dia],"<=" &$Q$11) -> 0 | D28: =SUMIFS(GERAL[LA],GERAL[Rua],B28,GERAL[Dia],">=" &$P$11,GERAL[Dia],"<=" &$Q$11) -> 0 | E28: =SUMIFS(GERAL[LE],GERAL[Rua],B28,GERAL[Dia],">=" &$P$11,GERAL[Dia],"<=" &$Q$11) -> 0 | F28: =SUMIFS(GERAL[PRA],GERAL[Rua],B28,GERAL[Dia],">=" &$P$11,GERAL[Dia],"<=" &$Q$11) -> 0 | G28: =SUMIFS(GERAL[PRE],GERAL[Rua],B28,GERAL[Dia],">=" &$P$11,GERAL[Dia],"<=" &$Q$11) -> 0 | H28: =SUMIFS(GERAL[PV''s],GERAL[Rua],B28,GERAL[Dia],">=" &$P$11,GERAL[Dia],"<=" &$Q$11) -> 0 | I28: =SUMIFS(GERAL[LIE],GERAL[Rua],B28,GERAL[Dia],">=" &$P$11,GERAL[Dia],"<=" &$Q$11) -> 0 | J28: =SUMIFS(GERAL[LIA],GERAL[Rua],B28,GERAL[Dia],">=" &$P$11,GERAL[Dia],"<=" &$Q$11) -> 0 | K28: =SUMIFS(GERAL[IHM],GERAL[Rua],B28,GERAL[Dia],">=" &$P$11,GERAL[Dia],"<=" &$Q$11) -> 0 | L28: =IFERROR(D28/C28,"") | M28: =IFERROR(E28/C28,"") | N28: =IFERROR(F28/C28,"") | O28: =IFERROR(G28/C28,"") | P28: =IFERROR(SUM(F28:G28)/C28,"") | Q28: =IFERROR(SUM(D28:E28)/C28,"")
C29: =COUNTIFS(GERAL[Dia Útil],"SIM",GERAL[Rua],B29,GERAL[Dia],">=" &$P$11,GERAL[Dia],"<=" &$Q$11) -> 0 | D29: =SUMIFS(GERAL[LA],GERAL[Rua],B29,GERAL[Dia],">=" &$P$11,GERAL[Dia],"<=" &$Q$11) -> 0 | E29: =SUMIFS(GERAL[LE],GERAL[Rua],B29,GERAL[Dia],">=" &$P$11,GERAL[Dia],"<=" &$Q$11) -> 0 | F29: =SUMIFS(GERAL[PRA],GERAL[Rua],B29,GERAL[Dia],">=" &$P$11,GERAL[Dia],"<=" &$Q$11) -> 0 | G29: =SUMIFS(GERAL[PRE],GERAL[Rua],B29,GERAL[Dia],">=" &$P$11,GERAL[Dia],"<=" &$Q$11) -> 0 | H29: =SUMIFS(GERAL[PV''s],GERAL[Rua],B29,GERAL[Dia],">=" &$P$11,GERAL[Dia],"<=" &$Q$11) -> 0 | I29: =SUMIFS(GERAL[LIE],GERAL[Rua],B29,GERAL[Dia],">=" &$P$11,GERAL[Dia],"<=" &$Q$11) -> 0 | J29: =SUMIFS(GERAL[LIA],GERAL[Rua],B29,GERAL[Dia],">=" &$P$11,GERAL[Dia],"<=" &$Q$11) -> 0 | K29: =SUMIFS(GERAL[IHM],GERAL[Rua],B29,GERAL[Dia],">=" &$P$11,GERAL[Dia],"<=" &$Q$11) -> 0 | L29: =IFERROR(D29/C29,"") | M29: =IFERROR(E29/C29,"") | N29: =IFERROR(F29/C29,"") | O29: =IFERROR(G29/C29,"") | P29: =IFERROR(SUM(F29:G29)/C29,"") | Q29: =IFERROR(SUM(D29:E29)/C29,"")
C30: =COUNTIFS(GERAL[Dia Útil],"SIM",GERAL[Rua],B30,GERAL[Dia],">=" &$P$11,GERAL[Dia],"<=" &$Q$11) -> 0 | D30: =SUMIFS(GERAL[LA],GERAL[Rua],B30,GERAL[Dia],">=" &$P$11,GERAL[Dia],"<=" &$Q$11) -> 0 | E30: =SUMIFS(GERAL[LE],GERAL[Rua],B30,GERAL[Dia],">=" &$P$11,GERAL[Dia],"<=" &$Q$11) -> 0 | F30: =SUMIFS(GERAL[PRA],GERAL[Rua],B30,GERAL[Dia],">=" &$P$11,GERAL[Dia],"<=" &$Q$11) -> 0 | G30: =SUMIFS(GERAL[PRE],GERAL[Rua],B30,GERAL[Dia],">=" &$P$11,GERAL[Dia],"<=" &$Q$11) -> 0 | H30: =SUMIFS(GERAL[PV''s],GERAL[Rua],B30,GERAL[Dia],">=" &$P$11,GERAL[Dia],"<=" &$Q$11) -> 0 | I30: =SUMIFS(GERAL[LIE],GERAL[Rua],B30,GERAL[Dia],">=" &$P$11,GERAL[Dia],"<=" &$Q$11) -> 0 | J30: =SUMIFS(GERAL[LIA],GERAL[Rua],B30,GERAL[Dia],">=" &$P$11,GERAL[Dia],"<=" &$Q$11) -> 0 | K30: =SUMIFS(GERAL[IHM],GERAL[Rua],B30,GERAL[Dia],">=" &$P$11,GERAL[Dia],"<=" &$Q$11) -> 0 | L30: =IFERROR(D30/C30,"") | M30: =IFERROR(E30/C30,"") | N30: =IFERROR(F30/C30,"") | O30: =IFERROR(G30/C30,"") | P30: =IFERROR(SUM(F30:G30)/C30,"") | Q30: =IFERROR(SUM(D30:E30)/C30,"")
