Workbook

Sheet APOIO
B2: Dias Úteis
B3: SIM
B4: NÃO

Sheet EXECUÇÃO
B1: LOCAL: | C1: PANTANAL BAIXO | G1: PREENCHIMENTO DE EXECUÇÃO DIÁRIA
B2: Não alterar | C2: Não alterar | D2: Não alterar | E2: Preencher | F2: Unidade | G2: Unidade | H2: Metros | I2: Metros | J2: Unidade | K2: Unidade | L2: Unidade | M2: Unidade
B3: Dia | C3: Dia Semana | D3: Mês | E3: Dia Útil | F3: Ligações (AG) | G3: Ligações (ES) | H3: Rede (AG) | I3: Rede (ES) | J3: PV's | K3: Intradomiciliar (Es) | L3: Intradomiciliar (AG)2 | M3: Padronização (AG)
B4: 45962 | C4: sábado | D4: 45962 | E4: NÃO
B5: 45963 | C5: domingo | D5: 45963 | E5: NÃO
B6: 45964 | C6: segunda-feira | D6: 45964 | E6: SIM | F6: 0 | G6: =50/15 -> 3.3333333
B7: 45965 | C7: terça-feira | D7: 45965 | E7: SIM | F7: 0 | G7: =50/15 -> 3.3333333
B8: 45966 | C8: quarta-feira | D8: 45966 | E8: SIM | F8: 0 | G8: =50/15 -> 3.3333333
B9: 45967 | C9: quinta-feira | D9: 45967 | E9: SIM | F9: 0 | G9: =50/15 -> 3.3333333
B10: 45968 | C10: sexta-feira | D10: 45968 | E10: SIM | F10: 0 | G10: =50/15 -> 3.3333333
B11: 45969 | C11: sábado | D11: 45969 | E11: NÃO
B12: 45970 | C12: domingo | D12: 45970 | E12: NÃO
B13: 45971 | C13: segunda-feira | D13: 45971 | E13: SIM | F13: 0 | G13: =50/15 -> 3.3333333
B14: 45972 | C14: terça-feira | D14: 45972 | E14: SIM | F14: 0 | G14: =50/15 -> 3.3333333
B15: 45973 | C15: quarta-feira | D15: 45973 | E15: SIM | F15: 0 | G15: =50/15 -> 3.3333333
B16: 45974 | C16: quinta-feira | D16: 45974 | E16: SIM | F16: 0 | G16: =50/15 -> 3.3333333
B17: 45975 | C17: sexta-feira | D17: 45975 | E17: SIM | F17: 0 | G17: =50/15 -> 3.3333333
B18: 45976 | C18: sábado | D18: 45976 | E18: NÃO
B19: 45977 | C19: domingo | D19: 45977 | E19: NÃO
B20: 45978 | C20: segunda-feira | D20: 45978 | E20: SIM | F20: 0 | G20: =50/15 -> 3.3333333
B21: 45979 | C21: terça-feira | D21: 45979 | E21: SIM | F21: 0 | G21: =50/15 -> 3.3333333
B22: 45980 | C22: quarta-feira | D22: 45980 | E22: SIM | F22: 0 | G22: =50/15 -> 3.3333333
B23: 45981 | C23: quinta-feira | D23: 45981 | E23: SIM | F23: 0 | G23: =50/15 -> 3.3333333
B24: 45982 | C24: sexta-feira | D24: 45982 | E24: SIM | F24: 0 | G24: =50/15 -> 3.3333333
B25: 45983 | C25: sábado | D25: 45983 | E25: NÃO
B26: 45984 | C26: domingo | D26: 45984 | E26: NÃO
B27: 45985 | C27: segunda-feira | D27: 45985 | E27: NÃO
B28: 45986 | C28: terça-feira | D28: 45986 | E28: NÃO
B29: 45987 | C29: quarta-feira | D29: 45987 | E29: NÃO
B30: 45988 | C30: quinta-feira | D30: 45988 | E30: NÃO
B31: 45989 | C31: sexta-feira | D31: 45989 | E31: NÃO
B32: 45990 | C32: sábado | D32: 45990 | E32: NÃO
B33: 45991 | C33: domingo | D33: 45991 | E33: NÃO
B34: 45992 | C34: segunda-feira | D34: 45992
B35: 45993 | C35: terça-feira | D35: 45993
B36: 45994 | C36: quarta-feira | D36: 45994
B37: 45995 | C37: quinta-feira | D37: 45995
B38: 45996 | C38: sexta-feira | D38: 45996
B39: 45997 | C39: sábado | D39: 45997 | E39: NÃO
B40: 45998 | C40: domingo | D40: 45998 | E40: NÃO
...

Sheet EXEC. POR EQUIPE
B1: LOCAL: | C1: PANTANAL BAIXO | M1: PREENCHIMENTO DE EXECUÇÃO DIÁRIA | Y1: =IF(U7>=1,1,IF(V7>=1,1,IF(W7>=1,1,IF(X7>=1,1,IF(Y7>=1,1,IF(Z7>=1,1,IF(AA7>=1,1,IF(AB7>=1,1,IF(AC7>=1,1,0))))))))) -> 0 | AH1: =IF(AD7>=1,1,IF(AE7>=1,1,IF(AF7>=1,1,IF(AG7>=1,1,IF(AH7>=1,1,IF(AI7>=1,1,IF(AJ7>=1,1,IF(AK7>=1,1,IF(AL7>=1,1,0))))))))) -> 0 | AQ1: =IF(AM7>=1,1,IF(AN7>=1,1,IF(AO7>=1,1,IF(AP7>=1,1,IF(AQ7>=1,1,IF(AR7>=1,1,IF(AS7>=1,1,IF(AT7>=1,1,IF(AU7>=1,1,0))))))))) -> 0 | AZ1: =IF(AV7>=1,1,IF(AW7>=1,1,IF(AX7>=1,1,IF(AY7>=1,1,IF(AZ7>=1,1,IF(BA7>=1,1,IF(BB7>=1,1,IF(BC7>=1,1,IF(BD7>=1,1,0))))))))) -> 0 | BI1: =IF(BE7>=1,1,IF(BF7>=1,1,IF(BG7>=1,1,IF(BH7>=1,1,IF(BI7>=1,1,IF(BJ7>=1,1,IF(BK7>=1,1,IF(BL7>=1,1,IF(BM7>=1,1,0))))))))) -> 1 | BR1: =IF(BN7>=1,1,IF(BO7>=1,1,IF(BP7>=1,1,IF(BQ7>=1,1,IF(BR7>=1,1,IF(BS7>=1,1,IF(BT7>=1,1,IF(BU7>=1,1,IF(BV7>=1,1,0))))))))) -> 1 | CA1: =IF(BW7>=1,1,IF(BX7>=1,1,IF(BY7>=1,1,IF(BZ7>=1,1,IF(CA7>=1,1,IF(CB7>=1,1,IF(CC7>=1,1,IF(CD7>=1,1,IF(CE7>=1,1,0))))))))) -> 1 | CJ1: =IF(CF7>=1,1,IF(CG7>=1,1,IF(CH7>=1,1,IF(CI7>=1,1,IF(CJ7>=1,1,IF(CK7>=1,1,IF(CL7>=1,1,IF(CM7>=1,1,IF(CN7>=1,1,0))))))))) -> 1 | CS1: =IF(CO7>=1,1,IF(CP7>=1,1,IF(CQ7>=1,1,IF(CR7>=1,1,IF(CS7>=1,1,IF(CT7>=1,1,IF(CU7>=1,1,IF(CV7>=1,1,IF(CW7>=1,1,0))))))))) -> 1 | DB1: =IF(CX7>=1,1,IF(CY7>=1,1,IF(CZ7>=1,1,IF(DA7>=1,1,IF(DB7>=1,1,IF(DC7>=1,1,IF(DD7>=1,1,IF(DE7>=1,1,IF(DF7>=1,1,0))))))))) -> 1 | DK1: =IF(DG7>=1,1,IF(DH7>=1,1,IF(DI7>=1,1,IF(DJ7>=1,1,IF(DK7>=1,1,IF(DL7>=1,1,IF(DM7>=1,1,IF(DN7>=1,1,IF(DO7>=1,1,0))))))))) -> 0 | DT1: =IF(DP7>=1,1,IF(DQ7>=1,1,IF(DR7>=1,1,IF(DS7>=1,1,IF(DT7>=1,1,IF(DU7>=1,1,IF(DV7>=1,1,IF(DW7>=1,1,IF(DX7>=1,1,0))))))))) -> 1 | EC1: =IF(DY7>=1,1,IF(DZ7>=1,1,IF(EA7>=1,1,IF(EB7>=1,1,IF(EC7>=1,1,IF(ED7>=1,1,IF(EE7>=1,1,IF(EF7>=1,1,IF(EG7>=1,1,0))))))))) -> 1 | EL1: =IF(EH7>=1,1,IF(EI7>=1,1,IF(EJ7>=1,1,IF(EK7>=1,1,IF(EL7>=1,1,IF(EM7>=1,1,IF(EN7>=1,1,IF(EO7>=1,1,IF(EP7>=1,1,0))))))))) -> 1 | EU1: =IF(EQ7>=1,1,IF(ER7>=1,1,IF(ES7>=1,1,IF(ET7>=1,1,IF(EU7>=1,1,IF(EV7>=1,1,IF(EW7>=1,1,IF(EX7>=1,1,IF(EY7>=1,1,0))))))))) -> 1 | FD1: =IF(EZ7>=1,1,IF(FA7>=1,1,IF(FB7>=1,1,IF(FC7>=1,1,IF(FD7>=1,1,IF(FE7>=1,1,IF(FF7>=1,1,IF(FG7>=1,1,IF(FH7>=1,1,0))))))))) -> 1 | FM1: =IF(FI7>=1,1,IF(FJ7>=1,1,IF(FK7>=1,1,IF(FL7>=1,1,IF(FM7>=1,1,IF(FN7>=1,1,IF(FO7>=1,1,IF(FP7>=1,1,IF(FQ7>=1,1,0))))))))) -> 0 | FV1: =IF(FR7>=1,1,IF(FS7>=1,1,IF(FT7>=1,1,IF(FU7>=1,1,IF(FV7>=1,1,IF(FW7>=1,1,IF(FX7>=1,1,IF(FY7>=1,1,IF(FZ7>=1,1,0))))))))) -> 0 | GE1: =IF(GA7>=1,1,IF(GB7>=1,1,IF(GC7>=1,1,IF(GD7>=1,1,IF(GE7>=1,1,IF(GF7>=1,1,IF(GG7>=1,1,IF(GH7>=1,1,IF(GI7>=1,1,0))))))))) -> 0 | GN1: =IF(GJ7>=1,1,IF(GK7>=1,1,IF(GL7>=1,1,IF(GM7>=1,1,IF(GN7>=1,1,IF(GO7>=1,1,IF(GP7>=1,1,IF(GQ7>=1,1,IF(GR7>=1,1,0))))))))) -> 1 | GW1: =IF(GS7>=1,1,IF(GT7>=1,1,IF(GU7>=1,1,IF(GV7>=1,1,IF(GW7>=1,1,IF(GX7>=1,1,IF(GY7>=1,1,IF(GZ7>=1,1,IF(HA7>=1,1,0))))))))) -> 1 | HF1: =IF(HB7>=1,1,IF(HC7>=1,1,IF(HD7>=1,1,IF(HE7>=1,1,IF(HF7>=1,1,IF(HG7>=1,1,IF(HH7>=1,1,IF(HI7>=1,1,IF(HJ7>=1,1,0))))))))) -> 1 | HO1: =IF(HK7>=1,1,IF(HL7>=1,1,IF(HM7>=1,1,IF(HN7>=1,1,IF(HO7>=1,1,IF(HP7>=1,1,IF(HQ7>=1,1,IF(HR7>=1,1,IF(HS7>=1,1,0))))))))) -> 1 | HX1: =IF(HT7>=1,1,IF(HU7>=1,1,IF(HV7>=1,1,IF(HW7>=1,1,IF(HX7>=1,1,IF(HY7>=1,1,IF(HZ7>=1,1,IF(IA7>=1,1,IF(IB7>=1,1,0))))))))) -> 0 | IG1: =IF(IC7>=1,1,IF(ID7>=1,1,IF(IE7>=1,1,IF(IF7>=1,1,IF(IG7>=1,1,IF(IH7>=1,1,IF(II7>=1,1,IF(IJ7>=1,1,IF(IK7>=1,1,0))))))))) -> 0 | IP1: =IF(IL7>=1,1,IF(IM7>=1,1,IF(IN7>=1,1,IF(IO7>=1,1,IF(IP7>=1,1,IF(IQ7>=1,1,IF(IR7>=1,1,IF(IS7>=1,1,IF(IT7>=1,1,0))))))))) -> 0 | IY1: =IF(IU7>=1,1,IF(IV7>=1,1,IF(IW7>=1,1,IF(IX7>=1,1,IF(IY7>=1,1,IF(IZ7>=1,1,IF(JA7>=1,1,IF(JB7>=1,1,IF(JC7>=1,1,0))))))))) -> 1 | JH1: =IF(JD7>=1,1,IF(JE7>=1,1,IF(JF7>=1,1,IF(JG7>=1,1,IF(JH7>=1,1,IF(JI7>=1,1,IF(JJ7>=1,1,IF(JK7>=1,1,IF(JL7>=1,1,0))))))))) -> 1 | JQ1: =IF(JM7>=1,1,IF(JN7>=1,1,IF(JO7>=1,1,IF(JP7>=1,1,IF(JQ7>=1,1,IF(JR7>=1,1,IF(JS7>=1,1,IF(JT7>=1,1,IF(JU7>=1,1,0))))))))) -> 1 | JZ1: =IF(JV7>=1,1,IF(JW7>=1,1,IF(JX7>=1,1,IF(JY7>=1,1,IF(JZ7>=1,1,IF(KA7>=1,1,IF(KB7>=1,1,IF(KC7>=1,1,IF(KD7>=1,1,0))))))))) -> 1 | KI1: =IF(KE7>=1,1,IF(KF7>=1,1,IF(KG7>=1,1,IF(KH7>=1,1,IF(KI7>=1,1,IF(KJ7>=1,1,IF(KK7>=1,1,IF(KL7>=1,1,IF(KM7>=1,1,0))))))))) -> 1 | KR1: =IF(KN7>=1,1,IF(KO7>=1,1,IF(KP7>=1,1,IF(KQ7>=1,1,IF(KR7>=1,1,IF(KS7>=1,1,IF(KT7>=1,1,IF(KU7>=1,1,IF(KV7>=1,1,0))))))))) -> 0 | LA1: =IF(KW7>=1,1,IF(KX7>=1,1,IF(KY7>=1,1,IF(KZ7>=1,1,IF(LA7>=1,1,IF(LB7>=1,1,IF(LC7>=1,1,IF(LD7>=1,1,IF(LE7>=1,1,0))))))))) -> 1 | LJ1: =IF(LF7>=1,1,IF(LG7>=1,1,IF(LH7>=1,1,IF(LI7>=1,1,IF(LJ7>=1,1,IF(LK7>=1,1,IF(LL7>=1,1,IF(LM7>=1,1,IF(LN7>=1,1,0))))))))) -> 1 | LS1: =IF(LO7>=1,1,IF(LP7>=1,1,IF(LQ7>=1,1,IF(LR7>=1,1,IF(LS7>=1,1,IF(LT7>=1,1,IF(LU7>=1,1,IF(LV7>=1,1,IF(LW7>=1,1,0))))))))) -> 1 | MB1: =IF(LX7>=1,1,IF(LY7>=1,1,IF(LZ7>=1,1,IF(MA7>=1,1,IF(MB7>=1,1,IF(MC7>=1,1,IF(MD7>=1,1,IF(ME7>=1,1,IF(MF7>=1,1,0))))))))) -> 0 | MK1: =IF(MG7>=1,1,IF(MH7>=1,1,IF(MI7>=1,1,IF(MJ7>=1,1,IF(MK7>=1,1,IF(ML7>=1,1,IF(MM7>=1,1,IF(MN7>=1,1,IF(MO7>=1,1,0))))))))) -> 1 | MT1: =IF(MP7>=1,1,IF(MQ7>=1,1,IF(MR7>=1,1,IF(MS7>=1,1,IF(MT7>=1,1,IF(MU7>=1,1,IF(MV7>=1,1,IF(MW7>=1,1,IF(MX7>=1,1,0))))))))) -> 1 | NC1: =IF(MY7>=1,1,IF(MZ7>=1,1,IF(NA7>=1,1,IF(NB7>=1,1,IF(NC7>=1,1,IF(ND7>=1,1,IF(NE7>=1,1,IF(NF7>=1,1,IF(NG7>=1,1,0))))))))) -> 0 | NL1: =IF(NH7>=1,1,IF(NI7>=1,1,IF(NJ7>=1,1,IF(NK7>=1,1,IF(NL7>=1,1,IF(NM7>=1,1,IF(NN7>=1,1,IF(NO7>=1,1,IF(NP7>=1,1,0))))))))) -> 1 | NU1: =IF(NQ7>=1,1,IF(NR7>=1,1,IF(NS7>=1,1,IF(NT7>=1,1,IF(NU7>=1,1,IF(NV7>=1,1,IF(NW7>=1,1,IF(NX7>=1,1,IF(NY7>=1,1,0))))))))) -> 1 | OD1: =IF(NZ7>=1,1,IF(OA7>=1,1,IF(OB7>=1,1,IF(OC7>=1,1,IF(OD7>=1,1,IF(OE7>=1,1,IF(OF7>=1,1,IF(OG7>=1,1,IF(OH7>=1,1,0))))))))) -> 1 | OM1: =IF(OI7>=1,1,IF(OJ7>=1,1,IF(OK7>=1,1,IF(OL7>=1,1,IF(OM7>=1,1,IF(ON7>=1,1,IF(OO7>=1,1,IF(OP7>=1,1,IF(OQ7>=1,1,0))))))))) -> 1 | OV1: =IF(OR7>=1,1,IF(OS7>=1,1,IF(OT7>=1,1,IF(OU7>=1,1,IF(OV7>=1,1,IF(OW7>=1,1,IF(OX7>=1,1,IF(OY7>=1,1,IF(OZ7>=1,1,0))))))))) -> 1 | PE1: =IF(PA7>=1,1,IF(PB7>=1,1,IF(PC7>=1,1,IF(PD7>=1,1,IF(PE7>=1,1,IF(PF7>=1,1,IF(PG7>=1,1,IF(PH7>=1,1,IF(PI7>=1,1,0))))))))) -> 0 | PN1: =IF(PJ7>=1,1,IF(PK7>=1,1,IF(PL7>=1,1,IF(PM7>=1,1,IF(PN7>=1,1,IF(PO7>=1,1,IF(PP7>=1,1,IF(PQ7>=1,1,IF(PR7>=1,1,0))))))))) -> 0 | PW1: =IF(PS7>=1,1,IF(PT7>=1,1,IF(PU7>=1,1,IF(PV7>=1,1,IF(PW7>=1,1,IF(PX7>=1,1,IF(PY7>=1,1,IF(PZ7>=1,1,IF(QA7>=1,1,0))))))))) -> 1 | QF1: =IF(QB7>=1,1,IF(QC7>=1,1,IF(QD7>=1,1,IF(QE7>=1,1,IF(QF7>=1,1,IF(QG7>=1,1,IF(QH7>=1,1,IF(QI7>=1,1,IF(QJ7>=1,1,0))))))))) -> 1 | QO1: =IF(QK7>=1,1,IF(QL7>=1,1,IF(QM7>=1,1,IF(QN7>=1,1,IF(QO7>=1,1,IF(QP7>=1,1,IF(QQ7>=1,1,IF(QR7>=1,1,IF(QS7>=1,1,0))))))))) -> 1 | QX1: =IF(QT7>=1,1,IF(QU7>=1,1,IF(QV7>=1,1,IF(QW7>=1,1,IF(QX7>=1,1,IF(QY7>=1,1,IF(QZ7>=1,1,IF(RA7>=1,1,IF(RB7>=1,1,0))))))))) -> 1 | RG1: =IF(RC7>=1,1,IF(RD7>=1,1,IF(RE7>=1,1,IF(RF7>=1,1,IF(RG7>=1,1,IF(RH7>=1,1,IF(RI7>=1,1,IF(RJ7>=1,1,IF(RK7>=1,1,0))))))))) -> 1 | RP1: =IF(RL7>=1,1,IF(RM7>=1,1,IF(RN7>=1,1,IF(RO7>=1,1,IF(RP7>=1,1,IF(RQ7>=1,1,IF(RR7>=1,1,IF(RS7>=1,1,IF(RT7>=1,1,0))))))))) -> 0 | RY1: =IF(RU7>=1,1,IF(RV7>=1,1,IF(RW7>=1,1,IF(RX7>=1,1,IF(RY7>=1,1,IF(RZ7>=1,1,IF(SA7>=1,1,IF(SB7>=1,1,IF(SC7>=1,1,0))))))))) -> 0 | SH1: =IF(SD7>=1,1,IF(SE7>=1,1,IF(SF7>=1,1,IF(SG7>=1,1,IF(SH7>=1,1,IF(SI7>=1,1,IF(SJ7>=1,1,IF(SK7>=1,1,IF(SL7>=1,1,0))))))))) -> 1 | SQ1: =IF(SM7>=1,1,IF(SN7>=1,1,IF(SO7>=1,1,IF(SP7>=1,1,IF(SQ7>=1,1,IF(SR7>=1,1,IF(SS7>=1,1,IF(ST7>=1,1,IF(SU7>=1,1,0))))))))) -> 1 | SZ1: =IF(SV7>=1,1,IF(SW7>=1,1,IF(SX7>=1,1,IF(SY7>=1,1,IF(SZ7>=1,1,IF(TA7>=1,1,IF(TB7>=1,1,IF(TC7>=1,1,IF(TD7>=1,1,0))))))))) -> 1 | TI1: =IF(TE7>=1,1,IF(TF7>=1,1,IF(TG7>=1,1,IF(TH7>=1,1,IF(TI7>=1,1,IF(TJ7>=1,1,IF(TK7>=1,1,IF(TL7>=1,1,IF(TM7>=1,1,0))))))))) -> 0 | TR1: =IF(TN7>=1,1,IF(TO7>=1,1,IF(TP7>=1,1,IF(TQ7>=1,1,IF(TR7>=1,1,IF(TS7>=1,1,IF(TT7>=1,1,IF(TU7>=1,1,IF(TV7>=1,1,0))))))))) -> 1 | UA1: =IF(TW7>=1,1,IF(TX7>=1,1,IF(TY7>=1,1,IF(TZ7>=1,1,IF(UA7>=1,1,IF(UB7>=1,1,IF(UC7>=1,1,IF(UD7>=1,1,IF(UE7>=1,1,0))))))))) -> 1 | UJ1: =IF(UF7>=1,1,IF(UG7>=1,1,IF(UH7>=1,1,IF(UI7>=1,1,IF(UJ7>=1,1,IF(UK7>=1,1,IF(UL7>=1,1,IF(UM7>=1,1,IF(UN7>=1,1,0))))))))) -> 0 | US1: =IF(UO7>=1,1,IF(UP7>=1,1,IF(UQ7>=1,1,IF(UR7>=1,1,IF(US7>=1,1,IF(UT7>=1,1,IF(UU7>=1,1,IF(UV7>=1,1,IF(UW7>=1,1,0))))))))) -> 1 | VB1: =IF(UX7>=1,1,IF(UY7>=1,1,IF(UZ7>=1,1,IF(VA7>=1,1,IF(VB7>=1,1,IF(VC7>=1,1,IF(VD7>=1,1,IF(VE7>=1,1,IF(VF7>=1,1,0))))))))) -> 0 | VK1: =IF(VG7>=1,1,IF(VH7>=1,1,IF(VI7>=1,1,IF(VJ7>=1,1,IF(VK7>=1,1,IF(VL7>=1,1,IF(VM7>=1,1,IF(VN7>=1,1,IF(VO7>=1,1,0))))))))) -> 0 | VT1: =IF(VP7>=1,1,IF(VQ7>=1,1,IF(VR7>=1,1,IF(VS7>=1,1,IF(VT7>=1,1,IF(VU7>=1,1,IF(VV7>=1,1,IF(VW7>=1,1,IF(VX7>=1,1,0))))))))) -> 0 | WC1: =IF(VY7>=1,1,IF(VZ7>=1,1,IF(WA7>=1,1,IF(WB7>=1,1,IF(WC7>=1,1,IF(WD7>=1,1,IF(WE7>=1,1,IF(WF7>=1,1,IF(WG7>=1,1,0))))))))) -> 0 | WL1: =IF(WH7>=1,1,IF(WI7>=1,1,IF(WJ7>=1,1,IF(WK7>=1,1,IF(WL7>=1,1,IF(WM7>=1,1,IF(WN7>=1,1,IF(WO7>=1,1,IF(WP7>=1,1,0))))))))) -> 0 | WU1: =IF(WQ7>=1,1,IF(WR7>=1,1,IF(WS7>=1,1,IF(WT7>=1,1,IF(WU7>=1,1,IF(WV7>=1,1,IF(WW7>=1,1,IF(WX7>=1,1,IF(WY7>=1,1,0))))))))) -> 0 | XD1: =IF(WZ7>=1,1,IF(XA7>=1,1,IF(XB7>=1,1,IF(XC7>=1,1,IF(XD7>=1,1,IF(XE7>=1,1,IF(XF7>=1,1,IF(XG7>=1,1,IF(XH7>=1,1,0))))))))) -> 0 | XM1: =IF(XI7>=1,1,IF(XJ7>=1,1,IF(XK7>=1,1,IF(XL7>=1,1,IF(XM7>=1,1,IF(XN7>=1,1,IF(XO7>=1,1,IF(XP7>=1,1,IF(XQ7>=1,1,0))))))))) -> 0 | XV1: =IF(XR7>=1,1,IF(XS7>=1,1,IF(XT7>=1,1,IF(XU7>=1,1,IF(XV7>=1,1,IF(XW7>=1,1,IF(XX7>=1,1,IF(XY7>=1,1,IF(XZ7>=1,1,0))))))))) -> 0 | YE1: =IF(YA7>=1,1,IF(YB7>=1,1,IF(YC7>=1,1,IF(YD7>=1,1,IF(YE7>=1,1,IF(YF7>=1,1,IF(YG7>=1,1,IF(YH7>=1,1,IF(YI7>=1,1,0))))))))) -> 0 | YN1: =IF(YJ7>=1,1,IF(YK7>=1,1,IF(YL7>=1,1,IF(YM7>=1,1,IF(YN7>=1,1,IF(YO7>=1,1,IF(YP7>=1,1,IF(YQ7>=1,1,IF(YR7>=1,1,0))))))))) -> 0 | YW1: =IF(YS7>=1,1,IF(YT7>=1,1,IF(YU7>=1,1,IF(YV7>=1,1,IF(YW7>=1,1,IF(YX7>=1,1,IF(YY7>=1,1,IF(YZ7>=1,1,IF(ZA7>=1,1,0))))))))) -> 0 | ZF1: =IF(ZB7>=1,1,IF(ZC7>=1,1,IF(ZD7>=1,1,IF(ZE7>=1,1,IF(ZF7>=1,1,IF(ZG7>=1,1,IF(ZH7>=1,1,IF(ZI7>=1,1,IF(ZJ7>=1,1,0))))))))) -> 0 | ZO1: =IF(ZK7>=1,1,IF(ZL7>=1,1,IF(ZM7>=1,1,IF(ZN7>=1,1,IF(ZO7>=1,1,IF(ZP7>=1,1,IF(ZQ7>=1,1,IF(ZR7>=1,1,IF(ZS7>=1,1,0))))))))) -> 0 | ZX1: =IF(ZT7>=1,1,IF(ZU7>=1,1,IF(ZV7>=1,1,IF(ZW7>=1,1,IF(ZX7>=1,1,IF(ZY7>=1,1,IF(ZZ7>=1,1,IF(AAA7>=1,1,IF(AAB7>=1,1,0))))))))) -> 0 | AAG1: =IF(AAC7>=1,1,IF(AAD7>=1,1,IF(AAE7>=1,1,IF(AAF7>=1,1,IF(AAG7>=1,1,IF(AAH7>=1,1,IF(AAI7>=1,1,IF(AAJ7>=1,1,IF(AAK7>=1,1,0))))))))) -> 0 | AAP1: =IF(AAL7>=1,1,IF(AAM7>=1,1,IF(AAN7>=1,1,IF(AAO7>=1,1,IF(AAP7>=1,1,IF(AAQ7>=1,1,IF(AAR7>=1,1,IF(AAS7>=1,1,IF(AAT7>=1,1,0))))))))) -> 0 | AAY1: =IF(AAU7>=1,1,IF(AAV7>=1,1,IF(AAW7>=1,1,IF(AAX7>=1,1,IF(AAY7>=1,1,IF(AAZ7>=1,1,IF(ABA7>=1,1,IF(ABB7>=1,1,IF(ABC7>=1,1,0))))))))) -> 0 | ABH1: =IF(ABD7>=1,1,IF(ABE7>=1,1,IF(ABF7>=1,1,IF(ABG7>=1,1,IF(ABH7>=1,1,IF(ABI7>=1,1,IF(ABJ7>=1,1,IF(ABK7>=1,1,IF(ABL7>=1,1,0))))))))) -> 0 | ABQ1: =IF(ABM7>=1,1,IF(ABN7>=1,1,IF(ABO7>=1,1,IF(ABP7>=1,1,IF(ABQ7>=1,1,IF(ABR7>=1,1,IF(ABS7>=1,1,IF(ABT7>=1,1,IF(ABU7>=1,1,0))))))))) -> 0 | ABZ1: =IF(ABV7>=1,1,IF(ABW7>=1,1,IF(ABX7>=1,1,IF(ABY7>=1,1,IF(ABZ7>=1,1,IF(ACA7>=1,1,IF(ACB7>=1,1,IF(ACC7>=1,1,IF(ACD7>=1,1,0))))))))) -> 0 | ACI1: =IF(ACE7>=1,1,IF(ACF7>=1,1,IF(ACG7>=1,1,IF(ACH7>=1,1,IF(ACI7>=1,1,IF(ACJ7>=1,1,IF(ACK7>=1,1,IF(ACL7>=1,1,IF(ACM7>=1,1,0))))))))) -> 0 | ACR1: =IF(ACN7>=1,1,IF(ACO7>=1,1,IF(ACP7>=1,1,IF(ACQ7>=1,1,IF(ACR7>=1,1,IF(ACS7>=1,1,IF(ACT7>=1,1,IF(ACU7>=1,1,IF(ACV7>=1,1,0))))))))) -> 0 | ADA1: =IF(ACW7>=1,1,IF(ACX7>=1,1,IF(ACY7>=1,1,IF(ACZ7>=1,1,IF(ADA7>=1,1,IF(ADB7>=1,1,IF(ADC7>=1,1,IF(ADD7>=1,1,IF(ADE7>=1,1,0))))))))) -> 0 | ADJ1: =IF(ADF7>=1,1,IF(ADG7>=1,1,IF(ADH7>=1,1,IF(ADI7>=1,1,IF(ADJ7>=1,1,IF(ADK7>=1,1,IF(ADL7>=1,1,IF(ADM7>=1,1,IF(ADN7>=1,1,0))))))))) -> 0 | ADS1: =IF(ADO7>=1,1,IF(ADP7>=1,1,IF(ADQ7>=1,1,IF(ADR7>=1,1,IF(ADS7>=1,1,IF(ADT7>=1,1,IF(ADU7>=1,1,IF(ADV7>=1,1,IF(ADW7>=1,1,0))))))))) -> 0 | AEB1: =IF(ADX7>=1,1,IF(ADY7>=1,1,IF(ADZ7>=1,1,IF(AEA7>=1,1,IF(AEB7>=1,1,IF(AEC7>=1,1,IF(AED7>=1,1,IF(AEE7>=1,1,IF(AEF7>=1,1,0))))))))) -> 0 | AEK1: =IF(AEG7>=1,1,IF(AEH7>=1,1,IF(AEI7>=1,1,IF(AEJ7>=1,1,IF(AEK7>=1,1,IF(AEL7>=1,1,IF(AEM7>=1,1,IF(AEN7>=1,1,IF(AEO7>=1,1,0))))))))) -> 0 | AET1: =IF(AEP7>=1,1,IF(AEQ7>=1,1,IF(AER7>=1,1,IF(AES7>=1,1,IF(AET7>=1,1,IF(AEU7>=1,1,IF(AEV7>=1,1,IF(AEW7>=1,1,IF(AEX7>=1,1,0))))))))) -> 0 | AFC1: =IF(AEY7>=1,1,IF(AEZ7>=1,1,IF(AFA7>=1,1,IF(AFB7>=1,1,IF(AFC7>=1,1,IF(AFD7>=1,1,IF(AFE7>=1,1,IF(AFF7>=1,1,IF(AFG7>=1,1,0))))))))) -> 0 | AFL1: =IF(AFH7>=1,1,IF(AFI7>=1,1,IF(AFJ7>=1,1,IF(AFK7>=1,1,IF(AFL7>=1,1,IF(AFM7>=1,1,IF(AFN7>=1,1,IF(AFO7>=1,1,IF(AFP7>=1,1,0))))))))) -> 0 | AFU1: =IF(AFQ7>=1,1,IF(AFR7>=1,1,IF(AFS7>=1,1,IF(AFT7>=1,1,IF(AFU7>=1,1,IF(AFV7>=1,1,IF(AFW7>=1,1,IF(AFX7>=1,1,IF(AFY7>=1,1,0))))))))) -> 0 | AGD1: =IF(AFZ7>=1,1,IF(AGA7>=1,1,IF(AGB7>=1,1,IF(AGC7>=1,1,IF(AGD7>=1,1,IF(AGE7>=1,1,IF(AGF7>=1,1,IF(AGG7>=1,1,IF(AGH7>=1,1,0))))))))) -> 0 | AGM1: =IF(AGI7>=1,1,IF(AGJ7>=1,1,IF(AGK7>=1,1,IF(AGL7>=1,1,IF(AGM7>=1,1,IF(AGN7>=1,1,IF(AGO7>=1,1,IF(AGP7>=1,1,IF(AGQ7>=1,1,0))))))))) -> 0 | AGV1: =IF(AGR7>=1,1,IF(AGS7>=1,1,IF(AGT7>=1,1,IF(AGU7>=1,1,IF(AGV7>=1,1,IF(AGW7>=1,1,IF(AGX7>=1,1,IF(AGY7>=1,1,IF(AGZ7>=1,1,0))))))))) -> 0 | AHE1: =IF(AHA7>=1,1,IF(AHB7>=1,1,IF(AHC7>=1,1,IF(AHD7>=1,1,IF(AHE7>=1,1,IF(AHF7>=1,1,IF(AHG7>=1,1,IF(AHH7>=1,1,IF(AHI7>=1,1,0))))))))) -> 0 | AHN1: =IF(AHJ7>=1,1,IF(AHK7>=1,1,IF(AHL7>=1,1,IF(AHM7>=1,1,IF(AHN7>=1,1,IF(AHO7>=1,1,IF(AHP7>=1,1,IF(AHQ7>=1,1,IF(AHR7>=1,1,0))))))))) -> 0 | AHW1: =IF(AHS7>=1,1,IF(AHT7>=1,1,IF(AHU7>=1,1,IF(AHV7>=1,1,IF(AHW7>=1,1,IF(AHX7>=1,1,IF(AHY7>=1,1,IF(AHZ7>=1,1,IF(AIA7>=1,1,0))))))))) -> 0 | AIF1: =IF(AIB7>=1,1,IF(AIC7>=1,1,IF(AID7>=1,1,IF(AIE7>=1,1,IF(AIF7>=1,1,IF(AIG7>=1,1,IF(AIH7>=1,1,IF(AII7>=1,1,IF(AIJ7>=1,1,0))))))))) -> 0 | AIO1: =IF(AIK7>=1,1,IF(AIL7>=1,1,IF(AIM7>=1,1,IF(AIN7>=1,1,IF(AIO7>=1,1,IF(AIP7>=1,1,IF(AIQ7>=1,1,IF(AIR7>=1,1,IF(AIS7>=1,1,0))))))))) -> 0 | AIX1: =IF(AIT7>=1,1,IF(AIU7>=1,1,IF(AIV7>=1,1,IF(AIW7>=1,1,IF(AIX7>=1,1,IF(AIY7>=1,1,IF(AIZ7>=1,1,IF(AJA7>=1,1,IF(AJB7>=1,1,0))))))))) -> 0 | AJG1: =IF(AJC7>=1,1,IF(AJD7>=1,1,IF(AJE7>=1,1,IF(AJF7>=1,1,IF(AJG7>=1,1,IF(AJH7>=1,1,IF(AJI7>=1,1,IF(AJJ7>=1,1,IF(AJK7>=1,1,0))))))))) -> 0 | AJP1: =IF(AJL7>=1,1,IF(AJM7>=1,1,IF(AJN7>=1,1,IF(AJO7>=1,1,IF(AJP7>=1,1,IF(AJQ7>=1,1,IF(AJR7>=1,1,IF(AJS7>=1,1,IF(AJT7>=1,1,0))))))))) -> 0
T2: Dia | U2: 46023 | AD2: 46024 | AM2: 46025 | AV2: 46026 | BE2: 46027 | BN2: 46028 | BW2: 46029 | CF2: 46030 | CO2: 46031 | CX2: 46032 | DG2: 46033 | DP2: 46034 | DY2: 46035 | EH2: 46036 | EQ2: 46037 | EZ2: 46038 | FI2: 46039 | FR2: 46040 | GA2: 46041 | GJ2: 46042 | GS2: 46043 | HB2: 46044 | HK2: 46045 | HT2: 46046 | IC2: 46047 | IL2: 46048 | IU2: 46049 | JD2: 46050 | JM2: 46051 | JV2: 46052 | KE2: 46053 | KN2: 46054 | KW2: 46055 | LF2: 46056 | LO2: 46057 | LX2: 46058 | MG2: 46059 | MP2: 46060 | MY2: 46061 | NH2: 46062 | NQ2: 46063 | NZ2: 46064 | OI2: 46065 | OR2: 46066 | PA2: 46067 | PJ2: 46068 | PS2: 46069 | QB2: 46070 | QK2: 46071 | QT2: 46072 | RC2: 46073 | RL2: 46074 | RU2: 46075 | SD2: 46076 | SM2: 46077 | SV2: 46078 | TE2: 46079 | TN2: 46080 | TW2: 46081 | UF2: 46082 | UO2: 46083 | UX2: 46084 | VG2: 46085 | VP2: 46086 | VY2: 46087 | WH2: 46088 | WQ2: 46089 | WZ2: 46090 | XI2: 46091 | XR2: 46092 | YA2: 46093 | YJ2: 46094 | YS2: 46095 | ZB2: 46096 | ZK2: 46097 | ZT2: 46098 | AAC2: 46099 | AAL2: 46100 | AAU2: 46101 | ABD2: 46102 | ABM2: 46103 | ABV2: 46104 | ACE2: 46105 | ACN2: 46106 | ACW2: 46107 | ADF2: 46108 | ADO2: 46109 | ADX2: 46110 | AEG2: 46111 | AEP2: 46112 | AEY2: 46113 | AFH2: 46114 | AFQ2: 46115 | AFZ2: 46116 | AGI2: 46117 | AGR2: 46118 | AHA2: 46119 | AHJ2: 46120 | AHS2: 46121 | AIB2: 46122 | AIK2: 46123 | AIT2: 46124 | AJC2: 46125 | AJL2: 46126
T3: Dia Semana | U3: quinta-feira | AD3: sexta-feira | AM3: sábado | AV3: domingo | BE3: segunda-feira | BN3: terça-feira | BW3: quarta-feira | CF3: quinta-feira | CO3: sexta-feira | CX3: sábado | DG3: domingo | DP3: segunda-feira | DY3: terça-feira | EH3: quarta-feira | EQ3: quinta-feira | EZ3: sexta-feira | FI3: sábado | FR3: domingo | GA3: segunda-feira | GJ3: terça-feira | GS3: quarta-feira | HB3: quinta-feira | HK3: sexta-feira | HT3: sábado | IC3: domingo | IL3: segunda-feira | IU3: terça-feira | JD3: quarta-feira | JM3: quinta-feira | JV3: sexta-feira | KE3: sábado | KN3: domingo | KW3: segunda-feira | LF3: terça-feira | LO3: quarta-feira | LX3: quinta-feira | MG3: sexta-feira | MP3: sábado | MY3: domingo | NH3: segunda-feira | NQ3: terça-feira | NZ3: quarta-feira | OI3: quinta-feira | OR3: sexta-feira | PA3: sábado | PJ3: domingo | PS3: segunda-feira | QB3: terça-feira | QK3: quarta-feira | QT3: quinta-feira | RC3: sexta-feira | RL3: sábado | RU3: domingo | SD3: segunda-feira | SM3: terça-feira | SV3: quarta-feira | TE3: quinta-feira | TN3: sexta-feira | TW3: sábado | UF3: domingo | UO3: segunda-feira | UX3: terça-feira | VG3: quarta-feira | VP3: quinta-feira | VY3: sexta-feira | WH3: sábado | WQ3: domingo | WZ3: segunda-feira | XI3: terça-feira | XR3: quarta-feira | YA3: quinta-feira | YJ3: sexta-feira | YS3: sábado | ZB3: domingo | ZK3: segunda-feira | ZT3: terça-feira | AAC3: quarta-feira | AAL3: quinta-feira | AAU3: sexta-feira | ABD3: sábado | ABM3: domingo | ABV3: segunda-feira | ACE3: terça-feira | ACN3: quarta-feira | ACW3: quinta-feira | ADF3: sexta-feira | ADO3: sábado | ADX3: domingo | AEG3: segunda-feira | AEP3: terça-feira | AEY3: quarta-feira | AFH3: quinta-feira | AFQ3: sexta-feira | AFZ3: sábado | AGI3: domingo | AGR3: segunda-feira | AHA3: terça-feira | AHJ3: quarta-feira | AHS3: quinta-feira | AIB3: sexta-feira | AIK3: sábado | AIT3: domingo | AJC3: segunda-feira | AJL3: terça-feira
T4: Mês | U4: 46023 | AD4: 46024 | AM4: 46025 | AV4: 46026 | BE4: 46027 | BN4: 46028 | BW4: 46029 | CF4: 46030 | CO4: 46031 | CX4: 46032 | DG4: 46033 | DP4: 46034 | DY4: 46035 | EH4: 46036 | EQ4: 46037 | EZ4: 46038 | FI4: 46039 | FR4: 46040 | GA4: 46041 | GJ4: 46042 | GS4: 46043 | HB4: 46044 | HK4: 46045 | HT4: 46046 | IC4: 46047 | IL4: 46048 | IU4: 46049 | JD4: 46050 | JM4: 46051 | JV4: 46052 | KE4: 46053 | KN4: 46054 | KW4: 46055 | LF4: 46056 | LO4: 46057 | LX4: 46058 | MG4: 46059 | MP4: 46060 | MY4: 46061 | NH4: 46062 | NQ4: 46063 | NZ4: 46064 | OI4: 46065 | OR4: 46066 | PA4: 46067 | PJ4: 46068 | PS4: 46069 | QB4: 46070 | QK4: 46071 | QT4: 46072 | RC4: 46073 | RL4: 46074 | RU4: 46075 | SD4: 46076 | SM4: 46077 | SV4: 46078 | TE4: 46079 | TN4: 46080 | TW4: 46081 | UF4: 46082 | UO4: 46083 | UX4: 46084 | VG4: 46085 | VP4: 46086 | VY4: 46087 | WH4: 46088 | WQ4: 46089 | WZ4: 46090 | XI4: 46091 | XR4: 46092 | YA4: 46093 | YJ4: 46094 | YS4: 46095 | ZB4: 46096 | ZK4: 46097 | ZT4: 46098 | AAC4: 46099 | AAL4: 46100 | AAU4: 46101 | ABD4: 46102 | ABM4: 46103 | ABV4: 46104 | ACE4: 46105 | ACN4: 46106 | ACW4: 46107 | ADF4: 46108 | ADO4: 46109 | ADX4: 46110 | AEG4: 46111 | AEP4: 46112 | AEY4: 46113 | AFH4: 46114 | AFQ4: 46115 | AFZ4: 46116 | AGI4: 46117 | AGR4: 46118 | AHA4: 46119 | AHJ4: 46120 | AHS4: 46121 | AIB4: 46122 | AIK4: 46123 | AIT4: 46124 | AJC4: 46125 | AJL4: 46126
T5: Dia Útil | Y5: NÃO | AH5: NÃO | BI5: SIM | BR5: SIM | CA5: SIM | CJ5: SIM | CS5: SIM | DB5: SIM | DK5: NÃO | DT5: SIM | EC5: SIM | EL5: SIM | EU5: SIM | FD5: SIM | FM5: SIM | GE5: SIM | GN5: SIM | GW5: SIM | HF5: SIM | HO5: SIM | HX5: SIM | IG5: NÃO | IP5: NÃO | IY5: SIM | JH5: SIM | JQ5: SIM | JZ5: SIM | KI5: SIM | KR5: NÃO | LA5: SIM | LJ5: SIM | LS5: SIM | MB5: SIM | MK5: SIM | MT5: NÃO | NC5: NÃO | NL5: SIM | NU5: SIM | OD5: SIM | OM5: SIM | OV5: SIM | PE5: NÃO | PN5: NÃO | PW5: SIM | QF5: SIM | QO5: SIM | QX5: SIM | RG5: SIM | RP5: NÃO | RY5: NÃO | SH5: SIM | SQ5: SIM | SZ5: SIM | TI5: SIM | TR5: SIM | UA5: SIM | UJ5: NÃO | US5: SIM
B6: Não alterar | C6: Não alterar | D6: Não alterar | E6: Não alterar | J6: Não alterar | K6: Não alterar | L6: Não alterar | M6: Não alterar | N6: Não alterar | O6: Não alterar | P6: Não alterar | Q6: Não alterar | R6: Não alterar | T6: Não alterar | U6: Unidade | V6: Unidade | W6: Metros | X6: Metros | Y6: Unidade | Z6: Unidade | AA6: Unidade | AB6: Unidade | AC6: Unidade | AD6: Unidade | AE6: Unidade | AF6: Metros | AG6: Metros | AH6: Unidade | AI6: Unidade | AJ6: Unidade | AK6: Unidade | AL6: Unidade | AM6: Unidade | AN6: Unidade | AO6: Metros | AP6: Metros | AQ6: Unidade | AR6: Unidade | AS6: Unidade | AT6: Unidade | AU6: Unidade | AV6: Unidade | AW6: Unidade | AX6: Metros | AY6: Metros | AZ6: Unidade | BA6: Unidade | BB6: Unidade | BC6: Unidade | BD6: Unidade | BE6: Unidade | BF6: Unidade | BG6: Metros | BH6: Metros | BI6: Unidade | BJ6: Unidade | BK6: Unidade | BL6: Unidade | BM6: Unidade | BN6: Unidade | BO6: Unidade | BP6: Metros | BQ6: Metros | BR6: Unidade | BS6: Unidade | BT6: Unidade | BU6: Unidade | BV6: Unidade | BW6: Unidade | BX6: Unidade | BY6: Metros | BZ6: Metros | CA6: Unidade | CB6: Unidade | CC6: Unidade | CD6: Unidade | CE6: Unidade | CF6: Unidade | CG6: Unidade | CH6: Metros | CI6: Metros | CJ6: Unidade | CK6: Unidade | CL6: Unidade | CM6: Unidade | CN6: Unidade | CO6: Unidade | CP6: Unidade | CQ6: Metros | CR6: Metros | CS6: Unidade | CT6: Unidade | CU6: Unidade | CV6: Unidade | CW6: Unidade | CX6: Unidade | CY6: Unidade | CZ6: Metros | DA6: Metros | DB6: Unidade | DC6: Unidade | DD6: Unidade | DE6: Unidade | DF6: Unidade | DG6: Unidade | DH6: Unidade | DI6: Metros | DJ6: Metros | DK6: Unidade | DL6: Unidade | DM6: Unidade | DN6: Unidade | DO6: Unidade | DP6: Unidade | DQ6: Unidade | DR6: Metros | DS6: Metros | DT6: Unidade | DU6: Unidade | DV6: Unidade | DW6: Unidade | DX6: Unidade | DY6: Unidade | DZ6: Unidade | EA6: Metros | EB6: Metros | EC6: Unidade | ED6: Unidade | EE6: Unidade | EF6: Unidade | EG6: Unidade | EH6: Unidade | EI6: Unidade | EJ6: Metros | EK6: Metros | EL6: Unidade | EM6: Unidade | EN6: Unidade | EO6: Unidade | EP6: Unidade | EQ6: Unidade | ER6: Unidade | ES6: Metros | ET6: Metros | EU6: Unidade | EV6: Unidade | EW6: Unidade | EX6: Unidade | EY6: Unidade | EZ6: Unidade | FA6: Unidade | FB6: Metros | FC6: Metros | FD6: Unidade | FE6: Unidade | FF6: Unidade | FG6: Unidade | FH6: Unidade | FI6: Unidade | FJ6: Unidade | FK6: Metros | FL6: Metros | FM6: Unidade | FN6: Unidade | FO6: Unidade | FP6: Unidade | FQ6: Unidade | FR6: Unidade | FS6: Unidade | FT6: Metros | FU6: Metros | FV6: Unidade | FW6: Unidade | FX6: Unidade | FY6: Unidade | FZ6: Unidade | GA6: Unidade | GB6: Unidade | GC6: Metros | GD6: Metros | GE6: Unidade | GF6: Unidade | GG6: Unidade | GH6: Unidade | GI6: Unidade | GJ6: Unidade | GK6: Unidade | GL6: Metros | GM6: Metros | GN6: Unidade | GO6: Unidade | GP6: Unidade | GQ6: Unidade | GR6: Unidade | GS6: Unidade | GT6: Unidade | GU6: Metros | GV6: Metros | GW6: Unidade | GX6: Unidade | GY6: Unidade | GZ6: Unidade | HA6: Unidade | HB6: Unidade | HC6: Unidade | HD6: Metros | HE6: Metros | HF6: Unidade | HG6: Unidade | HH6: Unidade | HI6: Unidade | HJ6: Unidade | HK6: Unidade | HL6: Unidade | HM6: Metros | HN6: Metros | HO6: Unidade | HP6: Unidade | HQ6: Unidade | HR6: Unidade | HS6: Unidade | HT6: Unidade | HU6: Unidade | HV6: Metros | HW6: Metros | HX6: Unidade | HY6: Unidade | HZ6: Unidade | IA6: Unidade | IB6: Unidade | IC6: Unidade | ID6: Unidade | IE6: Metros | IF6: Metros | IG6: Unidade | IH6: Unidade | II6: Unidade | IJ6: Unidade | IK6: Unidade | IL6: Unidade | IM6: Unidade | IN6: Metros | IO6: Metros | IP6: Unidade | IQ6: Unidade | IR6: Unidade | IS6: Unidade | IT6: Unidade | IU6: Unidade | IV6: Unidade | IW6: Metros | IX6: Metros | IY6: Unidade | IZ6: Unidade | JA6: Unidade | JB6: Unidade | JC6: Unidade | JD6: Unidade | JE6: Unidade | JF6: Metros | JG6: Metros | JH6: Unidade | JI6: Unidade | JJ6: Unidade | JK6: Unidade | JL6: Unidade | JM6: Unidade | JN6: Unidade | JO6: Metros | JP6: Metros | JQ6: Unidade | JR6: Unidade | JS6: Unidade | JT6: Unidade | JU6: Unidade | JV6: Unidade | JW6: Unidade | JX6: Metros | JY6: Metros | JZ6: Unidade | KA6: Unidade | KB6: Unidade | KC6: Unidade | KD6: Unidade | KE6: Unidade | KF6: Unidade | KG6: Metros | KH6: Metros | KI6: Unidade | KJ6: Unidade | KK6: Unidade | KL6: Unidade | KM6: Unidade | KN6: Unidade | KO6: Unidade | KP6: Metros | KQ6: Metros | KR6: Unidade | KS6: Unidade | KT6: Unidade | KU6: Unidade | KV6: Unidade | KW6: Unidade | KX6: Unidade | KY6: Metros | KZ6: Metros | LA6: Unidade | LB6: Unidade | LC6: Unidade | LD6: Unidade | LE6: Unidade | LF6: Unidade | LG6: Unidade | LH6: Metros | LI6: Metros | LJ6: Unidade | LK6: Unidade | LL6: Unidade | LM6: Unidade | LN6: Unidade | LO6: Unidade | LP6: Unidade | LQ6: Metros | LR6: Metros | LS6: Unidade | LT6: Unidade | LU6: Unidade | LV6: Unidade | LW6: Unidade | LX6: Unidade | LY6: Unidade | LZ6: Metros | MA6: Metros | MB6: Unidade | MC6: Unidade | MD6: Unidade | ME6: Unidade | MF6: Unidade | MG6: Unidade | MH6: Unidade | MI6: Metros | MJ6: Metros | MK6: Unidade | ML6: Unidade | MM6: Unidade | MN6: Unidade | MO6: Unidade | MP6: Unidade | MQ6: Unidade | MR6: Metros | MS6: Metros | MT6: Unidade | MU6: Unidade | MV6: Unidade | MW6: Unidade | MX6: Unidade | MY6: Unidade | MZ6: Unidade | NA6: Metros | NB6: Metros | NC6: Unidade | ND6: Unidade | NE6: Unidade | NF6: Unidade | NG6: Unidade | NH6: Unidade | NI6: Unidade | NJ6: Metros | NK6: Metros | NL6: Unidade | NM6: Unidade | NN6: Unidade | NO6: Unidade | NP6: Unidade | NQ6: Unidade | NR6: Unidade | NS6: Metros | NT6: Metros | NU6: Unidade | NV6: Unidade | NW6: Unidade | NX6: Unidade | NY6: Unidade | NZ6: Unidade | OA6: Unidade | OB6: Metros | OC6: Metros | OD6: Unidade | OE6: Unidade | OF6: Unidade | OG6: Unidade | OH6: Unidade | OI6: Unidade | OJ6: Unidade | OK6: Metros | OL6: Metros | OM6: Unidade | ON6: Unidade | OO6: Unidade | OP6: Unidade | OQ6: Unidade | OR6: Unidade | OS6: Unidade | OT6: Metros | OU6: Metros | OV6: Unidade | OW6: Unidade | OX6: Unidade | OY6: Unidade | OZ6: Unidade | PA6: Unidade | PB6: Unidade | PC6: Metros | PD6: Metros | PE6: Unidade | PF6: Unidade | PG6: Unidade | PH6: Unidade | PI6: Unidade | PJ6: Unidade | PK6: Unidade | PL6: Metros | PM6: Metros | PN6: Unidade | PO6: Unidade | PP6: Unidade | PQ6: Unidade | PR6: Unidade | PS6: Unidade | PT6: Unidade | PU6: Metros | PV6: Metros | PW6: Unidade | PX6: Unidade | PY6: Unidade | PZ6: Unidade | QA6: Unidade | QB6: Unidade | QC6: Unidade | QD6: Metros | QE6: Metros | QF6: Unidade | QG6: Unidade | QH6: Unidade | QI6: Unidade | QJ6: Unidade | QK6: Unidade | QL6: Unidade | QM6: Metros | QN6: Metros | QO6: Unidade | QP6: Unidade | QQ6: Unidade | QR6: Unidade | QS6: Unidade | QT6: Unidade | QU6: Unidade | QV6: Metros | QW6: Metros | QX6: Unidade | QY6: Unidade | QZ6: Unidade | RA6: Unidade | RB6: Unidade | RC6: Unidade | RD6: Unidade | RE6: Metros | RF6: Metros | RG6: Unidade | RH6: Unidade | RI6: Unidade | RJ6: Unidade | RK6: Unidade | RL6: Unidade | RM6: Unidade | RN6: Metros | RO6: Metros | RP6: Unidade | RQ6: Unidade | RR6: Unidade | RS6: Unidade | RT6: Unidade | RU6: Unidade | RV6: Unidade | RW6: Metros | RX6: Metros | RY6: Unidade | RZ6: Unidade | SA6: Unidade | SB6: Unidade | SC6: Unidade | SD6: Unidade | SE6: Unidade | SF6: Metros | SG6: Metros | SH6: Unidade | SI6: Unidade | SJ6: Unidade | SK6: Unidade | SL6: Unidade | SM6: Unidade | SN6: Unidade | SO6: Metros | SP6: Metros | SQ6: Unidade | SR6: Unidade | SS6: Unidade | ST6: Unidade | SU6: Unidade | SV6: Unidade | SW6: Unidade | SX6: Metros | SY6: Metros | SZ6: Unidade | TA6: Unidade | TB6: Unidade | TC6: Unidade | TD6: Unidade | TE6: Unidade | TF6: Unidade | TG6: Metros | TH6: Metros | TI6: Unidade | TJ6: Unidade | TK6: Unidade | TL6: Unidade | TM6: Unidade | TN6: Unidade | TO6: Unidade | TP6: Metros | TQ6: Metros | TR6: Unidade | TS6: Unidade | TT6: Unidade | TU6: Unidade | TV6: Unidade | TW6: Unidade | TX6: Unidade | TY6: Metros | TZ6: Metros | UA6: Unidade | UB6: Unidade | UC6: Unidade | UD6: Unidade | UE6: Unidade | UF6: Unidade | UG6: Unidade | UH6: Metros | UI6: Metros | UJ6: Unidade | UK6: Unidade | UL6: Unidade | UM6: Unidade | UN6: Unidade | UO6: Unidade | UP6: Unidade | UQ6: Metros | UR6: Metros | US6: Unidade | UT6: Unidade | UU6: Unidade | UV6: Unidade | UW6: Unidade | UX6: Unidade | UY6: Unidade | UZ6: Metros | VA6: Metros | VB6: Unidade | VC6: Unidade | VD6: Unidade | VE6: Unidade | VF6: Unidade | VG6: Unidade | VH6: Unidade | VI6: Metros | VJ6: Metros | VK6: Unidade | VL6: Unidade | VM6: Unidade | VN6: Unidade | VO6: Unidade | VP6: Unidade | VQ6: Unidade | VR6: Metros | VS6: Metros | VT6: Unidade | VU6: Unidade | VV6: Unidade | VW6: Unidade | VX6: Unidade | VY6: Unidade | VZ6: Unidade | WA6: Metros | WB6: Metros | WC6: Unidade | WD6: Unidade | WE6: Unidade | WF6: Unidade | WG6: Unidade | WH6: Unidade | WI6: Unidade | WJ6: Metros | WK6: Metros | WL6: Unidade | WM6: Unidade | WN6: Unidade | WO6: Unidade | WP6: Unidade | WQ6: Unidade | WR6: Unidade | WS6: Metros | WT6: Metros | WU6: Unidade | WV6: Unidade | WW6: Unidade | WX6: Unidade | WY6: Unidade | WZ6: Unidade | XA6: Unidade | XB6: Metros | XC6: Metros | XD6: Unidade | XE6: Unidade | XF6: Unidade | XG6: Unidade | XH6: Unidade | XI6: Unidade | XJ6: Unidade | XK6: Metros | XL6: Metros | XM6: Unidade | XN6: Unidade | XO6: Unidade | XP6: Unidade | XQ6: Unidade | XR6: Unidade | XS6: Unidade | XT6: Metros | XU6: Metros | XV6: Unidade | XW6: Unidade | XX6: Unidade | XY6: Unidade | XZ6: Unidade | YA6: Unidade | YB6: Unidade | YC6: Metros | YD6: Metros | YE6: Unidade | YF6: Unidade | YG6: Unidade | YH6: Unidade | YI6: Unidade | YJ6: Unidade | YK6: Unidade | YL6: Metros | YM6: Metros | YN6: Unidade | YO6: Unidade | YP6: Unidade | YQ6: Unidade | YR6: Unidade | YS6: Unidade | YT6: Unidade | YU6: Metros | YV6: Metros | YW6: Unidade | YX6: Unidade | YY6: Unidade | YZ6: Unidade | ZA6: Unidade | ZB6: Unidade | ZC6: Unidade | ZD6: Metros | ZE6: Metros | ZF6: Unidade | ZG6: Unidade | ZH6: Unidade | ZI6: Unidade | ZJ6: Unidade | ZK6: Unidade | ZL6: Unidade | ZM6: Metros | ZN6: Metros | ZO6: Unidade | ZP6: Unidade | ZQ6: Unidade | ZR6: Unidade | ZS6: Unidade | ZT6: Unidade | ZU6: Unidade | ZV6: Metros | ZW6: Metros | ZX6: Unidade | ZY6: Unidade | ZZ6: Unidade | AAA6: Unidade | AAB6: Unidade | AAC6: Unidade | AAD6: Unidade | AAE6: Metros | AAF6: Metros | AAG6: Unidade | AAH6: Unidade | AAI6: Unidade | AAJ6: Unidade | AAK6: Unidade | AAL6: Unidade | AAM6: Unidade | AAN6: Metros | AAO6: Metros | AAP6: Unidade | AAQ6: Unidade | AAR6: Unidade | AAS6: Unidade | AAT6: Unidade | AAU6: Unidade | AAV6: Unidade | AAW6: Metros | AAX6: Metros | AAY6: Unidade | AAZ6: Unidade | ABA6: Unidade | ABB6: Unidade | ABC6: Unidade | ABD6: Unidade | ABE6: Unidade | ABF6: Metros | ABG6: Metros | ABH6: Unidade | ABI6: Unidade | ABJ6: Unidade | ABK6: Unidade | ABL6: Unidade | ABM6: Unidade | ABN6: Unidade | ABO6: Metros | ABP6: Metros | ABQ6: Unidade | ABR6: Unidade | ABS6: Unidade | ABT6: Unidade | ABU6: Unidade | ABV6: Unidade | ABW6: Unidade | ABX6: Metros | ABY6: Metros | ABZ6: Unidade | ACA6: Unidade | ACB6: Unidade | ACC6: Unidade | ACD6: Unidade | ACE6: Unidade | ACF6: Unidade | ACG6: Metros | ACH6: Metros | ACI6: Unidade | ACJ6: Unidade | ACK6: Unidade | ACL6: Unidade | ACM6: Unidade | ACN6: Unidade | ACO6: Unidade | ACP6: Metros | ACQ6: Metros | ACR6: Unidade | ACS6: Unidade | ACT6: Unidade | ACU6: Unidade | ACV6: Unidade | ACW6: Unidade | ACX6: Unidade | ACY6: Metros | ACZ6: Metros | ADA6: Unidade | ADB6: Unidade | ADC6: Unidade | ADD6: Unidade | ADE6: Unidade | ADF6: Unidade | ADG6: Unidade | ADH6: Metros | ADI6: Metros | ADJ6: Unidade | ADK6: Unidade | ADL6: Unidade | ADM6: Unidade | ADN6: Unidade | ADO6: Unidade | ADP6: Unidade | ADQ6: Metros | ADR6: Metros | ADS6: Unidade | ADT6: Unidade | ADU6: Unidade | ADV6: Unidade | ADW6: Unidade | ADX6: Unidade | ADY6: Unidade | ADZ6: Metros | AEA6: Metros | AEB6: Unidade | AEC6: Unidade | AED6: Unidade | AEE6: Unidade | AEF6: Unidade | AEG6: Unidade | AEH6: Unidade | AEI6: Metros | AEJ6: Metros | AEK6: Unidade | AEL6: Unidade | AEM6: Unidade | AEN6: Unidade | AEO6: Unidade | AEP6: Unidade | AEQ6: Unidade | AER6: Metros | AES6: Metros | AET6: Unidade | AEU6: Unidade | AEV6: Unidade | AEW6: Unidade | AEX6: Unidade | AEY6: Unidade | AEZ6: Unidade | AFA6: Metros | AFB6: Metros | AFC6: Unidade | AFD6: Unidade | AFE6: Unidade | AFF6: Unidade | AFG6: Unidade | AFH6: Unidade | AFI6: Unidade | AFJ6: Metros | AFK6: Metros | AFL6: Unidade | AFM6: Unidade | AFN6: Unidade | AFO6: Unidade | AFP6: Unidade | AFQ6: Unidade | AFR6: Unidade | AFS6: Metros | AFT6: Metros | AFU6: Unidade | AFV6: Unidade | AFW6: Unidade | AFX6: Unidade | AFY6: Unidade | AFZ6: Unidade | AGA6: Unidade | AGB6: Metros | AGC6: Metros | AGD6: Unidade | AGE6: Unidade | AGF6: Unidade | AGG6: Unidade | AGH6: Unidade | AGI6: Unidade | AGJ6: Unidade | AGK6: Metros | AGL6: Metros | AGM6: Unidade | AGN6: Unidade | AGO6: Unidade | AGP6: Unidade | AGQ6: Unidade | AGR6: Unidade | AGS6: Unidade | AGT6: Metros | AGU6: Metros | AGV6: Unidade | AGW6: Unidade | AGX6: Unidade | AGY6: Unidade | AGZ6: Unidade | AHA6: Unidade | AHB6: Unidade | AHC6: Metros | AHD6: Metros | AHE6: Unidade | AHF6: Unidade | AHG6: Unidade | AHH6: Unidade | AHI6: Unidade | AHJ6: Unidade | AHK6: Unidade | AHL6: Metros | AHM6: Metros | AHN6: Unidade | AHO6: Unidade | AHP6: Unidade | AHQ6: Unidade | AHR6: Unidade | AHS6: Unidade | AHT6: Unidade | AHU6: Metros | AHV6: Metros | AHW6: Unidade | AHX6: Unidade | AHY6: Unidade | AHZ6: Unidade | AIA6: Unidade | AIB6: Unidade | AIC6: Unidade | AID6: Metros | AIE6: Metros | AIF6: Unidade | AIG6: Unidade | AIH6: Unidade | AII6: Unidade | AIJ6: Unidade | AIK6: Unidade | AIL6: Unidade | AIM6: Metros | AIN6: Metros | AIO6: Unidade | AIP6: Unidade | AIQ6: Unidade | AIR6: Unidade | AIS6: Unidade | AIT6: Unidade | AIU6: Unidade | AIV6: Metros | AIW6: Metros | AIX6: Unidade | AIY6: Unidade | AIZ6: Unidade | AJA6: Unidade | AJB6: Unidade | AJC6: Unidade | AJD6: Unidade | AJE6: Metros | AJF6: Metros | AJG6: Unidade | AJH6: Unidade | AJI6: Unidade | AJJ6: Unidade | AJK6: Unidade | AJL6: Unidade | AJM6: Unidade | AJN6: Metros | AJO6: Metros | AJP6: Unidade | AJQ6: Unidade | AJR6: Unidade | AJS6: Unidade | AJT6: Unidade
C7: DADOS DA EQUIPE | F7: PRODUTIVIDADE POR SERVIÇO | J7: PRODUTIVIDADE | O7: PRODUÇÃO ACUMULADA | U7: =SUM(U9:U24) -> 0 | V7: =SUM(V9:V24) -> 0 | W7: =SUM(W9:W24) -> 0 | X7: =SUM(X9:X24) -> 0 | Y7: =SUM(Y9:Y24) -> 0 | Z7: =SUM(Z9:Z24) -> 0 | AA7: =SUM(AA9:AA24) -> 0 | AB7: =SUM(AB9:AB24) -> 0 | ... AJT7: =SUM(AJT9:AJT24) -> 0
B8: Nº EQUIPE | C8: EMPRESA | D8: ENCARREGADO LIDER | E8: DIAS TRAB. | F8: Ind. Prod. LA | G8: Ind Prod LE | H8: Ind Prod PRA | I8: Ind Prod PRE | J8: IND. PROD REDE | K8: IND. PROD LIG | L8: LA | M8: LE | N8: PRA | O8: PRE | P8: PV's | Q8: LIE | R8: LIA | S8: IHM | T8: RHM | U8: LA | V8: LE | W8: PRA | X8: PRE | Y8: PV's | Z8: LIE | AA8: LIA | AB8: IHM | AC8: RHM | AD8: LA | AE8: LE | AF8: PRA | AG8: PRE | AH8: PV's | AI8: LIE | AJ8: LIA | AK8: IHM | AL8: RHM | AM8: LA | AN8: LE | AO8: PRA | AP8: PRE | AQ8: PV's | AR8: LIE | AS8: LIA | AT8: IHM | AU8: RHM | AV8: LA | AW8: LE | AX8: PRA | AY8: PRE | AZ8: PV's | BA8: LIE | BB8: LIA | BC8: IHM | BD8: RHM | BE8: LA | BF8: LE | BG8: PRA | BH8: PRE | BI8: PV's | BJ8: LIE | BK8: LIA | BL8: IHM | BM8: RHM | BN8: LA | BO8: LE | BP8: PRA | BQ8: PRE | BR8: PV's | BS8: LIE | BT8: LIA | BU8: IHM | BV8: RHM | BW8: LA | BX8: LE | BY8: PRA | BZ8: PRE | CA8: PV's | CB8: LIE | CC8: LIA | CD8: IHM | CE8: RHM | CF8: LA | CG8: LE | CH8: PRA | CI8: PRE | CJ8: PV's | CK8: LIE | CL8: LIA | CM8: IHM | CN8: RHM | CO8: LA | CP8: LE | CQ8: PRA | CR8: PRE | CS8: PV's | CT8: LIE | CU8: LIA | CV8: IHM | CW8: RHM | CX8: LA | CY8: LE | CZ8: PRA | DA8: PRE | DB8: PV's | DC8: LIE | DD8: LIA | DE8: IHM | DF8: RHM | DG8: LA | DH8: LE | DI8: PRA | DJ8: PRE | DK8: PV's | DL8: LIE | DM8: LIA | DN8: IHM | DO8: RHM | DP8: LA | DQ8: LE | DR8: PRA | DS8: PRE | DT8: PV's | DU8: LIE | DV8: LIA | DW8: IHM | DX8: RHM | DY8: LA | DZ8: LE | EA8: PRA | EB8: PRE | EC8: PV's | ED8: LIE | EE8: LIA | EF8: IHM | EG8: RHM | EH8: LA | EI8: LE | EJ8: PRA | EK8: PRE | EL8: PV's | EM8: LIE | EN8: LIA | EO8: IHM | EP8: RHM | EQ8: LA | ER8: LE | ES8: PRA | ET8: PRE | EU8: PV's | EV8: LIE | EW8: LIA | EX8: IHM | EY8: RHM | EZ8: LA | FA8: LE | FB8: PRA | FC8: PRE | FD8: PV's | FE8: LIE | FF8: LIA | FG8: IHM | FH8: RHM | FI8: LA | FJ8: LE | FK8: PRA | FL8: PRE | FM8: PV's | FN8: LIE | FO8: LIA | FP8: IHM | FQ8: RHM | FR8: LA | FS8: LE | FT8: PRA | FU8: PRE | FV8: PV's | FW8: LIE | FX8: LIA | FY8: IHM | FZ8: RHM | GA8: LA | GB8: LE | GC8: PRA | GD8: PRE | GE8: PV's | GF8: LIE | GG8: LIA | GH8: IHM | GI8: RHM | GJ8: LA | GK8: LE | GL8: PRA | GM8: PRE | GN8: PV's | GO8: LIE | GP8: LIA | GQ8: IHM | GR8: RHM | GS8: LA | GT8: LE | GU8: PRA | GV8: PRE | GW8: PV's | GX8: LIE | GY8: LIA | GZ8: IHM | HA8: RHM | HB8: LA | HC8: LE | HD8: PRA | HE8: PRE | HF8: PV's | HG8: LIE | HH8: LIA | HI8: IHM | HJ8: RHM | HK8: LA | HL8: LE | HM8: PRA | HN8: PRE | HO8: PV's | HP8: LIE | HQ8: LIA | HR8: IHM | HS8: RHM | HT8: LA | HU8: LE | HV8: PRA | HW8: PRE | HX8: PV's | HY8: LIE | HZ8: LIA | IA8: IHM | IB8: RHM | IC8: LA | ID8: LE | IE8: PRA | IF8: PRE | IG8: PV's | IH8: LIE | II8: LIA | IJ8: IHM | IK8: RHM | IL8: LA | IM8: LE | IN8: PRA | IO8: PRE | IP8: PV's | IQ8: LIE | IR8: LIA | IS8: IHM | IT8: RHM | IU8: LA | IV8: LE | IW8: PRA | IX8: PRE | IY8: PV's | IZ8: LIE | JA8: LIA | JB8: IHM | JC8: RHM | JD8: LA | JE8: LE | JF8: PRA | JG8: PRE | JH8: PV's | JI8: LIE | JJ8: LIA | JK8: IHM | JL8: RHM | JM8: LA | JN8: LE | JO8: PRA | JP8: PRE | JQ8: PV's | JR8: LIE | JS8: LIA | JT8: IHM | JU8: RHM | JV8: LA | JW8: LE | JX8: PRA | JY8: PRE | JZ8: PV's | KA8: LIE | KB8: LIA | KC8: IHM | KD8: RHM | KE8: LA | KF8: LE | KG8: PRA | KH8: PRE | KI8: PV's | KJ8: LIE | KK8: LIA | KL8: IHM | KM8: RHM | KN8: LA | KO8: LE | KP8: PRA | KQ8: PRE | KR8: PV's | KS8: LIE | KT8: LIA | KU8: IHM | KV8: RHM | KW8: LA | KX8: LE | KY8: PRA | KZ8: PRE | LA8: PV's | LB8: LIE | LC8: LIA | LD8: IHM | LE8: RHM | LF8: LA | LG8: LE | LH8: PRA | LI8: PRE | LJ8: PV's | LK8: LIE | LL8: LIA | LM8: IHM | LN8: RHM | LO8: LA | LP8: LE | LQ8: PRA | LR8: PRE | LS8: PV's | LT8: LIE | LU8: LIA | LV8: IHM | LW8: RHM | LX8: LA | LY8: LE | LZ8: PRA | MA8: PRE | MB8: PV's | MC8: LIE | MD8: LIA | ME8: IHM | MF8: RHM | MG8: LA | MH8: LE | MI8: PRA | MJ8: PRE | MK8: PV's | ML8: LIE | MM8: LIA | MN8: IHM | MO8: RHM | MP8: LA | MQ8: LE | MR8: PRA | MS8: PRE | MT8: PV's | MU8: LIE | MV8: LIA | MW8: IHM | MX8: RHM | MY8: LA | MZ8: LE | NA8: PRA | NB8: PRE | NC8: PV's | ND8: LIE | NE8: LIA | NF8: IHM | NG8: RHM | NH8: LA | NI8: LE | NJ8: PRA | NK8: PRE | NL8: PV's | NM8: LIE | NN8: LIA | NO8: IHM | NP8: RHM | NQ8: LA | NR8: LE | NS8: PRA | NT8: PRE | NU8: PV's | NV8: LIE | NW8: LIA | NX8: IHM | NY8: RHM | NZ8: LA | OA8: LE | OB8: PRA | OC8: PRE | OD8: PV's | OE8: LIE | OF8: LIA | OG8: IHM | OH8: RHM | OI8: LA | OJ8: LE | OK8: PRA | OL8: PRE | OM8: PV's | ON8: LIE | OO8: LIA | OP8: IHM | OQ8: RHM | OR8: LA | OS8: LE | OT8: PRA | OU8: PRE | OV8: PV's | OW8: LIE | OX8: LIA | OY8: IHM | OZ8: RHM | PA8: LA | PB8: LE | PC8: PRA | PD8: PRE | PE8: PV's | PF8: LIE | PG8: LIA | PH8: IHM | PI8: RHM | PJ8: LA | PK8: LE | PL8: PRA | PM8: PRE | PN8: PV's | PO8: LIE | PP8: LIA | PQ8: IHM | PR8: RHM | PS8: LA | PT8: LE | PU8: PRA | PV8: PRE | PW8: PV's | PX8: LIE | PY8: LIA | PZ8: IHM | QA8: RHM | QB8: LA | QC8: LE | QD8: PRA | QE8: PRE | QF8: PV's | QG8: LIE | QH8: LIA | QI8: IHM | QJ8: RHM | QK8: LA | QL8: LE | QM8: PRA | QN8: PRE | QO8: PV's | QP8: LIE | QQ8: LIA | QR8: IHM | QS8: RHM | QT8: LA | QU8: LE | QV8: PRA | QW8: PRE | QX8: PV's | QY8: LIE | QZ8: LIA | RA8: IHM | RB8: RHM | RC8: LA | RD8: LE | RE8: PRA | RF8: PRE | RG8: PV's | RH8: LIE | RI8: LIA | RJ8: IHM | RK8: RHM | RL8: LA | RM8: LE | RN8: PRA | RO8: PRE | RP8: PV's | RQ8: LIE | RR8: LIA | RS8: IHM | RT8: RHM | RU8: LA | RV8: LE | RW8: PRA | RX8: PRE | RY8: PV's | RZ8: LIE | SA8: LIA | SB8: IHM | SC8: RHM | SD8: LA | SE8: LE | SF8: PRA | SG8: PRE | SH8: PV's | SI8: LIE | SJ8: LIA | SK8: IHM | SL8: RHM | SM8: LA | SN8: LE | SO8: PRA | SP8: PRE | SQ8: PV's | SR8: LIE | SS8: LIA | ST8: IHM | SU8: RHM | SV8: LA | SW8: LE | SX8: PRA | SY8: PRE | SZ8: PV's | TA8: LIE | TB8: LIA | TC8: IHM | TD8: RHM | TE8: LA | TF8: LE | TG8: PRA | TH8: PRE | TI8: PV's | TJ8: LIE | TK8: LIA | TL8: IHM | TM8: RHM | TN8: LA | TO8: LE | TP8: PRA | TQ8: PRE | TR8: PV's | TS8: LIE | TT8: LIA | TU8: IHM | TV8: RHM | TW8: LA | TX8: LE | TY8: PRA | TZ8: PRE | UA8: PV's | UB8: LIE | UC8: LIA | UD8: IHM | UE8: RHM | UF8: LA | UG8: LE | UH8: PRA | UI8: PRE | UJ8: PV's | UK8: LIE | UL8: LIA | UM8: IHM | UN8: RHM | UO8: LA | UP8: LE | UQ8: PRA | UR8: PRE | US8: PV's | UT8: LIE | UU8: LIA | UV8: IHM | UW8: RHM | UX8: LA | UY8: LE | UZ8: PRA | VA8: PRE | VB8: PV's | VC8: LIE | VD8: LIA | VE8: IHM | VF8: RHM | VG8: LA | VH8: LE | VI8: PRA | VJ8: PRE | VK8: PV's | VL8: LIE | VM8: LIA | VN8: IHM | VO8: RHM | VP8: LA | VQ8: LE | VR8: PRA | VS8: PRE | VT8: PV's | VU8: LIE | VV8: LIA | VW8: IHM | VX8: RHM | VY8: LA | VZ8: LE | WA8: PRA | WB8: PRE | WC8: PV's | WD8: LIE | WE8: LIA | WF8: IHM | WG8: RHM | WH8: LA | WI8: LE | WJ8: PRA | WK8: PRE | WL8: PV's | WM8: LIE | WN8: LIA | WO8: IHM | WP8: RHM | WQ8: LA | WR8: LE | WS8: PRA | WT8: PRE | WU8: PV's | WV8: LIE | WW8: LIA | WX8: IHM | WY8: RHM | WZ8: LA | XA8: LE | XB8: PRA | XC8: PRE | XD8: PV's | XE8: LIE | XF8: LIA | XG8: IHM | XH8: RHM | XI8: LA | XJ8: LE | XK8: PRA | XL8: PRE | XM8: PV's | XN8: LIE | XO8: LIA | XP8: IHM | XQ8: RHM | XR8: LA | XS8: LE | XT8: PRA | XU8: PRE | XV8: PV's | XW8: LIE | XX8: LIA | XY8: IHM | XZ8: RHM | YA8: LA | YB8: LE | YC8: PRA | YD8: PRE | YE8: PV's | YF8: LIE | YG8: LIA | YH8: IHM | YI8: RHM | YJ8: LA | YK8: LE | YL8: PRA | YM8: PRE | YN8: PV's | YO8: LIE | YP8: LIA | YQ8: IHM | YR8: RHM | YS8: LA | YT8: LE | YU8: PRA | YV8: PRE | YW8: PV's | YX8: LIE | YY8: LIA | YZ8: IHM | ZA8: RHM | ZB8: LA | ZC8: LE | ZD8: PRA | ZE8: PRE | ZF8: PV's | ZG8: LIE | ZH8: LIA | ZI8: IHM | ZJ8: RHM | ZK8: LA | ZL8: LE | ZM8: PRA | ZN8: PRE | ZO8: PV's | ZP8: LIE | ZQ8: LIA | ZR8: IHM | ZS8: RHM | ZT8: LA | ZU8: LE | ZV8: PRA | ZW8: PRE | ZX8: PV's | ZY8: LIE | ZZ8: LIA | AAA8: IHM | AAB8: RHM | AAC8: LA | AAD8: LE | AAE8: PRA | AAF8: PRE | AAG8: PV's | AAH8: LIE | AAI8: LIA | AAJ8: IHM | AAK8: RHM | AAL8: LA | AAM8: LE | AAN8: PRA | AAO8: PRE | AAP8: PV's | AAQ8: LIE | AAR8: LIA | AAS8: IHM | AAT8: RHM | AAU8: LA | AAV8: LE | AAW8: PRA | AAX8: PRE | AAY8: PV's | AAZ8: LIE | ABA8: LIA | ABB8: IHM | ABC8: RHM | ABD8: LA | ABE8: LE | ABF8: PRA | ABG8: PRE | ABH8: PV's | ABI8: LIE | ABJ8: LIA | ABK8: IHM | ABL8: RHM | ABM8: LA | ABN8: LE | ABO8: PRA | ABP8: PRE | ABQ8: PV's | ABR8: LIE | ABS8: LIA | ABT8: IHM | ABU8: RHM | ABV8: LA | ABW8: LE | ABX8: PRA | ABY8: PRE | ABZ8: PV's | ACA8: LIE | ACB8: LIA | ACC8: IHM | ACD8: RHM | ACE8: LA | ACF8: LE | ACG8: PRA | ACH8: PRE | ACI8: PV's | ACJ8: LIE | ACK8: LIA | ACL8: IHM | ACM8: RHM | ACN8: LA | ACO8: LE | ACP8: PRA | ACQ8: PRE | ACR8: PV's | ACS8: LIE | ACT8: LIA | ACU8: IHM | ACV8: RHM | ACW8: LA | ACX8: LE | ACY8: PRA | ACZ8: PRE | ADA8: PV's | ADB8: LIE | ADC8: LIA | ADD8: IHM | ADE8: RHM | ADF8: LA | ADG8: LE | ADH8: PRA | ADI8: PRE | ADJ8: PV's | ADK8: LIE | ADL8: LIA | ADM8: IHM | ADN8: RHM | ADO8: LA | ADP8: LE | ADQ8: PRA | ADR8: PRE | ADS8: PV's | ADT8: LIE | ADU8: LIA | ADV8: IHM | ADW8: RHM | ADX8: LA | ADY8: LE | ADZ8: PRA | AEA8: PRE | AEB8: PV's | AEC8: LIE | AED8: LIA | AEE8: IHM | AEF8: RHM | AEG8: LA | AEH8: LE | AEI8: PRA | AEJ8: PRE | AEK8: PV's | AEL8: LIE | AEM8: LIA | AEN8: IHM | AEO8: RHM | AEP8: LA | AEQ8: LE | AER8: PRA | AES8: PRE | AET8: PV's | AEU8: LIE | AEV8: LIA | AEW8: IHM | AEX8: RHM | AEY8: LA | AEZ8: LE | AFA8: PRA | AFB8: PRE | AFC8: PV's | AFD8: LIE | AFE8: LIA | AFF8: IHM | AFG8: RHM | AFH8: LA | AFI8: LE | AFJ8: PRA | AFK8: PRE | AFL8: PV's | AFM8: LIE | AFN8: LIA | AFO8: IHM | AFP8: RHM | AFQ8: LA | AFR8: LE | AFS8: PRA | AFT8: PRE | AFU8: PV's | AFV8: LIE | AFW8: LIA | AFX8: IHM | AFY8: RHM | AFZ8: LA | AGA8: LE | AGB8: PRA | AGC8: PRE | AGD8: PV's | AGE8: LIE | AGF8: LIA | AGG8: IHM | AGH8: RHM | AGI8: LA | AGJ8: LE | AGK8: PRA | AGL8: PRE | AGM8: PV's | AGN8: LIE | AGO8: LIA | AGP8: IHM | AGQ8: RHM | AGR8: LA | AGS8: LE | AGT8: PRA | AGU8: PRE | AGV8: PV's | AGW8: LIE | AGX8: LIA | AGY8: IHM | AGZ8: RHM | AHA8: LA | AHB8: LE | AHC8: PRA | AHD8: PRE | AHE8: PV's | AHF8: LIE | AHG8: LIA | AHH8: IHM | AHI8: RHM | AHJ8: LA | AHK8: LE | AHL8: PRA | AHM8: PRE | AHN8: PV's | AHO8: LIE | AHP8: LIA | AHQ8: IHM | AHR8: RHM | AHS8: LA | AHT8: LE | AHU8: PRA | AHV8: PRE | AHW8: PV's | AHX8: LIE | AHY8: LIA | AHZ8: IHM | AIA8: RHM | AIB8: LA | AIC8: LE | AID8: PRA | AIE8: PRE | AIF8: PV's | AIG8: LIE | AIH8: LIA | AII8: IHM | AIJ8: RHM | AIK8: LA | AIL8: LE | AIM8: PRA | AIN8: PRE | AIO8: PV's | AIP8: LIE | AIQ8: LIA | AIR8: IHM | AIS8: RHM | AIT8: LA | AIU8: LE | AIV8: PRA | AIW8: PRE | AIX8: PV's | AIY8: LIE | AIZ8: LIA | AJA8: IHM | AJB8: RHM | AJC8: LA | AJD8: LE | AJE8: PRA | AJF8: PRE | AJG8: PV's | AJH8: LIE | AJI8: LIA | AJJ8: IHM | AJK8: RHM | AJL8: LA | AJM8: LE | AJN8: PRA | AJO8: PRE | AJP8: PV's | AJQ8: LIE | AJR8: LIA | AJS8: IHM | AJT8: RHM
B9: 1 | C9: CHIRA | D9: CASSIO | E9: 42 | F9: =Tabela23[[#This Row],[LA]]/Tabela23[[#This Row],[DIAS TRAB.]] -> 0.78571429 | G9: =Tabela23[[#This Row],[LE]]/Tabela23[[#This Row],[DIAS TRAB.]] -> 1 | H9: =Tabela23[[#This Row],[PRA]]/Tabela23[[#This Row],[DIAS TRAB.]] -> 1.2857143 | I9: =Tabela23[[#This Row],[PRE]]/Tabela23[[#This Row],[DIAS TRAB.]] -> 5.8095238 | J9: =SUM(Tabela23[[#This Row],[PRA]:[PRE]])/Tabela23[[#This Row],[DIAS TRAB.]] -> 7.0952381 | K9: {=SUM(L9:M9/Tabela23[[#This Row],[DIAS TRAB.]])} -> 1.7857143 | L9: =SUMIF($U$8:$AJT$8,"LA",$U9:$AJT9) -> 33 | M9: =SUMIF($U$8:$AJT$8,"LE",$U9:$AJT9) -> 42 | N9: =SUMIF($U$8:$AJT$8,"PRA",$U9:$AJT9) -> 54 | O9: =SUMIF($U$8:$AJT$8,"PRE",$U9:$AJT9) -> 244 | P9: =SUMIF($U$8:$AJT$8,"PV's",$U9:$AJT9) -> 5 | Q9: =SUMIF($U$8:$AJT$8,"LIE",$U9:$AJT9) -> 0 | R9: =SUMIF($U$8:$AJT$8,"LIA",$U9:$AJT9) -> 18 | S9: =SUMIF($U$8:$AJT$8,"IHM",$U9:$AJT9) -> 17 | T9: =SUMIF($U$8:$AJT$8,"RHM",$U9:$AJT9) -> 0 | BH9: 3 | BQ9: 3 | BZ9: 3 | CI9: 3 | CR9: 3 | DS9: 3 | EB9: 3 | EK9: 18 | ET9: 18 | FC9: 6 | GM9: 24 | GV9: 18 | HE9: 12 | HF9: 1 | HN9: 18 | IX9: =12 -> 12 | JF9: 10 | JK9: 2 | JM9: 4 | JT9: 4 | JX9: 15 | KB9: 14 | KZ9: 6 | LA9: 1 | LF9: 10 | LR9: 6 | MH9: 2 | MI9: 4 | MJ9: 6 | MQ9: 1 | NI9: 3 | NK9: 13 | NQ9: 11 | NR9: 4 | NT9: 6 | NX9: 2 | OG9: 5 | OL9: 6 | OM9: 1 | OO9: 4 | OP9: 4 | OR9: 3 | OS9: 5 | OT9: 10 | OU9: 6 | QL9: 2 | QN9: 10 | QU9: 3 | RD9: 3 | SD9: 5 | SE9: 5 | SF9: 15 | SG9: 6 | SN9: 1 | SQ9: 1 | SW9: 2 | SY9: 6 | TO9: 2 | TQ9: 12 | TR9: 1 | TX9: 4 | TZ9: 8 | UP9: 5 | UR9: 6
B10: 2 | C10: CHIRA | D10: MATEUS | E10: 42 | F10: =Tabela23[[#This Row],[LA]]/Tabela23[[#This Row],[DIAS TRAB.]] -> 2.1428571 | G10: =Tabela23[[#This Row],[LE]]/Tabela23[[#This Row],[DIAS TRAB.]] -> 0.47619048 | H10: =Tabela23[[#This Row],[PRA]]/Tabela23[[#This Row],[DIAS TRAB.]] -> 5.047619 | I10: =Tabela23[[#This Row],[PRE]]/Tabela23[[#This Row],[DIAS TRAB.]] -> 1.9285714 | J10: =SUM(Tabela23[[#This Row],[PRA]:[PRE]])/Tabela23[[#This Row],[DIAS TRAB.]] -> 6.9761905 | K10: {=SUM(L10:M10/Tabela23[[#This Row],[DIAS TRAB.]])} -> 2.6190476 | L10: =SUMIF($U$8:$AJT$8,"LA",$U10:$AJT10) -> 90 | M10: =SUMIF($U$8:$AJT$8,"LE",$U10:$AJT10) -> 20 | N10: =SUMIF($U$8:$AJT$8,"PRA",$U10:$AJT10) -> 212 | O10: =SUMIF($U$8:$AJT$8,"PRE",$U10:$AJT10) -> 81 | P10: =SUMIF($U$8:$AJT$8,"PV's",$U10:$AJT10) -> 6 | Q10: =SUMIF($U$8:$AJT$8,"LIE",$U10:$AJT10) -> 0 | R10: =SUMIF($U$8:$AJT$8,"LIA",$U10:$AJT10) -> 0 | S10: =SUMIF($U$8:$AJT$8,"IHM",$U10:$AJT10) -> 26 | T10: =SUMIF($U$8:$AJT$8,"RHM",$U10:$AJT10) -> 0 | BG10: 3 | BP10: 3 | BY10: 3 | CF10: 9 | CH10: 3 | CO10: 9 | CQ10: 3 | CX10: 9 | CZ10: 3 | DP10: 9 | DR10: 3 | DY10: 9 | EA10: 3 | EH10: 9 | EJ10: 3 | ES10: 3 | EU10: 1 | FD10: 1 | GS10: 10 | GU10: 11 | HD10: 30 | HM10: 8 | IU10: 10 | IV10: 4 | IW10: 20 | JD10: 4 | JF10: 10 | JG10: 14 | JK10: 6 | JM10: 3 | JN10: 2 | JO10: 6 | JP10: 11 | JT10: 5 | JY10: 9 | KC10: 10 | KL10: 5 | KW10: 6 | KY10: 36 | LI10: 5 | LR10: 6 | MR10: 12 | NJ10: 15 | QL10: 3 | SO10: 6 | SP10: 6 | SV10: 3 | SX10: 6 | SY10: 12 | TO10: 9 | TP10: 22 | TQ10: 6 | UA10: 2 | UP10: 2 | UR10: 12 | US10: 2
B11: 3 | C11: VF | D11: PAULO | E11: 42 | F11: =Tabela23[[#This Row],[LA]]/Tabela23[[#This Row],[DIAS TRAB.]] -> 1.2619048 | G11: =Tabela23[[#This Row],[LE]]/Tabela23[[#This Row],[DIAS TRAB.]] -> 0.76190476 | H11: =Tabela23[[#This Row],[PRA]]/Tabela23[[#This Row],[DIAS TRAB.]] -> 3.8738095 | I11: =Tabela23[[#This Row],[PRE]]/Tabela23[[#This Row],[DIAS TRAB.]] -> 5.0095238 | J11: =SUM(Tabela23[[#This Row],[PRA]:[PRE]])/Tabela23[[#This Row],[DIAS TRAB.]] -> 8.8833333 | K11: {=SUM(L11:M11/Tabela23[[#This Row],[DIAS TRAB.]])} -> 2.0238095 | L11: =SUMIF($U$8:$AJT$8,"LA",$U11:$AJT11) -> 53 | M11: =SUMIF($U$8:$AJT$8,"LE",$U11:$AJT11) -> 32 | N11: =SUMIF($U$8:$AJT$8,"PRA",$U11:$AJT11) -> 162.7 | O11: =SUMIF($U$8:$AJT$8,"PRE",$U11:$AJT11) -> 210.4 | P11: =SUMIF($U$8:$AJT$8,"PV's",$U11:$AJT11) -> 7 | Q11: =SUMIF($U$8:$AJT$8,"LIE",$U11:$AJT11) -> 0 | R11: =SUMIF($U$8:$AJT$8,"LIA",$U11:$AJT11) -> 42 | S11: =SUMIF($U$8:$AJT$8,"IHM",$U11:$AJT11) -> 5 | T11: =SUMIF($U$8:$AJT$8,"RHM",$U11:$AJT11) -> 0 | JD11: 4 | JF11: 17 | JG11: 15 | JN11: 1 | JP11: 6 | KE11: 6 | KF11: 2 | KG11: =17+2.8 -> 19.8 | KH11: 6 | MG11: 10 | MP11: 2 | MW11: 3 | NH11: 6 | NJ11: 6 | NQ11: 12 | NT11: 6 | OA11: 7 | OC11: 6 | OD11: 1 | OI11: 3 | OL11: 18 | OM11: 1 | OO11: 4 | OR11: 10 | OU11: 22 | PV11: 16 | PZ11: 2 | QH11: 5 | QM11: 96.9 | QO11: 1 | QQ11: 13 | RF11: =16+6.4 -> 22.4 | RI11: 20 | SF11: 23 | SG11: =6+6+9 -> 21 | SN11: 4 | SP11: 6 | SY11: 12 | TQ11: =18+6 -> 24 | TX11: 18 | TZ11: 18 | UR11: 12 | US11: 4
E24: PRODUTIVIDADE MÉDIA | F24: =AVERAGE(F9:F14) -> 1.3968254 | G24: =AVERAGE(G9:G14) -> 0.74603175 | H24: =AVERAGE(H9:H14) -> 3.402381 | I24: =AVERAGE(I9:I14) -> 4.2492063 | J24: =AVERAGE(J9:J10) -> 7.0357143 | K24: =AVERAGE(K9:K10) -> 2.202381
E25: Média Interna | F25: =TRIMMEAN(F9:F14,40%) -> 1.3968254 | G25: =TRIMMEAN(G9:G14,40%) -> 0.74603175 | H25: =TRIMMEAN(H9:H14,40%) -> 3.402381 | I25: =TRIMMEAN(I9:I14,40%) -> 4.2492063 | J25: =TRIMMEAN(J9:J14,40%) -> 7.6515873 | K25: =TRIMMEAN(K9:K14,40%) -> 2.1428571
US26: =SUM(US9:VA24) -> 6 | UT26: =SUM(UT9:VB24) -> 0 | UU26: =SUM(UU9:VC24) -> 0 | UV26: =SUM(UV9:VD24) -> 0 | UW26: =SUM(UW9:VE24) -> 0
K28: TOTAL EXECUTADO NÚCLEO | L28: =SUBTOTAL(109,L9:L22) -> 176 | M28: =SUBTOTAL(109,M9:M22) -> 94 | N28: =SUBTOTAL(109,N9:N22) -> 428.7 | O28: =SUBTOTAL(109,O9:O22) -> 535.4 | P28: =SUBTOTAL(109,P9:P22) -> 18 | Q28: =SUBTOTAL(109,Q9:Q22) -> 0 | R28: =SUBTOTAL(109,R9:R22) -> 60 | S28: =SUBTOTAL(109,S9:S22) -> 48 | T28: =SUBTOTAL(109,T9:T22) -> 0

Sheet RESUMO
B1: 46052
F3: Und | G3: m
B4: Data | C4: Dia Útil | D4: Lig_Água | E4: Lig_Esgoto | F4: Rede_Água | G4: Rede_Esgoto | H4: Ligações2 | I4: Rede | J4: Dia_semana | L4: Feriados
B5: 46061 | C5: {=_xlfn.IFS(OR(Tabela136[[#This Row],[Data]]=$L$5,Tabela136[[#This Row],[Data]]=$L$6,Tabela136[[#This Row],[Data]]=$L$7),"Não",J5=1,"Não",J5>1,"Sim")} -> Não | D5: 14 | E5: 0 | F5: 86.8 | G5: 44 | H5: =SUM(Tabela136[[#This Row],[Lig_Água]:[Lig_Esgoto]]) -> 14 | I5: =SUM(Tabela136[[#This Row],[Rede_Água]:[Rede_Esgoto]]) -> 130.8 | J5: =WEEKDAY(Tabela136[[#This Row],[Data]],1) -> 1 | L5: 46069
B6: 46062 | C6: {=_xlfn.IFS(OR(Tabela136[[#This Row],[Data]]=$L$5,Tabela136[[#This Row],[Data]]=$L$6,Tabela136[[#This Row],[Data]]=$L$7),"Não",J6=1,"Não",J6>1,"Sim")} -> Sim | D6: 0 | E6: 0 | F6: 21 | G6: 13 | H6: =SUM(Tabela136[[#This Row],[Lig_Água]:[Lig_Esgoto]]) -> 0 | I6: =SUM(Tabela136[[#This Row],[Rede_Água]:[Rede_Esgoto]]) -> 34 | J6: =WEEKDAY(Tabela136[[#This Row],[Data]],1) -> 2 | L6: 46070
B7: 46063 | C7: {=_xlfn.IFS(OR(Tabela136[[#This Row],[Data]]=$L$5,Tabela136[[#This Row],[Data]]=$L$6,Tabela136[[#This Row],[Data]]=$L$7),"Não",J7=1,"Não",J7>1,"Sim")} -> Sim | D7: 0 | E7: 0 | F7: 0 | G7: 12 | H7: =SUM(Tabela136[[#This Row],[Lig_Água]:[Lig_Esgoto]]) -> 0 | I7: =SUM(Tabela136[[#This Row],[Rede_Água]:[Rede_Esgoto]]) -> 12 | J7: =WEEKDAY(Tabela136[[#This Row],[Data]],1) -> 3 | L7: 46067
B8: 46064 | C8: {=_xlfn.IFS(OR(Tabela136[[#This Row],[Data]]=$L$5,Tabela136[[#This Row],[Data]]=$L$6,Tabela136[[#This Row],[Data]]=$L$7),"Não",J8=1,"Não",J8>1,"Sim")} -> Sim | D8: 0 | E8: 0 | F8: 0 | G8: 6 | H8: =SUM(Tabela136[[#This Row],[Lig_Água]:[Lig_Esgoto]]) -> 0 | I8: =SUM(Tabela136[[#This Row],[Rede_Água]:[Rede_Esgoto]]) -> 6 | J8: =WEEKDAY(Tabela136[[#This Row],[Data]],1) -> 4
B9: 46065 | C9: {=_xlfn.IFS(OR(Tabela136[[#This Row],[Data]]=$L$5,Tabela136[[#This Row],[Data]]=$L$6,Tabela136[[#This Row],[Data]]=$L$7),"Não",J9=1,"Não",J9>1,"Sim")} -> Sim | D9: 8 | E9: 0 | F9: 0 | G9: 24 | H9: =SUM(Tabela136[[#This Row],[Lig_Água]:[Lig_Esgoto]]) -> 8 | I9: =SUM(Tabela136[[#This Row],[Rede_Água]:[Rede_Esgoto]]) -> 24 | J9: =WEEKDAY(Tabela136[[#This Row],[Data]],1) -> 5
B10: 46066 | C10: {=_xlfn.IFS(OR(Tabela136[[#This Row],[Data]]=$L$5,Tabela136[[#This Row],[Data]]=$L$6,Tabela136[[#This Row],[Data]]=$L$7),"Não",J10=1,"Não",J10>1,"Sim")} -> Sim | D10: 0 | E10: 0 | F10: 10 | G10: 28 | H10: =SUM(Tabela136[[#This Row],[Lig_Água]:[Lig_Esgoto]]) -> 0 | I10: =SUM(Tabela136[[#This Row],[Rede_Água]:[Rede_Esgoto]]) -> 38 | J10: =WEEKDAY(Tabela136[[#This Row],[Data]],1) -> 6
B11: 46067 | C11: {=_xlfn.IFS(OR(Tabela136[[#This Row],[Data]]=$L$5,Tabela136[[#This Row],[Data]]=$L$6,Tabela136[[#This Row],[Data]]=$L$7),"Não",J11=1,"Não",J11>1,"Sim")} -> Não | D11: 0 | E11: 0 | F11: 0 | G11: 0 | H11: =SUM(Tabela136[[#This Row],[Lig_Água]:[Lig_Esgoto]]) -> 0 | I11: =SUM(Tabela136[[#This Row],[Rede_Água]:[Rede_Esgoto]]) -> 0 | J11: =WEEKDAY(Tabela136[[#This Row],[Data]],1) -> 7
B12: 46068 | C12: {=_xlfn.IFS(OR(Tabela136[[#This Row],[Data]]=$L$5,Tabela136[[#This Row],[Data]]=$L$6,Tabela136[[#This Row],[Data]]=$L$7),"Não",J12=1,"Não",J12>1,"Sim")} -> Não | D12: 0 | E12: 0 | F12: 0 | G12: 0 | H12: =SUM(Tabela136[[#This Row],[Lig_Água]:[Lig_Esgoto]]) -> 0 | I12: =SUM(Tabela136[[#This Row],[Rede_Água]:[Rede_Esgoto]]) -> 0 | J12: =WEEKDAY(Tabela136[[#This Row],[Data]],1) -> 1
B13: 46069 | C13: {=_xlfn.IFS(OR(Tabela136[[#This Row],[Data]]=$L$5,Tabela136[[#This Row],[Data]]=$L$6,Tabela136[[#This Row],[Data]]=$L$7),"Não",J13=1,"Não",J13>1,"Sim")} -> Não | D13: 0 | E13: 0 | F13: 0 | G13: 16 | H13: =SUM(Tabela136[[#This Row],[Lig_Água]:[Lig_Esgoto]]) -> 0 | I13: =SUM(Tabela136[[#This Row],[Rede_Água]:[Rede_Esgoto]]) -> 16 | J13: =WEEKDAY(Tabela136[[#This Row],[Data]],1) -> 2
B14: 46070 | C14: {=_xlfn.IFS(OR(Tabela136[[#This Row],[Data]]=$L$5,Tabela136[[#This Row],[Data]]=$L$6,Tabela136[[#This Row],[Data]]=$L$7),"Não",J14=1,"Não",J14>1,"Sim")} -> Não | D14: 5 | E14: 0 | F14: 0 | G14: 0 | H14: =SUM(Tabela136[[#This Row],[Lig_Água]:[Lig_Esgoto]]) -> 5 | I14: =SUM(Tabela136[[#This Row],[Rede_Água]:[Rede_Esgoto]]) -> 0 | J14: =WEEKDAY(Tabela136[[#This Row],[Data]],1) -> 3
B15: 46071 | C15: {=_xlfn.IFS(OR(Tabela136[[#This Row],[Data]]=$L$5,Tabela136[[#This Row],[Data]]=$L$6,Tabela136[[#This Row],[Data]]=$L$7),"Não",J15=1,"Não",J15>1,"Sim")} -> Sim | D15: 13 | E15: 0 | F15: 96.9 | G15: 10 | H15: =SUM(Tabela136[[#This Row],[Lig_Água]:[Lig_Esgoto]]) -> 13 | I15: =SUM(Tabela136[[#This Row],[Rede_Água]:[Rede_Esgoto]]) -> 106.9 | J15: =WEEKDAY(Tabela136[[#This Row],[Data]],1) -> 4
B16: 46072 | C16: {=_xlfn.IFS(OR(Tabela136[[#This Row],[Data]]=$L$5,Tabela136[[#This Row],[Data]]=$L$6,Tabela136[[#This Row],[Data]]=$L$7),"Não",J16=1,"Não",J16>1,"Sim")} -> Sim | D16: 0 | E16: 0 | F16: 0 | G16: 0 | H16: =SUM(Tabela136[[#This Row],[Lig_Água]:[Lig_Esgoto]]) -> 0 | I16: =SUM(Tabela136[[#This Row],[Rede_Água]:[Rede_Esgoto]]) -> 0 | J16: =WEEKDAY(Tabela136[[#This Row],[Data]],1) -> 5
B17: 46073 | C17: {=_xlfn.IFS(OR(Tabela136[[#This Row],[Data]]=$L$5,Tabela136[[#This Row],[Data]]=$L$6,Tabela136[[#This Row],[Data]]=$L$7),"Não",J17=1,"Não",J17>1,"Sim")} -> Sim | D17: 0 | E17: 0 | F17: 0 | G17: 16 | H17: =SUM(Tabela136[[#This Row],[Lig_Água]:[Lig_Esgoto]]) -> 0 | I17: =SUM(Tabela136[[#This Row],[Rede_Água]:[Rede_Esgoto]]) -> 16 | J17: =WEEKDAY(Tabela136[[#This Row],[Data]],1) -> 6
B18: 46074 | C18: {=_xlfn.IFS(OR(Tabela136[[#This Row],[Data]]=$L$5,Tabela136[[#This Row],[Data]]=$L$6,Tabela136[[#This Row],[Data]]=$L$7),"Não",J18=1,"Não",J18>1,"Sim")} -> Sim | D18: 0 | E18: 0 | F18: 0 | G18: 0 | H18: =SUM(Tabela136[[#This Row],[Lig_Água]:[Lig_Esgoto]]) -> 0 | I18: =SUM(Tabela136[[#This Row],[Rede_Água]:[Rede_Esgoto]]) -> 0 | J18: =WEEKDAY(Tabela136[[#This Row],[Data]],1) -> 7
B19: 46075 | C19: {=_xlfn.IFS(OR(Tabela136[[#This Row],[Data]]=$L$5,Tabela136[[#This Row],[Data]]=$L$6,Tabela136[[#This Row],[Data]]=$L$7),"Não",J19=1,"Não",J19>1,"Sim")} -> Não | D19: 0 | E19: 0 | F19: 0 | G19: 0 | H19: =SUM(Tabela136[[#This Row],[Lig_Água]:[Lig_Esgoto]]) -> 0 | I19: =SUM(Tabela136[[#This Row],[Rede_Água]:[Rede_Esgoto]]) -> 0 | J19: =WEEKDAY(Tabela136[[#This Row],[Data]],1) -> 1
